Workbook

Sheet INICIO
B2: AUTOEVALUACIÓN CONDICIONES DE HABILITACIÓN RESOLUCIÓN 3100/2019
B12: SERVICIOS | M12: HABILITADO | N12: AUTOEVALUADO | O12: CUMPLIMIENTO
B13: TODOS LOS SERVICIOS | M13: SI | N13: =IF(SUM('TODOS SERVICIOS'!C4:E4)=0,"NO","SI") -> SI | O13: ='TODOS SERVICIOS'!C5 -> 0.27692308
B15: GRUPO: CONSULTA EXTERNA
B16: CONSULTA EXTERNA GENERAL | M16: SI | N16: =IF(SUM('CE GENERAL'!C4:E4)=0,"NO","SI") -> NO | O16: ='CE GENERAL'!C5
B17: CONSULTA EXTERNA ESPECIALIZADA | M17: SI | N17: =IF(SUM('CE ESP'!C4:E4)=0,"NO","SI") -> SI | O17: ='CE ESP'!C5 -> 1
B18: VACUNACIÓN | M18: SI | N18: =IF(SUM(VACUN!C4:E4)=0,"NO","SI") -> NO | O18: =VACUN!C5
B19: SEGURIDAD Y SALUD EN EL TRABAJO | M19: NO | N19: =IF(SUM(SST!C4:E4)=0,"NO","SI") -> NO | O19: =SST!C5
B21: GRUPO: APOYO DIAGNOSTICO
B22: TERAPIAS | M22: SI | N22: =IF(SUM(TERAP!C4:E4)=0,"NO","SI") -> NO | O22: =TERAP!C5
B23: SERVICIO FARMACÉUTICO | M23: SI | N23: =IF(SUM(FARMAC!C4:E4)=0,"NO","SI") -> NO | O23: =FARMAC!C5
B24: RADIOLOGÍA ODONTOLÓGICA | M24: NO | N24: =IF(SUM('RAD ODONT'!C4:E4)=0,"NO","SI") -> SI | O24: ='RAD ODONT'!C5 -> 0.9375
B25: IMÁGENES DIAGNÓSTICAS - METODOS DIAGNÓSTICOS CON IMÁGENES OBTENIDAS MEDIANTE EQUIPOS GENERADORES DE RADIACIONES IONIZANTES | M25: SI | N25: =IF(SUM('IMAG DIAG ION'!C4:E4)=0,"NO","SI") -> NO | O25: ='IMAG DIAG ION'!C5
B26: IMÁGENES DIAGNÓSTICAS - MÉTODOS DIAGNÓSTICOS CON IMÁGENES OBTENIDAS MEDIANTE EQUIPOS GENERADORES DE RADIACIONES NO IONIZANTES | M26: SI | N26: =IF(SUM('IMAG DIAG NO ION'!C4:E4)=0,"NO","SI") -> NO | O26: ='IMAG DIAG NO ION'!C5
B27: MEDICINA NUCLEAR | M27: NO | N27: =IF(SUM('MED NUCL'!C4:E4)=0,"NO","SI") -> NO | O27: ='MED NUCL'!C5
B28: RADIOTERAPIA | M28: NO | N28: =IF(SUM(RADIOT!C4:E4)=0,"NO","SI") -> NO | O28: =RADIOT!C5
B29: QUIMIOTERAPIA | M29: NO | N29: =IF(SUM(QUIMIO!C4:E4)=0,"NO","SI") -> NO | O29: =QUIMIO!C5
B30: DIAGNÓSTICO VASCULAR | M30: SI | N30: =IF(SUM('DX VASC'!C4:E4)=0,"NO","SI") -> NO | O30: ='DX VASC'!C5
B31: HEMODINAMIA E INTERVENCIONISMO | M31: NO | N31: =IF(SUM(HEMOD!C4:E4)=0,"NO","SI") -> NO | O31: =HEMOD!C5
B32: GESTIÓN PRE TRANSFUSIONAL | M32: SI | N32: =IF(SUM(PRETRANS!C4:E4)=0,"NO","SI") -> NO | O32: =PRETRANS!C5
B33: TOMA DE MUESTRAS DE LABORATORIO CLÍNICO | M33: SI | N33: =IF(SUM('T MUEST'!C4:E4)=0,"NO","SI") -> NO | O33: ='T MUEST'!C5
B34: LABORATORIO CLÍNICO | M34: SI | N34: =IF(SUM(LABOR!C4:E4)=0,"NO","SI") -> NO | O34: =LABOR!C5
B35: TOMA DE MUESTRAS DE CUELLO UTERINO Y GINECOLÓGICAS | M35: NO | N35: =IF(SUM('TOMA CITO'!C4:E4)=0,"NO","SI") -> NO | O35: ='TOMA CITO'!C5
B36: LABORATORIO DE CITOLOGÍAS CERVICO-UTERINAS | M36: NO | N36: =IF(SUM('LAB CITO'!C4:E4)=0,"NO","SI") -> NO | O36: ='LAB CITO'!C5
B37: LABORATORIO DE HISTOTECNOLOGÍA | M37: NO | N37: =IF(SUM(HISTO!C4:E4)=0,"NO","SI") -> NO | O37: =HISTO!C5
B38: PATOLOGÍA | M38: NO | N38: =IF(SUM(PATOLO!C4:E4)=0,"NO","SI") -> NO | O38: =PATOLO!C5
B39: DIÁLISIS | M39: NO | N39: =IF(SUM(DIALISIS!C4:E4)=0,"NO","SI") -> NO | O39: =DIALISIS!C5
B41: GRUPO: INTERNACIÓN
B42: HOSPITALIZACIÓN | M42: SI | N42: =IF(SUM(HOSPI!C4:E4)=0,"NO","SI") -> NO | O42: =HOSPI!C5
B43: HOSPITALIZACIÓN PACIENTE CRÓNICO | M43: SI | N43: =IF(SUM('HOSP CRON'!C4:E4)=0,"NO","SI") -> NO | O43: ='HOSP CRON'!C5
B44: CUIDADO BÁSICO NEONATAL | M44: SI | N44: =IF(SUM('NEO BAS'!C4:E4)=0,"NO","SI") -> SI | O44: ='NEO BAS'!C5 -> 0.84126984
B45: CUIDADO INTERMEDIO NEONATAL | M45: SI | N45: =IF(SUM('NEO INTER'!C4:E4)=0,"NO","SI") -> SI | O45: ='NEO INTER'!C5 -> 0.91566265
B46: CUIDADO INTENSIVO NEONATAL | M46: SI | N46: =IF(SUM('NEO INTENS'!C4:E4)=0,"NO","SI") -> SI | O46: ='NEO INTENS'!C5 -> 0.90990991
B47: CUIDADO INTERMEDIO PEDIÁTRICO | M47: NO | N47: =IF(SUM('PED INTER'!C4:E4)=0,"NO","SI") -> NO | O47: ='PED INTER'!C5
B48: CUIDADO INTENSIVO PEDIÁTRICO | M48: NO | N48: =IF(SUM('PED INTENS'!C4:E4)=0,"NO","SI") -> NO | O48: ='PED INTENS'!C5
B49: CUIDADO INTERMEDIO ADULTO | M49: SI | N49: =IF(SUM('ADUL INTER'!C4:E4)=0,"NO","SI") -> NO | O49: ='ADUL INTER'!C5
B50: CUIDADO INTENSIVO ADULTOS | M50: SI | N50: =IF(SUM('ADUL INTENS'!C4:E4)=0,"NO","SI") -> NO | O50: ='ADUL INTENS'!C5
B51: HOSPITALIZACIÓN EN SALUD MENTAL O CONSUMO DE SUSTANCIAS PSICOACTIVAS | M51: NO | N51: =IF(SUM('HOSP SMENTAL'!C4:E4)=0,"NO","SI") -> NO | O51: ='HOSP SMENTAL'!C5
B52: HOSPITALIZACIÓN PARCIAL | M52: NO | N52: =IF(SUM('HOSP PARCIAL'!C4:E4)=0,"NO","SI") -> NO | O52: ='HOSP PARCIAL'!C5
B53: CUIDADO BÁSICO DEL CONSUMO DE SUSTANCIAS PSICOACTIVAS | M53: NO | N53: =IF(SUM('CUID BAS SUST'!D4:E4)=0,"NO","SI") -> NO | O53: ='CUID BAS SUST'!C5
...

Sheet TODOS SERVICIOS
B1: TODOS LOS SERVICIOS CONDICIONES DE HABILITACIÓN RESOLUCIÓN 3100/2019 | O1: ESTADO DE ACCIONES (Número de acciones y % por estado) | S1: ESTADO DE ACCIONES (Número de acciones y % por estado) | W1: ESTADO DE ACCIONES (Número de acciones y % por estado) | AA1: ESTADO DE ACCIONES (Número de acciones y % por estado) | AE1: ESTADO DE ACCIONES (Número de acciones y % por estado) | AI1: ESTADO DE ACCIONES (Número de acciones y % por estado)
O2: SIN INICIAR | P2: =COUNTIFS(Q$10:Q$501,O2) -> 0 | Q2: =IFERROR(P2/SUM(P$2:P$5),"") | S2: SIN INICIAR | T2: =COUNTIFS(U$10:U$501,S2) -> 0 | U2: =IFERROR(T2/SUM(T$2:T$5),"") | W2: SIN INICIAR | X2: =COUNTIFS(Y$10:Y$501,W2) -> 0 | Y2: =IFERROR(X2/SUM(X$2:X$5),"") | AA2: SIN INICIAR | AB2: =COUNTIFS(AC$10:AC$501,AA2) -> 0 | AC2: =IFERROR(AB2/SUM(AB$2:AB$5),"") | AE2: SIN INICIAR | AF2: =COUNTIFS(AG$10:AG$501,AE2) -> 0 | AG2: =IFERROR(AF2/SUM(AF$2:AF$5),"") | AI2: SIN INICIAR | AJ2: =COUNTIFS(AK$10:AK$501,AI2) -> 0 | AK2: =IFERROR(AJ2/SUM(AJ$2:AJ$5),"")
C3: TOTAL CUMPLE | D3: TOTAL NO CUMPLE | E3: TOTAL NO APLICA | O3: EN EJECUCION | P3: =COUNTIFS(Q$10:Q$501,O3) -> 0 | Q3: =IFERROR(P3/SUM(P$2:P$5),"") | S3: EN EJECUCION | T3: =COUNTIFS(U$10:U$501,S3) -> 0 | U3: =IFERROR(T3/SUM(T$2:T$5),"") | W3: EN EJECUCION | X3: =COUNTIFS(Y$10:Y$501,W3) -> 0 | Y3: =IFERROR(X3/SUM(X$2:X$5),"") | AA3: EN EJECUCION | AB3: =COUNTIFS(AC$10:AC$501,AA3) -> 0 | AC3: =IFERROR(AB3/SUM(AB$2:AB$5),"") | AE3: EN EJECUCION | AF3: =COUNTIFS(AG$10:AG$501,AE3) -> 0 | AG3: =IFERROR(AF3/SUM(AF$2:AF$5),"") | AI3: EN EJECUCION | AJ3: =COUNTIFS(AK$10:AK$501,AI3) -> 0 | AK3: =IFERROR(AJ3/SUM(AJ$2:AJ$5),"")
A4: NUMERO DE CRITERIOS EVALUADOS | C4: =COUNTA(G10:G501) -> 18 | D4: =COUNTA(H10:H501) -> 47 | E4: =COUNTA(I10:I501) -> 260 | O4: CERRADA | P4: =COUNTIFS(Q$10:Q$501,O4) -> 0 | Q4: =IFERROR(P4/SUM(P$2:P$5),"") | S4: CERRADA | T4: =COUNTIFS(U$10:U$501,S4) -> 0 | U4: =IFERROR(T4/SUM(T$2:T$5),"") | W4: CERRADA | X4: =COUNTIFS(Y$10:Y$501,W4) -> 0 | Y4: =IFERROR(X4/SUM(X$2:X$5),"") | AA4: CERRADA | AB4: =COUNTIFS(AC$10:AC$501,AA4) -> 0 | AC4: =IFERROR(AB4/SUM(AB$2:AB$5),"") | AE4: CERRADA | AF4: =COUNTIFS(AG$10:AG$501,AE4) -> 0 | AG4: =IFERROR(AF4/SUM(AF$2:AF$5),"") | AI4: CERRADA | AJ4: =COUNTIFS(AK$10:AK$501,AI4) -> 0 | AK4: =IFERROR(AJ4/SUM(AJ$2:AJ$5),"")
A5: CUMPLIMIENTO DEL SERVICIO EVALUADO | C5: =IFERROR(C4/(D4+C4),"") -> 0.27692308 | O5: CANCELADA | P5: =COUNTIFS(Q$10:Q$501,O5) -> 0 | Q5: =IFERROR(P5/SUM(P$2:P$5),"") | S5: CANCELADA | T5: =COUNTIFS(U$10:U$501,S5) -> 0 | U5: =IFERROR(T5/SUM(T$2:T$5),"") | W5: CANCELADA | X5: =COUNTIFS(Y$10:Y$501,W5) -> 0 | Y5: =IFERROR(X5/SUM(X$2:X$5),"") | AA5: CANCELADA | AB5: =COUNTIFS(AC$10:AC$501,AA5) -> 0 | AC5: =IFERROR(AB5/SUM(AB$2:AB$5),"") | AE5: CANCELADA | AF5: =COUNTIFS(AG$10:AG$501,AE5) -> 0 | AG5: =IFERROR(AF5/SUM(AF$2:AF$5),"") | AI5: CANCELADA | AJ5: =COUNTIFS(AK$10:AK$501,AI5) -> 0 | AK5: =IFERROR(AJ5/SUM(AJ$2:AJ$5),"")
O6: TOTAL | P6: =SUM(P2:P5) -> 0 | S6: TOTAL | T6: =SUM(T2:T5) -> 0 | W6: TOTAL | X6: =SUM(X2:X5) -> 0 | AA6: TOTAL | AB6: =SUM(AB2:AB5) -> 0 | AE6: TOTAL | AF6: =SUM(AF2:AF5) -> 0 | AI6: TOTAL | AJ6: =SUM(AJ2:AJ5) -> 0
O8: SEGUIMIENTO 1 - Fecha: 15 noviembre 2020 | S8: SEGUIMIENTO 2 - Fecha: | W8: SEGUIMIENTO 3 - Fecha: | AA8: SEGUIMIENTO 4 - Fecha: | AE8: SEGUIMIENTO 5 - Fecha: | AI8: SEGUIMIENTO 6 - Fecha:
A9: ESTANDAR | B9: MODALIDAD | C9: ARTICULO | D9: SECCIÓN | E9: APARTADO | F9: CRITERIO | G9: CUMPLE | H9: NO CUMPLE | I9: NO APLICA | J9: HALLAZGO | K9: ACCIÓN PARA EL CUMPLIMIENTO | L9: RESPONSABLE | M9: FECHA LIMITE PARA IMPLEMENTAR | O9: SEGUIMIENTO 1 | Q9: ESTADO DE LA ACCIÓN 1 | S9: SEGUIMIENTO 2 | U9: ESTADO DE LA ACCIÓN 2 | W9: SEGUIMIENTO 3 | Y9: ESTADO DE LA ACCIÓN 3 | AA9: SEGUIMIENTO 4 | AC9: ESTADO DE LA ACCIÓN 4 | AE9: SEGUIMIENTO 5 | AG9: ESTADO DE LA ACCIÓN 5 | AI9: SEGUIMIENTO 6 | AK9: ESTADO DE LA ACCIÓN 6
A10: TALENTO HUMANO | B10: Todas las modalidades | C10: 11.1.1 | D10: 1 | F10: El talento humano en salud y otros profesionales que se relacionan con la atención o resultados en salud de los usuarios, cuentan con los títulos, según aplique, de educación superior o certificados de aptitud ocupacional, expedidos por la entidad educativa competente. En el caso de títulos o certificados obtenidos en el extranjero, copia de la resolución de convalidación expedida por el Ministerio de Educación Nacional | H10: X | J10: odontologo -ortodoncia (no cuenta con carnet de vacunas - RETHUS)- auxiliar salud oral(Kenia yibeni mosquera) no cuenta con registro profesional-no cuenta con carnet de vacunas-RETHUS)-auxiliar salud oral (FLORICEL IBASGUE OLAYA)
A11: TALENTO HUMANO | B11: Todas las modalidades | C11: 11.1.1 | D11: 2 | F11: El talento humano en salud cuenta con copia de la resolución de autorización del ejercicio expedido por la autoridad competente o inscripción en el Registro Único Nacional de Talento Humano en Salud -ReTHUS. | H11: X
A12: TALENTO HUMANO | B12: Todas las modalidades | C12: 11.1.1 | D12: 3 | F12: El prestador de servicios de salud determina la cantidad necesaria de talento humano requerido para cada uno de los servicios ofertados y prestados, de acuerdo con la capacidad instalada, la relación entre oferta y demanda, la oportunidad en la prestación, tiempo de la atención y el riesgo en la atención. Este criterio no aplica para el profesional independiente de salud | G12: X | K12: incluir en docuemento de suficiencia de personal y cambiar version | L12: Milena Mesias-Ing Diego | M12: 44264
A13: TALENTO HUMANO | B13: Todas las modalidades | C13: 11.1.1 | D13: 4 | F13: El prestador de servicios de salud que actúe como escenario de práctica formativa en el área de la salud, cuenta con: | I13: X
A14: TALENTO HUMANO | B14: Todas las modalidades | C14: 11.1.1 | D14: 4 | E14: 4.1 | F14: • Convenio vigente con la institución educativa autorizada por la entidad competente. | I14: X
A15: TALENTO HUMANO | B15: Todas las modalidades | C15: 11.1.1 | D15: 4 | E15: 4.2 | F15: • Información documentada de los mecanismos de supervisión permanente del personal en entrenamiento. | I15: X
A16: TALENTO HUMANO | B16: Todas las modalidades | C16: 11.1.1 | D16: 4 | E16: 4.3 | F16: • Estudio de capacidad instalada en el cual se determine el número máximo de estudiantes que simultáneamente puedan acceder por programa de formación y por jornada, para cada uno de los servicios que se utilicen como escenarios de práctica formativa en el área de la salud, estudio que debe ser elaborado teniendo en cuenta los “lineamientos de referencia para la asignación de cupos de estudiantes en escenarios clínicos” publicados por el Ministerio de Salud y Protección Social. | I16: X
A17: TALENTO HUMANO | B17: Todas las modalidades | C17: 11.1.1 | D17: 5 | F17: En los servicios de salud diferentes al servicio de consulta externa especializada de dolor y cuidado paliativo, donde se atienden pacientes con enfermedades terminales, crónicas, degenerativas e irreversibles, a los cuales se les decida como conducta médica; como parte del plan integral de cuidado que gestiona el equipo de salud, o por solicitud del paciente; el manejo del dolor y cuidado paliativo, el profesional de la medicina tratante cuenta con constancia de asistencia en las acciones de formación continua en el manejo del dolor y cuidado paliativo, cuando no sea especialista en dolor y cuidado paliativo | I17: X
A18: TALENTO HUMANO | B18: Todas las modalidades | C18: 11.1.1 | D18: 6 | F18: El talento humano en salud de los servicios de atención del parto, cuidado intensivo y cuidado intermedio neonatal, pediátrico y adultos, cuentan con constancia de asistencia en las acciones de formación continua para la gestión del duelo | I18: X | K18: CAPACITAR AUXILIARES DE ENFERMERIA, ENFERMEROS, TERAPEUTAS, MEDICOS Y ESPECIALISTAS | L18: TALENTO HUMANO/DIR MEDICA | M18: 44265
A19: TALENTO HUMANO | B19: Todas las modalidades | C19: 11.1.1 | D19: 7 | F19: En los servicios de salud donde se realicen imágenes diagnósticas por ultrasonido, cuenta con médico especialista en radiología e imágenes diagnósticas también podrán realizar imágenes diagnosticas aquellos médicos especialistas, quienes en su pensum o formación académica hayan adquirido los conocimientos del manejo e interpretación del espectro electromagnético, del ultrasonido especialmente, así como de las radiaciones ionizantes para establecer el diagnóstico o el tratamiento de las enfermedades inherentes a su especialidad, para lo cual deberá acreditar el respectivo certificado | I19: X
A20: TALENTO HUMANO | B20: Todas las modalidades | C20: 11.1.1 | D20: 8 | F20: Los profesionales de la medicina de los servicios de hospitalización de baja, mediana y alta complejidad, hospitalización paciente crónico con y sin ventilador, cuidados intensivos neonatales, pediátricos y adultos; urgencias y servicios del grupo quirúrgico en modalidad intramural, cuentan con certificación vigente de aprobación de la evaluación de competencias esenciales para el cuidado de la donante expedida por el Instituto Nacional de Salud | I20: X
A21: TALENTO HUMANO | B21: Todas las modalidades | C21: 11.1.1 | D21: 9 | F21: Las Instituciones Prestadoras de Servicios de Salud con servicios de cuidado intensivo pediátrico y adulto que adicionalmente habiliten el servicio quirúrgico de neurocirugía, tienen disponibilidad de coordinador operativo de trasplantes | I21: X
A22: TALENTO HUMANO | B22: Todas las modalidades | C22: 11.1.1 | D22: 10 | F22: El talento humano en salud de los servicios de salud de los grupos de consulta externa, internación y el servicio de urgencias, cuentan con constancia de asistencia en las acciones de formación continua en la atención integral en salud de las personas víctimas de violencia sexual | H22: X | J22: REALIZARLO LOS DOS PROFESIONALES
A23: TALENTO HUMANO | B23: Todas las modalidades | C23: 11.1.1 | D23: 11 | F23: El talento humano en salud de los servicios de transporte asistencial, atención prehospitalaria y urgencias, cuentan con constancia de asistencia en las acciones de formación continua en la atención a personas víctimas de ataques con agentes químicos | I23: X
A24: TALENTO HUMANO | B24: Todas las modalidades | C24: 11.1.1 | D24: 12 | F24: Cuando en un servicio de salud se realicen “pruebas en el punto de atención del paciente – (Point of Care Testing –POCT)”, el talento humano en salud que las realice, con excepción del profesional de bacteriología cuenta con constancia de asistencia en las acciones de formación continua en el manejo de estas pruebas | I24: X
A25: TALENTO HUMANO | B25: Todas las modalidades | C25: 11.1.1 | D25: 13 | F25: Procedimientos bajo sedación
A26: TALENTO HUMANO | B26: Todas las modalidades | C26: 11.1.1 | D26: 13 | E26: 13.1 | F26: • Cuando fuera de salas de cirugía se realicen procedimientos bajo sedación Grado I y II, adicional al profesional de salud que realiza el procedimiento, cuenta con: | I26: X
A27: TALENTO HUMANO | B27: Todas las modalidades | C27: 11.1.1 | D27: 13 | E27: 13.1.1 | F27: • Profesional de la medicina especialista en anestesiología, o profesional de la medicina o profesional de la odontología, según aplique, el cual será el encargado de administrar el medicamento y realizar el monitoreo continuo del paciente (registro de signos vitales y la respuesta a la sedación). | I27: X
A28: TALENTO HUMANO | B28: Todas las modalidades | C28: 11.1.1 | D28: 13 | E28: 13.1.2 | F28: • Todos los profesionales, a excepción del profesional de la medicina especialista en anestesiología, deben demostrar constancia de asistencia a curso de formación continua en soporte vital básico y sedación. | I28: X
A29: TALENTO HUMANO | B29: Todas las modalidades | C29: 11.1.1 | D29: 13 | E29: 13.1.3 | F29: • Para sedación con óxido nitroso en odontología, el profesional de la odontología cuenta con constancia de asistencia en las acciones de formación continua para el uso clínico y práctico de este gas. | I29: X
A30: TALENTO HUMANO | B30: Todas las modalidades | C30: 11.1.1 | D30: 13 | E30: 13.2 | F30: • Cuando fuera de salas de cirugía, se realicen procedimientos bajo sedación Grado III, adicional al profesional de salud que realiza el procedimiento, cuenta con profesional de la medicina con especialidad médico - quirúrgica, quien será el responsable de administrar la sedación. | I30: X
A31: TALENTO HUMANO | B31: Todas las modalidades | C31: 11.1.1 | D31: 13 | E31: 13.3 | F31: • Cuando fuera de salas de cirugía, se realicen procedimientos bajo sedación Grado IV, adicional al profesional de salud que realiza el procedimiento, cuenta con profesional de la medicina especialista en anestesiología, quien será el responsable de administrar la sedación | I31: X
A32: TALENTO HUMANO | B32: Todas las modalidades | C32: 11.1.1 | D32: 13 | E32: 13.4 | F32: • Cuenta con profesional de la medicina especialista en anestesiología cuando la atención se trate de pacientes con características particulares: poco colaboradores; edades extremas; con enfermedades severas: cardíacas, pulmonares, hepáticas, renales o del sistema nervioso central; cualquier alteración del grado de consciencia, con obesidad mórbida, con apnea del sueño, embarazadas, o quienes abusan del alcohol o de las drogas; antecedentes de sedación fallida o que presentaron efectos adversos a algún medicamento utilizado en la sedación, por tener un elevado riesgo de desarrollar complicaciones relacionadas con la sedación o analgesia. | I32: X
A33: TALENTO HUMANO | B33: Modalidad de telemedicina prestador remisor - prestador de referencia | C33: 11.1.1 | D33: 14 | F33: Adicional a los criterios del estándar de talento humano enunciados que le aplique, el talento humano en salud que presta directamente un servicio de salud bajo la modalidad de telemedicina cuenta con constancia de asistencia en las acciones de formación continua en el manejo de la tecnología utilizada por el prestador, los procesos y herramientas inherentes a la prestación de servicios bajo esta modalidad. | I33: X
A34: INFRAESTRUCTURA | B34: Edificaciones de uso exclusivo en salud | C34: 11.1.2 | D34: 1 | F34: Los servicios de salud de urgencias, de atención del parto, hospitalarios y de cirugía que realicen procedimientos quirúrgicos no ambulatorios, solo se pueden prestar en edificaciones de uso exclusivo de salud. | I34: X
A35: INFRAESTRUCTURA | B35: Edificaciones de uso exclusivo en salud | C35: 11.1.2 | D35: 2 | F35: Los servicios de salud de: urgencias, cirugía y del grupo de internación, así como en los servicios de salud donde se realice el proceso de esterilización, deben contar con ambiente de aseo de uso exclusivo | I35: X
A36: INFRAESTRUCTURA | B36: Edificaciones de uso exclusivo en salud | C36: 11.1.2 | D36: 3 | F36: Cuando en una edificación de uso exclusivo de salud funcione más de un prestador de servicios de salud con servicios de los grupos de consulta externa y apoyo diagnóstico y complementación terapéutica, cada prestador cuenta con infraestructura separada y delimitada físicamente. Se pueden compartir los siguientes ambientes y áreas: aseo, salas de espera y unidades sanitarias. | G36: X
A37: INFRAESTRUCTURA | B37: Edificaciones de uso exclusivo en salud | C37: 11.1.2 | D37: 4 | F37: Las edificaciones donde se presten servicios de salud de urgencias y del grupo de internación, cuentan con tanque de almacenamiento de agua para el consumo humano que garantice como mínimo una reserva de 24 horas de servicio continuo, calculado con base en el consumo de 600 lt por cama/camilla día | I37: X
A38: INFRAESTRUCTURA | B38: Edificaciones de uso exclusivo en salud | C38: 11.1.2 | D38: 5 | F38: Cuando el prestador de servicios de salud cuente con más de una infraestructura y estas se puedan vincular funcionalmente entre sí, lo harán mediante túnel o puente cubierto, o muro(s) colindante(s) que cuente(n) con acceso(s) que intercomunique(n) las infraestructuras, de uso exclusivo del prestador y adicionalmente cumplen con las siguientes características: | I38: X
A39: INFRAESTRUCTURA | B39: Edificaciones de uso exclusivo en salud | C39: 11.1.2 | D39: 5 | E39: 5.1 | F39: • Ancho que permita la movilización de camas, camillas, sillas de ruedas, equipos biomédicos y personal para el traslado de los pacientes en condiciones seguras. | I39: X
A40: INFRAESTRUCTURA | B40: Edificaciones de uso exclusivo en salud | C40: 11.1.2 | D40: 5 | E40: 5.2 | F40: • El piso del túnel o puente debe ser uniforme y de material antideslizante o con elementos que garanticen esta propiedad en todo su recorrido, con pasamanos a ambos lados y con protecciones laterales hacia espacios libres | I40: X
A41: INFRAESTRUCTURA | B41: Edificaciones de uso exclusivo en salud | C41: 11.1.2 | D41: 5 | E41: 5.3 | F41: • Lo anterior siempre y cuando la norma urbanística de la jurisdicción donde se localizan las sedes haya aprobado esta forma de vinculación funcional entre las mismas | I41: X
...

Sheet CE GENERAL
B1: CONSULTA EXTERNA GENERAL CONDICIONES DE HABILITACIÓN RESOLUCIÓN 3100/2019 | P1: ESTADO DE ACCIONES (Número de acciones y % por estado) | T1: ESTADO DE ACCIONES (Número de acciones y % por estado) | X1: ESTADO DE ACCIONES (Número de acciones y % por estado) | AB1: ESTADO DE ACCIONES (Número de acciones y % por estado) | AF1: ESTADO DE ACCIONES (Número de acciones y % por estado) | AJ1: ESTADO DE ACCIONES (Número de acciones y % por estado)
P2: SIN INICIAR | Q2: =COUNTIFS(R$10:R$501,P2) -> 0 | R2: =IFERROR(Q2/SUM(Q$2:Q$5),"") | T2: SIN INICIAR | U2: =COUNTIFS(V$10:V$501,T2) -> 0 | V2: =IFERROR(U2/SUM(U$2:U$5),"") | X2: SIN INICIAR | Y2: =COUNTIFS(Z$10:Z$501,X2) -> 0 | Z2: =IFERROR(Y2/SUM(Y$2:Y$5),"") | AB2: SIN INICIAR | AC2: =COUNTIFS(AD$10:AD$501,AB2) -> 0 | AD2: =IFERROR(AC2/SUM(AC$2:AC$5),"") | AF2: SIN INICIAR | AG2: =COUNTIFS(AH$10:AH$501,AF2) -> 0 | AH2: =IFERROR(AG2/SUM(AG$2:AG$5),"") | AJ2: SIN INICIAR | AK2: =COUNTIFS(AL$10:AL$501,AJ2) -> 0 | AL2: =IFERROR(AK2/SUM(AK$2:AK$5),"")
C3: TOTAL CUMPLE | D3: TOTAL NO CUMPLE | E3: TOTAL NO APLICA | P3: EN EJECUCION | Q3: =COUNTIFS(R$10:R$501,P3) -> 0 | R3: =IFERROR(Q3/SUM(Q$2:Q$5),"") | T3: EN EJECUCION | U3: =COUNTIFS(V$10:V$501,T3) -> 0 | V3: =IFERROR(U3/SUM(U$2:U$5),"") | X3: EN EJECUCION | Y3: =COUNTIFS(Z$10:Z$501,X3) -> 0 | Z3: =IFERROR(Y3/SUM(Y$2:Y$5),"") | AB3: EN EJECUCION | AC3: =COUNTIFS(AD$10:AD$501,AB3) -> 0 | AD3: =IFERROR(AC3/SUM(AC$2:AC$5),"") | AF3: EN EJECUCION | AG3: =COUNTIFS(AH$10:AH$501,AF3) -> 0 | AH3: =IFERROR(AG3/SUM(AG$2:AG$5),"") | AJ3: EN EJECUCION | AK3: =COUNTIFS(AL$10:AL$501,AJ3) -> 0 | AL3: =IFERROR(AK3/SUM(AK$2:AK$5),"")
A4: NUMERO DE CRITERIOS EVALUADOS | C4: =COUNTA(H10:H115) -> 0 | D4: =COUNTA(I10:I115) -> 0 | E4: =COUNTA(J10:J115) -> 0 | P4: CERRADA | Q4: =COUNTIFS(R$10:R$501,P4) -> 0 | R4: =IFERROR(Q4/SUM(Q$2:Q$5),"") | T4: CERRADA | U4: =COUNTIFS(V$10:V$501,T4) -> 0 | V4: =IFERROR(U4/SUM(U$2:U$5),"") | X4: CERRADA | Y4: =COUNTIFS(Z$10:Z$501,X4) -> 0 | Z4: =IFERROR(Y4/SUM(Y$2:Y$5),"") | AB4: CERRADA | AC4: =COUNTIFS(AD$10:AD$501,AB4) -> 0 | AD4: =IFERROR(AC4/SUM(AC$2:AC$5),"") | AF4: CERRADA | AG4: =COUNTIFS(AH$10:AH$501,AF4) -> 0 | AH4: =IFERROR(AG4/SUM(AG$2:AG$5),"") | AJ4: CERRADA | AK4: =COUNTIFS(AL$10:AL$501,AJ4) -> 0 | AL4: =IFERROR(AK4/SUM(AK$2:AK$5),"")
A5: CUMPLIMIENTO DEL SERVICIO EVALUADO | C5: =IFERROR(C4/(D4+C4),"") | P5: CANCELADA | Q5: =COUNTIFS(R$10:R$501,P5) -> 0 | R5: =IFERROR(Q5/SUM(Q$2:Q$5),"") | T5: CANCELADA | U5: =COUNTIFS(V$10:V$501,T5) -> 0 | V5: =IFERROR(U5/SUM(U$2:U$5),"") | X5: CANCELADA | Y5: =COUNTIFS(Z$10:Z$501,X5) -> 0 | Z5: =IFERROR(Y5/SUM(Y$2:Y$5),"") | AB5: CANCELADA | AC5: =COUNTIFS(AD$10:AD$501,AB5) -> 0 | AD5: =IFERROR(AC5/SUM(AC$2:AC$5),"") | AF5: CANCELADA | AG5: =COUNTIFS(AH$10:AH$501,AF5) -> 0 | AH5: =IFERROR(AG5/SUM(AG$2:AG$5),"") | AJ5: CANCELADA | AK5: =COUNTIFS(AL$10:AL$501,AJ5) -> 0 | AL5: =IFERROR(AK5/SUM(AK$2:AK$5),"")
P6: TOTAL | Q6: =SUM(Q2:Q5) -> 0 | T6: TOTAL | U6: =SUM(U2:U5) -> 0 | X6: TOTAL | Y6: =SUM(Y2:Y5) -> 0 | AB6: TOTAL | AC6: =SUM(AC2:AC5) -> 0 | AF6: TOTAL | AG6: =SUM(AG2:AG5) -> 0 | AJ6: TOTAL | AK6: =SUM(AK2:AK5) -> 0
P8: SEGUIMIENTO 1 - Fecha: | T8: SEGUIMIENTO 2 - Fecha: | X8: SEGUIMIENTO 3 - Fecha: | AB8: SEGUIMIENTO 4 - Fecha: | AF8: SEGUIMIENTO 5 - Fecha: | AJ8: SEGUIMIENTO 6 - Fecha:
A9: ESTANDAR | B9: COMPLEJIDAD | C9: MODALIDAD | D9: ARTICULO | E9: SECCIÓN | F9: APARTADO | G9: CRITERIO | H9: CUMPLE | I9: NO CUMPLE | J9: NO APLICA | K9: HALLAZGOS | M9: ACCIÓN PARA EL CUMPLIMIENTO | N9: RESPONSABLE | O9: FECHA LIMITE PARA IMPLEMENTAR | P9: SEGUIMIENTO 1 | R9: ESTADO DE LA ACCIÓN 1 | T9: SEGUIMIENTO 2 | V9: ESTADO DE LA ACCIÓN 2 | X9: SEGUIMIENTO 3 | Z9: ESTADO DE LA ACCIÓN 3 | AB9: SEGUIMIENTO 4 | AD9: ESTADO DE LA ACCIÓN 4 | AF9: SEGUIMIENTO 5 | AH9: ESTADO DE LA ACCIÓN 5 | AJ9: SEGUIMIENTO 6 | AL9: ESTADO DE LA ACCIÓN 6
A10: TALENTO HUMANO | B10: Baja | C10: Modalidades intramural, extramural unidad móvil, jornada de salud y domiciliaria | D10: 11.2.1 | E10: 1 | F10: 1 | G10: Cumple con los criterios que le sean aplicables de todos los servicios y adicionalmente,
A11: TALENTO HUMANO | B11: Baja | C11: Modalidades intramural, extramural unidad móvil, jornada de salud y domiciliaria | D11: 11.2.1 | E11: 2 | F11: 2 | G11: Cuenta con el profesional de la salud de acuerdo con el servicio a ofertar.
A12: TALENTO HUMANO | B12: Baja | C12: Modalidades intramural, extramural unidad móvil, jornada de salud y domiciliaria | D12: 11.2.1 | E12: 3 | F12: 3 | G12: Cuando se oferte la estrategia para el manejo de la Enfermedad Respiratoria Aguda (ERA), el servicio tiene disponibilidad de:
A13: TALENTO HUMANO | B13: Baja | C13: Modalidades intramural, extramural unidad móvil, jornada de salud y domiciliaria | D13: 11.2.1 | E13: 3 | F13: 3.1 | G13: • Profesional de la medicina.
A14: TALENTO HUMANO | B14: Baja | C14: Modalidades intramural, extramural unidad móvil, jornada de salud y domiciliaria | D14: 11.2.1 | E14: 3 | F14: 3.2 | G14: • Profesional de la enfermería o terapia respiratoria o fisioterapia.
A15: TALENTO HUMANO | B15: Baja | C15: Modalidad telemedicina: Categoría interactiva y no interactiva – prestador de referencia | D15: 11.2.1 | E15: 4 | G15: Cumple con los criterios que le sean aplicables de todos los servicios y adicionalmente, cuenta con:
A16: TALENTO HUMANO | B16: Baja | C16: Modalidad telemedicina: Categoría interactiva y no interactiva – prestador de referencia | D16: 11.2.1 | E16: 4 | F16: 4.1 | G16: • Profesional de la salud de acuerdo con el servicio a ofertar.
A17: TALENTO HUMANO | B17: Baja | C17: Modalidad telemedicina: Categoría telexperticia - prestador remisor | D17: 11.2.1 | E17: 5 | G17: Cumple con los criterios que le sean aplicables de todos los servicios y adicionalmente:
A18: TALENTO HUMANO | B18: Baja | C18: Modalidad telemedicina: Categoría telexperticia - prestador remisor | D18: 11.2.1 | E18: 5 | F18: 5.1 | G18: • Cuando se realice telexperticia entre profesionales de la salud cuenta con el profesional de la salud de acuerdo con el servicio a ofertar.
A19: TALENTO HUMANO | B19: Baja | C19: Modalidad telemedicina: Categoría telexperticia - prestador remisor | D19: 11.2.1 | E19: 5 | F19: 5.2 | G19: • Cuando realice telexperticia entre personal de salud no profesional y un profesional de la salud, el prestador remisor cuenta con técnico, tecnólogo o auxiliar que atiende presencialmente al usuario.
A20: TALENTO HUMANO | B20: Baja | C20: Modalidad telemedicina: Categoría telexperticia - prestador de referencia | D20: 11.2.1 | E20: 6 | G20: Cumple con los criterios que le sean aplicables de todos los servicios y adicionalmente cuenta con profesional de la salud que atiende a distancia, de acuerdo con el servicio a ofertar
A21: TALENTO HUMANO | B21: Baja | C21: Modalidad telemedicina: Categoría telemonitoreo - prestador de referencia | D21: 11.2.1 | E21: 7 | G21: Cumple con los criterios que le sean aplicables de todos los servicios y adicionalmente cuenta con el personal de salud profesional que se requiera para realizar el telemonitoreo de acuerdo con lo documentado por el prestador de servicios de salud en el estándar de procesos prioritarios
A22: INFRAESTRUCTURA | B22: Baja | C22: Modalidad intramural | D22: 11.2.1 | E22: 8 | G22: Cumple con los criterios que le sean aplicables de todos los servicios y adicionalmente,
A23: INFRAESTRUCTURA | B23: Baja | C23: Modalidad intramural | D23: 11.2.1 | E23: 9 | G23: Cuenta con:
A24: INFRAESTRUCTURA | B24: Baja | C24: Modalidad intramural | D24: 11.2.1 | E24: 9 | F24: 9.1 | G24: • El tipo de ambiente o consultorio de acuerdo con la oferta, así:
A25: INFRAESTRUCTURA | B25: Baja | C25: Modalidad intramural | D25: 11.2.1 | E25: 9 | F25: 9.1.1 | G25: • Consultorio donde se realiza examen físico.
A26: INFRAESTRUCTURA | B26: Baja | C26: Modalidad intramural | D26: 11.2.1 | E26: 9 | F26: 9.1.2 | G26: • Ambiente de entrevista donde no se realiza examen físico ni procedimientos.
A27: INFRAESTRUCTURA | B27: Baja | C27: Modalidad intramural | D27: 11.2.1 | E27: 9 | F27: 9.1.3 | G27: • Consultorio donde se realizan procedimientos.
A28: INFRAESTRUCTURA | B28: Baja | C28: Modalidad intramural | D28: 11.2.1 | E28: 9 | F28: 9.1.4 | G28: • Consultorio odontológico con una unidad odontológica o más.
A29: INFRAESTRUCTURA | B29: Baja | C29: Modalidad intramural | D29: 11.2.1 | E29: 9 | F29: 9.2 | G29: • Sala de procedimientos, cuando se requiera.
A30: INFRAESTRUCTURA | B30: Baja | C30: Modalidad intramural | D30: 11.2.1 | E30: 10 | G30: Disponibilidad de:
A31: INFRAESTRUCTURA | B31: Baja | C31: Modalidad intramural | D31: 11.2.1 | E31: 10 | F31: 10.1 | G31: • Sala de espera.
A32: INFRAESTRUCTURA | B32: Baja | C32: Modalidad intramural | D32: 11.2.1 | E32: 10 | F32: 10.2 | G32: Mínimo una (1) unidad sanitaria de uso mixto, apta para personas con movilidad reducida, cuando el prestador cuente con hasta dos consultorios o ambientes de entrevista.
A33: INFRAESTRUCTURA | B33: Baja | C33: Modalidad intramural | D33: 11.2.1 | E33: 10 | F33: 10.3 | G33: • Mínimo una (1) unidad sanitaria discriminada por sexo apta para personas con movilidad reducida, o batería sanitaria discriminada por sexo con mínimo una (1) unidad sanitaria apta para personas con movilidad reducida, cuando el prestador cuente con más de dos consultorios o ambientes de entrevista.
A34: INFRAESTRUCTURA | B34: Baja | C34: Modalidad intramural | D34: 11.2.1 | E34: 11 | G34: Cuando se oferte la estrategia para el manejo de la Enfermedad Respiratoria Aguda (ERA), el ambiente cuenta con:
A35: INFRAESTRUCTURA | B35: Baja | C35: Modalidad intramural | D35: 11.2.1 | E35: 11 | F35: 11.1 | G35: • Lavamanos.
A36: INFRAESTRUCTURA | B36: Baja | C36: Modalidad intramural | D36: 11.2.1 | E36: 11 | F36: 11.2 | G36: • Mesón de trabajo.
A37: INFRAESTRUCTURA | B37: Baja | C37: Modalidad intramural | D37: 11.2.1 | E37: 11 | F37: 11.3 | G37: • Poceta, cuando la requiera, según los procedimientos que documente.
A38: INFRAESTRUCTURA | B38: Baja | C38: Modalidad intramural | D38: 11.2.1 | E38: 11 | F38: 11.4 | G38: • Barrera física móvil o fija, para separación entre sillas.
A39: INFRAESTRUCTURA | B39: Baja | C39: Modalidad intramural | D39: 11.2.1 | E39: 12 | G39: Cuando se realicen terapias e intervenciones grupales para la atención de personas con consumo de sustancias psicoactivas o alteraciones en salud mental, cuenta con ambiente con dimensión variable para su realización.
A40: INFRAESTRUCTURA | B40: Baja | C40: Modalidad intramural | D40: 11.2.1 | E40: 13 | G40: Cuando se realicen actividades grupales de educación para la salud, tiene disponibilidad de un ambiente con dimensión variable
A41: INFRAESTRUCTURA | B41: Baja | C41: Modalidad extramural: unidad móvil, jornada de salud, y domiciliaria | D41: 11.2.1 | E41: 14 | G41: Cumple con los criterios que le sean aplicables de todos los servicios
...

Sheet CE ESP
B1: CONSULTA EXTERNA ESPECIALIZADA CONDICIONES DE HABILITACIÓN RESOLUCIÓN 3100/2019 | P1: ESTADO DE ACCIONES (Número de acciones y % por estado) | T1: ESTADO DE ACCIONES (Número de acciones y % por estado) | X1: ESTADO DE ACCIONES (Número de acciones y % por estado) | AB1: ESTADO DE ACCIONES (Número de acciones y % por estado) | AF1: ESTADO DE ACCIONES (Número de acciones y % por estado) | AJ1: ESTADO DE ACCIONES (Número de acciones y % por estado)
P2: SIN INICIAR | Q2: =COUNTIFS(R$10:R$501,P2) -> 0 | R2: =IFERROR(Q2/SUM(Q$2:Q$5),"") | T2: SIN INICIAR | U2: =COUNTIFS(V$10:V$501,T2) -> 0 | V2: =IFERROR(U2/SUM(U$2:U$5),"") | X2: SIN INICIAR | Y2: =COUNTIFS(Z$10:Z$501,X2) -> 0 | Z2: =IFERROR(Y2/SUM(Y$2:Y$5),"") | AB2: SIN INICIAR | AC2: =COUNTIFS(AD$10:AD$501,AB2) -> 0 | AD2: =IFERROR(AC2/SUM(AC$2:AC$5),"") | AF2: SIN INICIAR | AG2: =COUNTIFS(AH$10:AH$501,AF2) -> 0 | AH2: =IFERROR(AG2/SUM(AG$2:AG$5),"") | AJ2: SIN INICIAR | AK2: =COUNTIFS(AL$10:AL$501,AJ2) -> 0 | AL2: =IFERROR(AK2/SUM(AK$2:AK$5),"")
C3: TOTAL CUMPLE | D3: TOTAL NO CUMPLE | E3: TOTAL NO APLICA | P3: EN EJECUCION | Q3: =COUNTIFS(R$10:R$501,P3) -> 0 | R3: =IFERROR(Q3/SUM(Q$2:Q$5),"") | T3: EN EJECUCION | U3: =COUNTIFS(V$10:V$501,T3) -> 0 | V3: =IFERROR(U3/SUM(U$2:U$5),"") | X3: EN EJECUCION | Y3: =COUNTIFS(Z$10:Z$501,X3) -> 0 | Z3: =IFERROR(Y3/SUM(Y$2:Y$5),"") | AB3: EN EJECUCION | AC3: =COUNTIFS(AD$10:AD$501,AB3) -> 0 | AD3: =IFERROR(AC3/SUM(AC$2:AC$5),"") | AF3: EN EJECUCION | AG3: =COUNTIFS(AH$10:AH$501,AF3) -> 0 | AH3: =IFERROR(AG3/SUM(AG$2:AG$5),"") | AJ3: EN EJECUCION | AK3: =COUNTIFS(AL$10:AL$501,AJ3) -> 0 | AL3: =IFERROR(AK3/SUM(AK$2:AK$5),"")
A4: NUMERO DE CRITERIOS EVALUADOS | C4: =COUNTA(H10:H47) -> 2 | D4: =COUNTA(I10:I47) -> 0 | E4: =COUNTA(J10:J47) -> 5 | P4: CERRADA | Q4: =COUNTIFS(R$10:R$501,P4) -> 0 | R4: =IFERROR(Q4/SUM(Q$2:Q$5),"") | T4: CERRADA | U4: =COUNTIFS(V$10:V$501,T4) -> 0 | V4: =IFERROR(U4/SUM(U$2:U$5),"") | X4: CERRADA | Y4: =COUNTIFS(Z$10:Z$501,X4) -> 0 | Z4: =IFERROR(Y4/SUM(Y$2:Y$5),"") | AB4: CERRADA | AC4: =COUNTIFS(AD$10:AD$501,AB4) -> 0 | AD4: =IFERROR(AC4/SUM(AC$2:AC$5),"") | AF4: CERRADA | AG4: =COUNTIFS(AH$10:AH$501,AF4) -> 0 | AH4: =IFERROR(AG4/SUM(AG$2:AG$5),"") | AJ4: CERRADA | AK4: =COUNTIFS(AL$10:AL$501,AJ4) -> 0 | AL4: =IFERROR(AK4/SUM(AK$2:AK$5),"")
A5: CUMPLIMIENTO DEL SERVICIO EVALUADO | C5: =IFERROR(C4/(D4+C4),"") -> 1 | P5: CANCELADA | Q5: =COUNTIFS(R$10:R$501,P5) -> 0 | R5: =IFERROR(Q5/SUM(Q$2:Q$5),"") | T5: CANCELADA | U5: =COUNTIFS(V$10:V$501,T5) -> 0 | V5: =IFERROR(U5/SUM(U$2:U$5),"") | X5: CANCELADA | Y5: =COUNTIFS(Z$10:Z$501,X5) -> 0 | Z5: =IFERROR(Y5/SUM(Y$2:Y$5),"") | AB5: CANCELADA | AC5: =COUNTIFS(AD$10:AD$501,AB5) -> 0 | AD5: =IFERROR(AC5/SUM(AC$2:AC$5),"") | AF5: CANCELADA | AG5: =COUNTIFS(AH$10:AH$501,AF5) -> 0 | AH5: =IFERROR(AG5/SUM(AG$2:AG$5),"") | AJ5: CANCELADA | AK5: =COUNTIFS(AL$10:AL$501,AJ5) -> 0 | AL5: =IFERROR(AK5/SUM(AK$2:AK$5),"")
P6: TOTAL | Q6: =SUM(Q2:Q5) -> 0 | T6: TOTAL | U6: =SUM(U2:U5) -> 0 | X6: TOTAL | Y6: =SUM(Y2:Y5) -> 0 | AB6: TOTAL | AC6: =SUM(AC2:AC5) -> 0 | AF6: TOTAL | AG6: =SUM(AG2:AG5) -> 0 | AJ6: TOTAL | AK6: =SUM(AK2:AK5) -> 0
P8: SEGUIMIENTO 1 - Fecha: | T8: SEGUIMIENTO 2 - Fecha: | X8: SEGUIMIENTO 3 - Fecha: | AB8: SEGUIMIENTO 4 - Fecha: | AF8: SEGUIMIENTO 5 - Fecha: | AJ8: SEGUIMIENTO 6 - Fecha:
A9: ESTANDAR | B9: COMPLEJIDAD | C9: MODALIDAD | D9: ARTICULO | E9: SECCIÓN | F9: APARTADO | G9: CRITERIO | H9: CUMPLE | I9: NO CUMPLE | J9: NO APLICA | K9: HALLAZGOS | M9: ACCIÓN PARA EL CUMPLIMIENTO | N9: RESPONSABLE | O9: FECHA LIMITE PARA IMPLEMENTAR | P9: SEGUIMIENTO 1 | R9: ESTADO DE LA ACCIÓN 1 | T9: SEGUIMIENTO 2 | V9: ESTADO DE LA ACCIÓN 2 | X9: SEGUIMIENTO 3 | Z9: ESTADO DE LA ACCIÓN 3 | AB9: SEGUIMIENTO 4 | AD9: ESTADO DE LA ACCIÓN 4 | AF9: SEGUIMIENTO 5 | AH9: ESTADO DE LA ACCIÓN 5 | AJ9: SEGUIMIENTO 6 | AL9: ESTADO DE LA ACCIÓN 6
A10: TALENTO HUMANO | B10: Mediana | C10: Modalidades intramural, extramural unidad móvil, jornada de salud y domiciliaria | D10: 11.2.2 | E10: 1 | G10: Cumple con los criterios definidos para el servicio de consulta externa general y adicionalmente cuenta con:
A11: TALENTO HUMANO | B11: Mediana | C11: Modalidades intramural, extramural unidad móvil, jornada de salud y domiciliaria | D11: 11.2.2 | E11: 1 | F11: 1.1 | G11: • Profesional de la salud con título de especialista, según los programas académicos autorizados por el Ministerio de Educación Nacional.
A12: TALENTO HUMANO | B12: Mediana | C12: Modalidades intramural, extramural unidad móvil, jornada de salud y domiciliaria | D12: 11.2.2 | E12: 1 | F12: 1.2 | G12: • Para medicina alternativa y terapias alternativas y complementarias, cuenta con profesional de la salud con título de especialista en el ámbito de su disciplina, para lo cual deberá acreditar la respectiva certificación académica de esa norma de competencia, expedida por una institución de educación superior legalmente reconocida por el Estado y de acuerdo con lo documentado por el prestador de servicios de salud en el estándar de procesos prioritarios.
A13: TALENTO HUMANO | B13: Mediana | C13: Modalidad telemedicina: Categoría interactiva y no interactiva – prestador de referencia | D13: 11.2.2 | E13: 2 | G13: Cumple con los criterios que le sean aplicables de todos los servicios y adicionalmente, cuenta con: Profesional de la salud con título de especialista de acuerdo con el servicio a ofertar.
A14: TALENTO HUMANO | B14: Mediana | C14: Modalidad telemedicina: Categoría telexperticia - prestador remisor | D14: 11.2.2 | E14: 3 | G14: Cumple con los criterios que le sean aplicables de todos los servicios y adicionalmente
A15: TALENTO HUMANO | B15: Mediana | C15: Modalidad telemedicina: Categoría telexperticia - prestador remisor | D15: 11.2.2 | E15: 3 | F15: 3.1 | G15: • Cuando se realice telexperticia entre profesionales de la salud cuenta con el profesional de la salud con título de especialista de acuerdo con el servicio a ofertar.
A16: TALENTO HUMANO | B16: Mediana | C16: Modalidad telemedicina: Categoría telexperticia - prestador remisor | D16: 11.2.2 | E16: 3 | F16: 3.2 | G16: • Cuando realice telexperticia entre personal de salud no profesional y un profesional de la salud con título de especialista, el prestador remisor cuenta con técnico, tecnólogo o auxiliar que atiende presencialmente al usuario.
A17: TALENTO HUMANO | B17: Mediana | C17: Modalidad telemedicina: Categoría telexperticia - prestador de referencia | D17: 11.2.2 | E17: 4 | G17: Cumple con los criterios que le sean aplicables de todos los servicios y adicionalmente cuenta con profesional de la salud con título de especialista que atiende a distancia, de acuerdo con el servicio a ofertar
A18: TALENTO HUMANO | B18: Mediana | C18: Modalidad telemedicina: Categoría telemonitoreo - prestador de referencia | D18: 11.2.2 | E18: 5 | G18: Cumple con los criterios que le sean aplicables de todos los servicios y adicionalmente cuenta con el personal de salud profesional con título de especialista que se requiera para realizar el telemonitoreo de acuerdo con lo documentado por el prestador de servicios de salud en el estándar de procesos prioritarios
A19: INFRAESTRUCTURA | B19: Mediana | C19: Modalidad intramural | D19: 11.2.2 | E19: 6 | G19: Cumple con los criterios definidos para el servicio de consulta externa general, de acuerdo con la oferta.
A20: INFRAESTRUCTURA | B20: Mediana | C20: Modalidad intramural | D20: 11.2.2 | E20: 7 | G20: El consultorio de las especialidades de ginecoobstetricia y urología, cuentan con unidad sanitaria.
A21: INFRAESTRUCTURA | B21: Mediana | C21: Modalidad extramural: unidad móvil, jornada de salud, y domiciliaria | D21: 11.2.2 | E21: 8 | G21: Cumple con los criterios que le sean aplicables de todos los servicios
A22: INFRAESTRUCTURA | B22: Mediana | C22: Modalidad telemedicina: Categoría interactiva y no interactiva – prestador de referencia | D22: 11.2.2 | E22: 9 | G22: Cumple con los criterios que le sean aplicables de todos los servicios.
A23: INFRAESTRUCTURA | B23: Mediana | C23: Modalidad telemedicina: Categoría telexperticia - prestador remisor | D23: 11.2.2 | E23: 10 | G23: Cumple con los criterios establecidos en el servicio de consulta externa general.
A24: INFRAESTRUCTURA | B24: Mediana | C24: Modalidad telemedicina: Categoría telexperticia - prestador de referencia | D24: 11.2.2 | E24: 11 | G24: Cumple con los criterios que le sean aplicables de todos los servicios
A25: INFRAESTRUCTURA | B25: Mediana | C25: Modalidad telemedicina: Categoría telemonitoreo - prestador de referencia | D25: 11.2.2 | E25: 12 | G25: Cumple con los criterios que le sean aplicables de todos los servicios
A26: DOTACIÓN | B26: Mediana | C26: Modalidades intramural, extramural unidad móvil, jornada de salud y domiciliaria | D26: 11.2.2 | E26: 13 | G26: Cumple con los criterios definidos para el servicio de consulta externa general y adicionalmente: Los consultorios de los especialistas cuentan con la dotación necesaria para realizar los procedimientos documentados en el estándar de procesos prioritarios
A27: DOTACIÓN | B27: Mediana | C27: Modalidad telemedicina: Categoría interactiva y no interactiva – prestador de referencia | D27: 11.2.2 | E27: 14 | G27: Cumple con los criterios que le sean aplicables de todos los servicios
A28: DOTACIÓN | B28: Mediana | C28: Modalidad telemedicina: Categoría telexperticia - prestador remisor | D28: 11.2.2 | E28: 15 | G28: Cumple con los criterios que le sean aplicables de todos los servicios y los establecidos en el servicio de consulta externa especializada
... A34: PROCESOS PRIORITARIOS | B34: Mediana | C34: Modalidades intramural, extramural unidad móvil, jornada de salud y domiciliaria | D34: 11.2.2 | E34: 21 | G34: Adicionalmente para el caso de medicina y terapias alternativas y complementarias, cuenta con información documentada de:
A35: PROCESOS PRIORITARIOS | B35: Mediana | C35: Modalidades intramural, extramural unidad móvil, jornada de salud y domiciliaria | D35: 11.2.2 | E35: 21 | F35: 21.1 | G35: • Criterios explícitos y documentados sobre el tipo de procedimientos que se pueden realizar y de los que no se pueden realizar teniendo como marco el ámbito de la competencia.
A36: PROCESOS PRIORITARIOS | B36: Mediana | C36: Modalidades intramural, extramural unidad móvil, jornada de salud y domiciliaria | D36: 11.2.2 | E36: 21 | F36: 21.2 | G36: • Procedimientos para la información al paciente sobre preparación y recomendaciones post procedimiento, controles, posibles complicaciones y disponibilidad de consulta permanente y en general las previsiones que se requieran para proteger al paciente de los riesgos de procedimientos que se realicen en la consulta.
A37: PROCESOS PRIORITARIOS | B37: Mediana | C37: Modalidad telemedicina: Categoría interactiva y no interactiva – prestador de referencia | D37: 11.2.2 | E37: 22 | G37: Cumple con los criterios que le sean aplicables de todos los servicios
A38: PROCESOS PRIORITARIOS | B38: Mediana | C38: Modalidad telemedicina: Categoría telexperticia - prestador remisor | D38: 11.2.2 | E38: 23 | G38: Cumple con los criterios que le sean aplicables de todos los servicios y los establecidos en el servicio de consulta externa especializada
A39: PROCESOS PRIORITARIOS | B39: Mediana | C39: Modalidad telemedicina: Categoría telexperticia - prestador de referencia | D39: 11.2.2 | E39: 24 | G39: Cumple con los criterios que le sean aplicables de todos los servicios
A40: PROCESOS PRIORITARIOS | B40: Mediana | C40: Modalidad telemedicina: Categoría telemonitoreo - prestador de referencia | D40: 11.2.2 | E40: 25 | G40: Cumple con los criterios que le sean aplicables de todos los servicios
A41: HISTORIA CLÍNICA Y REGISTRO | B41: Mediana | C41: Modalidades intramural, extramural unidad móvil, jornada de salud y domiciliaria | D41: 11.2.2 | E41: 26 | G41: Cumple con los criterios que le sean aplicables de todos los servicios | H41: x
A42: HISTORIA CLÍNICA Y REGISTRO | B42: Mediana | C42: Modalidad telemedicina. Categoría interactiva y no interactiva – prestador de referencia Categoría telexperticia - prestador remisor- prestador de referencia Categoría telemonitoreo - prestador de referencia | D42: 11.2.2 | E42: 27 | G42: Cumple con los criterios que le sean aplicables de todos los servicios | H42: x
A43: INTERDEPENDENCIA | B43: Mediana | C43: Modalidades intramural, extramural unidad móvil, jornada de salud y domiciliaria y telemedicina | D43: 11.2.2 | E43: 28 | G43: No aplica para la consulta externa médica especializada | J43: x
A44: INTERDEPENDENCIA | B44: Mediana | C44: Modalidades intramural, extramural unidad móvil, jornada de salud y domiciliaria y telemedicina | D44: 11.2.2 | E44: 29 | G44: Para la consulta odontológica especializada disponibilidad de: | J44: x
A45: INTERDEPENDENCIA | B45: Mediana | C45: Modalidades intramural, extramural unidad móvil, jornada de salud y domiciliaria y telemedicina | D45: 11.2.2 | E45: 29 | F45: 29.1 | G45: • Servicio de radiología odontológica | J45: x
A46: INTERDEPENDENCIA | B46: Mediana | C46: Modalidades intramural, extramural unidad móvil, jornada de salud y domiciliaria y telemedicina | D46: 11.2.2 | E46: 29 | F46: 29.2 | G46: • Transporte asistencial cuando se realicen procedimientos bajo sedación grado I y II. | J46: x
...

Sheet VACUN
B1: VACUNACIÓN CONDICIONES DE HABILITACIÓN RESOLUCIÓN 3100/2019 | P1: ESTADO DE ACCIONES (Número de acciones y % por estado) | T1: ESTADO DE ACCIONES (Número de acciones y % por estado) | X1: ESTADO DE ACCIONES (Número de acciones y % por estado) | AB1: ESTADO DE ACCIONES (Número de acciones y % por estado) | AF1: ESTADO DE ACCIONES (Número de acciones y % por estado) | AJ1: ESTADO DE ACCIONES (Número de acciones y % por estado)
P2: SIN INICIAR | Q2: =COUNTIFS(R$10:R$501,P2) -> 0 | R2: =IFERROR(Q2/SUM(Q$2:Q$5),"") | T2: SIN INICIAR | U2: =COUNTIFS(V$10:V$501,T2) -> 0 | V2: =IFERROR(U2/SUM(U$2:U$5),"") | X2: SIN INICIAR | Y2: =COUNTIFS(Z$10:Z$501,X2) -> 0 | Z2: =IFERROR(Y2/SUM(Y$2:Y$5),"") | AB2: SIN INICIAR | AC2: =COUNTIFS(AD$10:AD$501,AB2) -> 0 | AD2: =IFERROR(AC2/SUM(AC$2:AC$5),"") | AF2: SIN INICIAR | AG2: =COUNTIFS(AH$10:AH$501,AF2) -> 0 | AH2: =IFERROR(AG2/SUM(AG$2:AG$5),"") | AJ2: SIN INICIAR | AK2: =COUNTIFS(AL$10:AL$501,AJ2) -> 0 | AL2: =IFERROR(AK2/SUM(AK$2:AK$5),"")
C3: TOTAL CUMPLE | D3: TOTAL NO CUMPLE | E3: TOTAL NO APLICA | P3: EN EJECUCION | Q3: =COUNTIFS(R$10:R$501,P3) -> 0 | R3: =IFERROR(Q3/SUM(Q$2:Q$5),"") | T3: EN EJECUCION | U3: =COUNTIFS(V$10:V$501,T3) -> 0 | V3: =IFERROR(U3/SUM(U$2:U$5),"") | X3: EN EJECUCION | Y3: =COUNTIFS(Z$10:Z$501,X3) -> 0 | Z3: =IFERROR(Y3/SUM(Y$2:Y$5),"") | AB3: EN EJECUCION | AC3: =COUNTIFS(AD$10:AD$501,AB3) -> 0 | AD3: =IFERROR(AC3/SUM(AC$2:AC$5),"") | AF3: EN EJECUCION | AG3: =COUNTIFS(AH$10:AH$501,AF3) -> 0 | AH3: =IFERROR(AG3/SUM(AG$2:AG$5),"") | AJ3: EN EJECUCION | AK3: =COUNTIFS(AL$10:AL$501,AJ3) -> 0 | AL3: =IFERROR(AK3/SUM(AK$2:AK$5),"")
A4: NUMERO DE CRITERIOS EVALUADOS | C4: =COUNTA(H10:H67) -> 0 | D4: =COUNTA(I10:I67) -> 0 | E4: =COUNTA(J10:J67) -> 0 | P4: CERRADA | Q4: =COUNTIFS(R$10:R$501,P4) -> 0 | R4: =IFERROR(Q4/SUM(Q$2:Q$5),"") | T4: CERRADA | U4: =COUNTIFS(V$10:V$501,T4) -> 0 | V4: =IFERROR(U4/SUM(U$2:U$5),"") | X4: CERRADA | Y4: =COUNTIFS(Z$10:Z$501,X4) -> 0 | Z4: =IFERROR(Y4/SUM(Y$2:Y$5),"") | AB4: CERRADA | AC4: =COUNTIFS(AD$10:AD$501,AB4) -> 0 | AD4: =IFERROR(AC4/SUM(AC$2:AC$5),"") | AF4: CERRADA | AG4: =COUNTIFS(AH$10:AH$501,AF4) -> 0 | AH4: =IFERROR(AG4/SUM(AG$2:AG$5),"") | AJ4: CERRADA | AK4: =COUNTIFS(AL$10:AL$501,AJ4) -> 0 | AL4: =IFERROR(AK4/SUM(AK$2:AK$5),"")
A5: CUMPLIMIENTO DEL SERVICIO EVALUADO | C5: =IFERROR(C4/(D4+C4),"") | P5: CANCELADA | Q5: =COUNTIFS(R$10:R$501,P5) -> 0 | R5: =IFERROR(Q5/SUM(Q$2:Q$5),"") | T5: CANCELADA | U5: =COUNTIFS(V$10:V$501,T5) -> 0 | V5: =IFERROR(U5/SUM(U$2:U$5),"") | X5: CANCELADA | Y5: =COUNTIFS(Z$10:Z$501,X5) -> 0 | Z5: =IFERROR(Y5/SUM(Y$2:Y$5),"") | AB5: CANCELADA | AC5: =COUNTIFS(AD$10:AD$501,AB5) -> 0 | AD5: =IFERROR(AC5/SUM(AC$2:AC$5),"") | AF5: CANCELADA | AG5: =COUNTIFS(AH$10:AH$501,AF5) -> 0 | AH5: =IFERROR(AG5/SUM(AG$2:AG$5),"") | AJ5: CANCELADA | AK5: =COUNTIFS(AL$10:AL$501,AJ5) -> 0 | AL5: =IFERROR(AK5/SUM(AK$2:AK$5),"")
P6: TOTAL | Q6: =SUM(Q2:Q5) -> 0 | T6: TOTAL | U6: =SUM(U2:U5) -> 0 | X6: TOTAL | Y6: =SUM(Y2:Y5) -> 0 | AB6: TOTAL | AC6: =SUM(AC2:AC5) -> 0 | AF6: TOTAL | AG6: =SUM(AG2:AG5) -> 0 | AJ6: TOTAL | AK6: =SUM(AK2:AK5) -> 0
P8: SEGUIMIENTO 1 - Fecha: | T8: SEGUIMIENTO 2 - Fecha: | X8: SEGUIMIENTO 3 - Fecha: | AB8: SEGUIMIENTO 4 - Fecha: | AF8: SEGUIMIENTO 5 - Fecha: | AJ8: SEGUIMIENTO 6 - Fecha:
A9: ESTANDAR | B9: COMPLEJIDAD | C9: MODALIDAD | D9: ARTICULO | E9: SECCIÓN | F9: APARTADO | G9: CRITERIO | H9: CUMPLE | I9: NO CUMPLE | J9: NO APLICA | K9: HALLAZGOS | M9: ACCIÓN PARA EL CUMPLIMIENTO | N9: RESPONSABLE | O9: FECHA LIMITE PARA IMPLEMENTAR | P9: SEGUIMIENTO 1 | R9: ESTADO DE LA ACCIÓN 1 | T9: SEGUIMIENTO 2 | V9: ESTADO DE LA ACCIÓN 2 | X9: SEGUIMIENTO 3 | Z9: ESTADO DE LA ACCIÓN 3 | AB9: SEGUIMIENTO 4 | AD9: ESTADO DE LA ACCIÓN 4 | AF9: SEGUIMIENTO 5 | AH9: ESTADO DE LA ACCIÓN 5 | AJ9: SEGUIMIENTO 6 | AL9: ESTADO DE LA ACCIÓN 6
A10: TALENTO HUMANO | B10: Baja | C10: Modalidades intramural, extramural unidad móvil, jornada de salud y domiciliaria | D10: 11.2.3 | E10: 1 | G10: Cumple con los criterios que le sean aplicables de todos los servicios y adicionalmente, cuenta con:
A11: TALENTO HUMANO | B11: Baja | C11: Modalidades intramural, extramural unidad móvil, jornada de salud y domiciliaria | D11: 11.2.3 | E11: 1 | F11: 1.1 | G11: • Profesional de la medicina o profesional de la enfermería.
A12: TALENTO HUMANO | B12: Baja | C12: Modalidades intramural, extramural unidad móvil, jornada de salud y domiciliaria | D12: 11.2.3 | E12: 2 | G12: Si se requiere personal adicional para:
A13: TALENTO HUMANO | B13: Baja | C13: Modalidades intramural, extramural unidad móvil, jornada de salud y domiciliaria | D13: 11.2.3 | E13: 2 | F13: 2.1 | G13: • La administración de la vacuna cuenta con auxiliar de enfermería o auxiliar de salud pública bajo la supervisión del profesional de la medicina o profesional de la enfermería.
A14: TALENTO HUMANO | B14: Baja | C14: Modalidades intramural, extramural unidad móvil, jornada de salud y domiciliaria | D14: 11.2.3 | E14: 2 | F14: 2.2 | G14: • El manejo de la cadena de frío puede disponer de auxiliar de enfermería o auxiliar en salud pública o gestor comunitario en salud (en zonas de dispersión geográfica) o regentes de farmacia o químico farmacéutico con experiencia en cadena de frío.
A15: INFRAESTRUCTURA | B15: Baja | C15: Modalidad intramural | D15: 11.2.3 | E15: 3 | G15: Cumple con los criterios que le sean aplicables de todos los servicios y adicionalmente cuenta con:
A16: INFRAESTRUCTURA | B16: Baja | C16: Modalidad intramural | D16: 11.2.3 | E16: 4 | G16: Consultorio o ambiente que, de acuerdo con la oferta, cumple con los siguientes requisitos:
A17: INFRAESTRUCTURA | B17: Baja | C17: Modalidad intramural | D17: 11.2.3 | E17: 4 | G17: Para los servicios en modalidad intramural de prestadores de servicios de salud que separen el servicio de vacunación en dos ambientes cuenta con:
A18: INFRAESTRUCTURA | B18: Baja | C18: Modalidad intramural | D18: 11.2.3 | E18: 4 | F18: 4.1 | G18: • Consultorio para administración de medicamentos biológicos que cuenta con:
A19: INFRAESTRUCTURA | B19: Baja | C19: Modalidad intramural | D19: 11.2.3 | E19: 4 | F19: 4.1.1 | G19: • Área para entrevista.
A20: INFRAESTRUCTURA | B20: Baja | C20: Modalidad intramural | D20: 11.2.3 | E20: 4 | F20: 4.1.2 | G20: Área para el alistamiento y administración de medicamentos biológicos.
A21: INFRAESTRUCTURA | B21: Baja | C21: Modalidad intramural | D21: 11.2.3 | E21: 4 | F21: 4.1.3 | G21: • Lavamanos.
A22: INFRAESTRUCTURA | B22: Baja | C22: Modalidad intramural | D22: 11.2.3 | E22: 4 | F22: 4.2 | G22: • Ambiente para almacenamiento y alistamiento de dispositivos y termos que cuenta con:
A23: INFRAESTRUCTURA | B23: Baja | C23: Modalidad intramural | D23: 11.2.3 | E23: 4 | F23: 4.2.1 | G23: • Área para el alistamiento de termos o cajas térmicas.
A24: INFRAESTRUCTURA | B24: Baja | C24: Modalidad intramural | D24: 11.2.3 | E24: 4 | F24: 4.2.2 | G24: • Área de cadena de frío que incluye un mesón con poceta, con capacidad para el lavado de termos, con grifo cuello de cisne o ducha teléfono; que puede estar ubicado en otro ambiente diferente al consultorio.
A25: INFRAESTRUCTURA | B25: Baja | C25: Modalidad intramural | D25: 11.2.3 | E25: 4 | F25: 4.2.3 | G25: • Área para el almacenamiento de dispositivos médicos e insumos, que puede estar ubicado en otro ambiente diferente al consultorio.
A26: INFRAESTRUCTURA | B26: Baja | C26: Modalidad intramural | D26: 11.2.3 | E26: 4 | F26: 4.2.4 | G26: • Lavamanos.
A27: INFRAESTRUCTURA | B27: Baja | C27: Modalidad intramural | D27: 11.2.3 | E27: 4 | F27: 4.3 | G27: • Disponibilidad de:
A28: INFRAESTRUCTURA | B28: Baja | C28: Modalidad intramural | D28: 11.2.3 | E28: 4 | F28: 4.3.1 | G28: • Sala de espera.
A29: INFRAESTRUCTURA | B29: Baja | C29: Modalidad intramural | D29: 11.2.3 | E29: 4 | F29: 4.3.2 | G29: • Unidades sanitarias discriminadas por sexo.
A30: INFRAESTRUCTURA | B30: Baja | C30: Modalidad intramural | D30: 11.2.3 | E30: 4 | G30: Para los servicios en modalidad intramural de prestadores de servicios de salud que integren en un solo ambiente el servicio de vacunación cuenta con:
A31: INFRAESTRUCTURA | B31: Baja | C31: Modalidad intramural | D31: 11.2.3 | E31: 4 | F31: 4.4 | G31: • Ambiente de vacunación, para administración de medicamentos biológicos, que cuenta con:
A32: INFRAESTRUCTURA | B32: Baja | C32: Modalidad intramural | D32: 11.2.3 | E32: 4 | F32: 4.4.1 | G32: • Área para entrevista.
A33: INFRAESTRUCTURA | B33: Baja | C33: Modalidad intramural | D33: 11.2.3 | E33: 4 | F33: 4.4.2 | G33: • Área para el alistamiento y administración de medicamentos biológicos.
A34: INFRAESTRUCTURA | B34: Baja | C34: Modalidad intramural | D34: 11.2.3 | E34: 4 | F34: 4.4.3 | G34: • Área para el alistamiento de termos o cajas térmicas.
A35: INFRAESTRUCTURA | B35: Baja | C35: Modalidad intramural | D35: 11.2.3 | E35: 4 | F35: 4.4.4 | G35: • Área de cadena de frío que incluye un mesón con poceta, con capacidad para el lavado de los termos, con grifo cuello de cisne o ducha teléfono, que puede estar ubicado en otro ambiente diferente al consultorio.
A36: INFRAESTRUCTURA | B36: Baja | C36: Modalidad intramural | D36: 11.2.3 | E36: 4 | F36: 4.4.5 | G36: • Área para el almacenamiento de dispositivos médicos e insumos, que puede estar ubicado en otro ambiente diferente al consultorio.
A37: INFRAESTRUCTURA | B37: Baja | C37: Modalidad intramural | D37: 11.2.3 | E37: 4 | F37: 4.4.6 | G37: • Lavamanos.
A38: INFRAESTRUCTURA | B38: Baja | C38: Modalidad intramural | D38: 11.2.3 | E38: 4 | F38: 4.5 | G38: • Disponibilidad de:
A39: INFRAESTRUCTURA | B39: Baja | C39: Modalidad intramural | D39: 11.2.3 | E39: 4 | F39: 4.5.1 | G39: • Sala de espera.
A40: INFRAESTRUCTURA | B40: Baja | C40: Modalidad intramural | D40: 11.2.3 | E40: 4 | F40: 4.5.2 | G40: • Unidades sanitarias discriminadas por sexo.
A41: INFRAESTRUCTURA | B41: Baja | C41: Modalidades extramural unidad móvil, jornada de salud y domiciliaria | D41: 11.2.3 | E41: 5 | G41: Adicional a los criterios definidos para todos los servicios, la sede del prestador de servicios de salud que habilite el servicio de vacunación cuenta con:
...

Sheet SST
B1: SEGURIDAD Y SALUD EN EL TRABAJO CONDICIONES DE HABILITACIÓN RESOLUCIÓN 3100/2019 | P1: ESTADO DE ACCIONES (Número de acciones y % por estado) | T1: ESTADO DE ACCIONES (Número de acciones y % por estado) | X1: ESTADO DE ACCIONES (Número de acciones y % por estado) | AB1: ESTADO DE ACCIONES (Número de acciones y % por estado) | AF1: ESTADO DE ACCIONES (Número de acciones y % por estado) | AJ1: ESTADO DE ACCIONES (Número de acciones y % por estado)
P2: SIN INICIAR | Q2: =COUNTIFS(R$10:R$501,P2) -> 0 | R2: =IFERROR(Q2/SUM(Q$2:Q$5),"") | T2: SIN INICIAR | U2: =COUNTIFS(V$10:V$501,T2) -> 0 | V2: =IFERROR(U2/SUM(U$2:U$5),"") | X2: SIN INICIAR | Y2: =COUNTIFS(Z$10:Z$501,X2) -> 0 | Z2: =IFERROR(Y2/SUM(Y$2:Y$5),"") | AB2: SIN INICIAR | AC2: =COUNTIFS(AD$10:AD$501,AB2) -> 0 | AD2: =IFERROR(AC2/SUM(AC$2:AC$5),"") | AF2: SIN INICIAR | AG2: =COUNTIFS(AH$10:AH$501,AF2) -> 0 | AH2: =IFERROR(AG2/SUM(AG$2:AG$5),"") | AJ2: SIN INICIAR | AK2: =COUNTIFS(AL$10:AL$501,AJ2) -> 0 | AL2: =IFERROR(AK2/SUM(AK$2:AK$5),"")
C3: TOTAL CUMPLE | D3: TOTAL NO CUMPLE | E3: TOTAL NO APLICA | P3: EN EJECUCION | Q3: =COUNTIFS(R$10:R$501,P3) -> 0 | R3: =IFERROR(Q3/SUM(Q$2:Q$5),"") | T3: EN EJECUCION | U3: =COUNTIFS(V$10:V$501,T3) -> 0 | V3: =IFERROR(U3/SUM(U$2:U$5),"") | X3: EN EJECUCION | Y3: =COUNTIFS(Z$10:Z$501,X3) -> 0 | Z3: =IFERROR(Y3/SUM(Y$2:Y$5),"") | AB3: EN EJECUCION | AC3: =COUNTIFS(AD$10:AD$501,AB3) -> 0 | AD3: =IFERROR(AC3/SUM(AC$2:AC$5),"") | AF3: EN EJECUCION | AG3: =COUNTIFS(AH$10:AH$501,AF3) -> 0 | AH3: =IFERROR(AG3/SUM(AG$2:AG$5),"") | AJ3: EN EJECUCION | AK3: =COUNTIFS(AL$10:AL$501,AJ3) -> 0 | AL3: =IFERROR(AK3/SUM(AK$2:AK$5),"")
A4: NUMERO DE CRITERIOS EVALUADOS | C4: =COUNTA(H10:H37) -> 0 | D4: =COUNTA(I10:I37) -> 0 | E4: =COUNTA(J10:J37) -> 0 | P4: CERRADA | Q4: =COUNTIFS(R$10:R$501,P4) -> 0 | R4: =IFERROR(Q4/SUM(Q$2:Q$5),"") | T4: CERRADA | U4: =COUNTIFS(V$10:V$501,T4) -> 0 | V4: =IFERROR(U4/SUM(U$2:U$5),"") | X4: CERRADA | Y4: =COUNTIFS(Z$10:Z$501,X4) -> 0 | Z4: =IFERROR(Y4/SUM(Y$2:Y$5),"") | AB4: CERRADA | AC4: =COUNTIFS(AD$10:AD$501,AB4) -> 0 | AD4: =IFERROR(AC4/SUM(AC$2:AC$5),"") | AF4: CERRADA | AG4: =COUNTIFS(AH$10:AH$501,AF4) -> 0 | AH4: =IFERROR(AG4/SUM(AG$2:AG$5),"") | AJ4: CERRADA | AK4: =COUNTIFS(AL$10:AL$501,AJ4) -> 0 | AL4: =IFERROR(AK4/SUM(AK$2:AK$5),"")
A5: CUMPLIMIENTO DEL SERVICIO EVALUADO | C5: =IFERROR(C4/(D4+C4),"") | P5: CANCELADA | Q5: =COUNTIFS(R$10:R$501,P5) -> 0 | R5: =IFERROR(Q5/SUM(Q$2:Q$5),"") | T5: CANCELADA | U5: =COUNTIFS(V$10:V$501,T5) -> 0 | V5: =IFERROR(U5/SUM(U$2:U$5),"") | X5: CANCELADA | Y5: =COUNTIFS(Z$10:Z$501,X5) -> 0 | Z5: =IFERROR(Y5/SUM(Y$2:Y$5),"") | AB5: CANCELADA | AC5: =COUNTIFS(AD$10:AD$501,AB5) -> 0 | AD5: =IFERROR(AC5/SUM(AC$2:AC$5),"") | AF5: CANCELADA | AG5: =COUNTIFS(AH$10:AH$501,AF5) -> 0 | AH5: =IFERROR(AG5/SUM(AG$2:AG$5),"") | AJ5: CANCELADA | AK5: =COUNTIFS(AL$10:AL$501,AJ5) -> 0 | AL5: =IFERROR(AK5/SUM(AK$2:AK$5),"")
P6: TOTAL | Q6: =SUM(Q2:Q5) -> 0 | T6: TOTAL | U6: =SUM(U2:U5) -> 0 | X6: TOTAL | Y6: =SUM(Y2:Y5) -> 0 | AB6: TOTAL | AC6: =SUM(AC2:AC5) -> 0 | AF6: TOTAL | AG6: =SUM(AG2:AG5) -> 0 | AJ6: TOTAL | AK6: =SUM(AK2:AK5) -> 0
P8: SEGUIMIENTO 1 - Fecha: | T8: SEGUIMIENTO 2 - Fecha: | X8: SEGUIMIENTO 3 - Fecha: | AB8: SEGUIMIENTO 4 - Fecha: | AF8: SEGUIMIENTO 5 - Fecha: | AJ8: SEGUIMIENTO 6 - Fecha:
A9: ESTANDAR | B9: COMPLEJIDAD | C9: MODALIDAD | D9: ARTICULO | E9: SECCIÓN | F9: APARTADO | G9: CRITERIO | H9: CUMPLE | I9: NO CUMPLE | J9: NO APLICA | K9: HALLAZGOS | M9: ACCIÓN PARA EL CUMPLIMIENTO | N9: RESPONSABLE | O9: FECHA LIMITE PARA IMPLEMENTAR | P9: SEGUIMIENTO 1 | R9: ESTADO DE LA ACCIÓN 1 | T9: SEGUIMIENTO 2 | V9: ESTADO DE LA ACCIÓN 2 | X9: SEGUIMIENTO 3 | Z9: ESTADO DE LA ACCIÓN 3 | AB9: SEGUIMIENTO 4 | AD9: ESTADO DE LA ACCIÓN 4 | AF9: SEGUIMIENTO 5 | AH9: ESTADO DE LA ACCIÓN 5 | AJ9: SEGUIMIENTO 6 | AL9: ESTADO DE LA ACCIÓN 6
A10: TALENTO HUMANO | B10: Mediana | C10: Modalidades intramural, extramural unidad móvil y jornada de salud | D10: 11.2.4 | E10: 1 | G10: Cumple con los criterios que le sean aplicables de todos los servicios y adicionalmente cuenta con:
