Workbook
Name GRP_Apoyo_Dx_y_Complementacion_Terapeutica: _SVC_!$D$2:$D$23
Name GRP_Atencion_Inmediata: _SVC_!$E$2:$E$6
Name GRP_Consulta_Externa: _SVC_!$C$2:$C$92
Name GRP_Internacion: _SVC_!$A$2:$A$16
Name GRP_Quirurgicos: _SVC_!$B$2:$B$25
Name LISTA_GRUPOS: _SVC_!$A$1:$E$1

Sheet 🏠 PORTADA
A1: HERRAMIENTA INTEGRAL DE AUDITORÍA DOCUMENTAL Y VERIFICACIÓN REPS
A2: Resolución 3100 de 2019 · Ministerio de Salud y Protección Social · Colombia
A4: 🖼 LOGO CORPORATIVO | F4: 📋 DATOS DEL PRESTADOR AUDITADO
A5: [ LOGO DE LA EMPRESA ] Para insertar: Insertar → Imagen → Este dispositivo... Tamaño recomendado: 300 × 100 px · PNG | F5: Nombre / Razón Social
F6: NIT
F7: Código REPS
F8: Dirección Sede Principal
F9: Ciudad / Departamento
F10: Representante Legal
F11: Teléfono de Contacto
F12: Correo Electrónico Institucional
F14: 👤 DATOS DEL AUDITOR / VERIFICADOR
F15: Nombre del Auditor
F16: Empresa Auditora
F17: Fecha de la Auditoría
F18: No. Contrato / Expediente
A19: 🚦 SEMÁFORO
A20: ✅ CARGADO | F20: 🔗 CONSULTE EL REPS EN LÍNEA:
A21: ⏳ EN PROCESO | F21: https://prestadores.minsalud.gov.co/habilitacion/
A22: ❌ NO REALIZADO
A23: ⚪ NO APLICA

Sheet 📖 INSTRUCTIVO
A1: 📖 INSTRUCTIVO DE MANEJO – HERRAMIENTA DE AUDITORÍA DOCUMENTAL Y VERIFICACIÓN REPS
A2: Audisalud Colombia SAS · Versión 2025 · Resolución 3100 de 2019
A4: ▶ DESCRIPCIÓN GENERAL DE LA HERRAMIENTA
A5: Esta herramienta está diseñada para que auditores y prestadores de salud verifiquen el cumplimiento de los requisitos de habilitación establecidos en la Resolución 3100 de 2019 y el Registro Especial de Prestadores (REPS). Contiene 8 módulos interconectados con cálculo automático de indicadores.
A8: ▶ ESTRUCTURA DEL ARCHIVO – HOJAS Y SU FUNCIÓN
A9: 🏠 PORTADA | B9: Datos de identificación del prestador y auditor. Zona para insertar logo corporativo.
A10: 📖 INSTRUCTIVO | B10: Esta hoja. Guía completa de uso de la herramienta.
A11: 📄 MATRIZ DOCUMENTAL | B11: Listado de los 108 documentos exigidos por la Res. 3100. Registre el estado de cada documento.
A12: ⚕ REPS – Servicios | B12: Verificación de servicios habilitados en el REPS. Desplegable en cascada Grupo → Servicio → Código.
A13: 🏗 REPS – Capacidad | B13: Comparación de capacidad instalada registrada en REPS vs la real verificada en visita.
A14: ⚠ REPS – Sanciones | B14: Registro de medidas de seguridad y sanciones vigentes en el REPS.
A15: 📊 DASHBOARD | B15: Resumen ejecutivo con KPIs, indicadores porcentuales, semáforo automático y hallazgos.
A16: 📑 REPORTE EJECUTIVO | B16: Informe consolidado listo para imprimir o compartir. Se llena automáticamente.
A17: 📋 Catálogo REPS | B17: Referencia oficial de los 157 servicios habilitables. Protegido (solo lectura).
A20: ▶ PASO A PASO – CÓMO USAR LA HERRAMIENTA
A21: PASO 1 | B21: CONFIGURE LA PORTADA
B22: Abra la hoja 🏠 PORTADA. Complete los campos amarillos con los datos del prestador: nombre, NIT, dirección, representante legal, correo y teléfono. Luego complete los datos del auditor. Para insertar su logo: vaya a Insertar → Imagen → Este dispositivo, seleccione el archivo PNG o JPG y ubíquelo en el recuadro punteado.
A24: PASO 2 | B24: DILIGENCIE LA MATRIZ DOCUMENTAL
B25: Abra la hoja 📄 MATRIZ DOCUMENTAL. Para cada documento de la lista, haga clic en la columna ESTADO y seleccione una opción del menú desplegable: ✅ CARGADO (verde), ⏳ EN PROCESO (naranja), ❌ NO REALIZADO (rojo) o ⚪ NO APLICA (gris). El color cambia automáticamente. En la columna URL/NUBE pegue el enlace directo al documento en Google Drive, OneDrive o SharePoint.
A27: PASO 3 | B27: VERIFIQUE LOS SERVICIOS REPS
B28: Abra la hoja ⚕ REPS – Servicios. En la columna GRUPO seleccione el grupo del servicio (Internación, Quirúrgicos, Consulta Externa, etc.). La columna SERVICIO filtrará automáticamente los servicios de ese grupo. El CÓDIGO REPS aparece solo al seleccionar el servicio. Complete las columnas de coincidencia y cumplimiento Res. 3100.
A30: PASO 4 | B30: REGISTRE LA CAPACIDAD INSTALADA
B31: Abra la hoja 🏗 REPS – Capacidad. Ingrese en CANTIDAD REPS el dato que aparece en el sistema REPS, y en CANTIDAD REAL lo que verificó en la visita. La columna DIFERENCIA y la columna ¿COINCIDE? se calculan automáticamente.
A33: PASO 5 | B33: REGISTRE MEDIDAS Y SANCIONES
B34: Abra la hoja ⚠ REPS – Sanciones. Registre todas las medidas de seguridad o sanciones que aparezcan en el REPS para el prestador. Seleccione el tipo y el estado con el menú desplegable.
A36: PASO 6 | B36: REVISE EL DASHBOARD
B37: La hoja 📊 DASHBOARD se actualiza automáticamente con todos los indicadores. Revise los KPIs en la parte superior y la tabla de indicadores con semáforo: verde ≥80%, naranja entre 50-79%, rojo <50%. Registre los hallazgos en la tabla inferior con su clasificación y responsable.
A39: PASO 7 | B39: EXPORTE EL REPORTE EJECUTIVO
B40: La hoja 📑 REPORTE EJECUTIVO consolida automáticamente todos los resultados. Agregue sus conclusiones en el espacio de texto y obtenga las firmas del auditor y representante legal. Para imprimir: Archivo → Imprimir, o guarde como PDF: Archivo → Guardar como → PDF.
A42: PASO 8 | B42: COMPARTA Y ARCHIVE
B43: Guarde el archivo con el nombre del prestador y la fecha. Puede subir el archivo a Google Drive o OneDrive y compartir el enlace por correo electrónico. No se recomienda compartir por WhatsApp por temas de confidencialidad del documento.
A47: ▶ SIGNIFICADO DEL SEMÁFORO DE ESTADOS
A48: ✅ CARGADO | B48: El documento existe, está vigente y su URL está registrada en la herramienta.
A49: ⏳ EN PROCESO | B49: El documento está en elaboración, trámite o pendiente de carga en la nube.
A50: ❌ NO REALIZADO | B50: El documento no existe ni está en proceso. Constituye un hallazgo de no conformidad.
A51: ⚪ NO APLICA | B51: El documento no es exigible para este tipo de servicio o clase de prestador.
A52: ✅ SÍ (coincide/cumple) | B52: El servicio o dato registrado en REPS coincide con la realidad verificada.
A53: ❌ NO (no coincide/cumple) | B53: Existe discrepancia entre el REPS y la realidad. Genera hallazgo.
A56: ▶ PREGUNTAS FRECUENTES
A57: ❓ ¿Puedo editar este archivo desde el celular?
...

Sheet 📄 MATRIZ DOCUMENTAL
A1: MATRIZ DOCUMENTAL 2025 – RESOLUCIÓN 3100 DE 2019
A2: Habilitación de Prestadores de Servicios de Salud · Condiciones Técnico-Administrativas y Técnico-Científicas
A3: Prestador: | G3: Fecha Auditoría:
A4: TOTAL DOCS | C4: ✅ CARGADOS | D4: ⏳ EN PROCESO | E4: ❌ NO REALIZ. | F4: ⚪ NO APLICA | H4: 🎯 % CUMPL. | J4: 📋 CON URL
A5: =COUNTA(C8:C146)-COUNTBLANK(C8:C146) -> 77 | C5: =COUNTIF(E8:E146,"✅ CARGADO") -> 0 | D5: =COUNTIF(E8:E146,"⏳ EN PROCESO") -> 108 | E5: =COUNTIF(E8:E146,"❌ NO REALIZADO") -> 0 | F5: =COUNTIF(E8:E146,"⚪ NO APLICA") -> 0 | H5: =IFERROR(COUNTIF(E8:E146,"✅ CARGADO")/MAX(1,COUNTA(C8:C146)-COUNTBLANK(C8:C146)),0) -> 0 | J5: =COUNTA(F8:F146)-COUNTBLANK(F8:F146) -> -137
A7: # | B7: ESTÁNDAR | C7: DOCUMENTO / PROCEDIMIENTO | D7: APLICA | E7: ESTADO | F7: URL / UBICACIÓN EN NUBE | G7: FECHA CARGA | H7: RESPONSABLE | I7: OBSERVACIONES / HALLAZGOS | J7: CUMPLE Res.3100 | K7: ACCIÓN REQUERIDA
A8: ▶ CONDICIONES TÉCNICO ADMINISTRATIVAS
A9: 1 | B9: CONDICIONES TÉCNICO ADMINISTRATIVAS | C9: Cámara de comercio no mayor a 30 días | D9: S | E9: ⏳ EN PROCESO
A10: 2 | B10: CONDICIONES TÉCNICO ADMINISTRATIVAS | C10: Cédula representante legal | D10: S | E10: ⏳ EN PROCESO
A11: ▶ CONDICIONES SUFICIENCIA PATRIMONIAL
A12: 3 | B12: CONDICIONES SUFICIENCIA PATRIMONIAL | C12: Cédula y tarjeta profesional del contador - revisor fiscal | D12: S | E12: ⏳ EN PROCESO
A13: 4 | B13: CONDICIONES SUFICIENCIA PATRIMONIAL | C13: Certificado de cuenta bancaria a nombre de la IPS | D13: S | E13: ⏳ EN PROCESO
A14: 5 | B14: CONDICIONES SUFICIENCIA PATRIMONIAL | C14: Licencia del software contable | D14: S | E14: ⏳ EN PROCESO
A15: 6 | B15: CONDICIONES SUFICIENCIA PATRIMONIAL | C15: Registro de los libros acta y socios | D15: S | E15: ⏳ EN PROCESO
A16: 7 | B16: CONDICIONES SUFICIENCIA PATRIMONIAL | C16: RUT | D16: S | E16: ⏳ EN PROCESO
A17: 8 | B17: CONDICIONES SUFICIENCIA PATRIMONIAL | C17: Estados financieros | D17: S | E17: ⏳ EN PROCESO
A18: 9 | B18: CONDICIONES SUFICIENCIA PATRIMONIAL | C18: Certificado condiciones de suficiencia patrimonial | D18: S | E18: ⏳ EN PROCESO
A19: ▶ ESTÁNDAR 1 – TALENTO HUMANO
A20: 10 | B20: ESTÁNDAR 1 – TALENTO HUMANO | C20: Relación del personal de la entidad | D20: S | E20: ⏳ EN PROCESO
A21: 11 | B21: ESTÁNDAR 1 – TALENTO HUMANO | C21: Hojas de vida por servicio que incluya los soportes legales | D21: S | E21: ⏳ EN PROCESO
A22: 12 | B22: ESTÁNDAR 1 – TALENTO HUMANO | C22: Formato de capacidad instalada | D22: S | E22: ⏳ EN PROCESO
A23: 13 | B23: ESTÁNDAR 1 – TALENTO HUMANO | C23: Programa de capacitaciones y cronograma | D23: S | E23: ⏳ EN PROCESO
A24: 14 | B24: ESTÁNDAR 1 – TALENTO HUMANO | C24: Capacitaciones realizadas del año | D24: S | E24: ⏳ EN PROCESO
A25: 15 | B25: ESTÁNDAR 1 – TALENTO HUMANO | C25: Comités y cronograma | D25: S | E25: ⏳ EN PROCESO
A26: ▶ ESTÁNDAR 2 – INFRAESTRUCTURA
A27: 16 | B27: ESTÁNDAR 2 – INFRAESTRUCTURA | C27: Concepto del uso del suelo | D27: S | E27: ⏳ EN PROCESO
A28: 17 | B28: ESTÁNDAR 2 – INFRAESTRUCTURA | C28: Licencia de construcción | D28: S | E28: ⏳ EN PROCESO
A29: 18 | B29: ESTÁNDAR 2 – INFRAESTRUCTURA | C29: Plan de mantenimiento de infraestructura y cronograma | D29: S | E29: ⏳ EN PROCESO
A30: 19 | B30: ESTÁNDAR 2 – INFRAESTRUCTURA | C30: Certificado de bomberos (vigente, no mayor a 1 año) | D30: S | E30: ⏳ EN PROCESO
A31: 20 | B31: ESTÁNDAR 2 – INFRAESTRUCTURA | C31: Certificado eléctrico (vigente, no mayor a 5 años) | D31: S | E31: ⏳ EN PROCESO
A32: 21 | B32: ESTÁNDAR 2 – INFRAESTRUCTURA | C32: Planillas de limpieza y desinfección | D32: S | E32: ⏳ EN PROCESO
A33: 22 | B33: ESTÁNDAR 2 – INFRAESTRUCTURA | C33: Plano de la institución con medidas por servicio | D33: S | E33: ⏳ EN PROCESO
A34: 23 | B34: ESTÁNDAR 2 – INFRAESTRUCTURA | C34: Plan hospitalario de emergencias | D34: S | E34: ⏳ EN PROCESO
A35: 24 | B35: ESTÁNDAR 2 – INFRAESTRUCTURA | C35: Plano Ruta de evacuación por piso | D35: S | E35: ⏳ EN PROCESO
A36: 25 | B36: ESTÁNDAR 2 – INFRAESTRUCTURA | C36: Mantenimiento de ascensor cuando aplica | D36: S | E36: ⏳ EN PROCESO
A37: 26 | B37: ESTÁNDAR 2 – INFRAESTRUCTURA | C37: Plano de ruta sanitaria | D37: S | E37: ⏳ EN PROCESO
A38: ▶ CONCEPTO SANITARIO
A39: 27 | B39: CONCEPTO SANITARIO | C39: Certificado de fumigación - licencia del proveedor | D39: S | E39: ⏳ EN PROCESO
A40: 28 | B40: CONCEPTO SANITARIO | C40: Certificado de lavado de tanques de reserva de agua | D40: S | E40: ⏳ EN PROCESO
A41: 29 | B41: CONCEPTO SANITARIO | C41: Timbre de emergencia unidades sanitarias persona movilidad reducida | D41: S | E41: ⏳ EN PROCESO
...

Sheet ⚕ REPS – Servicios
A1: SERVICIOS HABILITADOS – REGISTRO ESPECIAL DE PRESTADORES (REPS)
A2: 157 servicios · Seleccione GRUPO → el SERVICIO filtra automáticamente → el CÓDIGO aparece solo
A3: Prestador: | G3: Sede: | K3: Fecha:
A4: SERVICIOS REGISTRADOS | C4: ✅ COINCIDEN REPS | E4: ❌ NO COINCIDEN | G4: ✅ CUMPLEN Res.3100 | I4: % COINCIDENCIA | K4: GRUPOS ACTIVOS
A5: =COUNTA(C9:C300)-COUNTBLANK(C9:C300) -> -292 | C5: =COUNTIF(K9:K300,"✅ SÍ") -> 0 | E5: =COUNTIF(K9:K300,"❌ NO") -> 0 | G5: =COUNTIF(L9:L300,"✅ SÍ") -> 0 | I5: =IFERROR(COUNTIF(K9:K300,"✅ SÍ")/MAX(1,COUNTA(C9:C300)-COUNTBLANK(C9:C300)),0) -> 0 | K5: =IFERROR(SUMPRODUCT((1/IF(COUNTIF(B9:B308,B9:B308)=0,1,COUNTIF(B9:B308,B9:B308)))*(B9:B308<>"")),0) -> 0
A7: ℹ️ PASO 1: Seleccione GRUPO (col B) ▶ PASO 2: Elija SERVICIO en col C (filtra automáticamente) ▶ CÓDIGO se completa solo (col D)
A8: No. | B8: GRUPO | C8: SERVICIO (desplegable) | D8: CÓDIGO REPS | E8: MODALIDAD | F8: COMPLEJIDAD | G8: ESPECIFICIDADES | H8: HORARIO | I8: No. DISTINTIVO HAB. | J8: FECHA APERTURA | K8: ¿COINCIDE REPS? | L8: ¿CUMPLE Res.3100? | M8: OBSERVACIONES
A9: 1 | D9: =IFERROR(VLOOKUP(C9,_COD_!$A:$B,2,0),"")
A10: 2 | D10: =IFERROR(VLOOKUP(C10,_COD_!$A:$B,2,0),"")
A11: 3 | D11: =IFERROR(VLOOKUP(C11,_COD_!$A:$B,2,0),"")
A12: 4 | D12: =IFERROR(VLOOKUP(C12,_COD_!$A:$B,2,0),"")
A13: 5 | D13: =IFERROR(VLOOKUP(C13,_COD_!$A:$B,2,0),"")
A14: 6 | D14: =IFERROR(VLOOKUP(C14,_COD_!$A:$B,2,0),"")
A15: 7 | D15: =IFERROR(VLOOKUP(C15,_COD_!$A:$B,2,0),"")
A16: 8 | D16: =IFERROR(VLOOKUP(C16,_COD_!$A:$B,2,0),"")
A17: 9 | D17: =IFERROR(VLOOKUP(C17,_COD_!$A:$B,2,0),"")
A18: 10 | D18: =IFERROR(VLOOKUP(C18,_COD_!$A:$B,2,0),"")
A19: 11 | D19: =IFERROR(VLOOKUP(C19,_COD_!$A:$B,2,0),"")
A20: 12 | D20: =IFERROR(VLOOKUP(C20,_COD_!$A:$B,2,0),"")
... A108: 100 | D108: =IFERROR(VLOOKUP(C108,_COD_!$A:$B,2,0),"")

Sheet 🏗 REPS – Capacidad
A1: CAPACIDAD INSTALADA – REGISTRO REPS
A2: Ingrese Cant. REPS y Cant. Real · Diferencia y ¿Coincide? se calculan automáticamente
A3: COINCIDENCIAS | C3: NO COINCIDEN | E3: % COINCIDENCIA | G3: DIFERENCIA TOTAL
A4: =COUNTIF(G7:G200,"✅ SÍ") -> 0 | C4: =COUNTIF(G7:G200,"❌ NO") -> 0 | E4: =IFERROR(COUNTIF(G7:G200,"✅ SÍ")/MAX(1,COUNTA(C7:C200)-COUNTBLANK(C7:C200)),0) -> 0 | G4: =IFERROR(SUMIF(G7:G200,"❌ NO",F7:F200),0) -> 0
A5: ℹ️ Ingrese CANTIDAD REPS y CANTIDAD REAL — Diferencia y ¿Coincide? se calculan solos
A6: No. | B6: GRUPO | C6: CONCEPTO / SERVICIO | D6: CANTIDAD REPS | E6: CANTIDAD REAL | F6: DIFERENCIA | G6: ¿COINCIDE? | H6: OBSERVACIONES
A7: 1 | B7: CONSULTORIOS | F7: =IFERROR(IF(AND(ISNUMBER(D7),ISNUMBER(E7)),E7-D7,""),"") | G7: =IFERROR(IF(D7="","",IF(E7=D7,"✅ SÍ","❌ NO")),"")
A8: 2 | B8: CAMAS HOSPITALIZACIÓN | F8: =IFERROR(IF(AND(ISNUMBER(D8),ISNUMBER(E8)),E8-D8,""),"") | G8: =IFERROR(IF(D8="","",IF(E8=D8,"✅ SÍ","❌ NO")),"")
A9: 3 | B9: CAMAS UCI ADULTOS | F9: =IFERROR(IF(AND(ISNUMBER(D9),ISNUMBER(E9)),E9-D9,""),"") | G9: =IFERROR(IF(D9="","",IF(E9=D9,"✅ SÍ","❌ NO")),"")
A10: 4 | B10: CAMAS UCI PEDIÁTRICA | F10: =IFERROR(IF(AND(ISNUMBER(D10),ISNUMBER(E10)),E10-D10,""),"") | G10: =IFERROR(IF(D10="","",IF(E10=D10,"✅ SÍ","❌ NO")),"")
A11: 5 | B11: CAMAS UCI NEONATAL | F11: =IFERROR(IF(AND(ISNUMBER(D11),ISNUMBER(E11)),E11-D11,""),"") | G11: =IFERROR(IF(D11="","",IF(E11=D11,"✅ SÍ","❌ NO")),"")
A12: 6 | B12: SALAS DE CIRUGÍA | F12: =IFERROR(IF(AND(ISNUMBER(D12),ISNUMBER(E12)),E12-D12,""),"") | G12: =IFERROR(IF(D12="","",IF(E12=D12,"✅ SÍ","❌ NO")),"")
A13: 7 | B13: SALAS DE PARTO | F13: =IFERROR(IF(AND(ISNUMBER(D13),ISNUMBER(E13)),E13-D13,""),"") | G13: =IFERROR(IF(D13="","",IF(E13=D13,"✅ SÍ","❌ NO")),"")
A14: 8 | B14: UNIDADES ODONTOLÓGICAS | F14: =IFERROR(IF(AND(ISNUMBER(D14),ISNUMBER(E14)),E14-D14,""),"") | G14: =IFERROR(IF(D14="","",IF(E14=D14,"✅ SÍ","❌ NO")),"")
A15: 9 | B15: AMBULANCIAS BÁSICAS | F15: =IFERROR(IF(AND(ISNUMBER(D15),ISNUMBER(E15)),E15-D15,""),"") | G15: =IFERROR(IF(D15="","",IF(E15=D15,"✅ SÍ","❌ NO")),"")
A16: 10 | B16: AMBULANCIAS MEDICALIZADAS | F16: =IFERROR(IF(AND(ISNUMBER(D16),ISNUMBER(E16)),E16-D16,""),"") | G16: =IFERROR(IF(D16="","",IF(E16=D16,"✅ SÍ","❌ NO")),"")
A17: 11 | B17: UNIDADES MÓVILES | F17: =IFERROR(IF(AND(ISNUMBER(D17),ISNUMBER(E17)),E17-D17,""),"") | G17: =IFERROR(IF(D17="","",IF(E17=D17,"✅ SÍ","❌ NO")),"")
A18: 12 | B18: CAMILLAS | F18: =IFERROR(IF(AND(ISNUMBER(D18),ISNUMBER(E18)),E18-D18,""),"") | G18: =IFERROR(IF(D18="","",IF(E18=D18,"✅ SÍ","❌ NO")),"")
... A21: 15 | B21: IMÁGENES DIAGNÓSTICAS | F21: =IFERROR(IF(AND(ISNUMBER(D21),ISNUMBER(E21)),E21-D21,""),"") | G21: =IFERROR(IF(D21="","",IF(E21=D21,"✅ SÍ","❌ NO")),"")
A22: 16 | F22: =IFERROR(IF(AND(ISNUMBER(D22),ISNUMBER(E22)),E22-D22,""),"") | G22: =IFERROR(IF(D22="","",IF(E22=D22,"✅ SÍ","❌ NO")),"")
A23: 17 | F23: =IFERROR(IF(AND(ISNUMBER(D23),ISNUMBER(E23)),E23-D23,""),"") | G23: =IFERROR(IF(D23="","",IF(E23=D23,"✅ SÍ","❌ NO")),"")
A24: 18 | F24: =IFERROR(IF(AND(ISNUMBER(D24),ISNUMBER(E24)),E24-D24,""),"") | G24: =IFERROR(IF(D24="","",IF(E24=D24,"✅ SÍ","❌ NO")),"")
A25: 19 | F25: =IFERROR(IF(AND(ISNUMBER(D25),ISNUMBER(E25)),E25-D25,""),"") | G25: =IFERROR(IF(D25="","",IF(E25=D25,"✅ SÍ","❌ NO")),"")
A26: 20 | F26: =IFERROR(IF(AND(ISNUMBER(D26),ISNUMBER(E26)),E26-D26,""),"") | G26: =IFERROR(IF(D26="","",IF(E26=D26,"✅ SÍ","❌ NO")),"")
A27: 21 | F27: =IFERROR(IF(AND(ISNUMBER(D27),ISNUMBER(E27)),E27-D27,""),"") | G27: =IFERROR(IF(D27="","",IF(E27=D27,"✅ SÍ","❌ NO")),"")
A28: 22 | F28: =IFERROR(IF(AND(ISNUMBER(D28),ISNUMBER(E28)),E28-D28,""),"") | G28: =IFERROR(IF(D28="","",IF(E28=D28,"✅ SÍ","❌ NO")),"")
A29: 23 | F29: =IFERROR(IF(AND(ISNUMBER(D29),ISNUMBER(E29)),E29-D29,""),"") | G29: =IFERROR(IF(D29="","",IF(E29=D29,"✅ SÍ","❌ NO")),"")
A30: 24 | F30: =IFERROR(IF(AND(ISNUMBER(D30),ISNUMBER(E30)),E30-D30,""),"") | G30: =IFERROR(IF(D30="","",IF(E30=D30,"✅ SÍ","❌ NO")),"")
A31: 25 | F31: =IFERROR(IF(AND(ISNUMBER(D31),ISNUMBER(E31)),E31-D31,""),"") | G31: =IFERROR(IF(D31="","",IF(E31=D31,"✅ SÍ","❌ NO")),"")
A32: 26 | F32: =IFERROR(IF(AND(ISNUMBER(D32),ISNUMBER(E32)),E32-D32,""),"") | G32: =IFERROR(IF(D32="","",IF(E32=D32,"✅ SÍ","❌ NO")),"")
A33: 27 | F33: =IFERROR(IF(AND(ISNUMBER(D33),ISNUMBER(E33)),E33-D33,""),"") | G33: =IFERROR(IF(D33="","",IF(E33=D33,"✅ SÍ","❌ NO")),"")
... A41: 35 | F41: =IFERROR(IF(AND(ISNUMBER(D41),ISNUMBER(E41)),E41-D41,""),"") | G41: =IFERROR(IF(D41="","",IF(E41=D41,"✅ SÍ","❌ NO")),"")

Sheet ⚠ REPS – Sanciones
A1: MEDIDAS DE SEGURIDAD Y SANCIONES – REPS
A2: Registre todas las medidas de seguridad y sanciones vigentes del REPS para este prestador
A3: TOTAL MEDIDAS | C3: MEDIDAS ACTIVAS | E3: LEVANTADAS | G3: EN APELACIÓN
A4: =COUNTA(B7:B100)-COUNTBLANK(B7:B100) -> -94 | C4: =COUNTIF(E7:E100,"Activa") -> 0 | E4: =COUNTIF(E7:E100,"Levantada") -> 0 | G4: =COUNTIF(E7:E100,"En Apelación") -> 0
A6: No. | B6: TIPO DE MEDIDA | C6: DESCRIPCIÓN DETALLADA | D6: FECHA | E6: ESTADO | F6: OBSERVACIONES | G6: URL ACTO ADMINISTRATIVO
A7: 1
A8: 2
A9: 3
A10: 4
A11: 5
A12: 6
A13: 7
A14: 8
A15: 9
A16: 10
A17: 11
A18: 12
... A31: 25

Sheet 📊 DASHBOARD
A1: 📊 DASHBOARD EJECUTIVO – INDICADORES DE CUMPLIMIENTO EN TIEMPO REAL
A2: Todos los indicadores se actualizan automáticamente al diligenciar las hojas de auditoría
A4: DOCUMENTOS EVALUADOS | C4: ✅ CARGADOS | E4: ⏳ EN PROCESO | G4: ❌ NO REALIZADOS | I4: ⚪ NO APLICA | K4: 🎯 % CUMPLIMIENTO | M4: 📋 HALLAZGOS ABIERTOS
A5: =COUNTA('📄 MATRIZ DOCUMENTAL'!C8:C500)-COUNTBLANK('📄 MATRIZ DOCUMENTAL'!C8:C500) -> -277 | C5: =COUNTIF('📄 MATRIZ DOCUMENTAL'!E8:E500,"✅ CARGADO") -> 0 | E5: =COUNTIF('📄 MATRIZ DOCUMENTAL'!E8:E500,"⏳ EN PROCESO") -> 108 | G5: =COUNTIF('📄 MATRIZ DOCUMENTAL'!E8:E500,"❌ NO REALIZADO") -> 0 | I5: =COUNTIF('📄 MATRIZ DOCUMENTAL'!E8:E500,"⚪ NO APLICA") -> 0 | K5: =IFERROR(COUNTIF('📄 MATRIZ DOCUMENTAL'!E8:E500,"✅ CARGADO")/MAX(1,COUNTA('📄 MATRIZ DOCUMENTAL'!C8:C500)-COUNTBLANK('📄 MATRIZ DOCUMENTAL'!C8:C500)),0) -> 0 | M5: =COUNTIF(H20:H100,"Abierto") -> 0
A7: INDICADORES DETALLADOS DE CUMPLIMIENTO
A8: 📄 Documentos Cargados / Total | I8: =IFERROR(COUNTIF('📄 MATRIZ DOCUMENTAL'!E8:E500,"✅ CARGADO")/MAX(1,COUNTA('📄 MATRIZ DOCUMENTAL'!C8:C500)-COUNTBLANK('📄 MATRIZ DOCUMENTAL'!C8:C500)),0) -> 0 | L8: =IFERROR(COUNTIF('📄 MATRIZ DOCUMENTAL'!E8:E500,"✅ CARGADO")/MAX(1,COUNTA('📄 MATRIZ DOCUMENTAL'!C8:C500)-COUNTBLANK('📄 MATRIZ DOCUMENTAL'!C8:C500)),0) -> 0
A9: 📄 Documentos En Proceso / Total | I9: =IFERROR(COUNTIF('📄 MATRIZ DOCUMENTAL'!E8:E500,"⏳ EN PROCESO")/MAX(1,COUNTA('📄 MATRIZ DOCUMENTAL'!C8:C500)-COUNTBLANK('📄 MATRIZ DOCUMENTAL'!C8:C500)),0) -> 108 | L9: =IFERROR(COUNTIF('📄 MATRIZ DOCUMENTAL'!E8:E500,"⏳ EN PROCESO")/MAX(1,COUNTA('📄 MATRIZ DOCUMENTAL'!C8:C500)-COUNTBLANK('📄 MATRIZ DOCUMENTAL'!C8:C500)),0) -> 108
A10: 📄 Documentos No Realizados / Total | I10: =IFERROR(COUNTIF('📄 MATRIZ DOCUMENTAL'!E8:E500,"❌ NO REALIZADO")/MAX(1,COUNTA('📄 MATRIZ DOCUMENTAL'!C8:C500)-COUNTBLANK('📄 MATRIZ DOCUMENTAL'!C8:C500)),0) -> 0 | L10: =IFERROR(COUNTIF('📄 MATRIZ DOCUMENTAL'!E8:E500,"❌ NO REALIZADO")/MAX(1,COUNTA('📄 MATRIZ DOCUMENTAL'!C8:C500)-COUNTBLANK('📄 MATRIZ DOCUMENTAL'!C8:C500)),0) -> 0
A11: 📄 Cumplen Resolución 3100 | I11: =IFERROR(COUNTIF('📄 MATRIZ DOCUMENTAL'!J8:J500,"✅ SÍ")/MAX(1,COUNTA('📄 MATRIZ DOCUMENTAL'!C8:C500)-COUNTBLANK('📄 MATRIZ DOCUMENTAL'!C8:C500)),0) -> 0 | L11: =IFERROR(COUNTIF('📄 MATRIZ DOCUMENTAL'!J8:J500,"✅ SÍ")/MAX(1,COUNTA('📄 MATRIZ DOCUMENTAL'!C8:C500)-COUNTBLANK('📄 MATRIZ DOCUMENTAL'!C8:C500)),0) -> 0
A12: ⚕ Servicios Coinciden REPS | I12: =IFERROR(COUNTIF('⚕ REPS – Servicios'!K9:K300,"✅ SÍ")/MAX(1,COUNTA('⚕ REPS – Servicios'!C9:C300)-COUNTBLANK('⚕ REPS – Servicios'!C9:C300)),0) -> 0 | L12: =IFERROR(COUNTIF('⚕ REPS – Servicios'!K9:K300,"✅ SÍ")/MAX(1,COUNTA('⚕ REPS – Servicios'!C9:C300)-COUNTBLANK('⚕ REPS – Servicios'!C9:C300)),0) -> 0
A13: ⚕ Servicios Cumplen Res. 3100 | I13: =IFERROR(COUNTIF('⚕ REPS – Servicios'!L9:L300,"✅ SÍ")/MAX(1,COUNTA('⚕ REPS – Servicios'!C9:C300)-COUNTBLANK('⚕ REPS – Servicios'!C9:C300)),0) -> 0 | L13: =IFERROR(COUNTIF('⚕ REPS – Servicios'!L9:L300,"✅ SÍ")/MAX(1,COUNTA('⚕ REPS – Servicios'!C9:C300)-COUNTBLANK('⚕ REPS – Servicios'!C9:C300)),0) -> 0
A14: 🏗 Capacidad Instalada Coincidente | I14: =IFERROR(COUNTIF('🏗 REPS – Capacidad'!G7:G200,"✅ SÍ")/MAX(1,COUNTA('🏗 REPS – Capacidad'!C7:C200)-COUNTBLANK('🏗 REPS – Capacidad'!C7:C200)),0) -> 0 | L14: =IFERROR(COUNTIF('🏗 REPS – Capacidad'!G7:G200,"✅ SÍ")/MAX(1,COUNTA('🏗 REPS – Capacidad'!C7:C200)-COUNTBLANK('🏗 REPS – Capacidad'!C7:C200)),0) -> 0
A15: ⚠ Medidas de Seguridad Activas / Total | I15: =IFERROR(COUNTIF('⚠ REPS – Sanciones'!E7:E100,"Activa")/MAX(1,COUNTA('⚠ REPS – Sanciones'!B7:B100)-COUNTBLANK('⚠ REPS – Sanciones'!B7:B100)),0) -> 0 | L15: =IFERROR(COUNTIF('⚠ REPS – Sanciones'!E7:E100,"Activa")/MAX(1,COUNTA('⚠ REPS – Sanciones'!B7:B100)-COUNTBLANK('⚠ REPS – Sanciones'!B7:B100)),0) -> 0
A17: REGISTRO Y SEGUIMIENTO DE HALLAZGOS
A19: No. | B19: COMPONENTE | C19: HALLAZGO | D19: CLASIFICACIÓN | E19: ACCIÓN REQUERIDA | F19: RESPONSABLE | G19: FECHA LÍMITE | H19: ESTADO | I19: EVIDENCIA / URL | J19: FECHA CIERRE | K19: IMPACTO | L19: PRIORIDAD | M19: VERIFICADO POR | N19: OBSERVACIONES
A20: 1
A21: 2
A22: 3
A23: 4
A24: 5
A25: 6
A26: 7
A27: 8
A28: 9
A29: 10
A30: 11
A31: 12
... A59: 40
A63: © 2025 AUDISALUD COLOMBIA SAS · USO INSTITUCIONAL EXCLUSIVO · Prohibida su venta, reproducción, distribución o cesión a terceros sin autorización escrita.

Sheet 📑 REPORTE EJECUTIVO
A1: INFORME EJECUTIVO DE VERIFICACIÓN Y AUDITORÍA DOCUMENTAL
A2: Generado automáticamente · Resolución 3100 de 2019 · Habilitación de Prestadores de Salud
A4: INFORMACIÓN DEL PRESTADOR
A5: Nombre / Razón Social | D5: ='🏠 PORTADA'!I5 -> 0
A6: NIT | D6: ='🏠 PORTADA'!I6 -> 0
A7: Dirección | D7: ='🏠 PORTADA'!I8 -> 0
A8: Ciudad | D8: ='🏠 PORTADA'!I9 -> 0
A9: Auditor | D9: ='🏠 PORTADA'!I15 -> 0
A10: Fecha Auditoría | D10: ='🏠 PORTADA'!I17 -> 0
A12: RESUMEN EJECUTIVO DE CUMPLIMIENTO
A13: Total documentos evaluados | G13: =COUNTA('📄 MATRIZ DOCUMENTAL'!C8:C500)-COUNTBLANK('📄 MATRIZ DOCUMENTAL'!C8:C500) -> -277
A14: Documentos CARGADOS ✅ | G14: =COUNTIF('📄 MATRIZ DOCUMENTAL'!E8:E500,"✅ CARGADO") -> 0
A15: Documentos EN PROCESO ⏳ | G15: =COUNTIF('📄 MATRIZ DOCUMENTAL'!E8:E500,"⏳ EN PROCESO") -> 108
A16: Documentos NO REALIZADOS ❌ | G16: =COUNTIF('📄 MATRIZ DOCUMENTAL'!E8:E500,"❌ NO REALIZADO") -> 0
A17: % Cumplimiento Documental | G17: =IFERROR(COUNTIF('📄 MATRIZ DOCUMENTAL'!E8:E500,"✅ CARGADO")/MAX(1,COUNTA('📄 MATRIZ DOCUMENTAL'!C8:C500)-COUNTBLANK('📄 MATRIZ DOCUMENTAL'!C8:C500)),0) -> 0
A18: Servicios que coinciden REPS ✅ | G18: =COUNTIF('⚕ REPS – Servicios'!K9:K300,"✅ SÍ") -> 0
A19: Servicios que NO coinciden ❌ | G19: =COUNTIF('⚕ REPS – Servicios'!K9:K300,"❌ NO") -> 0
A20: Capacidad instalada coincidente | G20: =COUNTIF('🏗 REPS – Capacidad'!G7:G200,"✅ SÍ") -> 0
A21: Medidas de seguridad activas | G21: =COUNTIF('⚠ REPS – Sanciones'!E7:E100,"Activa") -> 0
A22: Total hallazgos registrados | G22: =COUNTA('📊 DASHBOARD'!B20:B100)-COUNTBLANK('📊 DASHBOARD'!B20:B100) -> -81
A23: Hallazgos No Conformidad Mayor | G23: =COUNTIF('📊 DASHBOARD'!D20:D100,"No Conformidad Mayor") -> 0
A24: Hallazgos Abiertos / Pendientes | G24: =COUNTIF('📊 DASHBOARD'!H20:H100,"Abierto") -> 0
A25: Hallazgos Cerrados | G25: =COUNTIF('📊 DASHBOARD'!H20:H100,"Cerrado") -> 0
A27: CONCLUSIÓN Y FIRMA DEL AUDITOR
A37: _______________________________ Firma del Auditor | F37: _______________________________ Firma Representante Legal IPS

Sheet 📋 Catálogo REPS
A1: CATÁLOGO OFICIAL REPS – 157 SERVICIOS
A2: Solo lectura · Resolución 2003 de 2014 · Ministerio de Salud y Protección Social
A4: CÓDIGO | B4: NOMBRE DEL SERVICIO | C4: GRUPO
A5: ▶ Internación (15 servicios)
A6: 105 | B6: CUIDADO INTERMEDIO NEONATAL | C6: Internación
A7: 106 | B7: CUIDADO INTERMEDIO PEDIÁTRICO | C7: Internación
A8: 107 | B8: CUIDADO INTERMEDIO ADULTOS | C8: Internación
A9: 108 | B9: CUIDADO INTENSIVO NEONATAL | C9: Internación
A10: 109 | B10: CUIDADO INTENSIVO PEDIÁTRICO | C10: Internación
A11: 110 | B11: CUIDADO INTENSIVO ADULTOS | C11: Internación
A12: 120 | B12: CUIDADO BÁSICO NEONATAL | C12: Internación
A13: 129 | B13: HOSPITALIZACIÓN ADULTOS | C13: Internación
A14: 130 | B14: HOSPITALIZACIÓN PEDIÁTRICA | C14: Internación
A15: 131 | B15: HOSPITALIZACIÓN EN SALUD MENTAL | C15: Internación
A16: 132 | B16: HOSPITALIZACIÓN PARCIAL | C16: Internación
A17: 133 | B17: HOSPITALIZACIÓN PACIENTE CRÓNICO CON VENTILADOR | C17: Internación
... A20: 138 | B20: CUIDADO BÁSICO DEL CONSUMO DE SPA | C20: Internación
A21: ▶ Quirúrgicos (24 servicios)
A22: 201 | B22: CIRUGÍA DE CABEZA Y CUELLO | C22: Quirúrgicos
A23: 202 | B23: CIRUGÍA CARDIOVASCULAR | C23: Quirúrgicos
A24: 203 | B24: CIRUGÍA GENERAL | C24: Quirúrgicos
A25: 204 | B25: CIRUGÍA GINECOLÓGICA | C25: Quirúrgicos
A26: 205 | B26: CIRUGÍA MAXILOFACIAL | C26: Quirúrgicos
A27: 207 | B27: CIRUGÍA ORTOPÉDICA | C27: Quirúrgicos
A28: 208 | B28: CIRUGÍA OFTALMOLÓGICA | C28: Quirúrgicos
A29: 209 | B29: CIRUGÍA OTORRINOLARINGOLOGÍA | C29: Quirúrgicos
A30: 210 | B30: CIRUGÍA ONCOLÓGICA | C30: Quirúrgicos
A31: 211 | B31: CIRUGÍA ORAL | C31: Quirúrgicos
A32: 212 | B32: CIRUGÍA PEDIÁTRICA | C32: Quirúrgicos
A33: 213 | B33: CIRUGÍA PLÁSTICA Y ESTÉTICA | C33: Quirúrgicos
... A45: 245 | B45: NEUROCIRUGÍA | C45: Quirúrgicos
A46: ▶ Consulta Externa (91 servicios)
A47: 301 | B47: ANESTESIA | C47: Consulta Externa
A48: 302 | B48: CARDIOLOGÍA | C48: Consulta Externa
A49: 303 | B49: CIRUGÍA CARDIOVASCULAR | C49: Consulta Externa
A50: 304 | B50: CIRUGÍA GENERAL | C50: Consulta Externa
A51: 306 | B51: CIRUGÍA PEDIÁTRICA | C51: Consulta Externa
A52: 308 | B52: DERMATOLOGÍA | C52: Consulta Externa
A53: 309 | B53: DOLOR Y CUIDADOS PALIATIVOS | C53: Consulta Externa
A54: 310 | B54: ENDOCRINOLOGÍA | C54: Consulta Externa
...

Sheet _SVC_
A1: Internación | B1: Quirúrgicos | C1: Consulta Externa | D1: Apoyo Dx y Complementación Terapéutica | E1: Atención Inmediata
A2: CUIDADO INTERMEDIO NEONATAL | B2: CIRUGÍA DE CABEZA Y CUELLO | C2: ANESTESIA | D2: LABORATORIO CLÍNICO | E2: ATENCIÓN DEL PARTO
A3: CUIDADO INTERMEDIO PEDIÁTRICO | B3: CIRUGÍA CARDIOVASCULAR | C3: CARDIOLOGÍA | D3: QUIMIOTERAPIA | E3: URGENCIAS
A4: CUIDADO INTERMEDIO ADULTOS | B4: CIRUGÍA GENERAL | C4: CIRUGÍA CARDIOVASCULAR | D4: RADIOTERAPIA | E4: TRANSPORTE ASISTENCIAL BÁSICO
A5: CUIDADO INTENSIVO NEONATAL | B5: CIRUGÍA GINECOLÓGICA | C5: CIRUGÍA GENERAL | D5: TOMA DE MUESTRAS DE LABORATORIO CLÍNICO | E5: TRANSPORTE ASISTENCIAL MEDICALIZADO
A6: CUIDADO INTENSIVO PEDIÁTRICO | B6: CIRUGÍA MAXILOFACIAL | C6: CIRUGÍA PEDIÁTRICA | D6: SERVICIO FARMACÉUTICO | E6: ATENCIÓN PREHOSPITALARIA
A7: CUIDADO INTENSIVO ADULTOS | B7: CIRUGÍA ORTOPÉDICA | C7: DERMATOLOGÍA | D7: MEDICINA NUCLEAR
A8: CUIDADO BÁSICO NEONATAL | B8: CIRUGÍA OFTALMOLÓGICA | C8: DOLOR Y CUIDADOS PALIATIVOS | D8: LABORATORIO CITOLOGÍAS CERVICO-UTERINAS
A9: HOSPITALIZACIÓN ADULTOS | B9: CIRUGÍA OTORRINOLARINGOLOGÍA | C9: ENDOCRINOLOGÍA | D9: TERAPIA OCUPACIONAL
A10: HOSPITALIZACIÓN PEDIÁTRICA | B10: CIRUGÍA ONCOLÓGICA | C10: ENDODONCIA | D10: TERAPIA RESPIRATORIA
A11: HOSPITALIZACIÓN EN SALUD MENTAL | B11: CIRUGÍA ORAL | C11: ENFERMERÍA | D11: LABORATORIO DE HISTOTECNOLOGÍA
A12: HOSPITALIZACIÓN PARCIAL | B12: CIRUGÍA PEDIÁTRICA | C12: ESTOMATOLOGÍA | D12: HEMODIÁLISIS
A13: HOSPITALIZACIÓN PACIENTE CRÓNICO CON VENTILADOR | B13: CIRUGÍA PLÁSTICA Y ESTÉTICA | C13: GASTROENTEROLOGÍA | D13: DIÁLISIS PERITONEAL
A14: HOSPITALIZACIÓN PACIENTE CRÓNICO SIN VENTILADOR | B14: CIRUGÍA VASCULAR Y ANGIOLÓGICA | C14: GENÉTICA | D14: FISIOTERAPIA
A15: HOSPITALIZACIÓN EN CONSUMO DE SPA | B15: CIRUGÍA UROLÓGICA | C15: GERIATRÍA | D15: FONOAUDIOLOGÍA Y/O TERAPIA DEL LENGUAJE
A16: CUIDADO BÁSICO DEL CONSUMO DE SPA | B16: OTRAS CIRUGÍAS | C16: GINECOBSTETRICIA | D16: DIAGNÓSTICO VASCULAR
B17: CIRUGÍA ENDOVASCULAR NEUROLÓGICA | C17: HEMATOLOGÍA | D17: HEMODINAMIA E INTERVENCIONISMO
B18: CIRUGÍA ONCOLÓGICA PEDIÁTRICA | C18: INFECTOLOGÍA | D18: IMÁGENES DIAGNÓSTICAS - IONIZANTES
B19: CIRUGÍA DE LA MANO | C19: INMUNOLOGÍA | D19: IMÁGENES DIAGNÓSTICAS - NO IONIZANTES
B20: CIRUGÍA DE MAMA Y TUMORES TEJIDOS BLANDOS | C20: MEDICINA FAMILIAR | D20: GESTIÓN PRE-TRANSFUSIONAL
B21: CIRUGÍA DERMATOLÓGICA | C21: MEDICINA FÍSICA Y DEL DEPORTE | D21: PATOLOGÍA
B22: CIRUGÍA DE TÓRAX | C22: MEDICINA FÍSICA Y REHABILITACIÓN | D22: RADIOLOGÍA ODONTOLÓGICA
B23: CIRUGÍA GASTROINTESTINAL | C23: MEDICINA GENERAL | D23: TOMA DE MUESTRAS CERVICO-UTERINAS Y GINECOLÓGICAS
B24: CIRUGÍA PLÁSTICA ONCOLÓGICA | C24: MEDICINA INTERNA
B25: NEUROCIRUGÍA | C25: NEFROLOGÍA
C26: NEUMOLOGÍA
C27: NEUROLOGÍA
C28: NUTRICIÓN Y DIETÉTICA
C29: ODONTOLOGÍA GENERAL
C30: OFTALMOLOGÍA
C31: ONCOLOGÍA CLÍNICA
C32: OPTOMETRÍA
C33: ORTODONCIA
C34: ORTOPEDIA Y/O TRAUMATOLOGÍA
C35: OTORRINOLARINGOLOGÍA
C36: PEDIATRÍA
C37: PERIODONCIA
... C92: SEGURIDAD Y SALUD EN EL TRABAJO

Sheet _COD_
A1: Servicio | B1: Código
A2: CUIDADO INTERMEDIO NEONATAL | B2: 105
A3: CUIDADO INTERMEDIO PEDIÁTRICO | B3: 106
A4: CUIDADO INTERMEDIO ADULTOS | B4: 107
A5: CUIDADO INTENSIVO NEONATAL | B5: 108
A6: CUIDADO INTENSIVO PEDIÁTRICO | B6: 109
A7: CUIDADO INTENSIVO ADULTOS | B7: 110
A8: CUIDADO BÁSICO NEONATAL | B8: 120
A9: HOSPITALIZACIÓN ADULTOS | B9: 129
A10: HOSPITALIZACIÓN PEDIÁTRICA | B10: 130
A11: HOSPITALIZACIÓN EN SALUD MENTAL | B11: 131
A12: HOSPITALIZACIÓN PARCIAL | B12: 132
A13: HOSPITALIZACIÓN PACIENTE CRÓNICO CON VENTILADOR | B13: 133
... A158: ATENCIÓN PREHOSPITALARIA | B158: 1105

Sheet _LK_
A2: Internación | B2: GRP_Internacion
A3: Quirúrgicos | B3: GRP_Quirurgicos
A4: Consulta Externa | B4: GRP_Consulta_Externa
A5: Apoyo Dx y Complementación Terapéutica | B5: GRP_Apoyo_Dx_y_Complementacion_Terapeutica
A6: Atención Inmediata | B6: GRP_Atencion_Inmediata
