Workbook

Sheet Tabla de contenido
A2: Grupo servicio | B2: Servicio | C2: Páginas
A3: 11.1. ESTÁNDARES Y CRITERIOS APLICABLES A TODOS LOS SERVICIOS | B3: 11.1.1 TALENTO HUMANO | C3: 59 -61
B4: 11.1.2. INFRAESTRUCTURA | C4: 61 - 68
B5: 11.1.3. DOTACIÓN | C5: 68 - 71
B6: 11.1.4. MEDICAMENTOS, DISPOSITIVOS MÉDICOS E INSUMOS | C6: 71 - 73
B7: 11.1.5. PROCESOS PRIORITARIOS | C7: 73 - 77
B8: 11.1.6. HISTORIA CLÍNICA Y REGISTROS | C8: 77 - 79
B9: 11.1.7. INTERDEPENDENCIA | C9: 79
A10: 11.2. GRUPO CONSULTA EXTERNA | B10: 11.2.1. SERVICIO DE CONSULTA EXTERNA GENERAL | C10: 80-84
B11: 11.2.2. SERVICIO DE CONSULTA EXTERNA ESPECIALIZADA | C11: 85-88
B12: 11.2.3. SERVICIO DE VACUNACIÓN | C12: 88-91
B13: 11.2.4. SERVICIO DE SEGURIDAD Y SALUD EN EL TRABAJO | C13: 91-93
A14: 11.3. GRUPO APOYO DIAGNÓSTICO Y COMPLEMENTACIÓN TERAPÉUTICA | B14: 11.3.1. SERVICIO DE TERAPIAS | C14: 94-97
B15: 11.3.2. SERVICIO FARMACÉUTICO | C15: 97-101
B16: 11.3.3 SERVICIO DE RADIOLOGiA ODONTOLÓGICA | C16: 101-103
B17: 11.3.4 SERVICIO DE IMÁGENES DIAGNÓSTICAS | C17: 103-104
B18: 11.3.5 SERVICIO DE MEDICINA NUCLEAR | C18: 112-115
B19: 11.3.6 SERVICIO DE RADIOTERAPIA | C19: 116-119
B20: 11.3.7 SERVICIO DE QUIMIOTERAPIA | C20: 119-123
B21: 11.3.8 SERVICIO DE DIAGNÓSTICO VASCULAR | C21: 123-125
B22: 11.3.9 SERVICIO DE HEMODINAMIA E INTERVENCIONISMO | C22: 125-128
B23: 11.3.10 SERVICIO DE GESTIÓN PRE TRANSFUSIONAL | C23: 129-130
B24: 11.3.11. SERVICIO DE TOMA DE MUESTRAS DE LABORATORIO CLÍNICO
B25: 11.3.12 SERVICIO DE LABORATORIO CLÍNICO | C25: 132-135
B26: 11.3.13 SERVICIO DE TOMA DE MUESTRAS DE CUELLO UTERINO Y GINECOLÓGICAS | C26: 135-137
B27: 11.3.14 SERVICIO DE LABORATORIO DE CITOLOGiAS CERVICO-UTERINAS | C27: 137-138
B28: 11.3.15 SERVICIO DE LABORATORIO DE HISTOTECNOLOGIA | C28: 138-139
B29: 11.3.16 SERVICIO DE PATOLOGÍA | C29: 140-142
B30: 11.3.17 SERVICIO DE DIÁLISIS | C30: 142-146
A31: 11.4 GRUPO INTERNACIÓN | B31: 11.4.1 SERVICIO DE HOSPITALIZACIÓN | C31: 146-154
B32: 11.4.2 SERVICIO DE HOSPITALIZACIÓN PACIENTE CRÓNICO | C32: 154-162
B33: 11.4.3 SERVICIO DE CUIDADO BÁSICO NEONATAL | C33: 162-165
B34: 11.4.4 SERVICIO DE CUIDADO INTERMEDIO NEONATAL | C34: 165-168
B35: 11.4.5 SERVICIO DE CUIDADO INTENSIVO NEONATAL | C35: 168-172
B36: 11.4.6 SERVICIO DE CUIDADO INTERMEDIO PEDIÁTRICO | C36: 172-175
B37: 11.4.7 SERVICIO DE CUIDADO INTENSIVO PEDIÁTRICO | C37: 175-179
B38: 11.4.8 SERVICIO DE CUIDADO INTERMEDIO ADULTO | C38: 179-182
B39: 11.4.9 SERVICIO DE CUIDADO INTENSIVO ADULTOS | C39: 182-186
B40: 11.4.10 SERVICIO DE HOSPITALIZACIÓN EN SALUD MENTAL O CONSUMO DE SUSTANCIAS PSICOACTIVAS | C40: 186-190
B41: 11.4.11 SERVICIO DE HOSPITALIZACIÓN PARCIAL | C41: 190-195
...

Sheet Consolidado
B3: Estándares y criterios aplicables a todos los servicios | C3: Total criterios | D3: C | E3: NC | F3: NA | G3: Cumplimiento
B4: TS - Talento Humano | C4: 21 | D4: ='11.1.1TH'!C30 -> 19 | E4: ='11.1.1TH'!C31 -> 1 | F4: ='11.1.1TH'!C32 -> 1 | G4: =D4/(C4-F4) -> 0.95
B5: TS - Infraestructura | C5: 167 | D5: ='11.1.2.INF'!C202 -> 1 | E5: ='11.1.2.INF'!C203 -> 1 | F5: ='11.1.2.INF'!C204 -> 1 | G5: =D5/(C5-F5) -> 0.0060240964
B6: TS - Dotación | C6: 52 | D6: ='11.1.3.DOT'!C68 -> 1 | E6: ='11.1.3.DOT'!C69 -> 1 | F6: ='11.1.3.DOT'!C70 -> 1 | G6: =D6/(C6-F6) -> 0.019607843
B7: TS - Medicamentos, dispositivos médicos e insumos | C7: 51 | D7: ='11.1.4MD'!C65 -> 1 | E7: ='11.1.4MD'!C66 -> 1 | F7: ='11.1.4MD'!C67 -> 1 | G7: =D7/(C7-F7) -> 0.02
B8: TS - Procesos prioritarios | C8: 91 | D8: ='11.1.5.PP'!C115 -> 2 | E8: ='11.1.5.PP'!C116 -> 1 | F8: ='11.1.5.PP'!C117 -> 1 | G8: =D8/(C8-F8) -> 0.022222222
B9: TS - Historia clinica y registros | C9: 50 | D9: ='11.1.6.HCR'!C64 -> 1 | E9: ='11.1.6.HCR'!C65 -> 1 | F9: ='11.1.6.HCR'!C66 -> 1 | G9: =D9/(C9-F9) -> 0.020408163
B10: TS - Interdependencia | C10: 5 | D10: ='11.1.7INT'!C12 -> 1 | E10: ='11.1.7INT'!C13 -> 1 | F10: ='11.1.7INT'!C14 -> 1 | G10: =D10/(C10-F10) -> 0.25
B23: Grupo consulta externa | C23: Total criterios | D23: C | E23: NC | F23: NA | G23: Cumplimiento
B24: Servicio de consulta externa general | C24: 95 | D24: ='11.2.1.S_CE_G'!C161 -> 1 | E24: ='11.2.1.S_CE_G'!C162 -> 1 | F24: ='11.2.1.S_CE_G'!C163 -> 1 | G24: =D24/(C24-F24) -> 0.010638298
B25: Servicio de consulta externa especializada | C25: 39 | D25: ='11.2.2.S_CE_E'!C94 -> 1 | E25: ='11.2.2.S_CE_E'!C95 -> 1 | F25: ='11.2.2.S_CE_E'!C96 -> 1 | G25: =D25/(C25-F25) -> 0.026315789
B26: Servicio de vacunación | C26: 57 | D26: ='11.2.3.S_CE_V'!C84 -> 1 | E26: ='11.2.3.S_CE_V'!C85 -> 1 | F26: ='11.2.3.S_CE_V'!C86 -> 1 | G26: =D26/(C26-F26) -> 0.017857143
B27: Servicio de seguridad y salud en el trabajo | C27: 29 | D27: ='11.2.4.S_CE_SST'!C56 -> 1 | E27: ='11.2.4.S_CE_SST'!C57 -> 1 | F27: ='11.2.4.S_CE_SST'!C58 -> 1 | G27: =D27/(C27-F27) -> 0.035714286
B40: Grupo apoyo diagnóstico y complementación terapéutica | C40: Total criterios | D40: C | E40: NC | F40: NA | G40: Cumplimiento
B41: Servicio de terapias | C41: 44 | D41: ='11.3.1.S_TR'!C80 -> 1 | E41: ='11.3.1.S_TR'!C81 -> 1 | F41: ='11.3.1.S_TR'!C82 -> 1 | G41: =D41/(C41-F41) -> 0.023255814
B42: Servicio farmacéutico | C42: 38 | D42: =' 11.3.2.SF'!C74 -> 1 | E42: =' 11.3.2.SF'!C75 -> 1 | F42: =' 11.3.2.SF'!C76 -> 1 | G42: =D42/(C42-F42) -> 0.027027027
B43: Servicio de radiología odontológica | C43: 44 | D43: ='11.3.3.S_Rx_OD'!C72 -> 1 | E43: ='11.3.3.S_Rx_OD'!C73 -> 1 | F43: ='11.3.3.S_Rx_OD'!C74 -> 1 | G43: =D43/(C43-F43) -> 0.023255814
B44: Servicio de imágenes diagnósticas | C44: =88+31 -> 119 | D44: ='11.3.4.S_IDx'!C218 -> 1 | E44: ='11.3.4.S_IDx'!C219 -> 1 | F44: ='11.3.4.S_IDx'!C220 -> 1 | G44: =D44/(C44-F44) -> 0.0084745763
B45: Servicio de medicina nuclear | C45: 63 | D45: =' 11.3.5.S_MNuc'!C102 -> 1 | E45: =' 11.3.5.S_MNuc'!C103 -> 1 | F45: =' 11.3.5.S_MNuc'!C104 -> 1 | G45: =D45/(C45-F45) -> 0.016129032
B46: Servicio de radioterapia | C46: 82 | D46: ='11.3.6.S_Radio'!C118 -> 1 | E46: ='11.3.6.S_Radio'!C119 -> 1 | F46: ='11.3.6.S_Radio'!C120 -> 1 | G46: =D46/(C46-F46) -> 0.012345679
B47: Servicio de quimioterapia | C47: 80 | D47: ='11.3.7.S_Quimio'!C110 -> 1 | E47: ='11.3.7.S_Quimio'!C111 -> 1 | F47: ='11.3.7.S_Quimio'!C112 -> 1 | G47: =D47/(C47-F47) -> 0.012658228
B48: Servicio de diagnóstico vascular 1 | C48: 33 | D48: ='11.3.8 S_Dx VASC'!C56 -> 1 | E48: ='11.3.8 S_Dx VASC'!C57 -> 1 | F48: ='11.3.8 S_Dx VASC'!C58 -> 1 | G48: =D48/(C48-F48) -> 0.03125
B49: Servicio de diagnóstico vascular 2 | C49: 33 | D49: ='11.3.8 S_Dx VASC'!F56 -> 1 | E49: ='11.3.8 S_Dx VASC'!F57 -> 1 | F49: ='11.3.8 S_Dx VASC'!F58 -> 1 | G49: =D49/(C49-F49) -> 0.03125
B50: Servicio de diagnóstico vascular 3 | C50: 33 | D50: ='11.3.8 S_Dx VASC'!I56 -> 1 | E50: ='11.3.8 S_Dx VASC'!I57 -> 1 | F50: ='11.3.8 S_Dx VASC'!I58 -> 1 | G50: =D50/(C50-F50) -> 0.03125
B51: Servicio de diagnóstico vascular 4 | C51: 33 | D51: ='11.3.8 S_Dx VASC'!L56 -> 1 | E51: ='11.3.8 S_Dx VASC'!L57 -> 1 | F51: ='11.3.8 S_Dx VASC'!L58 -> 1 | G51: =D51/(C51-F51) -> 0.03125
B52: Servicio de diagnóstico vascular 5 | C52: 33 | D52: ='11.3.8 S_Dx VASC'!O56 -> 1 | E52: ='11.3.8 S_Dx VASC'!O57 -> 1 | F52: ='11.3.8 S_Dx VASC'!O58 -> 1 | G52: =D52/(C52-F52) -> 0.03125
B53: Servicio de diagnóstico vascular 6 | C53: 33 | D53: ='11.3.8 S_Dx VASC'!R56 -> 1 | E53: ='11.3.8 S_Dx VASC'!R57 -> 1 | F53: ='11.3.8 S_Dx VASC'!R58 -> 1 | G53: =D53/(C53-F53) -> 0.03125
B54: Servicio de diagnóstico vascular 7 | C54: 33 | D54: ='11.3.8 S_Dx VASC'!U56 -> 1 | E54: ='11.3.8 S_Dx VASC'!U57 -> 1 | F54: ='11.3.8 S_Dx VASC'!U58 -> 1 | G54: =D54/(C54-F54) -> 0.03125
B55: Servicio de hemodinamia e intervencionismo | C55: 91 | D55: ='11.3.9S_HI'!C119 -> 1 | E55: ='11.3.9S_HI'!C120 -> 1 | F55: ='11.3.9S_HI'!C121 -> 1 | G55: =D55/(C55-F55) -> 0.011111111
B56: Servicio de gestión pre transfusional | C56: 40 | D56: ='11.3.10 S_GPT'!C50 -> 1 | E56: ='11.3.10 S_GPT'!C51 -> 1 | F56: ='11.3.10 S_GPT'!C52 -> 1 | G56: =D56/(C56-F56) -> 0.025641026
B57: Servicio de toma de muestras de laboratorio clínico | C57: 29 | D57: ='11.3.11.S_TMLC'!C48 -> 1 | E57: ='11.3.11.S_TMLC'!C49 -> 1 | F57: ='11.3.11.S_TMLC'!C50 -> 1 | G57: =D57/(C57-F57) -> 0.035714286
B58: Servicio de laboratorio clínico | C58: 59 | D58: ='11.3.12.S_LC'!C81 -> 1 | E58: ='11.3.12.S_LC'!C82 -> 1 | F58: ='11.3.12.S_LC'!C83 -> 1 | G58: =D58/(C58-F58) -> 0.017241379
B59: Servicio de toma de muestras de cuello uterino y ginecológicas | C59: 42 | D59: =' 11.3.13 S_TM_CU'!C60 -> 2 | E59: =' 11.3.13 S_TM_CU'!C61 -> 0 | F59: =' 11.3.13 S_TM_CU'!C62 -> 1 | G59: =D59/(C59-F59) -> 0.048780488
B60: Servicio de laboratorio de citologías cérvico-uterinas | C60: 32 | D60: ='11.3.14.S_LCU'!C55 -> 1 | E60: ='11.3.14.S_LCU'!C56 -> 1 | F60: ='11.3.14.S_LCU'!C57 -> 1 | G60: =D60/(C60-F60) -> 0.032258065
B61: Servicio de laboratorio de histotecnología | C61: 33 | D61: ='11.3.15.S_LHT'!C46 -> 1 | E61: ='11.3.15.S_LHT'!C47 -> 1 | F61: ='11.3.15.S_LHT'!C48 -> 1 | G61: =D61/(C61-F61) -> 0.03125
B62: Servicio de patología | C62: 51 | D62: ='11.3.16.S_LPT'!C75 -> 1 | E62: ='11.3.16.S_LPT'!C76 -> 1 | F62: ='11.3.16.S_LPT'!C77 -> 1 | G62: =D62/(C62-F62) -> 0.02
B63: Servicio de diálisis | C63: 100 | D63: ='11.3.17.S_Dial'!C127 -> 1 | E63: ='11.3.17.S_Dial'!C128 -> 1 | F63: ='11.3.17.S_Dial'!C129 -> 1 | G63: =D63/(C63-F63) -> 0.01010101
B66: Grupo de internación | C66: Total criterios | D66: C | E66: NC | F66: NA | G66: Cumplimiento
B67: Servicio de hospitalización | C67: 183 | D67: ='11.4.1.S_HP'!C266 -> 1 | E67: ='11.4.1.S_HP'!C267 -> 1 | F67: ='11.4.1.S_HP'!C268 -> 1 | G67: =D67/(C67-F67) -> 0.0054945055
B68: Servicio de hospitalización paciente crónico | C68: 167 | D68: ='11.4.2.S_HP_PC'!C247 -> 1 | E68: ='11.4.2.S_HP_PC'!C248 -> 1 | F68: ='11.4.2.S_HP_PC'!C249 -> 1 | G68: =D68/(C68-F68) -> 0.0060240964
...

Sheet 11.1.1TH
B1: VOLVER A TABLA DE CONTENIDO
B2: Estandar de Talento Humano
A3: Estandar | B3: Criterios | C3: Estado | D3: Comentarios
A4: TSTH | B4: 1. El talento humano en salud y otros profesionales que se relacionan con la atención o resultados en salud de los usuarios, cuentan con los titulos, según aplique, de educación superior o certificados de aptitud ocupacional, expedidos por la entidad educativa competente. En el caso de títulos o certificados obtenidos en el extranjero, copia de la resolución de convalidación expedida por el Ministerio de Educación Nacional | C4: C
A5: TSTH | B5: 2. El talento humano en salud cuenta con copia de la resolución de autorización del ejercicio expedido por la autoridad competente o inscripción e en el ReTHUS | C5: NC
A6: TSTH | B6: 3. El prestador de servicios de salud determina la cantidad necesaria de talento humano requerido para cada uno de los servicios ofertados y prestados, de acuerdo con la capacidad instalada, la relación entre la oferta y demanda, la oportunidad en la prestación, tiempo de la atención y el riesgo en la atención. Este criterio no aplica para profesionales independientes de salud | C6: NA
A7: TSTH | B7: 4. El prestador de servicios de salud que actúe como escenario de práctica formativa en el área de la salud, cuenta con:
A8: TSTH | B8: 4.1. Convenio vigente con la institución educativa autorizada por la entidad competente | C8: C
A9: TSTH | B9: 4.2. Información documentada de los mecanismos de supervisión permanente del personal en entrnamiento | C9: C
A10: TSTH | B10: 4.3. Estudio de la capacidad instalada en el cual se dtermine el número máximo de estudiantes que simultaneamente puedan acceder por programa de formación y por jornada, para cada uno de los servicios que se utilicen como escenarios de práctica formativa en el área de la salud, estudio que debe ser elaborado teniendo en cuenta los "lineamientos de referencia para la asignación de cupos de estudiantes en escenarios clinicos" publicados por el Ministerio de Salud y Protección Social | C10: C
A11: TSTH | B11: 5. En los servicios de salud diferentes a los servicios de consulta externa especializada de dolor y cuidado paliativo, donde se atienden pacientes con enfermedades terminales, crónicas, degenerativas e irreversibles, a los cuales se les decida como conducta médica: como parte del plan integral de cuidado que gestiona el equipo de salud, o por solicitud del paciente; el manejo de dolor y cuidado paliativo, el profesional en medicina tratante cuenta con constancia de asistencia en las acciones de formación continua en el manejo de dolor y cuidado paliativo, cuando no sea especialista en dolor y cuidado paliativo | C11: C
A12: TSTH | B12: 6. El talento humano en salud de los servicios de atención del parto, cuidado intensivo y cuidado intermedio neonatal, pediátrico y adultos, cuentan con constancia de asistencia en las acciones de formación continua para la gestión del duelo | C12: C
A13: TSTH | B13: 7. En los servicios de salud donde se realicen imagenes diagnósticas por ultrasonido, cuenta con médico especialista en radiologia e imagenes diagnósticas también podrán realizar imagenes diagnósticas aquellos médicos especialistas, quienes en su pensum o formación académica hayan adquirido los conocimientos del manejo e interpretación del espectro electromagnetico, del ultrasonido especialmente, así como de la radiaciones ionizantes para establecer el diagnóstico o el tratamiento de las enfermedades inherentes a su especialidad, para lo cual deberá acreditar el respectivo certificado. | C13: C
A14: TSTH | B14: 8. Los profesionales de la medicina de los servicios de hospitalización de baja, mediana y alta complejidad, hospitalización paciente crónico con y sin ventilador, cuidados intensivos neonatales, pediátricos y adultos; urgencias, y servicios del grupo quirurgico en modalidad intramural,cuentan con certificación vigente de aprobación de la evaluación de competencias esenciales para el cuidado de la donante expedida por el Instituto Nacional de Salud. | C14: C
A15: TSTH | B15: 9. Las instituciones prestadoras de servicios de salud con servicios de cuidado intensivo pediatrico y adulto que adicionalmente habiliten servicio quirurgico de neurocirugía, tienen disponibilidad de coordinador operativo de trasplantes. | C15: C
A16: TSTH | B16: 10. El talento humano en salud de los servicios de salud de los grupos de consulta externa, internación y el servicio de urgencias, cuentan con constancia de asistencia en las acciones de formación continua en la atención integral en salud de las personas victimas de violencia sexual. | C16: C
A17: TSTH | B17: 11. El talento humano en salud de los servicios de transporte asistencial, atención prehospitalaria y urgencias, cuentasn con constancia de asistencia en las acciones de formación continua en la atención a personas víctimas de ataques con agentes químicos. | C17: C
A18: TSTH | B18: 12. Cuando en un servicio de salud se realicen "pruebas en punto de atención del paciente - (point of care testing - POCT)", el talento humano en salud qeu las realice, a excepción del profesional en bacteriologia cuenta con constancia de asistencia en las acciones de formación continua en la atención a personas víctimas de ataques con agentes químicos. | C18: C
A19: TSTH | B19: 13. Procedimientos bajo sedación:
A20: TSTH | B20: 13.1 Cuando fuera de salas de cirugía, se realicen procedimientos bajo sedación Grado I y II, adicional al profesional de salud que realiza el procedimiento, cuenta con:
A21: TSTH | B21: 13.1.1. Profesional en la medicina especialista en anestesiologia, o profesional de la medicina o profesional en odontologia, según aplique, el cual será el encargado de administrar el medicamento y realizar el monitoreo continuo del paciente (registro de signos vitales y la respuesta a la sedación) | C21: C
A22: TSTH | B22: 13.1.2. Todos los profesionales, a excepción del profesional de la medicina especialista en anestesiologia, deben demostrar constancia de asistencia a curso de formación continua en soporte vital básico y sedación | C22: C
A23: TSTH | B23: 13.1.3 Para sedacción con óxido nitroso en odontologia, el profesional de la odontología cuenta con constancia de asistencia en las acciones de formación continua para uso clínico y práctico de este gas. | C23: C
A24: TSTH | B24: 13.2. Cuando fuera de las salas de cirugia, se realicen procedimientos bajo sedación grado III, adicional al profesional de salud que realiza el procedimiento, cuenta con profesional de la medicina con especialidad médico - quirúrgica, quién será el responsable de administrar la sedación | C24: C
A25: TSTH | B25: 13.3. Cuando fuera de las salas de cirugía, se realicen procedimientos bajo sedación grado IV, adicional al profesional de salud que realiza el procedimiento, cuenta con profesional de la medicina especialisa en anestesiologia, quién será el responsable de administrar la sedación | C25: C
A26: TSTH | B26: 13.4 Cuenta con profesional de la medicina especialista en anestesiologia cuando la atención de trate de pacientes con caracteristicas particulares: poco colaboradores; edades extremas; con enfermedades severas:cardíacas, pulmonares, hepáticas, renales o del sistema nervioso central;cualquier alteración del grado de consciencia, con obesidad mórbida, con apnea del sueño, embarazadas, o quienes abusan del alcohol o de las drogas; antecedentes de sedación fallida o que presentaron efectos adversos a algún medicamento utilizado en la sedación, por tener un elevado riesgo de desarrollar complicaciones relacionadas con la sedación analgesia | C26: C
A27: TSTH | B27: Modalidad de telemedicina prestador remisor - prestador de referencia
A28: TSTH | B28: 14. Adicional a los criterios del estándar de talento humano enunciados que le aplique, el talento humano en salud que preste directamente un servicio de salud bajo la modalidad telemedicina cuentan con constancia de asistencia en las acciones de formación continua en el manejo de tecnología utilizada por el prestador, los procesos y herramientas inherentes a la prestación de servicios bajo esta modalidad | C28: C
B30: CUMPLE | C30: =COUNTIF($C$4:$C$28,"C") -> 19
B31: NO CUMPLE | C31: =COUNTIF($C$4:$C$28,"NC") -> 1
B32: NO APLICA | C32: =COUNTIF($C$4:$C$28,"NA") -> 1

Sheet 11.1.2.INF
B1: VOLVER A TABLA DE CONTENIDO
B2: Estandar de Infraestructura
A3: Estandar | B3: Criterios | C3: Estado | D3: Comentarios
A4: TSINF | B4: Edificaciones de uso exclusivo en salud
A5: TSINF | B5: 1. Los servicios de salud de urgencias, de atención del parto, hospitalarios y de cirugía que realicen procedimientos quirúrgicos no ambulatorios, solo se pueden prestar en edificaciones de uso exclusivo de salud. | C5: C
A6: TSINF | B6: 2. Los servicios de salud de: urgencias, cirugía y del grupo de internación, así como en los servicios de salud donde se realice el proceso de esterilización, deben contar con ambiente de aseo de uso exclusivo | C6: NC
A7: TSINF | B7: 3. Cuando en una edificación de uso exclusivo de salud funcione más de un prestador de servicios de salud con servicios de los grupos de consulta externa y apoyo diagnóstico y complementación terapeutica, cada prestador cuenta con infraestructura separada delimitada fisicamente. Se pueden compartir los siguientes ambientes y áreas: aseo, salas de espera y unidades sanitarias. | C7: NA
A8: TSINF | B8: 4. Las edificaciones donde se presten servicios de salud de urgencias y del grupo de internación, cuentan con tanque de almacenamientode agua para el consumo humano que garantice como mínimo una reserva de 24 horas de servicio continuo, calculando con base en el consumo de 600 lt por cama/camilla al día.
A9: TSINF | B9: 5. Cuando el prestador de servicios de salud cuente con mas de una infraestructura y estas se puedan vincular funcionalmente entre si, lo harán mediante tunel o puente cubierto, o muro(s) colindante(s) que cuenten con acceso (s) que intercomuniquen las infraestructuras, de uso exclusivo del prestador y adicionalmente cumplen con las siguientes caracteristicas:
A10: TSINF | B10: 5.1. Ancho que permita la movilización de camas, camillas, sillas de ruedas, equipos biomédicos y personal para el traslado de los pacientes en condiciones seguras.
A11: TSINF | B11: 5.2. El piso del túnel o puente debe ser uniforme y de material antideslizante o con elementos que garanticen esta propiedad en todo su recorrido, con pasamanos d a ambos lados y con protecciones laterales hacia espacios libres.
A12: TSINF | B12: 5.3. Lo anterior siempre y cuando la norma urbanística de la jurisdicción donde se localizan las sedes hayan aprobado esta forma de vinculación funcional entre las mismas.
A13: TSINF | B13: 5.4. Esta edificación se podrá habilitar como una o varias sedes, de acuerdo con lo que determine el prestador de servicios de salud
A14: TSINF | B14: Edificaciones de uso mixto
A15: TSINF | B15: 6. Cuando en una edificación de uso mixto funcione más de un prestador de servicios de salud, cada uno cuenta con infraestructura separada y delimitada físicamente. Se pueden compartir las salas de espera y las unidades sanitarias.
A16: TSINF | B16: 7. En edificaciones de uso mixto pueden funsionar los prestadores de servicios de salud que oferten y presten servicios de los grupos de consulta externa. de apoyo diagnóstico y complementación terapeutica y los servicios del grupo quirurgico que realicen exclusivamente procedimientos de cirugia ambulatoria.
A17: TSINF | B17: Edificaciones de uso exclusivo en salud y edificaciones de uso mixto
A18: TSINF | B18: 8. Los prestadores de servicios de salud ubicados en edificaciones de hasta tres (3) pisos o niveles contados a partir del nivel más bajo construido, y que funcione en segundo o tercer nivel o piso, cuentan con ascensor o rampa o sistema alternativo de elevación. El sistema alternativo de elevación no puede ser utilizado cuando se presten servicios hospitalarios, cirugía, urgencias o de atención del parto.
A19: TSINF | B19: 9. Los sistemas alternativos de elevación deben cumplir con las siguientes condiciones:
... A200: TSINF | B200: 53.5. Nivel de iluminación homogénea.
B202: CUMPLE | C202: =COUNTIF($C$5:$C$200,"C") -> 1
B203: NO CUMPLE | C203: =COUNTIF($C$5:$C$200,"NC") -> 1
B204: NO APLICA | C204: =COUNTIF($C$5:$C$200,"NA") -> 1

Sheet 11.1.3.DOT
B1: VOLVER A TABLA DE CONTENIDO
B2: Estandar de Dotación
A3: Estandar | B3: Criterios | C3: Estado | D3: Comentarios
A4: TSDOT | B4: 1. El prestador de servicios de salud cuenta con el registro de la relación de los equipos biomédicos requeridos para la prestación de servicios de salud, este registro cuenta como mínimo con la siguiente información:
A5: TSDOT | B5: 1.1. Nombre del equipo biomédico. | C5: C
A6: TSDOT | B6: 1.2. Marca. | C6: NC
A7: TSDOT | B7: 1.3. Modelo. | C7: NA
A8: TSDOT | B8: 1.4. Serie.
A9: TSDOT | B9: 1.5. Registro sanitario para dispositivos médicos o permiso de comercialización para equipos biomédicos de tecnología controlada, cuando lo requiera.
A10: TSDOT | B10: 1.6. Clasificación por riesgo, cuando el equipo lo requiera.
A11: TSDOT | B11: 2. El prestador de servicios de salud garantiza las condiciones técnicas de calidad de los equipos biomédicos, para lo cual cuenta con:
A12: TSDOT | B12: 2.1. Programa de mantenimiento preventivo de los equipos biomédicos, que incluya el cumplimiento de las recomendaciones establecidas por el fabricante o de acuerdo con el protocolo de mantenimiento que tenga definido el prestador, éste último cuando no esté definido por el fabricante.
A13: TSDOT | B13: 2.2. Hoja(s) de vida del(los) equipo(s) biomédico(s), con los registros de los mantenimientos preventivos y correctivos, según corresponda.
A14: TSDOT | B14: 3. El prestador de servicios de salud cuenta con un programa de capacitación en el uso de dispositivos médicos cuando éstos lo requieran, el cual puede ser desarrollado por el fabricante, importador o por el mismo prestador.
A15: TSDOT | B15: 4. La dotación de los servicios de salud está en concordancia con lo definido por el prestador en el estándar de procesos prioritarios.
A16: TSDOT | B16: 5. La suficiencia de equipos biomédicos está relacionada con la frecuencia de uso de los mismo, incluyendo los tiempos del proceso de esterilización, cuando aplique.
A17: TSDOT | B17: 6. El mantenimiento de los equipos biomédicps es ejecutado por el talento humano profesional, tecnólogo o técnico en áreas relacionadas. Este mantenimiento puede ser realizado directamente por el prestador de servicios de salud o mediante contrato o convenio con un tercero.
A18: TSDOT | B18: 7. Los prestadores que oferten servicios de salud en modalidad extramural no pueden elaborar ni adaptar dispositivos médicos sobre medida.
A19: TSDOT | B19: 8. Los servicios de salud que requieren carro de paro, cuenta con la siguiente dotación:
... A66: TSDOT | B66: 17.2.2. Las pantallas o monitores grado médico utilizados para el despliegue de imágenes cuentan con una distancia máxima de 0.19 milímetros entre pixeles (dot pitch), resolución mínima de 1024 x 768 pixeles, como mínimo un ratio de contraste de 500:1 y mínimo de luminancia (brillo) de 250 cd/m2 que permita garantizar la interpretación adecuada de la información recibida.
B68: CUMPLE | C68: =COUNTIF($C$5:$C$66,"C") -> 1
B69: NO CUMPLE | C69: =COUNTIF($C$5:$C$66,"NC") -> 1
B70: NO APLICA | C70: =COUNTIF($C$5:$C$66,"NA") -> 1

Sheet 11.1.4MD
B1: VOLVER A TABLA DE CONTENIDO
B2: Estandar de Medicamentos, dispositivos médicos e insumos
A3: Estandar | B3: Criterios | C3: Estado | D3: Comentarios
A4: TSMD | B4: 1. El prestador de servicios de salud lleva registros con la información de todos los medicamentos para uso humano requeridos en la prestación de los servicios que oferte; dichos registros cuentan con la siguiente información:
A5: TSMD | B5: 1.1. Principio activo. | C5: C
A6: TSMD | B6: 1.2. Forma farmacéutica. | C6: NC
A7: TSMD | B7: 1.3. Concentración | C7: NA
A8: TSMD | B8: 1.4. Lote.
A9: TSMD | B9: 1.5. Fecha de vencimiento.
A10: TSMD | B10: 1.6. Presentación comercial.
A11: TSMD | B11: 1.7. Unidad de medida.
A12: TSMD | B12: 1.8. Registro sanitario vigente o permiso cuando se autorice, expedido por el Invima.
A13: TSMD | B13: 2. Los dispositivos médicos de uso humano requeridos para la prestación de los servicios de salud cuentan con información documentada que dé cuenta de la verificación y seguimiento de la siguiente información:
A14: TSMD | B14: 2.1. Descripción.
A15: TSMD | B15: 2.2. Marca del dispositivo.
A16: TSMD | B16: 2.3. Serie (cuando le aplique).
A17: TSMD | B17: 2.4. Presentación comercial.
A18: TSMD | B18: 2.5. Registro sanitario vigente o permiso de comercialización expedido por el Invima.
A19: TSMD | B19: 2.6. Clasificación por riesgo (información consignada en el registro sanitario o permiso de comercialización).
... A62: TSMD | B62: 17. El prestador de servicio de salud cumple con los criterios que le apliquen del presente estándar.
B65: CUMPLE | C65: =COUNTIF($C$5:$C$62,"C") -> 1
B66: NO CUMPLE | C66: =COUNTIF($C$5:$C$62,"NC") -> 1
B67: NO APLICA | C67: =COUNTIF($C$5:$C$62,"NA") -> 1

Sheet 11.1.5.PP
B1: VOLVER A TABLA DE CONTENIDO
B2: Estandar de Procesos Prioritarios
A3: Estandar | B3: Criterios | C3: Estado | D3: Comentarios
A4: TSPP | B4: 1. El prestador de servicios de salud cuenta con una política de seguridad del paciente acorde con los lineamientos expedidos por el Ministerio de Salud y Protección Social. | C4: C
A5: TSPP | B5: 2. El prestador de servicios de salud realiza actividades encaminadas a gestionar la seguridad del paciente. | C5: NC
A6: TSPP | B6: 3. El prestador de servicios de salud cuenta con un comité o instancia que orienta y promueve la política de seguridad del paciente, el control de infecciones y ta optimización del uso de antibióticos, cuando tos prescriba o administre. En el caso de profesionales independientes de salud podrá ser el mismo prestador. | C6: NA
A7: TSPP | B7: 4. El prestador de servicios de salud adopta y realiza las siguientes prácticas seguras, según aplique a su servicio de salud y cuenta con información documentada para:
A8: TSPP | B8: 4.1. Asegurar la correcta identificación del paciente en los procesos asistenciales. (que incluya como mínimo dos identificadores: nombre completo y número de identificación)
A9: TSPP | B9: 4.2. Gestionar y desarrollar una adecuada comunicación entre las personas que atienden y cuidan a los pacientes que incluyan enfoques diferenciales.
A10: TSPP | B10: 4.3. Detectar, prevenir y reducir infecciones asociadas con la atención en salud (que incluya protocolo de higiene de manos o higienización con soluciones a base de alcohol).
A11: TSPP | B11: 4.4. Detectar, ana!izar y gestionar eventos adversos.
A12: TSPP | B12: 4.5. Garantizar la funcionalidad de los procedimientos de consentimiento informado.
A13: TSPP | B13: 4.6. Mejorar la seguridad en la utilización de medicamentos, en los servicios donde aplique.
A14: TSPP | B14: 4.7. Prevenir y reducir la frecuencia de caídas, en los servicios donde aplique.
A15: TSPP | B15: 4.8. Garantizar la atención segura de ta gestante y el recién nacido, en los servicios donde aplique.
A16: TSPP | B16: 4.9. Prevenir complicaciones asociadas a disponibilidad y manejo de sangre, componentes y a la transfusión sanguínea, en los servicios donde aplique.
A17: TSPP | B17: 4.10. Prevenir úlceras por presión, en los servicios donde aplique.
A18: TSPP | B18: 4.11. Mejorar la seguridad en los procedimientos quirúrgicos, en los servicios donde aplique. | C18: C
A19: TSPP | B19: 5. El prestador de servicios de salud promueve la cultura de seguridad del paciente que involucra a todo el personal de manera sistemática con un enfoque educativo no punitivo mediante:
A20: TSPP | B20: 5.1. Capacitación del personal en el tema de seguridad del paciente y en los principales riesgos de la atención.
A21: TSPP | B21: 5.2. Actividades donde se ilustra al paciente y sus allegados en el autocuidado de su seguridad.
A22: TSPP | B22: 6. El prestador de servicios de salud cuenta con información documentada de las actividades y procedimientos que se realizan en el servicio acordes con su objeto, alcance y enfoque diferencial, mediante guías de práctica clínica- GPC, procedimientos de atención, protocolos de atención y otros documentos que el prestador de servicios de salud determine, dicha información incluye talento humano, equipos biomédicos, medicamentos y dispositivos médicos e insumos requeridos.
A23: TSPP | B23: 7. La información documentada es conocida mediante acciones de formación continua por el talento humano encargado y responsable de su aplicación, incluyendo el talento humano en entrenamiento, y existe evidencia de su socialización.
A24: TSPP | B24: 8. Las guías de práctica clínica y protocolos a adoptar son en primera medida los que disponga el Ministerio de Salud y Protección Social. En caso de no estar disponibles, o si existe nueva evidencia científica que actualice alguna o algunas de las recomendaciones de las guías de práctica clínica o requerimientos de los protocolos, el prestador de servicios de salud adopta, adapta o desarrolla guías de práctica clínica o protocolos basados en evidencia científica, publicados nacional o internacionalmente.
A25: TSPP | B25: 9. El prestador de servicios de salud de acuerdo con las patologías más frecuentes en el servicio define la guía o guías de práctica clínica a adoptar, o adaptar o desarrollar.
A26: TSPP | B26: 10. El prestador de servicios de salud cuenta con información documentada de la adopción, o adaptación o desarrollo de guías práctica clínica o protocolos basados en evidencia científica.
A27: TSPP | B27: 11. Los servicios de salud donde se atiendan pacientes con enfermedades terminales, crónicas, degenerativas e irreversibles, a los cuales se determine el manejo del dolor y cuidado paliativo, cuentan con información documentada para su manejo.
A28: TSPP | B28: 12. El prestador de servicios de salud cuenta con la siguiente información documentada:
A29: TSPP | B29: 12.1. Detección, prevención y disminución del riesgo de accidentes e incidentes de carácter radiológico, en los servicios donde aplique.
A30: TSPP | B30: 12.2. Aseo, limpieza y desinfección de áreas y superficies.
... A112: TSPP | B112: 32. Adicional a los criterios solicitados para el prestador remisor, cuenta con información documentada de las actividades y procedimientos de los servicios que oferte, acordes con su objeto, alcance y enfoque diferencial, mediante guías de práctica clínica- GPC, procedimientos de atención, protocolos de atención y otros documentos que el prestador de servicios de salud determine, dicha información incluye talento humano, equipos biomédicos, medicamentos y dispositivos médicos e insumos requeridos.
B115: CUMPLE | C115: =COUNTIF($C$4:$C$112,"C") -> 2
B116: NO CUMPLE | C116: =COUNTIF($C$4:$C$112,"NC") -> 1
B117: NO APLICA | C117: =COUNTIF($C$4:$C$112,"NA") -> 1

Sheet 11.1.6.HCR
B1: VOLVER A TABLA DE CONTENIDO
B2: Estandar de Historia Clínica y Registros
B3: Modalidades intramural, extramural: unidad movil, domicialiria, jornada de salud y telemedicina prestador remisor - prestador de referencia.
A4: Estandar | B4: Criterios | C4: Estado | D4: Comentarios
A5: TSHCR | B5: 1. Toda atención de primera vez a un usuario debe incluir el proceso de apertura de historia clínica. Todos los pacientes atendidos cuentan con historia clínica. | C5: C
A6: TSHCR | B6: 2. El prestador de servicios de salud cuenta con procedimientos para utilizar una historia única y para el registro de entrada y salida de historias del archivo físico. Ello implica que el prestador de servicios de salud cuente con un mecanismo para unificar la información de cada paciente y su disponibilidad para el equipo de salud. | C6: NC
A7: TSHCR | B7: 3. Los medios electrónicos para la gestión de la historia clínica garantizan la confidencialidad y seguridad, así como el carácter permanente de registrar en ésta y en otros registros asistenciales, sin que se puedan modificar los datos una vez se guarden los registros. | C7: NA
A8: TSHCR | B8: 4. Las historias clínicas cuentan con los componentes y los contenidos mínimos definidos en la normatividad que regula la materia
A9: TSHCR | B9: 5. La historia clínica y los registros asistenciales se diligencian en forma clara, legible, sin tachones, enmendaduras, intercalaciones, sin dejar espacios en blanco y sin utilizar siglas.
A10: TSHCR | B10: 6. Cada anotación lleva la fecha y hora en la que se realiza, con el nombre completo y firma del autor de la misma.
A11: TSHCR | B11: 7. El diligenciamiento de los registros de atención de la historia clínica se realiza simultánea o inmediatamente después de la atención en salud.
A12: TSHCR | B12: 8. La historia clínica y demás registros son conservados en archivo único garantizando la custodia y confidencialidad de los documentos o registros protegidos legalmente por reserva.
A13: TSHCR | B13: 9. El prestador de servicios de salud cuenta con un procedimiento de consentimiento informado que incluye mecanismos para verificar su aplicación, para que el paciente o su responsable, aprueben o no documentalmente, el procedimiento e intervención en salud a que va a ser sometido, previa información de los beneficios, riesgos, alternativas e implicaciones del acto asistencial
A14: TSHCR | B14: 10. Cuando el prestador de servicios de salud utilice mecanismos electrónicos, ópticos o similares para generar, recibir, almacenar, o disponer datos de la historia clínica y para conservarlos, debe avalar que el mecanismo utilizado cumple con características de: autenticidad, fiabilidad, integridad y disponibilidad del documento, de acuerdo con lo establecido en la normatividad vigente expedida por el Archivo General de la Nación, la Superintendencia de Industria y Comercio y el Ministerio de Tecnologías de información y Comunicaciones, para lo cual, el prestador presentará un documento firmado por un ingeniero de sistemas con tarjeta profesional vigente, certificando que el mecanismo usado por el prestador cumple con la normatividad mencionada
A15: TSHCR | B15: Cuenta con los siguientes registros, cuando los prestadores de servicios de salud realicen el proceso de esterilización dentro del servicio y fuera de centrales de esterilización:
A16: TSHCR | B16: 11.1. Actividades documentadas y realizadas en el procedimiento de reúso de dispositivos médicos acorde con las recomendaciones del fabricante, incluyendo el número de reúsos por cada dispositivo esterilizado.
A17: TSHCR | B17: 11.2. Registro de cargas.
A18: TSHCR | B18: 11.3. Resultados del control de calidad.
A19: TSHCR | B19: 11.4. Listas del contenido de los paquetes que se esterilizan.
... A32: TSHCR | B32: 13.1. Registro de donantes detectados
B33: 13.2. Registro de consulta del documento de voluntad anticipada de todos los pacientes facellidos
A34: TSHCR | B34: 13.3. Registros en la historia clínica de la información sobre el proceso de donación efectuado por los profesionales de salud inscritos ante el Instituto Nacional de Salud
A35: TSHCR | B35: Modalidad Extramural
A36: TSHCR | B36: 14. La historia clínica utilizada en la modalidad extramural es custodiada por el prestador de servicios de salud que oferta y presta el servicio de salud en la modalidad extramural y cuenta con los siguientes registros:
A37: TSHCR | B37: Modalidad Extramural Domiciliaria
A38: TSHCR | B38: 14.1. Valoración de ingreso con el respectivo plan de tratamiento
A39: TSHCR | B39: 14.2. Nombre de los pacientes atendidos
A40: TSHCR | B40: 14.3. Registros de referencia y contrarreferencia, cuando se requieran
A41: TSHCR | B41: 14.4. Cuidados por parte del personal de salud
A42: TSHCR | B42: 14.5. Cuidados encargados a la familia cuando aplique
A43: TSHCR | B43: Modalidad Extramural Jornada de Salud y Unidad Móvil
A44: TSHCR | B44: 14.6. Registro de rutas, horarios y frecuencias de la prestación de los servicios ofertados
A45: TSHCR | B45: 14.7. Nombre de los pacientes atendidos.
... A61: TSHCR | B61: 18. Registro de las atenciones realizadas en la modalidad de telemedicina
B64: CUMPLE | C64: =COUNTIF($C$5:$C$61,"C") -> 1
B65: NO CUMPLE | C65: =COUNTIF($C$5:$C$61,"NC") -> 1
B66: NO APLICA | C66: =COUNTIF($C$5:$C$61,"NA") -> 1

Sheet 11.1.7INT
B1: VOLVER A TABLA DE CONTENIDO
B2: Estandar de Interdependencia
A3: Estandar | B3: Criterios | C3: Estado | D3: Comentarios
A4: TSINT | B4: 1. Cuando el servicio interdependiente sea contratado, debe mediar un contrato o un acuerdo escrito entre las dos partes, en el que se establezca que el servicio interdependiente apoya el servicio principal, estableciendo como mínimo:
A5: TSINT | B5: 1.1 Calidad en la entrega de los productos | C5: C
A6: TSINT | B6: 1.2. Procedimientos documentados de atención en cada servicio independiente | C6: NC
A7: TSINT | B7: 1.3 Tiempos de entrega de los productos | C7: NA
A8: TSINT | B8: 1.4 Supervisión al contratista que garantice la seguridad del resultado del producto contratado.
A9: TSINT | B9: 2. Cuando fuera de salas de cirugía, se realicen procedimientos bajo sedación y monitorización electroencelfalografica con video y radio; el prestador de servicios de salud tendrá disponibilidad del servicio de transporte asistencial
B12: CUMPLE | C12: =COUNTIF($C$5:$C$9,"C") -> 1
B13: NO CUMPLE | C13: =COUNTIF($C$5:$C$9,"NC") -> 1
B14: NO APLICA | C14: =COUNTIF($C$5:$C$9,"NA") -> 1

Sheet 11.2.1.S_CE_G
B1: VOLVER A TABLA DE CONTENIDO
B2: Grupo Consulta Externa
B3: Servicio de Consulta Externa General
A4: Estandar | B4: Criterios | C4: Estado | D4: Comentarios
A5: CEG_TH | B5: Complejidad baja
A6: CEG_TH | B6: Modalidad intramural, extramural unidad móvil, jornada de salud y domiciliaria
A7: CEG_TH | B7: 1. Cumple con los criterios que le sean aplicables de todos los servicios y adicionalmente. | C7: C
A8: CEG_TH | B8: 2. Cuenta con el profesional de la salud de acuerdo con el servicio a ofertar. | C8: NC
A9: CEG_TH | B9: 3. Cuando se oferte la estrategia para el majo de la Enfermedad Respiratoria Aguda (ERA), el servicio tiene disponibilidad de:
A10: CEG_TH | B10: 3.1. Profesional de la medicina. | C10: NA
A11: CEG_TH | B11: 3.2. Profesional de la enfermería o terapia respiratoria o fisioterapia.
A12: CEG_TH | B12: Modalidad telemedicina
A13: CEG_TH | B13: Categoría interactiva y no interactiva-prestador de referencia
A14: CEG_TH | B14: 4. Cumple con los criterios que le sean aplicables de todos los servicios y adicionalmente, cuenta con:
A15: CEG_TH | B15: 4.1. Profesional de la salud de acuerdo con el servicio a ofertar.
A16: CEG_TH | B16: Categoria telexperticia- prestador de remisor
A17: CEG_TH | B17: 5. Cumple con los criterios que le sean aplicables de todos los servicios y adicionalmente:
A18: CEG_TH | B18: 5.1. Cuando se realice telexperticia entre profesionales de la salud cuenta con el profesional de la salud de acuerdo con el servicio a ofertar.
A19: CEG_TH | B19: 5.2. Cuando realice telexperticia entre personal de salud no profesional y un profesional de la salud, el prestador remisor cuenta con técnico, tecnólogo o auxiliar que atiende presencialmente al usuario.
A20: CEG_TH | B20: Categoria telexperticia-prestador de referencia
A21: CEG_TH | B21: 6. Cumple con los criterios que le sean aplicables de todos los servicios y adicionalmente cuenta con profesional de la salud que atiende a distancia, de acuerdo con el servicio a ofertar.
A22: CEG_TH | B22: Categoría telemonitoreo-prestador de referencia
... A158: CEG_INT | B158: 44. No aplica
B161: CUMPLE | C161: =COUNTIF($C$5:$C$158,"C") -> 1
B162: NO CUMPLE | C162: =COUNTIF($C$5:$C$158,"NC") -> 1
B163: NO APLICA | C163: =COUNTIF($C$5:$C$158,"NA") -> 1

Sheet 11.2.2.S_CE_E
B1: VOLVER A TABLA DE CONTENIDO
B2: Grupo Consulta Externa
B3: Servicio de Consulta Externa Especializada | C3: Servicio xxx
A4: Estandar | B4: Criterios | C4: Estado | D4: Comentarios
A5: CEE_TH | B5: Complejidad mediana
A6: CEE_TH | B6: Modalidades intramural, extramural unidad móvil, jornada de salud y domiciliaria
A7: CEE_TH | B7: 1. Cumple con los criterios definidos para el servicio de consulta externa general y adicionalmente cuenta con: | C7: C
A8: CEE_TH | B8: 1.1. Profesional de la salud con titulo de especialista, según los programas académicos autorizados por el Ministerio de Educación Nacional. | C8: NC
A9: CEE_TH | B9: 1.2. Para medicina alternativa y terapias alternativas y complementarias, cuenta con profesional de la salud con título de especialista en el ámbito de su disciplina, para lo cual deberá acreditar la respectiva certificación académica de esa norma de competencia, expedida por una institución de educación superior legalmente reconocida por el Estado y de acuerdo con lo documentado por el prestador de servicios de salud en el estándar de procesos prioritarios. | C9: NA
A10: CEE_TH | B10: Modalidad telemedicina
A11: CEE_TH | B11: Categoría interactiva y no interactiva-prestador de referencia
A12: CEE_TH | B12: 2. Cumple con los criterios que le sean aplicables de todos los servicios y adicionalmente, cuenta con:
A13: CEE_TH | B13: Profesional de la salud con título de especialista de acuerdo con el servicio a o ofertar
A14: CEE_TH | B14: Categoría telexperticia -prestador remisor
A15: CEE_TH | B15: 3. Cumple con los criterios que le sean aplicables de todos los servicios y adicionalmente:
A16: CEE_TH | B16: 3.1. Cuando se realice telexperticia entre profesionales de la salud cuenta con el profesional de salud con título de especialista de acuerdo con el servicio a ofertar.
A17: CEE_TH | B17: 3.2. Cuando realice telexperticia entre personal de salud no profesional y un profesional de la salud con título de especialista, el prestador remisor cuenta con técnico, tecnólogo o auxiliar que atiende presencialmente al usuario.
A18: CEE_TH | B18: Categoría telexperticia-prestador de referencia
A19: CEE_TH | B19: 4. Cumple con los criterios que le sean aplicables de todos los servicios y adicionalmente cuenta con profesional de la salud con título de especailista que atiende a distancia, de acuedo con el servicio a ofertar.
A20: CEE_TH | B20: Categoría telemonitoreo-prestador referencia
A21: CEE_TH | B21: 5. Cumple con los criterios que le sean aplicables de todos los servicios y adicionalmente cuenta con el personal de salud profesional con título de especialista que se requiera para realizar el telemonitoreo de acuerdo con lo documentado por el prestador de servicios de salud en el estándar de procesos prioritarios.
... A91: CEE_ INT | B91: 30. No aplica
B94: CUMPLE | C94: =COUNTIF($C$5:$C$91,"C") -> 1
B95: NO CUMPLE | C95: =COUNTIF($C$5:$C$91,"NC") -> 1
B96: NO APLICA | C96: =COUNTIF($C$5:$C$91,"NA") -> 1

Sheet 11.2.3.S_CE_V
B1: VOLVER A TABLA DE CONTENIDO
B2: Grupo Consulta Externa
B3: Servicio de Vacunación
A4: Estandar | B4: Criterios | C4: Estado | D4: Comentarios
A5: CEV_TH | B5: Complejidad baja
A6: CEV_TH | B6: Modalidades intramural, extramural unidad móvil, jornada de salud y domiciliaria
A7: CEV_TH | B7: 1. Cumple con los criterios que le sean aplicables de todos los servicios y adicionalmente, cuenta con: | C7: C
A8: CEV_TH | B8: 1.1 Profesional de la medicina o profesional de la enfermeria. | C8: NC
A9: CEV_TH | B9: 2. Si se requiere personal adicional para:
A10: CEV_TH | B10: 2.1 La administración de la vacuna cuenta con auxiliar de enfermerla o auxiliar de salud pública bajo la supervisión del profesional de la medicina o profesional de la enfermería. | C10: NA
A11: CEV_TH | B11: 2.2. El manejo de la cadena de frio puede disponer de auxiliar de enfermeria o auxiliar en salud pública o gestor comunitario en salud (en zonas de dispersión geográfica) o regentes de farmacia o qulmico farmaceutico con experiencia en cadena de frio.
A12: CEV_INF | B12: Complejidad baja
A13: CEV_INF | B13: Modalidad intramural
A14: CEV_INF | B14: 3. Cumple con los criterios que le sean aplicables de todos los servicios y adicionalmente cuenta con:
A15: CEV_INF | B15: Para los servicios en modalidad intramural de prestadores de servicios de salud que separen el servicio de vacunación en dos ambientes cuenta con:
A16: CEV_INF | B16: 4. Consultorio o ambiente que, de acuerdo con la oferta, cumple con los siguientes requisitos:
A17: CEV_INF | B17: 4.1 Consultorio para administración de medicamentos biologicos que cuenta con:
A18: CEV_INF | B18: 4.1.1. Área para entrevista.
A19: CEV_INF | B19: 4.1.2. Área para el alistamiento y administración de medicamentos biológicos.
A20: CEV_INF | B20: 4.1.3. Lavamanos
A21: CEV_INF | B21: 4.2. Ambiente para almacenamiento y alistamiento de dispositivos y termos que cuenta con:
A22: CEV_INF | B22: 4.2.1. Área para el alistamiento de termos o cajas témicas.
... A81: CEV_INT | B81: 12. No aplica
B84: CUMPLE | C84: =COUNTIF($C$5:$C$81,"C") -> 1
B85: NO CUMPLE | C85: =COUNTIF($C$5:$C$81,"NC") -> 1
B86: NO APLICA | C86: =COUNTIF($C$5:$C$81,"NA") -> 1

Sheet 11.2.4.S_CE_SST
B1: VOLVER A TABLA DE CONTENIDO
B2: Grupo Consulta Externa
B3: Servicio de Seguridad y Salud en el Trabajo
A4: Estandar | B4: Criterios | C4: Estado | D4: Comentarios
A5: CESST_TH | B5: Complejidad mediana
A6: CESST_TH | B6: Modalidades intramural, extramural unidad móvil y jornada de salud
A7: CESST_TH | B7: 1. Cumple con los criterios que le sean aplicables de todos los servicios y adicionalmente cuenta con: | C7: C
A8: CESST_TH | B8: 1.1. Profesional de la medicina especialista en medicina del trabajo o medicina laboral o seguridad y salud en el trabajo con licencia vigente de seguridad y salud en el trabajo expedida por autoridad competente. | C8: NC
A9: CESST_TH | B9: 1.2. Cuando se realicen pruebas complementarlas de tamización (audiometria, visiometria, espirometrla según aplique), disponibilidad de profesionales de la salud de conformidad con lo documentado en el estándar de procesos prioritarios. | C9: NA
A10: CESST_TH | B10: Modalidad telemedicina-prestador remisor
A11: CESST_TH | B11: 2. Cumple con los criterios que le sean aplicables de todos los servicios y adicionalmente:
A12: CESST_TH | B12: 2.1. Cuando se realice telexperticia entre profesionales de la salud cuenta con el profesional de la salud.
A13: CESST_TH | B13: Modalidad telemedicina-prestador de referencia
A14: CESST_TH | B14: 3. Cumple con los criterios que le sean aplicables de todos los servicios y adicionalmente cuenta con:
A15: CESST_TH | B15: Profesional en salud según la oferta definida por el prestador de servicios de salud en el estándar de procesos prioritarios.
A16: CESST_INF | B16: Complejidad mediana
A17: CESST_INF | B17: Modalidades intramural y extramural unidad móvil, jornada de salud y telemedicina-prestador remisor
A18: CESST_INF | B18: 4. Cumple con los criterios definidos del servicio de consulta externa para consultorio donde se realiza examen físico.
A19: CESST_INF | B19: Modalidad telemedicina -prestador de referencia
A20: CESST_INF | B20: 5. Cumple con los criterios que le sean aplicables de todos los servicios.
A21: CESST_DOT | B21: Complejidad mediana
... A53: CESST_INT | B53: 14. No aplica
B56: CUMPLE | C56: =COUNTIF($C$5:$C$53,"C") -> 1
B57: NO CUMPLE | C57: =COUNTIF($C$5:$C$53,"NC") -> 1
B58: NO APLICA | C58: =COUNTIF($C$5:$C$53,"NA") -> 1

Sheet 11.3.1.S_TR
B1: VOLVER A TABLA DE CONTENIDO
B2: Grupo apoyo diagnóstico y complementación tereapeutica
B3: Servicio de Terapias
A4: Estandar | B4: Criterios | C4: Estado | D4: Comentarios
A5: TR_TH | B5: Modalidad intramural y extramural unidad móvil, jornada de salud y domiciliaria
A6: TR_TH | B6: 1. Cumple con los criterios definidos para todos los servicios y adicionalmente cuenta con: | C6: C
A7: TR_TH | B7: 1.1. Profesionales de la salud con título según los programas académicos autorizados por el Ministerio de Educación Nacional en el ámbito de la rehabilitación, según oferta. | C7: NC
A8: TR_TH | B8: 1.2. Si oferta evaluación y tratamiento desde el enfoque de integración neurosensorial, cuenta con constancia de asistencia en las acciones de formación continua para la realización de los procedimientos según la oferta. | C8: NA
A9: TR_TH | B9: Modalidad telemedicina Categoría interactiva y no interactiva - prestador de referencia
A10: TR_TH | B10: 2. Cumple con los criterios que le sean aplicables de todos los servicios y adicionalmente, cuenta con:
A11: TR_TH | B11: 2.1 Profesional de la salud de acuerdo con el servicio a ofertar.
A12: TR_TH | B12: Categoría telexperticia - prestador remisor
A13: TR_TH | B13: 3. Cumple con los criterios que le sean aplicables de todos los servicios y adicionalmente
A14: TR_TH | B14: 3.1. Cuando se realice telexperticia entre profesionales de la salud cuenta con el profesional de la salud de acuerdo con el servicio a ofertar
A15: TR_TH | B15: Categoría telexperticia - prestador de referencia
A16: TR_TH | B16: 4. Cumple con los criterios que le sean aplicablesde todos los servicios y adicionalmente cuenta con profesional de la salud que atiende a distancia, de acuerdo con el servicio a ofertar.
A17: TR_TH | B17: Categoría telemonitoreo - prestador de referencia
A18: TR_TH | B18: 5. Cumple con los criterios que le sean aplicables de todos los servicios y adicionalmente cuenta con el personal de la salud profesional que se requiere para realizar el telemonitoreo de acuerdo con lo documentado por el prestador de servicios de salud en el estándar de procesos prioritarios.
A19: TR_INF | B19: 6. Cumple con los criterios que le sean aplicables de todos los servicios, y adicionalmente
A20: TR_INF | B20: 7. De acuerdo con el tipo de terapia ofertada, el servicio cuenta con:
... A77: TER_INT | B77: 30. No aplica.
B80: CUMPLE | C80: =COUNTIF($C$5:$C$77,"C") -> 1
B81: NO CUMPLE | C81: =COUNTIF($C$5:$C$77,"NC") -> 1
B82: NO APLICA | C82: =COUNTIF($C$5:$C$77,"NA") -> 1

Sheet  11.3.2.SF
B1: VOLVER A TABLA DE CONTENIDO
B2: Grupo apoyo diagnóstico y complementación tereapeutica
B3: Servicio Farmacéutico
A4: Estandar | B4: Criterios | C4: Estado | D4: Comentarios
A5: SF_TH | B5: Modalidades intramural y extramural domiciliaria
A6: SF_TH | B6: 1. Cumple con los criterios definidos para todos los servicios y adicionalmente: | C6: C
A7: SF_TH | B7: Cumple con lo definido en el Decreto 2200 de 2005 compilado en el Decreto 780 de 2016 (Art 2.5.3.10.9) y la Resolución 1403 de 2007 (Manual de condiciones esenciales y procedimientos del servicio farmacéutico Título I Capitulo II Numeral 3.2 y Capítulo III Numeral 1.2), o las normas que los modifiquen, adicionen o sustituyan. | C7: NC
A8: SF_TH | B8: Modalidad telemedicina Categoría interactiva y no interactiva – prestador de referencia Categoría telexperticia – prestador remisor – prestador de referencia
A9: SF_TH | B9: 2. Cumple con los criterios que le sean aplicables de todos los servicios y adicionalmente, cuenta con lo definido con el numeral 1 del servicio farmacéutico. | C9: NA
A10: SF_TH | B10: 3. El talento humano brinda en esta modalidad lo relacionado con la atención farmacéutica a los pacientes que lo requieran, a través de telemedicina – categorías interactiva y no interactiva, telexperticia sincrónico y asincrónico.
A11: SF_TH | B11: El apoyo a distancia del profesional Químico Farmacéutico no reemplaza el contar con el talento humano definido en el servicio
A12: SF_INF | B12: Complejidad baja
A13: SF_INF | B13: Modalidades intramural, extramural domiciliaria, telemedicina categoría telexperticia – prestador remisor
A14: SF_INF | B14: 4. Cumple con los criterios que le sean aplicables a todos los servicios
A15: SF_INF | B15: 5. Cuenta con:
A16: SF_INF | B16: 5.1. Ambiente o área administrativa.
A17: SF_INF | B17: 5.2. Ambiente o área de recepción de medicamentos y dispositivos médicos.
A18: SF_INF | B18: 5.3. Ambiente o área de dispensación de medicamentos y entrega de dispositivos médicos.
A19: SF_INF | B19: 5.4. Ambiente o área de almacenamiento, que garantice las condiciones temperatura y humedad recomendadas por el fabricante. Incluye cadena de frio, cuando aplique.
A20: SF_INF | B20: 5.5. Ambiente o área independiente de medicamentos de control especial cuando aplique, que garantice las condiciones temperatura y humedad recomendadas por el fabricante.
A21: SF_INF | B21: 5.6. Ambiente o área para almacenamiento de productos rechazados, devueltos y retirados.
... A71: SF_INT | B71: 22. No aplica.
B74: CUMPLE | C74: =COUNTIF($C$5:$C$71,"C") -> 1
B75: NO CUMPLE | C75: =COUNTIF($C$5:$C$71,"NC") -> 1
B76: NO APLICA | C76: =COUNTIF($C$5:$C$71,"NA") -> 1

Sheet 11.3.3.S_Rx_OD
B1: VOLVER A TABLA DE CONTENIDO
B2: Grupo apoyo diagnóstico y complementación tereapeutica
B3: Servicio de Radiologia Odontológica
A4: Estandar | B4: Criterios | C4: Estado | D4: Comentarios
A5: Rx_OD_TH | B5: Modalidades intramural y extramural unidad móvil
A6: Rx_OD_TH | B6: 1. Cumple con los criterios que le sean aplicables de todos los servicios y adicionalmente, cuenta con: | C6: C
A7: Rx_OD_TH | B7: Profesional de odontología o tecnólogo en radiología e imágenes diagnósticas, o técnico profesional o auxiliar de odontología o auxiliar en salud oral o auxiliar de higiene oral. | C7: NC
A8: Rx_OD_TH | B8: 2. Disponibilidad de profesional de la odontología, si la toma de radiografías la realiza un auxiliar de odontología o auxiliar en salud oral o auxiliar de higiene oral. | C8: NA
A9: Rx_OD_TH | B9: 3. La interpretación de las radiografías odontológicas es realizada por el profesional de la odontología.
A10: Rx_OD_TH | B10: Modalidad Telemedicina: Categoría telexperticia - prestador remisor
A11: Rx_OD_TH | B11: 4. Cumple con los criterios que le sean aplicables de todos los servicios y adicionalmente:
A12: Rx_OD_TH | B12: 4.1. Cuando se realice telexperticia entre profesionales de la salud cuenta con el profesional de la salud.
A13: Rx_OD_TH | B13: 4.2. Cuando realice telexperticia entre personal de salud no profesional y un profesional de la salud, el prestador remisor cuenta con técnico, tecnólogo o auxiliar que atiende presencialmente al usuario.
A14: Rx_OD_TH | B14: Categoría telexperticia - prestador de referencia
A15: Rx_OD_TH | B15: 5. Cumple con los criterios que le sean aplicables de todos los servicios y adicionalmente cuenta con profesional de la salud que atiende a distancia.
A16: RX_OD_INF | B16: Modalidades intramural, telemedicina - prestador remisor
A17: RX_OD_INF | B17: 6. Cumple con los criterios que le sean aplicables de todos los servicios y adicionalmente cuenta con:
A18: RX_OD_INF | B18: 6.1. Ambiente de radiología odontológica, si la tecnología lo requiere. Las dimensiones estarán determinadas según la ficha técnica del equipo.
A19: RX_OD_INF | B19: 6.2. Área de revelado o ambiente oscuro con extracción de gases e iluminación adecuada, con mesón de trabajo con poceta, si la tecnología lo requiere.
A20: RX_OD_INF | B20: 7. Disponibilidad de:
... A69: RX_OD_INT | B69: 21. No aplica.
B72: CUMPLE | C72: =COUNTIF($C$5:$C$69,"C") -> 1
B73: NO CUMPLE | C73: =COUNTIF($C$5:$C$69,"NC") -> 1
B74: NO APLICA | C74: =COUNTIF($C$5:$C$69,"NA") -> 1

Sheet 11.3.4.S_IDx
B1: VOLVER A TABLA DE CONTENIDO
B2: Grupo apoyo diagnóstico y complementación tereapeutica
B3: Servicio de imágenes diagnósticas
B4: Métodos diagnósticos con imágenes obtenidas mediante equipos generadores de radiaciones ionizantes
A5: Estandar | B5: Criterios | C5: Estado | D5: Comentarios
A6: IDX_TH | B6: Complejidad baja
A7: IDX_TH | B7: Modalidades intramural, extramural unidad móvil, telemedicina - prestador remisor
A8: IDX_TH | B8: 1. Cumple con los criterios definidos para todos los servicios y adicionalmente, | C8: C
A9: IDX_TH | B9: 2. Cuenta con:
A10: IDX_TH | B10: Técnico profesional o tecnólogo en imágenes diagnósticas, para la operación de equipos y adquisición de imágenes. | C10: NC
A11: IDX_TH | B11: 3. Disponibilidad de:
A12: IDX_TH | B12: Médico especializado en radiología e imágenes diagnósticas o aquellos médicos especialistas quienes en su pensum o formación académica hayan adquirido los conocimientos del manejo e interpretación del espectro electromagnético, del ultrasonido especialmente, así como de las radiaciones ionizantes para establecer el diagnóstico y/o el tratamiento de las enfermedades inherentes a sus especialidades, para lo cual deberán acreditar el respectivo certificado. La interpretación de las radiografías e imágenes diagnósticas y la supervisión del técnico profesional o tecnólogo en imágenes diagnósticas es realizada por dichos profesionales. | C12: NA
A13: IDX_TH | B13: Complejidad mediana
A14: IDX_TH | B14: Modalidades extramural unidad móvil, telemedicina - prestador remisor
A15: IDX_TH | B15: 4. Cumple con los criterios que le sean aplicables de todos los servicios y adicionalmente cuenta con:
A16: IDX_TH | B16: 4.1. Tecnólogo en radiología e imágenes diagnósticas para la operación de equipos y adquisición de imágenes, con supervisión por el profesional de la medicina especialista en radiología e imágenes diagnósticas.
A17: IDX_TH | B17: 4.2. Médico especializado en radiología e imágenes diagnósticas o aquellos médicos especialistas quienes en su pensum o formación académica hayan adquirido los conocimientos del manejo e interpretación del espectro electromagnético, del ultrasonido especialmente, así como de las radiaciones ionizantes para establecer el diagnóstico y/o el tratamiento de las enfermedades inherentes a sus especialidades. Para lo cual deberá acreditar el respectivo certificado. La interpretación de las radiografías e imágenes diagnósticas y la supervisión del técnico profesional o tecnólogo en imágenes diagnósticas es realizada por dichos profesionales.
A18: IDX_TH | B18: Complejidades mediana y alta
A19: IDX_TH | B19: Modalidades intramural, telemedicina - prestador remisor
A20: IDX_TH | B20: 5. Cumple con los criterios que le sean aplicables de todos los servicios y adicionalmente cuenta con:
A21: IDX_TH | B21: 5.1. Tecnólogo en radiología e imágenes diagnósticas para la operación de equipos y adquisición de imágenes, con supervisión por el profesional de la medicina especialista en radiología e imágenes diagnósticas.
