Workbook
Name CODIGO: PRIORIZACION[[#All],[CODIGO]]
Name FACTIBILIDAD_DE_INTERVENCIÓN: PRIORIZACION[[#All],[FACTIBILIDAD DE INTERVENCIÓN]]
Name FACTIBILIDAD_DE_INTERVENCIÓN: PRIORIZACION[[#All],[FACTIBILIDAD DE INTERVENCIÓN]]
Name GRADO_DE_SEVERIDAD: '2-PRIORIZACION'!$I$5:$I$59
Name GRAFOP.1.1: '3. RESULTADO IND'!$AW$5:$BH$5
Name GRAVEDAD_DEL_EFECTO: PRIORIZACION[[#All],[GRAVEDAD DEL EFECTO]]
Name GRAVEDAD_DEL_EFECTO: PRIORIZACION[[#All],[GRAVEDAD DEL EFECTO]]
Name INDICADOR: PRIORIZACION[[#All],[INDICADOR]]
Name INDICADOR: PRIORIZACION[[#All],[INDICADOR]]

Sheet FASES MOCA
B1: Plantilla para el monitoreo de la calidad (MOCA) en el Sistema de Información para la Calidad
A22: Fuente imágenes: Flaticon.com
A23: Fuente metodologica: GESTIÓN DEL MEJORAMIENTO CONTINUO DE LA CALIDAD. Orientaciones técnicas para la gestión de los resultados del monitoreo de la calidad. Documento técnico nº 1. Implementación Plan Nacional de Mejoramiento de la Calidad en Salud. Ministerio de Salud y Protección Social. 2016. Disponible en: https://www.minsalud.gov.co/sites/rid/Lists/BibliotecaDigital/RIDE/DE/CA/orientaciones-tecnicas-gestion-resultados-monitoreo-calidad.pdf

Sheet INDICADORES
A1: CODIGO | B1: DOMINIO | C1: NOMBRE DEL INDICADOR | D1: DEFINICIÓN | E1: FORMULA DE CÁLCULO | F1: NUMERADOR | G1: DENOMINADOR | H1: UNIDAD DE MEDIDA | I1: OBSERVACIONES | J1: APLICA A LA IPS | L1: AUXILIAR | M1: ORDEN
A2: P.1.1 | B2: Efectividad | C2: Proporción de gestantes con consulta de control prenatal de primera vez antes de las 12 semanas de gestación | D2: Proporción de gestantes con consulta de control prenatal de primera vez antes de las 12 semanas de gestación | E2: Cociente entre el número de gestantes que ingresan al control prenatal antes de las 12 semanas de gestación y el número total de gestantes en el periodo, multiplicado por 100 y expresado como porcentaje (%). | F2: Número de gestantes que ingresan al control prenatal antes de las 12 semanas de gestación | G2: Total de gestantes | H2: Por 100 (%) | I2: Aplica para IPS, no aplica para los Servicios de Transporte Especial de pacientes | L2: =IF(INDICADORES[[#This Row],[APLICA A LA IPS]]="",0,(INDICADORES[[#This Row],[APLICA A LA IPS]]<>"No")*1) -> 0 | M2: =(RANK($L2,$L$2:$L$56,0)+COUNTIF($L$2:$L2,L2)-1)*L2 -> 0
A3: P.1.2 | B3: Efectividad | C3: Proporción de gestantes con valoración por odontología | D3: Expresa la proporción de gestantes que recibieron consulta de odontología durante su embarazo. | E3: Cociente entre el número de gestantes que recibieron consulta de odontología y el número total de gestantes en un periodo determinado, multiplicado por 100%. | F3: Número de gestantes con valoración por Odontología | G3: Total de gestantes | H3: Por 100 (%) | I3: Aplica para IPS, no aplica para los Servicios de Transporte Especial de pacientes | L3: =IF(INDICADORES[[#This Row],[APLICA A LA IPS]]="",0,(INDICADORES[[#This Row],[APLICA A LA IPS]]<>"No")*1) -> 0 | M3: =(RANK($L3,$L$2:$L$56,0)+COUNTIF($L$2:$L3,L3)-1)*L3 -> 0
A4: P.1.3 | B4: Efectividad | C4: Proporción de partos por cesárea | D4: Expresa la proporción de nacimientos por cesárea en la Institución Prestadora de Servicios de Salud en un periodo determinado. | E4: Cociente entre el número de nacidos vivos por cesárea y el total de nacidos vivos en un periodo determinado, multiplicado por 100%. | F4: Número de nacidos vivos por cesárea | G4: Total de nacidos vivos | H4: Por 100 (%) | I4: Aplica para IPS, no aplica para los Servicios de Transporte Especial de pacientes. | L4: =IF(INDICADORES[[#This Row],[APLICA A LA IPS]]="",0,(INDICADORES[[#This Row],[APLICA A LA IPS]]<>"No")*1) -> 0 | M4: =(RANK($L4,$L$2:$L$56,0)+COUNTIF($L$2:$L4,L4)-1)*L4 -> 0
A5: P.1.4 | B5: Efectividad | C5: Tasa de mortalidad perinatal | D5: Expresa la relación entre de defunciones de fetos de 22 semanas completas (154 días) de gestación o con 500 gramos o más de peso y los siete días completos después del nacimiento, por cada 1.000 nacimientos | E5: Cociente entre el número de muertes fetales con 22 semanas completas (154 días) de gestación o con 500 gramos o más de peso y los siete días completos después del nacimiento y el número de nacidos vivos más el número de muertes fetales con 22 semanas completas (154 días) de gestación o con 500 gramos o más de peso en un periodo determinado multiplicado por 1000. | F5: Número de muertes fetales con 22 semanas completas (154 días) de gestación o con 500 gramos o más de peso y los siete días completos después del nacimiento. | G5: Número total de nacidos vivos más el número de muertes fetales con 22 semanas completas (154 días) de gestación o con 500 gramos o más de peso | H5: Por 1.000 nacimientos | I5: Aplica para IPS, no aplica para los Servicios de Transporte Especial de pacientes. | L5: =IF(INDICADORES[[#This Row],[APLICA A LA IPS]]="",0,(INDICADORES[[#This Row],[APLICA A LA IPS]]<>"No")*1) -> 0 | M5: =(RANK($L5,$L$2:$L$56,0)+COUNTIF($L$2:$L5,L5)-1)*L5 -> 0
A6: P.1.5 | B6: Efectividad | C6: Relación Morbilidad Materna Extrema(MME) / Muerte Materna temprana (MM) | D6: Expresa la relación de MME / MM indica el número de casos de morbilidad materna extrema por cada caso de muerte materna temprana. | E6: Cociente entre el número de casos de Morbilidad Materna Extrema (MME) y el número de casos de Muerte Materna temprana (MM). | F6: Número de casos de MME | G6: Número de casos de muerte materna ( 42 días) | H6: Número absoluto | I6: Se define un caso de morbilidad materna extrema como una mujer con una complicación durante el embarazo, el parto o dentro de los 42 días siguientes a la terminación del embarazo, que pone en riesgo su vida pero sobrevive y que cumple con al menos uno de los criterios de inclusión. Aplica para IPS, no aplica para los Servicios de Transporte Especial de pacientes | L6: =IF(INDICADORES[[#This Row],[APLICA A LA IPS]]="",0,(INDICADORES[[#This Row],[APLICA A LA IPS]]<>"No")*1) -> 0 | M6: =(RANK($L6,$L$2:$L$56,0)+COUNTIF($L$2:$L6,L6)-1)*L6 -> 0
A7: P.1.6 | B7: Efectividad | C7: Proporción de recién nacidos con tamizaje para Hipotiroidismo | D7: Expresa el número de recién nacidos a quienes se les realizó tamizaje para Hipotiroidismo. | E7: Cociente entre el número de recién nacidos a quienes se les realiza tamizaje para Hipotiroidismo y el número de nacidos vios reportados en el período multiplizado por 100 y expresado en (%). | F7: Número de nacidos vivos a quienes se realiza tamizaje de hipotiroidismo | G7: Número total de nacidos vivos reportados | H7: Por 100 (%) | I7: Aplica para IPS, no aplica para los Servicios de Transporte Especial de pacientes | L7: =IF(INDICADORES[[#This Row],[APLICA A LA IPS]]="",0,(INDICADORES[[#This Row],[APLICA A LA IPS]]<>"No")*1) -> 0 | M7: =(RANK($L7,$L$2:$L$56,0)+COUNTIF($L$2:$L7,L7)-1)*L7 -> 0
A8: P.1.7 | B8: Efectividad | C8: Proporción de reingreso hospitalario por Infección Respiratoria Aguda (IRA) en menores de 5 años | D8: Expresa la proporción de reingreso hospitalario por IRA en menores de 5 años, en un periodo determinado | E8: Cociente entre el número de menores de 5 años con reingreso hospitalario por IRA dentro de los 20 días después del primer egreso por IRA, en la misma institución y el número de menores de 5 años con al menos un egreso por IRA multiplicado por 100 y expresado como porcentaje (%). | F8: Número de menores de 5 años con reingreso hospitalario por IRA dentro de los 20 días después del primer egreso por IRA, en la misma institución | G8: Número de menores de 5 años con al menos un egreso por IRA | H8: Por 100 (%) | I8: Aplica para IPS, no aplica para los Servicios de Transporte Especial de pacientes. | L8: =IF(INDICADORES[[#This Row],[APLICA A LA IPS]]="",0,(INDICADORES[[#This Row],[APLICA A LA IPS]]<>"No")*1) -> 0 | M8: =(RANK($L8,$L$2:$L$56,0)+COUNTIF($L$2:$L8,L8)-1)*L8 -> 0
A9: P.1.8 | B9: Efectividad | C9: Letalidad por Infección Respiratoria Aguda (IRA) en menores de 5 años | D9: Expresa la proporción de defunciones de niños menores de 5 años cuya causa básica de muerte fue Infección Respiratoria Aguda (IRA) con relación al número total de menores de 5 años atendidos con diagnóstico de IRA | E9: Cociente entre el número de muertes por IRA en menores de 5 años y número total de menores de 5 años atendidos por diagnóstico de IRA en un periodo determinado multiplicado por 100 y expresado como porcentaje (%). | F9: Número de muertes por IRA en menores de 5 años | G9: Número total de menores de 5 años atendidos por diagnóstico de IRA | H9: Por 100 (%) | I9: Aplica para IPS, no aplica para los Servicios de Transporte Especial de pacientes. | L9: =IF(INDICADORES[[#This Row],[APLICA A LA IPS]]="",0,(INDICADORES[[#This Row],[APLICA A LA IPS]]<>"No")*1) -> 0 | M9: =(RANK($L9,$L$2:$L$56,0)+COUNTIF($L$2:$L9,L9)-1)*L9 -> 0
A10: P.1.9 | B10: Efectividad | C10: Letalidad en menores de 5 años por Enfermedad Diarreica Aguda (EDA) | D10: Expresa la proporción de defunciones de niños menores de 5 años cuya causa básica de muerte fue Enfermedad Diarreica Aguda (EDA) con relación al número total de menores de 5 años atendidos con diagnóstico de EDA. | E10: Cociente entre el número de muertes por EDA en menores de 5 años y Número total de menores de 5 años atendidos con diagnóstico de EDA en un periodo determinado multiplicado por 100 y expresado como porcentaje (%). | F10: Número de muertes por EDA en menores de 5 años | G10: Número total de menores de 5 años atendidos con diagnóstico de EDA | H10: Por 100 (%) | I10: Aplica para IPS, no aplica para los Servicios de Transporte Especial de pacientes | L10: =IF(INDICADORES[[#This Row],[APLICA A LA IPS]]="",0,(INDICADORES[[#This Row],[APLICA A LA IPS]]<>"No")*1) -> 0 | M10: =(RANK($L10,$L$2:$L$56,0)+COUNTIF($L$2:$L10,L10)-1)*L10 -> 0
A11: P.1.10 | B11: Efectividad | C11: Proporción de gestantes con asesoría pre-test para prueba de Virus de la inmunodeficiencia Humana (VIH) | D11: Indica el número de gestantes a quienes se les realizó asesoría pre-test para prueba de VIH (ELISA) | E11: Cociente entre el número de gestantes a quienes se les realizó asesoría pre-test para prueba de VIH (ELISA) y el número total de gestantes por 100 y expresado como porcentaje (%). | F11: Número de gestantes a quienes se les realizó asesoría pretest para prueba de VIH (ELISA) | G11: Total de gestantes | H11: Por 100 (%) | I11: Aplica para IPS, no aplica para los Servicios de Transporte Especial de pacientes | L11: =IF(INDICADORES[[#This Row],[APLICA A LA IPS]]="",0,(INDICADORES[[#This Row],[APLICA A LA IPS]]<>"No")*1) -> 0 | M11: =(RANK($L11,$L$2:$L$56,0)+COUNTIF($L$2:$L11,L11)-1)*L11 -> 0
A12: P.1.11 | B12: Efectividad | C12: Proporción de niños y niñas menores de 18 meses, hijos de madre viviendo con VIH, con diagnóstico de VIH | D12: Proporción de niños y niñas menores de 18 meses, hijos de madre viviendo con VIH, con diagnóstico de VIH. | E12: Cociente entre el número de niños menores de 18 meses con diagnóstico de VIH/Sida hijos de madres con VIH/Sida y el número de menores de 18 meses hijos de madres con VIH/Sida por 100 expresado como porcentaje (%). | F12: Número de niños menores de 18 meses con diagnóstico de VIH/Sida hijos de madres con VIH/Sida | G12: Número de menores de 18 meses hijos de madres con VIH/Sida | H12: Por 100 (%) | I12: Solo aplica para IPS que hayan realizado el control prenatal a la madre y el seguimiento al recien nacido hasta por lo menos los seis meses de edad | L12: =IF(INDICADORES[[#This Row],[APLICA A LA IPS]]="",0,(INDICADORES[[#This Row],[APLICA A LA IPS]]<>"No")*1) -> 0 | M12: =(RANK($L12,$L$2:$L$56,0)+COUNTIF($L$2:$L12,L12)-1)*L12 -> 0
A13: P.1.12 | B13: Efectividad | C13: Proporción de mujeres a las que se les realizó toma de serología en el momento del parto o aborto | D13: Expresa la proporción de mujeres a las que se les realizó serología en el momento del parto o aborto. | E13: Cociente entre el número de mujeres a las que se les realizó toma de serología en el momento del parto o aborto y el número total de gestantes de los últimos 6 meses que a la fecha de corte están en embarazo reportadas por 100 expresado como porcentaje (%). | F13: Número de mujeres a las que se les realizó toma de serología en el momento del parto o aborto | G13: Número total de gestantes de los últimos 6 meses reportadas | H13: Por 100 (%) | I13: Aplica para IPS, no aplica para los Servicios de Transporte Especial de pacientes. | L13: =IF(INDICADORES[[#This Row],[APLICA A LA IPS]]="",0,(INDICADORES[[#This Row],[APLICA A LA IPS]]<>"No")*1) -> 0 | M13: =(RANK($L13,$L$2:$L$56,0)+COUNTIF($L$2:$L13,L13)-1)*L13 -> 0
... A29: P.2.3 | B29: Seguridad | C29: Tasa de Incidencia de Infección del Torrente Sanguíneo Asociada a Catéter (ITS- AC) | D29: Es un estimador del riesgo de ITS-AC en la población de pacientes con catéter central en la Unidad de Cuidado Intensivo-UCI | E29: Cociente entre ITS-AC nuevas en la UCI en un mes de seguimiento y el número de días catéter central en UCI (Adulto o Pediátrica o Neonatal) en un mes de seguimiento por 1.000 catéter central. | F29: Sumatoria de casos nuevos de Infección del Torrente Sanguíneo Asociada a Catéter en un mes de seguimiento. | G29: Número días catéter central en UCI (Adulto o Pediátrica o Neonatal) en un mes de seguimiento | H29: Por 1000 días catéter central | I29: Sólo aplica para UCI Pediátrica, Neonatal y Adulto | L29: =IF(INDICADORES[[#This Row],[APLICA A LA IPS]]="",0,(INDICADORES[[#This Row],[APLICA A LA IPS]]<>"No")*1) -> 0 | M29: =(RANK($L29,$L$2:$L$56,0)+COUNTIF($L$2:$L29,L29)-1)*L29 -> 0
A30: P.2.4 | B30: Seguridad | C30: Proporción de endometritis pos parto vaginal | D30: Es un estimador del riesgo de endometritis pos parto en las gestantes atendidos en la institucion en un mes de seguimiento | E30: Cociente entre número de endometritis pos parto vaginal y el total de partos atendidos en un mes de seguimiento, multiplicado por 100 y expresado en (%) | F30: Número de endometritis pos parto vaginal | G30: Número total de partos atendidos | H30: Por 100 (%) | L30: =IF(INDICADORES[[#This Row],[APLICA A LA IPS]]="",0,(INDICADORES[[#This Row],[APLICA A LA IPS]]<>"No")*1) -> 0 | M30: =(RANK($L30,$L$2:$L$56,0)+COUNTIF($L$2:$L30,L30)-1)*L30 -> 0
A31: P.2.5 | B31: Seguridad | C31: Proporción de endometritis pos cesárea | D31: Es un estimador de riesgo de endometritis pos cesárea en las gestantes atendidas en la institucion en un mes de seguimiento | E31: Cociente entre número total de endometritis pos cesárea y el total de cesáreas realizadas en un mes de seguimiento, multiplicado por 100 y expresado en (%) | F31: Número de endometritis pos cesárea | G31: Número total de cesáreas realizadas | H31: Por 100 (%) | L31: =IF(INDICADORES[[#This Row],[APLICA A LA IPS]]="",0,(INDICADORES[[#This Row],[APLICA A LA IPS]]<>"No")*1) -> 0 | M31: =(RANK($L31,$L$2:$L$56,0)+COUNTIF($L$2:$L31,L31)-1)*L31 -> 0
A32: P.2.6 | B32: Seguridad | C32: Tasa de caída de pacientes en el servicio de hospitalización | D32: Es un estimador de las caídas de pacientes en hospitalización en un mes de seguimiento | E32: Cociente entre el número total de pacientes hospitalizados que sufren caídas en el periodo y la sumatoria de días de estancia de los pacientes en los servicios de hospitalización por 1000. | F32: Número total de pacientes hospitalizados que sufren caídas en el periodo. | G32: Sumatoria de días de estancia de los pacientes en los servicios de hospitalización en el periodo. | H32: Por 1000 días de estancia | I32: Aplica para IPS, no aplica para los Servicios de Transporte Especial de pacientes. | L32: =IF(INDICADORES[[#This Row],[APLICA A LA IPS]]="",0,(INDICADORES[[#This Row],[APLICA A LA IPS]]<>"No")*1) -> 0 | M32: =(RANK($L32,$L$2:$L$56,0)+COUNTIF($L$2:$L32,L32)-1)*L32 -> 0
A33: P.2.7 | B33: Seguridad | C33: Tasa de caída de pacientes en el servicio de urgencias | D33: Es un estimador de las caídas de pacientes en urgencias en un mes de seguimiento. | E33: Cociente entre el número total de pacientes atendidos en urgencias que sufren caídas en el periodo y el total de personas atendidas en urgencias en el periodo por 1000 | F33: Número total de pacientes atendidos en urgencias que sufren caídas en el periodo. | G33: Total de personas atendidas en urgencias en el periodo | H33: Por 1000 personas atendidas en urgencias | I33: Aplica para IPS, no aplica para los Servicios de Transporte Especial de pacientes | L33: =IF(INDICADORES[[#This Row],[APLICA A LA IPS]]="",0,(INDICADORES[[#This Row],[APLICA A LA IPS]]<>"No")*1) -> 0 | M33: =(RANK($L33,$L$2:$L$56,0)+COUNTIF($L$2:$L33,L33)-1)*L33 -> 0
A34: P.2.8 | B34: Seguridad | C34: Tasa de caída de pacientes en el servicio de consulta externa | D34: Es un estimador de las caídas de pacientes en consulta externa en un mes de seguimiento. | E34: Cociente entre el número total de pacientes atendidos en consulta externa que sufren caídas en el periodo y el total de personas atendidas en consulta externa en el periodo por 1000 | F34: Número total de pacientes atendidos en consulta externa que sufren caídas en el periodo | G34: Total de personas atendidas en consulta externa | H34: Por 1000 personas atendidas en consulta externa | I34: Aplica para IPS, no aplica para los Servicios de Transporte Especial de pacientes | L34: =IF(INDICADORES[[#This Row],[APLICA A LA IPS]]="",0,(INDICADORES[[#This Row],[APLICA A LA IPS]]<>"No")*1) -> 0 | M34: =(RANK($L34,$L$2:$L$56,0)+COUNTIF($L$2:$L34,L34)-1)*L34 -> 0
A35: P.2.9 | B35: Seguridad | C35: Tasa de caída de pacientes en el servicio de Apoyo Diagnóstico y Complementación Terapéutica | D35: Es un estimador de las caídas de pacientes en Apoyo Diagnóstico y Complementación Terapéutica en un mes de seguimiento. | E35: Cociente entre el número total de pacientes atendidos en el servicio de Apoyo Diagnóstico y Complementación Terapéutica que sufren caídas en el periodo y el total de personas atendidas en Apoyo Diagnóstico y Complementación Terapéutica en el periodo por 1000 | F35: Número total de pacientes atendidos en el servicio denApoyo Diagnóstico y Complementación Terapéutica que sufren caídas | G35: Total de personas atendidas en el servicio de apoyo diagnóstico y complementación terapéutica. | H35: Por 1000 personas atendidas en Apoyo Diagnóstico y Complementación Terapéutica | I35: Aplica para IPS, no aplica para los Servicios de Transporte Especial de pacientes. | L35: =IF(INDICADORES[[#This Row],[APLICA A LA IPS]]="",0,(INDICADORES[[#This Row],[APLICA A LA IPS]]<>"No")*1) -> 0 | M35: =(RANK($L35,$L$2:$L$56,0)+COUNTIF($L$2:$L35,L35)-1)*L35 -> 0
A36: P.2.10 | B36: Seguridad | C36: Proporción de eventos adversos relacionados con la administración de medicamentos en hospitalización | D36: Expresa el número de eventos adversos relacionados con la administración de medicamentos en el servicio de hospitalización. | E36: Cociente entre el número de eventos adversos relacionados con la administración de medicamentos en hospitalización y el total de egresos de hospitalización en el periodo por 100 expresado como porcentaje (%). | F36: Número de eventos adversos relacionados con la administración de medicamentos en hospitalización. | G36: Total de egresos de hospitalización | H36: Por 100 (%) | I36: Para este indicador el evento adverso solo corresponde a la etapa de administración de medicamentos | L36: =IF(INDICADORES[[#This Row],[APLICA A LA IPS]]="",0,(INDICADORES[[#This Row],[APLICA A LA IPS]]<>"No")*1) -> 0 | M36: =(RANK($L36,$L$2:$L$56,0)+COUNTIF($L$2:$L36,L36)-1)*L36 -> 0
A37: P.2.11 | B37: Seguridad | C37: Proporción de eventos adversos relacionados con la administración de medicamentos en urgencias | D37: Expresa el número de eventos adversos relacionados con la administración de medicamentos en el servicio de urgencias. | E37: Cociente entre el número de eventos adversos relacionados con la administración de medicamentos en urgencias y el total de personas atendidas en urgencias en el periodo por 100 expresado como porcentaje (%) | F37: Número de eventos adversos relacionados con la administración de medicamentos en urgencias. | G37: Total de personas atendidas en urgencias. | H37: Por 100 (%) | I37: Para este indicador el evento adverso solo corresponde a la etapa de administración de medicamentos. Aplica sólo para IPS | L37: =IF(INDICADORES[[#This Row],[APLICA A LA IPS]]="",0,(INDICADORES[[#This Row],[APLICA A LA IPS]]<>"No")*1) -> 0 | M37: =(RANK($L37,$L$2:$L$56,0)+COUNTIF($L$2:$L37,L37)-1)*L37 -> 0
A38: P.2.12 | B38: Seguridad | C38: Tasa de úlceras por presión. | D38: Expresa el número de pacientes hospitalizados que durante su permanencia desarrollaron úlceras por presión en un periodo determinado | E38: Cociente entre el número de pacientes que desarrollan úlceras por presión en la institución y la sumatoria de días de estancia de los pacientes en los servicios de hospitalización por 1000. | F38: Número de pacientes que desarrollan úlceras por presión en la institución en el periodo | G38: Sumatoria de días de estancia de los pacientes en los servicios de hospitalización | H38: Por 1000 días paciente | I38: No aplica en: -Pacientes con diagnóstico principal de la úlcera por presión o diagnóstico secundario presente al ingreso.-Pacientes con diagnóstico de hemiplejía, paraplejía y tetraplejía o con diagnóstico de espina bífida o daño cerebral por anoxia. Aplica para IPS y no aplica para los Servicios de Transporte Especial de pacientes | L38: =IF(INDICADORES[[#This Row],[APLICA A LA IPS]]="",0,(INDICADORES[[#This Row],[APLICA A LA IPS]]<>"No")*1) -> 0 | M38: =(RANK($L38,$L$2:$L$56,0)+COUNTIF($L$2:$L38,L38)-1)*L38 -> 0
A39: P.2.13 | B39: Seguridad | C39: Proporción de reingreso de pacientes al servicio de Urgencias en menos de 72 horas. | D39: Expresa la proporción de pacientes atendidos en urgencias que reingresan al mismo servicio de la misma institución por el mismo diagnóstico de egreso dentro de las 72 horas posteriores dado de alta | E39: Cociente entre el número de pacientes que reingresan al servicio de urgencias en la misma institución antes de 72 horas con el mismo diagnóstico de egreso y el número total de egresos vivos atendidos en el servicio de urgencias durante el periodo definido, multiplicado por 100 expresado como porcentaje (%). | F39: Número de pacientes que reingresan al servicio de urgencias en la misma institución antes de 72 horas con el mismo diagnóstico de egreso | G39: Número total de egresos vivos atendidos en el servicio de urgencias durante el periodo definido | H39: Por 100 (%) | I39: Aplica para IPS y no aplica para los Servicios de Transporte Especial de pacientes. Se debe excluir el reingreso programado | L39: =IF(INDICADORES[[#This Row],[APLICA A LA IPS]]="",0,(INDICADORES[[#This Row],[APLICA A LA IPS]]<>"No")*1) -> 0 | M39: =(RANK($L39,$L$2:$L$56,0)+COUNTIF($L$2:$L39,L39)-1)*L39 -> 0
A40: P.2.14 | B40: Seguridad | C40: Tasa de reingreso de pacientes hospitalizados en menos de 15 días | D40: Expresa la proporción de reingresos de pacientes hospitalizados en menos de 15 días, en un periodo determinado. | E40: Cociente entre el número de pacientes que reingresan al servicio de hospitalización, en la misma institución, antes de 15 días, por el mismo diagnóstico de egreso en el período y el número total de egresos vivos atendidos en el servicio de hospitalización en el periodo por 1000 egresos. | F40: Número de pacientes que reingresan al servicio de hospitalización, en la misma institución,antes de 15 días, por el mismo diagnóstico de egreso en el período | G40: Número total de egresos vivos atendidos en el servicio de hospitalización en el periodo | H40: Por 1000 egresos | I40: Aplica para IPS y no aplica para los Servicios de Transporte Especial de pacientes. | L40: =IF(INDICADORES[[#This Row],[APLICA A LA IPS]]="",0,(INDICADORES[[#This Row],[APLICA A LA IPS]]<>"No")*1) -> 0 | M40: =(RANK($L40,$L$2:$L$56,0)+COUNTIF($L$2:$L40,L40)-1)*L40 -> 0
A41: P.2.15 | B41: Seguridad | C41: Proporción de cancelación de cirugía | D41: Expresa la proporción de cirugías programadas en quirófano que son canceladas por causas atribuibles a la institución. | E41: Cociente entre el número total de cirugías programadas que fueron canceladas por causas atribuibles a la institución y número total de cirugías programadas en un periodo determinado por 100 expresado como porcentaje (%). | F41: Número total de cirugías programadas que fueron canceladas por causas atribuibles a la institución | G41: Número total de cirugías programadas | H41: Por 100 (%) | I41: Incluye los procedimientos quirúrgicos realizados en quirófano de acuerdo a Clasificación Única de Procedimientos CUPS del código 01.0.1.01 al 86.9.7.00 Aplica para IPS y no aplica para los Servicios de Transporte Especial de pacientes | L41: =IF(INDICADORES[[#This Row],[APLICA A LA IPS]]="",0,(INDICADORES[[#This Row],[APLICA A LA IPS]]<>"No")*1) -> 0 | M41: =(RANK($L41,$L$2:$L$56,0)+COUNTIF($L$2:$L41,L41)-1)*L41 -> 0
A42: P.3.1 | B42: Experiencia de la atención | C42: Tiempo promedio de espera para la asignación de cita de Medicina General | D42: Expresa el tiempo de espera en días calendario, que transcurren entre la fecha de solicitud de la cita para consulta por Medicina General de primera vez por parte del paciente/usuario a la IPS y la fecha en que es asignada. | E42: Cociente entre la sumatoria de la diferencia de los días calendario entre la fecha en la que se asignó la cita de Medicina general de primera vez y la fecha en la cual el usuario la solicitó y el número total de citas de Medicina General de primera vez asignadas en un periodo determinado. | F42: Sumatoria de la diferencia de días calendario entre la fecha en la que se asignó la cita de Medicina general de primera vez y la fecha en la cual el usuario la solicitó | G42: Número total de citas de Medicina General de primera vez asignadas | H42: Días | I42: La consulta de primera vez, hace referencia a la primera consulta del paciente que se registra por primera vez en el año, razón por la cual se excluye la consulta de control. Aplica sólo para IPS | L42: =IF(INDICADORES[[#This Row],[APLICA A LA IPS]]="",0,(INDICADORES[[#This Row],[APLICA A LA IPS]]<>"No")*1) -> 0 | M42: =(RANK($L42,$L$2:$L$56,0)+COUNTIF($L$2:$L42,L42)-1)*L42 -> 0
A43: P.3.2 | B43: Experiencia de la atención | C43: Tiempo promedio de espera para la asignación de cita de Odontología General | D43: Expresa el tiempo de espera en días calendario, que transcurren entre la fecha de solicitud de la cita para consulta por Odontología General de primera vez por parte del paciente/usuario a la IPS y la fecha en que es asignada | E43: Cociente entre la sumatoria de la diferencia de días calendario entre la fecha en la que se asignó la cita de Odontología general de primera vez y la fecha en la cual el usuario la solicitó y el número total de citas de Odontología General de primera vez asignadas en el periodo | F43: Sumatoria de la diferencia de días calendario entre la fecha en la que se asignó la cita de Odontología general de primera vez y la fecha en la cual el usuario la solicitó | G43: Número total de citas de Odontología General de primera vez asignadas | H43: Días | I43: La consulta de primera vez, hace referencia a la primera consulta del paciente que se registra por primera vez en el año, razón por la cual se excluye la consulta de control. Aplica para IPS y no aplica para los Servicios de Transporte Especial de Pacientes | L43: =IF(INDICADORES[[#This Row],[APLICA A LA IPS]]="",0,(INDICADORES[[#This Row],[APLICA A LA IPS]]<>"No")*1) -> 0 | M43: =(RANK($L43,$L$2:$L$56,0)+COUNTIF($L$2:$L43,L43)-1)*L43 -> 0
... A56: P.3.15 | B56: Experiencia de la atención | C56: Proporción de usuarios que recomendaría su IPS a familiares y amigos | D56: Expresa la proporción de usuarios que recomendaría su IPS a familiares y amigos | E56: Se calcula como el cociente entre el número de usuarios que respondieron “definitivamente sí” o “probablemente sí” a la pregunta:” ¿recomendaría a sus familiares y amigos esta IPS?”, y el número de usuarios que respondieron la pregunta, por 100 expresado como porcentaje (%) | F56: Número de usuarios que respondieron “definitivamente sí” o “probablemente sí” a la pregunta:” ¿recomendaría a sus familiares y amigos esta IPS?” | G56: Número de usuarios que respondieron la pregunta | H56: Por 100 (%) | I56: Las opciones de respuesta del usuario a la pregunta ¿Recomendaría a sus familiares y amigos esta IPS?” serian: a) Definitivamente no b) Probablemente no c) Probablemente si d) Definitivamente si e) No informa. Aplica para IPS y no aplica para los Servicios de Transporte Especial de pacientes | L56: =IF(INDICADORES[[#This Row],[APLICA A LA IPS]]="",0,(INDICADORES[[#This Row],[APLICA A LA IPS]]<>"No")*1) -> 0 | M56: =(RANK($L56,$L$2:$L$56,0)+COUNTIF($L$2:$L56,L56)-1)*L56 -> 0
A57: Fuente: https://www.minsalud.gov.co/sites/rid/Lists/BibliotecaDigital/RIDE/DE/CA/fichas-tecnicas-indicadores-resolucion-0256-2016.pdf

Sheet 1-ANALISIS
A1: 1- ANÁLISIS DE INDICADORES PARA EL MONITOREO DE LA CALIDAD EN SALUD
A5: No. | B5: CODIGO | C5: INDICADOR A AUTOEVALUAR | D5: META | E5: UNIDAD | F5: 1. RESULTADO TRIMESTRE 1 AÑO xxxx | G5: 2. RESULTADO TRIMESTRE 2 AÑO xxx | H5: 3. RESULTADO TRIMESTRE 3 AÑO xxx | I5: 4. RESULTADO TRIMESTRE 4 AÑO xxxx | J5: DISTANCIA A LA META
A6: =ROW(A1) -> 1 | B6: =IFERROR(INDEX(INDICADORES[[CODIGO]:[OBSERVACIONES]],MATCH(ANALISIS[[#This Row],[No.]],INDICADORES!$M$2:$M$56,0),1),"") | C6: =IFERROR(INDEX(INDICADORES[[CODIGO]:[OBSERVACIONES]],MATCH(ANALISIS[[#This Row],[No.]],INDICADORES!$M$2:$M$56,0),3),"") | E6: =IFERROR(VLOOKUP(ANALISIS[[#This Row],[CODIGO]],GRAFOS!A62:E116,5,FALSE),"") | J6: =IF(I6-D6=0,0,ABS(IFERROR((I6-D6)/D6,""))) -> 0
A7: =ROW(A2) -> 2 | B7: =IFERROR(INDEX(INDICADORES[[CODIGO]:[OBSERVACIONES]],MATCH(ANALISIS[[#This Row],[No.]],INDICADORES!$M$2:$M$56,0),1),"") | C7: =IFERROR(INDEX(INDICADORES[[CODIGO]:[OBSERVACIONES]],MATCH(ANALISIS[[#This Row],[No.]],INDICADORES!$M$2:$M$56,0),3),"") | E7: =IFERROR(VLOOKUP(ANALISIS[[#This Row],[CODIGO]],GRAFOS!A63:E117,5,FALSE),"") | J7: =IF(I7-D7=0,0,ABS(IFERROR((I7-D7)/D7,""))) -> 0
A8: =ROW(A3) -> 3 | B8: =IFERROR(INDEX(INDICADORES[[CODIGO]:[OBSERVACIONES]],MATCH(ANALISIS[[#This Row],[No.]],INDICADORES!$M$2:$M$56,0),1),"") | C8: =IFERROR(INDEX(INDICADORES[[CODIGO]:[OBSERVACIONES]],MATCH(ANALISIS[[#This Row],[No.]],INDICADORES!$M$2:$M$56,0),3),"") | E8: =IFERROR(VLOOKUP(ANALISIS[[#This Row],[CODIGO]],GRAFOS!A64:E118,5,FALSE),"") | J8: =IF(I8-D8=0,0,ABS(IFERROR((I8-D8)/D8,""))) -> 0
A9: =ROW(A4) -> 4 | B9: =IFERROR(INDEX(INDICADORES[[CODIGO]:[OBSERVACIONES]],MATCH(ANALISIS[[#This Row],[No.]],INDICADORES!$M$2:$M$56,0),1),"") | C9: =IFERROR(INDEX(INDICADORES[[CODIGO]:[OBSERVACIONES]],MATCH(ANALISIS[[#This Row],[No.]],INDICADORES!$M$2:$M$56,0),3),"") | E9: =IFERROR(VLOOKUP(ANALISIS[[#This Row],[CODIGO]],GRAFOS!A65:E119,5,FALSE),"") | J9: =IF(I9-D9=0,0,ABS(IFERROR((I9-D9)/D9,""))) -> 0
A10: =ROW(A5) -> 5 | B10: =IFERROR(INDEX(INDICADORES[[CODIGO]:[OBSERVACIONES]],MATCH(ANALISIS[[#This Row],[No.]],INDICADORES!$M$2:$M$56,0),1),"") | C10: =IFERROR(INDEX(INDICADORES[[CODIGO]:[OBSERVACIONES]],MATCH(ANALISIS[[#This Row],[No.]],INDICADORES!$M$2:$M$56,0),3),"") | E10: =IFERROR(VLOOKUP(ANALISIS[[#This Row],[CODIGO]],GRAFOS!A66:E120,5,FALSE),"") | J10: =IF(I10-D10=0,0,ABS(IFERROR((I10-D10)/D10,""))) -> 0
A11: =ROW(A6) -> 6 | B11: =IFERROR(INDEX(INDICADORES[[CODIGO]:[OBSERVACIONES]],MATCH(ANALISIS[[#This Row],[No.]],INDICADORES!$M$2:$M$56,0),1),"") | C11: =IFERROR(INDEX(INDICADORES[[CODIGO]:[OBSERVACIONES]],MATCH(ANALISIS[[#This Row],[No.]],INDICADORES!$M$2:$M$56,0),3),"") | E11: =IFERROR(VLOOKUP(ANALISIS[[#This Row],[CODIGO]],GRAFOS!A67:E121,5,FALSE),"") | J11: =IF(I11-D11=0,0,ABS(IFERROR((I11-D11)/D11,""))) -> 0
A12: =ROW(A7) -> 7 | B12: =IFERROR(INDEX(INDICADORES[[CODIGO]:[OBSERVACIONES]],MATCH(ANALISIS[[#This Row],[No.]],INDICADORES!$M$2:$M$56,0),1),"") | C12: =IFERROR(INDEX(INDICADORES[[CODIGO]:[OBSERVACIONES]],MATCH(ANALISIS[[#This Row],[No.]],INDICADORES!$M$2:$M$56,0),3),"") | E12: =IFERROR(VLOOKUP(ANALISIS[[#This Row],[CODIGO]],GRAFOS!A68:E122,5,FALSE),"") | J12: =IF(I12-D12=0,0,ABS(IFERROR((I12-D12)/D12,""))) -> 0
A13: =ROW(A8) -> 8 | B13: =IFERROR(INDEX(INDICADORES[[CODIGO]:[OBSERVACIONES]],MATCH(ANALISIS[[#This Row],[No.]],INDICADORES!$M$2:$M$56,0),1),"") | C13: =IFERROR(INDEX(INDICADORES[[CODIGO]:[OBSERVACIONES]],MATCH(ANALISIS[[#This Row],[No.]],INDICADORES!$M$2:$M$56,0),3),"") | E13: =IFERROR(VLOOKUP(ANALISIS[[#This Row],[CODIGO]],GRAFOS!A69:E123,5,FALSE),"") | J13: =IF(I13-D13=0,0,ABS(IFERROR((I13-D13)/D13,""))) -> 0
A14: =ROW(A9) -> 9 | B14: =IFERROR(INDEX(INDICADORES[[CODIGO]:[OBSERVACIONES]],MATCH(ANALISIS[[#This Row],[No.]],INDICADORES!$M$2:$M$56,0),1),"") | C14: =IFERROR(INDEX(INDICADORES[[CODIGO]:[OBSERVACIONES]],MATCH(ANALISIS[[#This Row],[No.]],INDICADORES!$M$2:$M$56,0),3),"") | E14: =IFERROR(VLOOKUP(ANALISIS[[#This Row],[CODIGO]],GRAFOS!A70:E124,5,FALSE),"") | J14: =IF(I14-D14=0,0,ABS(IFERROR((I14-D14)/D14,""))) -> 0
A15: =ROW(A10) -> 10 | B15: =IFERROR(INDEX(INDICADORES[[CODIGO]:[OBSERVACIONES]],MATCH(ANALISIS[[#This Row],[No.]],INDICADORES!$M$2:$M$56,0),1),"") | C15: =IFERROR(INDEX(INDICADORES[[CODIGO]:[OBSERVACIONES]],MATCH(ANALISIS[[#This Row],[No.]],INDICADORES!$M$2:$M$56,0),3),"") | E15: =IFERROR(VLOOKUP(ANALISIS[[#This Row],[CODIGO]],GRAFOS!A71:E125,5,FALSE),"") | J15: =IF(I15-D15=0,0,ABS(IFERROR((I15-D15)/D15,""))) -> 0
A16: =ROW(A11) -> 11 | B16: =IFERROR(INDEX(INDICADORES[[CODIGO]:[OBSERVACIONES]],MATCH(ANALISIS[[#This Row],[No.]],INDICADORES!$M$2:$M$56,0),1),"") | C16: =IFERROR(INDEX(INDICADORES[[CODIGO]:[OBSERVACIONES]],MATCH(ANALISIS[[#This Row],[No.]],INDICADORES!$M$2:$M$56,0),3),"") | E16: =IFERROR(VLOOKUP(ANALISIS[[#This Row],[CODIGO]],GRAFOS!A72:E126,5,FALSE),"") | J16: =IF(I16-D16=0,0,ABS(IFERROR((I16-D16)/D16,""))) -> 0
A17: =ROW(A12) -> 12 | B17: =IFERROR(INDEX(INDICADORES[[CODIGO]:[OBSERVACIONES]],MATCH(ANALISIS[[#This Row],[No.]],INDICADORES!$M$2:$M$56,0),1),"") | C17: =IFERROR(INDEX(INDICADORES[[CODIGO]:[OBSERVACIONES]],MATCH(ANALISIS[[#This Row],[No.]],INDICADORES!$M$2:$M$56,0),3),"") | E17: =IFERROR(VLOOKUP(ANALISIS[[#This Row],[CODIGO]],GRAFOS!A73:E127,5,FALSE),"") | J17: =IF(I17-D17=0,0,ABS(IFERROR((I17-D17)/D17,""))) -> 0
... A60: =ROW(A55) -> 55 | B60: =IFERROR(INDEX(INDICADORES[[CODIGO]:[OBSERVACIONES]],MATCH(ANALISIS[[#This Row],[No.]],INDICADORES!$M$2:$M$56,0),1),"") | C60: =IFERROR(INDEX(INDICADORES[[CODIGO]:[OBSERVACIONES]],MATCH(ANALISIS[[#This Row],[No.]],INDICADORES!$M$2:$M$56,0),3),"") | E60: =IFERROR(VLOOKUP(ANALISIS[[#This Row],[CODIGO]],GRAFOS!A116:E170,5,FALSE),"") | J60: =IF(I60-D60=0,0,ABS(IFERROR((I60-D60)/D60,""))) -> 0

Sheet 2-PRIORIZACION
B1: 2- Priorización de Indicadores
G3: CRITERIOS DE PRIORIZACIÓN
B4: No. | C4: ORDEN PRIORIZADO NO BORRAR | D4: CODIGO | E4: INDICADOR | F4: DISTANCIA A LA META | G4: FACTIBILIDAD DE INTERVENCIÓN | H4: GRAVEDAD DEL EFECTO | I4: GRADO DE SEVERIDAD | J4: CATEGORIA DE SEVERIDAD | K4: ¿PRIORIZAR? | L4: CONSULTE EL PLAN DE MEJORA
B5: ='1-ANALISIS'!A6 -> 1 | C5: {=IF(K5="SI",(SUMPRODUCT(((I5<$I$5:$I$59)*1),((K5=$K$5:$K$59)*1))+1),"")} | D5: ='1-ANALISIS'!B6 | E5: ='1-ANALISIS'!C6 | F5: ='1-ANALISIS'!J6 -> 0 | I5: =IF(OR(PRIORIZACION[[#This Row],[FACTIBILIDAD DE INTERVENCIÓN]]="",PRIORIZACION[[#This Row],[GRAVEDAD DEL EFECTO]]=""),"",(PRIORIZACION[[#This Row],[FACTIBILIDAD DE INTERVENCIÓN]]*PRIORIZACION[[#This Row],[GRAVEDAD DEL EFECTO]]-0.000001*ROW(I5))) | J5: =IFERROR(VLOOKUP(G5&";"&H5,CALCULOS!$S$3:$U$18,3,FALSE),"") | K5: =IF(J5="","",IFERROR(IF(OR(J5="Alto",J5="Extremo"),"SI","NO"),"")) | L5: =IF(D5="","",HYPERLINK("#'"&(SUBSTITUTE(D5,".",""))&"'!A1","Consulte el plan de mejora del indicador "&D5))
B6: ='1-ANALISIS'!A7 -> 2 | C6: {=IF(K6="SI",(SUMPRODUCT(((I6<$I$5:$I$59)*1),((K6=$K$5:$K$59)*1))+1),"")} | D6: ='1-ANALISIS'!B7 | E6: ='1-ANALISIS'!C7 | F6: ='1-ANALISIS'!J7 -> 0 | I6: =IF(OR(PRIORIZACION[[#This Row],[FACTIBILIDAD DE INTERVENCIÓN]]="",PRIORIZACION[[#This Row],[GRAVEDAD DEL EFECTO]]=""),"",(PRIORIZACION[[#This Row],[FACTIBILIDAD DE INTERVENCIÓN]]*PRIORIZACION[[#This Row],[GRAVEDAD DEL EFECTO]]-0.000001*ROW(I6))) | J6: =IFERROR(VLOOKUP(G6&";"&H6,CALCULOS!$S$3:$U$18,3,FALSE),"") | K6: =IF(J6="","",IFERROR(IF(OR(J6="Alto",J6="Extremo"),"SI","NO"),"")) | L6: =IF(D6="","",HYPERLINK("#'"&(SUBSTITUTE(D6,".",""))&"'!A1","Consulte el plan de mejora del indicador "&D6))
B7: ='1-ANALISIS'!A8 -> 3 | C7: {=IF(K7="SI",(SUMPRODUCT(((I7<$I$5:$I$59)*1),((K7=$K$5:$K$59)*1))+1),"")} | D7: ='1-ANALISIS'!B8 | E7: ='1-ANALISIS'!C8 | F7: ='1-ANALISIS'!J8 -> 0 | I7: =IF(OR(PRIORIZACION[[#This Row],[FACTIBILIDAD DE INTERVENCIÓN]]="",PRIORIZACION[[#This Row],[GRAVEDAD DEL EFECTO]]=""),"",(PRIORIZACION[[#This Row],[FACTIBILIDAD DE INTERVENCIÓN]]*PRIORIZACION[[#This Row],[GRAVEDAD DEL EFECTO]]-0.000001*ROW(I7))) | J7: =IFERROR(VLOOKUP(G7&";"&H7,CALCULOS!$S$3:$U$18,3,FALSE),"") | K7: =IF(J7="","",IFERROR(IF(OR(J7="Alto",J7="Extremo"),"SI","NO"),"")) | L7: =IF(D7="","",HYPERLINK("#'"&(SUBSTITUTE(D7,".",""))&"'!A1","Consulte el plan de mejora del indicador "&D7))
B8: ='1-ANALISIS'!A9 -> 4 | C8: {=IF(K8="SI",(SUMPRODUCT(((I8<$I$5:$I$59)*1),((K8=$K$5:$K$59)*1))+1),"")} | D8: ='1-ANALISIS'!B9 | E8: ='1-ANALISIS'!C9 | F8: ='1-ANALISIS'!J9 -> 0 | I8: =IF(OR(PRIORIZACION[[#This Row],[FACTIBILIDAD DE INTERVENCIÓN]]="",PRIORIZACION[[#This Row],[GRAVEDAD DEL EFECTO]]=""),"",(PRIORIZACION[[#This Row],[FACTIBILIDAD DE INTERVENCIÓN]]*PRIORIZACION[[#This Row],[GRAVEDAD DEL EFECTO]]-0.000001*ROW(I8))) | J8: =IFERROR(VLOOKUP(G8&";"&H8,CALCULOS!$S$3:$U$18,3,FALSE),"") | K8: =IF(J8="","",IFERROR(IF(OR(J8="Alto",J8="Extremo"),"SI","NO"),"")) | L8: =IF(D8="","",HYPERLINK("#'"&(SUBSTITUTE(D8,".",""))&"'!A1","Consulte el plan de mejora del indicador "&D8))
B9: ='1-ANALISIS'!A10 -> 5 | C9: {=IF(K9="SI",(SUMPRODUCT(((I9<$I$5:$I$59)*1),((K9=$K$5:$K$59)*1))+1),"")} | D9: ='1-ANALISIS'!B10 | E9: ='1-ANALISIS'!C10 | F9: ='1-ANALISIS'!J10 -> 0 | I9: =IF(OR(PRIORIZACION[[#This Row],[FACTIBILIDAD DE INTERVENCIÓN]]="",PRIORIZACION[[#This Row],[GRAVEDAD DEL EFECTO]]=""),"",(PRIORIZACION[[#This Row],[FACTIBILIDAD DE INTERVENCIÓN]]*PRIORIZACION[[#This Row],[GRAVEDAD DEL EFECTO]]-0.000001*ROW(I9))) | J9: =IFERROR(VLOOKUP(G9&";"&H9,CALCULOS!$S$3:$U$18,3,FALSE),"") | K9: =IF(J9="","",IFERROR(IF(OR(J9="Alto",J9="Extremo"),"SI","NO"),"")) | L9: =IF(D9="","",HYPERLINK("#'"&(SUBSTITUTE(D9,".",""))&"'!A1","Consulte el plan de mejora del indicador "&D9))
B10: ='1-ANALISIS'!A11 -> 6 | C10: {=IF(K10="SI",(SUMPRODUCT(((I10<$I$5:$I$59)*1),((K10=$K$5:$K$59)*1))+1),"")} | D10: ='1-ANALISIS'!B11 | E10: ='1-ANALISIS'!C11 | F10: ='1-ANALISIS'!J11 -> 0 | I10: =IF(OR(PRIORIZACION[[#This Row],[FACTIBILIDAD DE INTERVENCIÓN]]="",PRIORIZACION[[#This Row],[GRAVEDAD DEL EFECTO]]=""),"",(PRIORIZACION[[#This Row],[FACTIBILIDAD DE INTERVENCIÓN]]*PRIORIZACION[[#This Row],[GRAVEDAD DEL EFECTO]]-0.000001*ROW(I10))) | J10: =IFERROR(VLOOKUP(G10&";"&H10,CALCULOS!$S$3:$U$18,3,FALSE),"") | K10: =IF(J10="","",IFERROR(IF(OR(J10="Alto",J10="Extremo"),"SI","NO"),"")) | L10: =IF(D10="","",HYPERLINK("#'"&(SUBSTITUTE(D10,".",""))&"'!A1","Consulte el plan de mejora del indicador "&D10))
B11: ='1-ANALISIS'!A12 -> 7 | C11: {=IF(K11="SI",(SUMPRODUCT(((I11<$I$5:$I$59)*1),((K11=$K$5:$K$59)*1))+1),"")} | D11: ='1-ANALISIS'!B12 | E11: ='1-ANALISIS'!C12 | F11: ='1-ANALISIS'!J12 -> 0 | I11: =IF(OR(PRIORIZACION[[#This Row],[FACTIBILIDAD DE INTERVENCIÓN]]="",PRIORIZACION[[#This Row],[GRAVEDAD DEL EFECTO]]=""),"",(PRIORIZACION[[#This Row],[FACTIBILIDAD DE INTERVENCIÓN]]*PRIORIZACION[[#This Row],[GRAVEDAD DEL EFECTO]]-0.000001*ROW(I11))) | J11: =IFERROR(VLOOKUP(G11&";"&H11,CALCULOS!$S$3:$U$18,3,FALSE),"") | K11: =IF(J11="","",IFERROR(IF(OR(J11="Alto",J11="Extremo"),"SI","NO"),"")) | L11: =IF(D11="","",HYPERLINK("#'"&(SUBSTITUTE(D11,".",""))&"'!A1","Consulte el plan de mejora del indicador "&D11))
B12: ='1-ANALISIS'!A13 -> 8 | C12: {=IF(K12="SI",(SUMPRODUCT(((I12<$I$5:$I$59)*1),((K12=$K$5:$K$59)*1))+1),"")} | D12: ='1-ANALISIS'!B13 | E12: ='1-ANALISIS'!C13 | F12: ='1-ANALISIS'!J13 -> 0 | I12: =IF(OR(PRIORIZACION[[#This Row],[FACTIBILIDAD DE INTERVENCIÓN]]="",PRIORIZACION[[#This Row],[GRAVEDAD DEL EFECTO]]=""),"",(PRIORIZACION[[#This Row],[FACTIBILIDAD DE INTERVENCIÓN]]*PRIORIZACION[[#This Row],[GRAVEDAD DEL EFECTO]]-0.000001*ROW(I12))) | J12: =IFERROR(VLOOKUP(G12&";"&H12,CALCULOS!$S$3:$U$18,3,FALSE),"") | K12: =IF(J12="","",IFERROR(IF(OR(J12="Alto",J12="Extremo"),"SI","NO"),"")) | L12: =IF(D12="","",HYPERLINK("#'"&(SUBSTITUTE(D12,".",""))&"'!A1","Consulte el plan de mejora del indicador "&D12))
B13: ='1-ANALISIS'!A14 -> 9 | C13: {=IF(K13="SI",(SUMPRODUCT(((I13<$I$5:$I$59)*1),((K13=$K$5:$K$59)*1))+1),"")} | D13: ='1-ANALISIS'!B14 | E13: ='1-ANALISIS'!C14 | F13: ='1-ANALISIS'!J14 -> 0 | I13: =IF(OR(PRIORIZACION[[#This Row],[FACTIBILIDAD DE INTERVENCIÓN]]="",PRIORIZACION[[#This Row],[GRAVEDAD DEL EFECTO]]=""),"",(PRIORIZACION[[#This Row],[FACTIBILIDAD DE INTERVENCIÓN]]*PRIORIZACION[[#This Row],[GRAVEDAD DEL EFECTO]]-0.000001*ROW(I13))) | J13: =IFERROR(VLOOKUP(G13&";"&H13,CALCULOS!$S$3:$U$18,3,FALSE),"") | K13: =IF(J13="","",IFERROR(IF(OR(J13="Alto",J13="Extremo"),"SI","NO"),"")) | L13: =IF(D13="","",HYPERLINK("#'"&(SUBSTITUTE(D13,".",""))&"'!A1","Consulte el plan de mejora del indicador "&D13))
B14: ='1-ANALISIS'!A15 -> 10 | C14: {=IF(K14="SI",(SUMPRODUCT(((I14<$I$5:$I$59)*1),((K14=$K$5:$K$59)*1))+1),"")} | D14: ='1-ANALISIS'!B15 | E14: ='1-ANALISIS'!C15 | F14: ='1-ANALISIS'!J15 -> 0 | I14: =IF(OR(PRIORIZACION[[#This Row],[FACTIBILIDAD DE INTERVENCIÓN]]="",PRIORIZACION[[#This Row],[GRAVEDAD DEL EFECTO]]=""),"",(PRIORIZACION[[#This Row],[FACTIBILIDAD DE INTERVENCIÓN]]*PRIORIZACION[[#This Row],[GRAVEDAD DEL EFECTO]]-0.000001*ROW(I14))) | J14: =IFERROR(VLOOKUP(G14&";"&H14,CALCULOS!$S$3:$U$18,3,FALSE),"") | K14: =IF(J14="","",IFERROR(IF(OR(J14="Alto",J14="Extremo"),"SI","NO"),"")) | L14: =IF(D14="","",HYPERLINK("#'"&(SUBSTITUTE(D14,".",""))&"'!A1","Consulte el plan de mejora del indicador "&D14))
B15: ='1-ANALISIS'!A16 -> 11 | C15: {=IF(K15="SI",(SUMPRODUCT(((I15<$I$5:$I$59)*1),((K15=$K$5:$K$59)*1))+1),"")} | D15: ='1-ANALISIS'!B16 | E15: ='1-ANALISIS'!C16 | F15: ='1-ANALISIS'!J16 -> 0 | I15: =IF(OR(PRIORIZACION[[#This Row],[FACTIBILIDAD DE INTERVENCIÓN]]="",PRIORIZACION[[#This Row],[GRAVEDAD DEL EFECTO]]=""),"",(PRIORIZACION[[#This Row],[FACTIBILIDAD DE INTERVENCIÓN]]*PRIORIZACION[[#This Row],[GRAVEDAD DEL EFECTO]]-0.000001*ROW(I15))) | J15: =IFERROR(VLOOKUP(G15&";"&H15,CALCULOS!$S$3:$U$18,3,FALSE),"") | K15: =IF(J15="","",IFERROR(IF(OR(J15="Alto",J15="Extremo"),"SI","NO"),"")) | L15: =IF(D15="","",HYPERLINK("#'"&(SUBSTITUTE(D15,".",""))&"'!A1","Consulte el plan de mejora del indicador "&D15))
B16: ='1-ANALISIS'!A17 -> 12 | C16: {=IF(K16="SI",(SUMPRODUCT(((I16<$I$5:$I$59)*1),((K16=$K$5:$K$59)*1))+1),"")} | D16: ='1-ANALISIS'!B17 | E16: ='1-ANALISIS'!C17 | F16: ='1-ANALISIS'!J17 -> 0 | I16: =IF(OR(PRIORIZACION[[#This Row],[FACTIBILIDAD DE INTERVENCIÓN]]="",PRIORIZACION[[#This Row],[GRAVEDAD DEL EFECTO]]=""),"",(PRIORIZACION[[#This Row],[FACTIBILIDAD DE INTERVENCIÓN]]*PRIORIZACION[[#This Row],[GRAVEDAD DEL EFECTO]]-0.000001*ROW(I16))) | J16: =IFERROR(VLOOKUP(G16&";"&H16,CALCULOS!$S$3:$U$18,3,FALSE),"") | K16: =IF(J16="","",IFERROR(IF(OR(J16="Alto",J16="Extremo"),"SI","NO"),"")) | L16: =IF(D16="","",HYPERLINK("#'"&(SUBSTITUTE(D16,".",""))&"'!A1","Consulte el plan de mejora del indicador "&D16))
... B59: ='1-ANALISIS'!A60 -> 55 | C59: {=IF(K59="SI",(SUMPRODUCT(((I59<$I$5:$I$59)*1),((K59=$K$5:$K$59)*1))+1),"")} | D59: ='1-ANALISIS'!B60 | E59: ='1-ANALISIS'!C60 | F59: ='1-ANALISIS'!J60 -> 0 | I59: =IF(OR(PRIORIZACION[[#This Row],[FACTIBILIDAD DE INTERVENCIÓN]]="",PRIORIZACION[[#This Row],[GRAVEDAD DEL EFECTO]]=""),"",(PRIORIZACION[[#This Row],[FACTIBILIDAD DE INTERVENCIÓN]]*PRIORIZACION[[#This Row],[GRAVEDAD DEL EFECTO]]-0.000001*ROW(I59))) | J59: =IFERROR(VLOOKUP(G59&";"&H59,CALCULOS!$S$3:$U$18,3,FALSE),"") | K59: =IF(J59="","",IFERROR(IF(OR(J59="Alto",J59="Extremo"),"SI","NO"),"")) | L59: =IF(D59="","",HYPERLINK("#'"&(SUBSTITUTE(D59,".",""))&"'!A1","Consulte el plan de mejora del indicador "&D59))

Sheet 2.A CRITERIOS
B4: CRITERIOS DE PRIORIZACIÓN
B5: La factibilidad de intervención se refiere a la capacidad institucional para dar viabilidad a la resolución del problema. La calificación de este criterio debe considerar la disponibilidad de intervenciones costo-efectivas para el efecto en evaluación, así como la posibilidad de gestionar su riesgo. De igual forma, se debe contemplar la factibilidad económica para desarrollar las intervenciones, la aceptabilidad de las intervenciones posibles, los recursos disponibles y la legalidad de la intervención. | E5: La gravedad debe considerar tanto la magnitud –es decir, qué tanta población está siendo afectada por el efecto en evaluación– como la contribución en la carga de mortalidad (enfermedad) del efecto. Asimismo, debe tener en cuenta el potencial de mortalidad prematura o discapacidad relativa y el alto costo que el efecto en evaluación puede generar a los servicios de salud, entre otras características que determinen la gravedad del efecto, tales como amenaza al desarrollo humano o amenaza al derecho a la salud
B6: Escala de factibilidad de intervención | E6: Escala de gravedad del efecto
B7: VALORACIÓN | C7: CRITERIO | E7: VALORACIÓN | F7: CRITERIO
B8: 1 | C8: Factible solo a largo plazo | E8: 1 | F8: Poco grave
B9: 2 | C9: Factible a mediano o largo plazo | E9: 2 | F9: Moderadamente grave
B10: 3 | C10: Factible a corto plazo | E10: 3 | F10: Grave
B11: 4 | C11: Muy factible a corto plazo | E11: 4 | F11: Muy grave

Sheet CALCULOS
B2: 1 | C2: 2 | D2: 3 | E2: 4 | F2: 5 | G2: 6 | H2: 7 | I2: 8 | J2: 9 | K2: 10 | L2: 11 | M2: 12 | N2: 13 | O2: 14 | P2: 15 | Q2: 16 | S2: FACTIBILIDAD X GRAVEDAD | V2: POS MR | W2: POS MR1 | X2: NIVEL PRIORIZACIÓN
A3: ='2-PRIORIZACION'!D5 | B3: =IF($W3=B$2,$A3&" ","") | C3: =IF($W3=C$2,$A3&" ","") | D3: =IF($W3=D$2,$A3&" ","") | E3: =IF($W3=E$2,$A3&" ","") | F3: =IF($W3=F$2,$A3&" ","") | G3: =IF($W3=G$2,$A3&" ","") | H3: =IF($W3=H$2,$A3&" ","") | I3: =IF($W3=I$2,$A3&" ","") | ... Q3: =IF($W3=Q$2,$A3&" ","") | S3: 1;1 | T3: 1 | U3: Bajo | V3: ='2-PRIORIZACION'!G5&";"&'2-PRIORIZACION'!H5 -> ; | W3: =IFERROR(VLOOKUP(V3,$S$3:$T$18,2,FALSE),"") | X3: =IFERROR(VLOOKUP(W3,$T$3:$U$18,2),"")
A4: ='2-PRIORIZACION'!D6 | B4: =IF($W4=B$2,$A4&" ","") | C4: =IF($W4=C$2,$A4&" ","") | D4: =IF($W4=D$2,$A4&" ","") | E4: =IF($W4=E$2,$A4&" ","") | F4: =IF($W4=F$2,$A4&" ","") | G4: =IF($W4=G$2,$A4&" ","") | H4: =IF($W4=H$2,$A4&" ","") | I4: =IF($W4=I$2,$A4&" ","") | ... Q4: =IF($W4=Q$2,$A4&" ","") | S4: 1;2 | T4: 2 | U4: Bajo | V4: ='2-PRIORIZACION'!G6&";"&'2-PRIORIZACION'!H6 -> ; | W4: =IFERROR(VLOOKUP(V4,$S$3:$T$18,2,FALSE),"") | X4: =IFERROR(VLOOKUP(W4,$T$3:$U$18,2),"")
A5: ='2-PRIORIZACION'!D7 | B5: =IF($W5=B$2,$A5&" ","") | C5: =IF($W5=C$2,$A5&" ","") | D5: =IF($W5=D$2,$A5&" ","") | E5: =IF($W5=E$2,$A5&" ","") | F5: =IF($W5=F$2,$A5&" ","") | G5: =IF($W5=G$2,$A5&" ","") | H5: =IF($W5=H$2,$A5&" ","") | I5: =IF($W5=I$2,$A5&" ","") | ... Q5: =IF($W5=Q$2,$A5&" ","") | S5: 1;3 | T5: 3 | U5: Bajo | V5: ='2-PRIORIZACION'!G7&";"&'2-PRIORIZACION'!H7 -> ; | W5: =IFERROR(VLOOKUP(V5,$S$3:$T$18,2,FALSE),"") | X5: =IFERROR(VLOOKUP(W5,$T$3:$U$18,2),"")
A6: ='2-PRIORIZACION'!D8 | B6: =IF($W6=B$2,$A6&" ","") | C6: =IF($W6=C$2,$A6&" ","") | D6: =IF($W6=D$2,$A6&" ","") | E6: =IF($W6=E$2,$A6&" ","") | F6: =IF($W6=F$2,$A6&" ","") | G6: =IF($W6=G$2,$A6&" ","") | H6: =IF($W6=H$2,$A6&" ","") | I6: =IF($W6=I$2,$A6&" ","") | ... Q6: =IF($W6=Q$2,$A6&" ","") | S6: 1;4 | T6: 4 | U6: Moderado | V6: ='2-PRIORIZACION'!G8&";"&'2-PRIORIZACION'!H8 -> ; | W6: =IFERROR(VLOOKUP(V6,$S$3:$T$18,2,FALSE),"") | X6: =IFERROR(VLOOKUP(W6,$T$3:$U$18,2),"")
A7: ='2-PRIORIZACION'!D9 | B7: =IF($W7=B$2,$A7&" ","") | C7: =IF($W7=C$2,$A7&" ","") | D7: =IF($W7=D$2,$A7&" ","") | E7: =IF($W7=E$2,$A7&" ","") | F7: =IF($W7=F$2,$A7&" ","") | G7: =IF($W7=G$2,$A7&" ","") | H7: =IF($W7=H$2,$A7&" ","") | I7: =IF($W7=I$2,$A7&" ","") | ... Q7: =IF($W7=Q$2,$A7&" ","") | S7: 2;1 | T7: 5 | U7: Bajo | V7: ='2-PRIORIZACION'!G9&";"&'2-PRIORIZACION'!H9 -> ; | W7: =IFERROR(VLOOKUP(V7,$S$3:$T$18,2,FALSE),"") | X7: =IFERROR(VLOOKUP(W7,$T$3:$U$18,2),"")
A8: ='2-PRIORIZACION'!D10 | B8: =IF($W8=B$2,$A8&" ","") | C8: =IF($W8=C$2,$A8&" ","") | D8: =IF($W8=D$2,$A8&" ","") | E8: =IF($W8=E$2,$A8&" ","") | F8: =IF($W8=F$2,$A8&" ","") | G8: =IF($W8=G$2,$A8&" ","") | H8: =IF($W8=H$2,$A8&" ","") | I8: =IF($W8=I$2,$A8&" ","") | ... Q8: =IF($W8=Q$2,$A8&" ","") | S8: 2;2 | T8: 6 | U8: Bajo | V8: ='2-PRIORIZACION'!G10&";"&'2-PRIORIZACION'!H10 -> ; | W8: =IFERROR(VLOOKUP(V8,$S$3:$T$18,2,FALSE),"") | X8: =IFERROR(VLOOKUP(W8,$T$3:$U$18,2),"")
A9: ='2-PRIORIZACION'!D11 | B9: =IF($W9=B$2,$A9&" ","") | C9: =IF($W9=C$2,$A9&" ","") | D9: =IF($W9=D$2,$A9&" ","") | E9: =IF($W9=E$2,$A9&" ","") | F9: =IF($W9=F$2,$A9&" ","") | G9: =IF($W9=G$2,$A9&" ","") | H9: =IF($W9=H$2,$A9&" ","") | I9: =IF($W9=I$2,$A9&" ","") | ... Q9: =IF($W9=Q$2,$A9&" ","") | S9: 2;3 | T9: 7 | U9: Moderado | V9: ='2-PRIORIZACION'!G11&";"&'2-PRIORIZACION'!H11 -> ; | W9: =IFERROR(VLOOKUP(V9,$S$3:$T$18,2,FALSE),"") | X9: =IFERROR(VLOOKUP(W9,$T$3:$U$18,2),"")
A10: ='2-PRIORIZACION'!D12 | B10: =IF($W10=B$2,$A10&" ","") | C10: =IF($W10=C$2,$A10&" ","") | D10: =IF($W10=D$2,$A10&" ","") | E10: =IF($W10=E$2,$A10&" ","") | F10: =IF($W10=F$2,$A10&" ","") | G10: =IF($W10=G$2,$A10&" ","") | H10: =IF($W10=H$2,$A10&" ","") | I10: =IF($W10=I$2,$A10&" ","") | ... Q10: =IF($W10=Q$2,$A10&" ","") | S10: 2;4 | T10: 8 | U10: Alto | V10: ='2-PRIORIZACION'!G12&";"&'2-PRIORIZACION'!H12 -> ; | W10: =IFERROR(VLOOKUP(V10,$S$3:$T$18,2,FALSE),"") | X10: =IFERROR(VLOOKUP(W10,$T$3:$U$18,2),"")
A11: ='2-PRIORIZACION'!D13 | B11: =IF($W11=B$2,$A11&" ","") | C11: =IF($W11=C$2,$A11&" ","") | D11: =IF($W11=D$2,$A11&" ","") | E11: =IF($W11=E$2,$A11&" ","") | F11: =IF($W11=F$2,$A11&" ","") | G11: =IF($W11=G$2,$A11&" ","") | H11: =IF($W11=H$2,$A11&" ","") | I11: =IF($W11=I$2,$A11&" ","") | ... Q11: =IF($W11=Q$2,$A11&" ","") | S11: 3;1 | T11: 9 | U11: Bajo | V11: ='2-PRIORIZACION'!G13&";"&'2-PRIORIZACION'!H13 -> ; | W11: =IFERROR(VLOOKUP(V11,$S$3:$T$18,2,FALSE),"") | X11: =IFERROR(VLOOKUP(W11,$T$3:$U$18,2),"")
A12: ='2-PRIORIZACION'!D14 | B12: =IF($W12=B$2,$A12&" ","") | C12: =IF($W12=C$2,$A12&" ","") | D12: =IF($W12=D$2,$A12&" ","") | E12: =IF($W12=E$2,$A12&" ","") | F12: =IF($W12=F$2,$A12&" ","") | G12: =IF($W12=G$2,$A12&" ","") | H12: =IF($W12=H$2,$A12&" ","") | I12: =IF($W12=I$2,$A12&" ","") | ... Q12: =IF($W12=Q$2,$A12&" ","") | S12: 3;2 | T12: 10 | U12: Moderado | V12: ='2-PRIORIZACION'!G14&";"&'2-PRIORIZACION'!H14 -> ; | W12: =IFERROR(VLOOKUP(V12,$S$3:$T$18,2,FALSE),"") | X12: =IFERROR(VLOOKUP(W12,$T$3:$U$18,2),"")
A13: ='2-PRIORIZACION'!D15 | B13: =IF($W13=B$2,$A13&" ","") | C13: =IF($W13=C$2,$A13&" ","") | D13: =IF($W13=D$2,$A13&" ","") | E13: =IF($W13=E$2,$A13&" ","") | F13: =IF($W13=F$2,$A13&" ","") | G13: =IF($W13=G$2,$A13&" ","") | H13: =IF($W13=H$2,$A13&" ","") | I13: =IF($W13=I$2,$A13&" ","") | ... Q13: =IF($W13=Q$2,$A13&" ","") | S13: 3;3 | T13: 11 | U13: Alto | V13: ='2-PRIORIZACION'!G15&";"&'2-PRIORIZACION'!H15 -> ; | W13: =IFERROR(VLOOKUP(V13,$S$3:$T$18,2,FALSE),"") | X13: =IFERROR(VLOOKUP(W13,$T$3:$U$18,2),"")
A14: ='2-PRIORIZACION'!D16 | B14: =IF($W14=B$2,$A14&" ","") | C14: =IF($W14=C$2,$A14&" ","") | D14: =IF($W14=D$2,$A14&" ","") | E14: =IF($W14=E$2,$A14&" ","") | F14: =IF($W14=F$2,$A14&" ","") | G14: =IF($W14=G$2,$A14&" ","") | H14: =IF($W14=H$2,$A14&" ","") | I14: =IF($W14=I$2,$A14&" ","") | ... Q14: =IF($W14=Q$2,$A14&" ","") | S14: 3;4 | T14: 12 | U14: Extremo | V14: ='2-PRIORIZACION'!G16&";"&'2-PRIORIZACION'!H16 -> ; | W14: =IFERROR(VLOOKUP(V14,$S$3:$T$18,2,FALSE),"") | X14: =IFERROR(VLOOKUP(W14,$T$3:$U$18,2),"")
... A18: ='2-PRIORIZACION'!D20 | B18: =IF($W18=B$2,$A18&" ","") | C18: =IF($W18=C$2,$A18&" ","") | D18: =IF($W18=D$2,$A18&" ","") | E18: =IF($W18=E$2,$A18&" ","") | F18: =IF($W18=F$2,$A18&" ","") | G18: =IF($W18=G$2,$A18&" ","") | H18: =IF($W18=H$2,$A18&" ","") | I18: =IF($W18=I$2,$A18&" ","") | ... Q18: =IF($W18=Q$2,$A18&" ","") | S18: 4;4 | T18: 16 | U18: Extremo | V18: ='2-PRIORIZACION'!G20&";"&'2-PRIORIZACION'!H20 -> ; | W18: =IFERROR(VLOOKUP(V18,$S$3:$T$18,2,FALSE),"") | X18: =IFERROR(VLOOKUP(W18,$T$3:$U$18,2),"")
A19: ='2-PRIORIZACION'!D21 | B19: =IF($W19=B$2,$A19&" ","") | C19: =IF($W19=C$2,$A19&" ","") | D19: =IF($W19=D$2,$A19&" ","") | E19: =IF($W19=E$2,$A19&" ","") | F19: =IF($W19=F$2,$A19&" ","") | G19: =IF($W19=G$2,$A19&" ","") | H19: =IF($W19=H$2,$A19&" ","") | I19: =IF($W19=I$2,$A19&" ","") | ... Q19: =IF($W19=Q$2,$A19&" ","") | V19: ='2-PRIORIZACION'!G21&";"&'2-PRIORIZACION'!H21 -> ; | W19: =IFERROR(VLOOKUP(V19,$S$3:$T$18,2,FALSE),"") | X19: =IFERROR(VLOOKUP(W19,$T$3:$U$18,2),"")
A20: ='2-PRIORIZACION'!D22 | B20: =IF($W20=B$2,$A20&" ","") | C20: =IF($W20=C$2,$A20&" ","") | D20: =IF($W20=D$2,$A20&" ","") | E20: =IF($W20=E$2,$A20&" ","") | F20: =IF($W20=F$2,$A20&" ","") | G20: =IF($W20=G$2,$A20&" ","") | H20: =IF($W20=H$2,$A20&" ","") | I20: =IF($W20=I$2,$A20&" ","") | ... Q20: =IF($W20=Q$2,$A20&" ","") | V20: ='2-PRIORIZACION'!G22&";"&'2-PRIORIZACION'!H22 -> ; | W20: =IFERROR(VLOOKUP(V20,$S$3:$T$18,2,FALSE),"") | X20: =IFERROR(VLOOKUP(W20,$T$3:$U$18,2),"")
A21: ='2-PRIORIZACION'!D23 | B21: =IF($W21=B$2,$A21&" ","") | C21: =IF($W21=C$2,$A21&" ","") | D21: =IF($W21=D$2,$A21&" ","") | E21: =IF($W21=E$2,$A21&" ","") | F21: =IF($W21=F$2,$A21&" ","") | G21: =IF($W21=G$2,$A21&" ","") | H21: =IF($W21=H$2,$A21&" ","") | I21: =IF($W21=I$2,$A21&" ","") | ... Q21: =IF($W21=Q$2,$A21&" ","") | V21: ='2-PRIORIZACION'!G23&";"&'2-PRIORIZACION'!H23 -> ; | W21: =IFERROR(VLOOKUP(V21,$S$3:$T$18,2,FALSE),"") | X21: =IFERROR(VLOOKUP(W21,$T$3:$U$18,2),"")
A22: ='2-PRIORIZACION'!D24 | B22: =IF($W22=B$2,$A22&" ","") | C22: =IF($W22=C$2,$A22&" ","") | D22: =IF($W22=D$2,$A22&" ","") | E22: =IF($W22=E$2,$A22&" ","") | F22: =IF($W22=F$2,$A22&" ","") | G22: =IF($W22=G$2,$A22&" ","") | H22: =IF($W22=H$2,$A22&" ","") | I22: =IF($W22=I$2,$A22&" ","") | ... Q22: =IF($W22=Q$2,$A22&" ","") | V22: ='2-PRIORIZACION'!G24&";"&'2-PRIORIZACION'!H24 -> ; | W22: =IFERROR(VLOOKUP(V22,$S$3:$T$18,2,FALSE),"") | X22: =IFERROR(VLOOKUP(W22,$T$3:$U$18,2),"")
A23: ='2-PRIORIZACION'!D25 | B23: =IF($W23=B$2,$A23&" ","") | C23: =IF($W23=C$2,$A23&" ","") | D23: =IF($W23=D$2,$A23&" ","") | E23: =IF($W23=E$2,$A23&" ","") | F23: =IF($W23=F$2,$A23&" ","") | G23: =IF($W23=G$2,$A23&" ","") | H23: =IF($W23=H$2,$A23&" ","") | I23: =IF($W23=I$2,$A23&" ","") | ... Q23: =IF($W23=Q$2,$A23&" ","") | V23: ='2-PRIORIZACION'!G25&";"&'2-PRIORIZACION'!H25 -> ; | W23: =IFERROR(VLOOKUP(V23,$S$3:$T$18,2,FALSE),"") | X23: =IFERROR(VLOOKUP(W23,$T$3:$U$18,2),"")
A24: ='2-PRIORIZACION'!D26 | B24: =IF($W24=B$2,$A24&" ","") | C24: =IF($W24=C$2,$A24&" ","") | D24: =IF($W24=D$2,$A24&" ","") | E24: =IF($W24=E$2,$A24&" ","") | F24: =IF($W24=F$2,$A24&" ","") | G24: =IF($W24=G$2,$A24&" ","") | H24: =IF($W24=H$2,$A24&" ","") | I24: =IF($W24=I$2,$A24&" ","") | ... Q24: =IF($W24=Q$2,$A24&" ","") | V24: ='2-PRIORIZACION'!G26&";"&'2-PRIORIZACION'!H26 -> ; | W24: =IFERROR(VLOOKUP(V24,$S$3:$T$18,2,FALSE),"") | X24: =IFERROR(VLOOKUP(W24,$T$3:$U$18,2),"")
A25: ='2-PRIORIZACION'!D27 | B25: =IF($W25=B$2,$A25&" ","") | C25: =IF($W25=C$2,$A25&" ","") | D25: =IF($W25=D$2,$A25&" ","") | E25: =IF($W25=E$2,$A25&" ","") | F25: =IF($W25=F$2,$A25&" ","") | G25: =IF($W25=G$2,$A25&" ","") | H25: =IF($W25=H$2,$A25&" ","") | I25: =IF($W25=I$2,$A25&" ","") | ... Q25: =IF($W25=Q$2,$A25&" ","") | V25: ='2-PRIORIZACION'!G27&";"&'2-PRIORIZACION'!H27 -> ; | W25: =IFERROR(VLOOKUP(V25,$S$3:$T$18,2,FALSE),"") | X25: =IFERROR(VLOOKUP(W25,$T$3:$U$18,2),"")
A26: ='2-PRIORIZACION'!D28 | B26: =IF($W26=B$2,$A26&" ","") | C26: =IF($W26=C$2,$A26&" ","") | D26: =IF($W26=D$2,$A26&" ","") | E26: =IF($W26=E$2,$A26&" ","") | F26: =IF($W26=F$2,$A26&" ","") | G26: =IF($W26=G$2,$A26&" ","") | H26: =IF($W26=H$2,$A26&" ","") | I26: =IF($W26=I$2,$A26&" ","") | ... Q26: =IF($W26=Q$2,$A26&" ","") | V26: ='2-PRIORIZACION'!G28&";"&'2-PRIORIZACION'!H28 -> ; | W26: =IFERROR(VLOOKUP(V26,$S$3:$T$18,2,FALSE),"") | X26: =IFERROR(VLOOKUP(W26,$T$3:$U$18,2),"")
A27: ='2-PRIORIZACION'!D29 | B27: =IF($W27=B$2,$A27&" ","") | C27: =IF($W27=C$2,$A27&" ","") | D27: =IF($W27=D$2,$A27&" ","") | E27: =IF($W27=E$2,$A27&" ","") | F27: =IF($W27=F$2,$A27&" ","") | G27: =IF($W27=G$2,$A27&" ","") | H27: =IF($W27=H$2,$A27&" ","") | I27: =IF($W27=I$2,$A27&" ","") | ... Q27: =IF($W27=Q$2,$A27&" ","") | V27: ='2-PRIORIZACION'!G29&";"&'2-PRIORIZACION'!H29 -> ; | W27: =IFERROR(VLOOKUP(V27,$S$3:$T$18,2,FALSE),"") | X27: =IFERROR(VLOOKUP(W27,$T$3:$U$18,2),"")
A28: ='2-PRIORIZACION'!D30 | B28: =IF($W28=B$2,$A28&" ","") | C28: =IF($W28=C$2,$A28&" ","") | D28: =IF($W28=D$2,$A28&" ","") | E28: =IF($W28=E$2,$A28&" ","") | F28: =IF($W28=F$2,$A28&" ","") | G28: =IF($W28=G$2,$A28&" ","") | H28: =IF($W28=H$2,$A28&" ","") | I28: =IF($W28=I$2,$A28&" ","") | ... Q28: =IF($W28=Q$2,$A28&" ","") | V28: ='2-PRIORIZACION'!G30&";"&'2-PRIORIZACION'!H30 -> ; | W28: =IFERROR(VLOOKUP(V28,$S$3:$T$18,2,FALSE),"") | X28: =IFERROR(VLOOKUP(W28,$T$3:$U$18,2),"")
A29: ='2-PRIORIZACION'!D31 | B29: =IF($W29=B$2,$A29&" ","") | C29: =IF($W29=C$2,$A29&" ","") | D29: =IF($W29=D$2,$A29&" ","") | E29: =IF($W29=E$2,$A29&" ","") | F29: =IF($W29=F$2,$A29&" ","") | G29: =IF($W29=G$2,$A29&" ","") | H29: =IF($W29=H$2,$A29&" ","") | I29: =IF($W29=I$2,$A29&" ","") | ... Q29: =IF($W29=Q$2,$A29&" ","") | V29: ='2-PRIORIZACION'!G31&";"&'2-PRIORIZACION'!H31 -> ; | W29: =IFERROR(VLOOKUP(V29,$S$3:$T$18,2,FALSE),"") | X29: =IFERROR(VLOOKUP(W29,$T$3:$U$18,2),"")
A30: ='2-PRIORIZACION'!D32 | B30: =IF($W30=B$2,$A30&" ","") | C30: =IF($W30=C$2,$A30&" ","") | D30: =IF($W30=D$2,$A30&" ","") | E30: =IF($W30=E$2,$A30&" ","") | F30: =IF($W30=F$2,$A30&" ","") | G30: =IF($W30=G$2,$A30&" ","") | H30: =IF($W30=H$2,$A30&" ","") | I30: =IF($W30=I$2,$A30&" ","") | ... Q30: =IF($W30=Q$2,$A30&" ","") | V30: ='2-PRIORIZACION'!G32&";"&'2-PRIORIZACION'!H32 -> ; | W30: =IFERROR(VLOOKUP(V30,$S$3:$T$18,2,FALSE),"") | X30: =IFERROR(VLOOKUP(W30,$T$3:$U$18,2),"")
... A57: ='2-PRIORIZACION'!D59 | B57: =IF($W57=B$2,$A57&" ","") | C57: =IF($W57=C$2,$A57&" ","") | D57: =IF($W57=D$2,$A57&" ","") | E57: =IF($W57=E$2,$A57&" ","") | F57: =IF($W57=F$2,$A57&" ","") | G57: =IF($W57=G$2,$A57&" ","") | H57: =IF($W57=H$2,$A57&" ","") | I57: =IF($W57=I$2,$A57&" ","") | ... Q57: =IF($W57=Q$2,$A57&" ","") | V57: ='2-PRIORIZACION'!G59&";"&'2-PRIORIZACION'!H59 -> ; | W57: =IFERROR(VLOOKUP(V57,$S$3:$T$18,2,FALSE),"") | X57: =IFERROR(VLOOKUP(W57,$T$3:$U$18,2),"")
