Workbook
Name acciones: planaccion[Qué / Acción]
Name alcance: 'DOCUMENTO PAMEC'!$B$47
Name Apoyo_Diagnóstico_Compl._Terapéutica: Datos!$D$2:$D$23
Name Atención_Inmediata: Datos!$E$2:$E$6
Name categoria: 'AUTOEV CUALIT'!$E$5:$E$204
Name Cirugía: Datos!$B$2:$B$25
Name Consulta_Externa: Datos!$A$2:$A$92
Name criterio: 'AUTOEV CUALIT'!$F$5:$F$204
Name criterio_priorizado: planaccion[Criterio]
Name duracion: 'DOCUMENTO PAMEC'!$B$60
Name Eje_de_Seguridad: 'AUTOEV CUALIT'!$C$5:$C$204
Name eje_priorizado: planaccion[Eje Seguridad]
Name fortaleza: 'AUTOEV CUALIT'!$G$5:$G$204
Name institucion: 'DOCUMENTO PAMEC'!$B$64
Name Internación: Datos!$C$2:$C$16
Name intro: 'DOCUMENTO PAMEC'!$B$18
Name justifica: 'DOCUMENTO PAMEC'!$B$36
Name justificacion: 'DOCUMENTO PAMEC'!$B$37
Name legal: 'DOCUMENTO PAMEC'!$B$26
Name marco: 'DOCUMENTO PAMEC'!$B$74
Name marcolegal: 'DOCUMENTO PAMEC'!$B$27
Name MARCOTEO: 'DOCUMENTO PAMEC'!$B$75
Name metodologia: 'DOCUMENTO PAMEC'!$B$99
Name nivelauditoria: 'DOCUMENTO PAMEC'!$B$56
Name objetivo: 'DOCUMENTO PAMEC'!$B$39
Name OBJETIVOPAMEC: 'DOCUMENTO PAMEC'!$B$40
Name om: 'AUTOEV CUALIT'!$H$5:$H$204
Name om_priorizada: planaccion[Oportunidad de Mejora]
Name practica_priorizada: planaccion[Práctica Segura]
Name practica_segura: 'AUTOEV CUALIT'!$D$5:$D$204
Name proceso1: PROCESOS!$D$5
Name proceso10: PROCESOS!$L$7
Name proceso11: PROCESOS!$D$9
Name proceso12: PROCESOS!$F$9
Name proceso13: PROCESOS!$H$9
Name proceso14: PROCESOS!$J$9
Name proceso15: PROCESOS!$L$9
Name proceso16: PROCESOS!$D$13
Name proceso17: PROCESOS!$F$13
Name proceso18: PROCESOS!$H$13
Name proceso19: PROCESOS!$J$13
Name proceso2: PROCESOS!$F$5
Name proceso20: PROCESOS!$L$13
Name proceso21: PROCESOS!$D$15
Name proceso22: PROCESOS!$F$15
Name proceso23: PROCESOS!$H$15
Name proceso24: PROCESOS!$J$15
Name proceso25: PROCESOS!$L$15
Name proceso26: PROCESOS!$D$17
Name proceso27: PROCESOS!$F$17
Name proceso28: PROCESOS!$H$17
Name proceso29: PROCESOS!$J$17
Name proceso3: PROCESOS!$H$5
Name proceso30: PROCESOS!$L$17
Name proceso31: PROCESOS!$D$19
Name proceso32: PROCESOS!$F$19
Name proceso33: PROCESOS!$H$19
Name proceso34: PROCESOS!$J$19
Name proceso35: PROCESOS!$L$19
Name proceso36: PROCESOS!$D$23

Sheet RUTA CRITICA

Sheet IDENTIFICACIÓN
C1: Información del Prestador y Servicios Habilitados
C3: Desde | D3: Hasta
B4: Ciclo de Mejora
B6: Nombre del Prestador | C6: IPS ABC
B8: NIT
B10: Código REPS
B12: Ciudad Sede
B14: Nombre de la Sede
B16: Código REPS de la Sede
B18: Dirección y teléfono sede
B20: Gerente / Director / Responsable Sede
B22: Contratos Activos
B24: ="Servicios Habilitados por el Prestador en la Sede "&C14 -> Servicios Habilitados por el Prestador en la Sede
B26: Grupo | C26: Servicio | D26: Complejidad | E26: Modalidad (Intramural-Unidad móvil-Domiciliario-Jornada salud-Extramural-Prestador Ref. Telem. Interactiva-Prestador Ref. Telem. no interactiva-Prestador Ref. Telexperticia-Prestador Ref. Telemonitoreo-Prestador Rem. Telemonitoreo-Prestador Rem. Telexpert

Sheet LOGO
C1: <--- Inserte su logo en esta celda "A1"

Sheet PROCESOS
D1: ="Mapa de Procesos "&IDENTIFICACIÓN!C14 -> Mapa de Procesos
B3: Cliente | D3: Procesos de Planeación o Estratégicos | N3: Cliente
D11: Procesos Misionales
D21: Procesos de Apoyo o Soporte

Sheet DOCUMENTO PAMEC
C1: ="Documento PAMEC "&IDENTIFICACIÓN!C14 -> Documento PAMEC
B3: Contenido
C5: Introducción
C6: Marco legal
C7: Justificación
C8: Objetivo
C9: Alcance
C10: Duración y cronograma Ruta Crítica
C11: Tipos de acciones
C12: Niveles de auditoria
C13: Presentación Institucional y Contexto Operativo
C14: Marco Conceptual
C15: Metodología de Implementación
B18: Introducción
B19: La gestión de la calidad en el ámbito de la salud desempeña un papel fundamental en asegurar que los servicios proporcionados alcancen los estándares más elevados, garantizando así la seguridad y el bienestar de los pacientes. En este contexto, el Programa de Auditoría para el Mejoramiento de la Calidad en Salud (PAMEC) emerge como una herramienta estratégica crucial para evaluar y fortalecer los procesos internos de las instituciones.
B20: El propósito fundamental del Programa de Auditoría para el Mejoramiento de Calidad en Salud con enfoque en la Política Nacional de Seguridad del Paciente en la institución ____________________ consiste en llevar a cabo un proceso de mejora continua, iniciando con un análisis exhaustivo a través de la autoevaluación. Este proceso permite identificar posibles deficiencias en la calidad de los servicios ofrecidos, considerando estas deficiencias como áreas prioritarias para la implementación de mejoras continuas.
B21: La siguiente fase implica la identificación de procesos institucionales con brechas de calidad, estrechamente relacionados con el proceso de atención, orientados hacia el usuario. En consonancia con la disponibilidad de recursos institucionales, estos procesos serán priorizados para su intervención.
B22: Posteriormente, después de identificar los procesos que requieren mejora, se da un paso crucial al definir el nivel de calidad esperado en su ejecución y resultados mediante una planificación cuantitativa de la calidad. Con base en estos parámetros, se formulan acciones de mejora y se establecen las herramientas y mecanismos de auditoría necesarios para su seguimiento.
B23: La fase de ejecución y seguimiento de las actividades definidas, marca otro hito en el proceso de mejora continua. La creación de espacios dedicados al seguimiento minucioso del cumplimiento de los planes de acción y la evaluación de los resultados obtenidos, mediante los indicadores designados se vuelve prioritaria. La efectividad de las estrategias se evalúa a través del seguimiento de indicadores y la verificación de los resultados de las auditorías.
B24: Al concluir el ciclo de mejora, se realiza un análisis integral de las oportunidades de mejora abordadas, junto con un resumen detallado que destaca la naturaleza del problema, el análisis realizado, las causas identificadas y las acciones emprendidas. Este resumen proporciona una visión clara del progreso alcanzado y permite llevar a cabo una evaluación de la efectividad y eficiencia de la implementación de acciones y auditorías. Esto permite una evaluación completa de los resultados obtenidos a lo largo de la Ruta Crítica del PAMEC.
B26: Marco Legal
B27: • Decreto 780 de 2016: Por medio del cual se expide el Decreto Único Reglamentario del Sector Salud y Protección Social. Establece lo referente al PAMEC en el Parte 5, Titulo 1, Capitulo 4.
B28: • Resolución 3100 del 2019: Por la cual se definen los procedimientos y condiciones de inscripción de los prestadores de servicios de salud y de habilitación de los servicios de salud y se adopta el Manual de Inscripción de Prestadores y Habilitación de Servicios de Salud
B29: • Resolución 0256 de 2016: Por la cual se dictan disposiciones en relación con el Sistema de Información para la Calidad y se establecen los indicadores para el monitoreo de la calidad en salud
B30: • Circular 012 de 2016: Por la cual se hacen adiciones, eliminaciones y modificaciones a la Circular 047 de 2007 y se imparten instrucciones en lo relacionado con el programa de auditoria para el mejoramiento de la calidad de la atención en salud y el sistema de información de la calidad.
... B49: Tipos de Acciones
B50: ="En "&IDENTIFICACIÓN!C6&" se contemplan tres tipos de acciones para la auditoría de la calidad de la atención en salud:" -> En IPS ABC se contemplan tres tipos de acciones para la auditoría de la calidad de la atención en salud:
B51: Acciones Preventivas: Comprenden un conjunto de procedimientos, actividades o mecanismos de auditoría sobre los procesos prioritarios definidos por la entidad, que tanto las personas como la organización deben llevar a cabo antes de la atención de los usuarios, con el objetivo de garantizar la calidad. Estas acciones están orientadas a evitar la aparición de problemas de calidad ya identificados. Entre las acciones preventivas definidas en la institución se encuentran: (AJUSTE LAS ACCIONES SEGÚN LAS PRÁCTICAS DE LA INSTITUCIÓN) - Adopción de guías de práctica clínica basadas en las principales causas de consulta. - Documentación y estandarización de procesos mediante el sistema de gestión de calidad. - Inducción a nuevos colaboradores, incluyendo los procesos prioritarios. - Jornadas de capacitación al personal asistencial en temas clave para la calidad y seguridad en la atención. - Programa de mantenimiento preventivo de equipos biomédicos e infraestructura.
B52: Acciones de Seguimiento: Son aquellas que se realizan lo más cercano posible al tiempo real de la ejecución de los procesos, con el fin de identificar y resolver de manera oportuna los problemas reales o potenciales. Estas acciones buscan evidenciar brechas de desempeño y asegurar la correcta aplicación de guías, normas y procedimientos conforme a los referentes legales y de calidad adoptados. Las acciones de seguimiento incluyen: (AJUSTE LAS ACCIONES SEGÚN LAS PRÁCTICAS DE LA INSTITUCIÓN) - Rondas de seguridad del paciente. - Auditorías de calidad a procesos. - Encuestas de satisfacción del usuario. - Auditoría de historias clínicas. Acciones Coyunturales: Estas acciones comprenden procedimientos, actividades o mecanismos de auditoría que se realizan con el objetivo de alertar, informar y analizar la ocurrencia de eventos adversos durante la atención en salud, facilitando intervenciones inmediatas para resolver los problemas detectados y prevenir su recurrencia. Estas acciones tienen un enfoque retrospectivo, permitiendo detectar, informar y analizar resultados no esperados. Las acciones coyunturales incluyen: (AJUSTE LAS ACCIONES SEGÚN LAS PRÁCTICAS DE LA INSTITUCIÓN) - Análisis y gestión de eventos adversos. - Seguimiento y gestión de PQRS (Peticiones, Quejas, Reclamos y Sugerencias) de los usuarios. - Gestión de no conformidades.
B55: Niveles de Auditoria
B56: El programa de auditoría para el mejoramiento de la calidad se concibe como un sistema de monitoreo continuo que compara la calidad observada con la calidad esperada. Para garantizar su efectividad, se establecen tres niveles de auditoría: autocontrol, auditoría interna y auditoría externa. Autocontrol: Este es el nivel más eficiente de auditoría, en el cual cada miembro de la organización se responsabiliza por planear, ejecutar, verificar y ajustar los procedimientos en los que participa, asegurándose de que se cumplan los estándares de calidad establecidos tanto por la normativa vigente como por la entidad. Entre los mecanismos de autocontrol definidos se incluyen: (AJUSTE LAS PRÁCTICAS DE AUDITORIA EN CADA NIVEL SEGÚN LA REALIDAD DE LA INSTITUCIÓN) - Diseño y estandarización de los procesos de atención. - Capacitación y entrenamiento de los colaboradores en las actividades bajo su responsabilidad. - Implementación de mecanismos de auto-chequeo en prácticas seguras durante la atención.
B57: Auditoría Interna: Es una evaluación sistemática realizada dentro de la institución, cuyo objetivo es monitorear la adherencia a los protocolos y prácticas institucionales, así como verificar la correcta ejecución del autocontrol. Para llevar a cabo la auditoría interna, se establecen procedimientos, programas y herramientas de auditoría. Sus principales objetivos son: (AJUSTE LAS PRÁCTICAS DE AUDITORIA EN CADA NIVEL SEGÚN LA REALIDAD DE LA INSTITUCIÓN) - Analizar las causas que impiden alcanzar los resultados esperados en los procesos priorizados. - Implementar acciones necesarias para alcanzar el nivel de calidad deseado. - Acompañar a los responsables de los procesos en su seguimiento y mejora continua. Auditoría Externa: Esta auditoría es llevada a cabo por una entidad externa a la organización y tiene como propósito evaluar la efectividad de la auditoría interna y del autocontrol. Las auditorías externas son comúnmente realizadas por aseguradoras, clientes, y las Secretarías de Salud Pública a nivel municipal y departamental.
B59: Duración y Cronograma de la Ruta Crítica
B60: ="Se ha definido un cronograma de trabajo que inicia el "&DAY(IDENTIFICACIÓN!C4)&"/"&MONTH(IDENTIFICACIÓN!C4)&"/"&YEAR(IDENTIFICACIÓN!C4)&" y culmina el "&DAY(IDENTIFICACIÓN!D4)&"/"&MONTH(IDENTIFICACIÓN!D4)&"/"&YEAR(IDENTIFICACIÓN!D4)&". A continuación, se detallan las fases clave y sus respectivas fechas estimadas:" -> Se ha definido un cronograma de trabajo que inicia el 0/1/1900 y culmina el 0/1/1900. A continuación, se detallan las fases clave y sus respectivas fechas estimadas:
B61: Ver Cronograma en este vinculo
B63: Presentación Institucional y Contexto Operativo
B64: En esta sección realice una descripción exhaustiva de la institución, abordando aspectos como la gama de servicios ofrecidos y el marco estratégico en el cual la institución se desenvuelve, destacando los elementos fundamentales que respaldan sus objetivos y metas a largo plazo. Nam tellus nisi, lacinia nec pretium in, euismod nec purus. Mauris eleifend lacus lectus, et euismod leo maximus non. Cras justo tellus, semper vel sapien et, ultricies pellentesque ex. Lorem ipsum dolor sit amet, consectetur adipiscing elit. Vivamus vitae leo justo. Nulla lacus purus, lobortis in elementum id, convallis vestibulum arcu. Phasellus viverra lectus ut aliquam tristique. Sed nec massa nec libero fringilla efficitur ut quis mi. Ut condimentum mollis tortor a pharetra. Nam venenatis finibus enim nec ultricies. Quisque nec blandit sem
B65: Ver ficha técnica de información del prestador y servicios habilitados en este vínculo
B67: Registre la misión corporativa Phasellus imperdiet arcu et maximus vestibulum. Nullam finibus posuere semper. Pellentesque egestas lobortis odio, quis fringilla est. In turpis arcu, mollis ut accumsan quis, pretium dapibus ante. Aenean elementum convallis mollis.
B69: Registre la visión corporativa Aliquam ac cursus arcu. Morbi blandit lobortis congue. Maecenas iaculis neque sit amet feugiat vulputate. In imperdiet velit eget libero volutpat fermentum. Nulla accumsan sem sed ligula scelerisque, sit amet tempus libero pulvinar.
...

Sheet EQUIPO
C1: Conformación de Equipo PAMEC
B3: Ciudad y Fecha
B5: Lugar de reunión
B7: Asistentes
B9: Objetivo | C9: Formalizar la creación del equipo de PAMEC en [Nombre de la institución de salud] y definir sus responsabilidades y funciones.
B11: Reuniones | C11: El equipo de PAMEC se reunirá de manera regular [especificar la frecuencia, por ejemplo, mensual] para revisar y discutir los resultados de sus auditorías y otras actividades.
B13: Recursos | C13: La Gerencia/Dirección se compromete a proporcionar los recursos necesarios, como personal, tiempo y capacitación, para que el equipo de PAMEC pueda llevar a cabo sus funciones de manera efectiva.
B15: Funciones del equipo | C15: El equipo de PAMEC tendrá las siguientes funciones y responsabilidades: • Desarrollar cada una de las etapas de la ruta crítica • Desarrollar los planes de acción definidos a las brechas de calidad identificadas • Realizar un seguimiento regular de la implementación de las acciones para garantizar que se estén llevando a cabo según lo planeado • Proporcionar retroalimentación a los equipos responsables de la implementación y realizar ajustes según sea necesario • Evaluar los resultados de las acciones de mejora implementadas • Comunicar de manera efectiva los resultados y logros al equipo de alta dirección y demás interesados • Promover una cultura de calidad en la institución a través de la capacitación, la sensibilización y la participación activa de los colaboradores en los esfuerzos de mejora continua.
B17: Líder del Equipo (cargo)
B19: Miembros del Equipo (cargo)

Sheet CRONOGRAMA
C1: Cronograma Ruta Crítica
B3: % Cumplimiento de la Ruta Crítica | C3: =IFERROR((COUNT(cronograma[Fecha de fin Real]))/COUNT(cronograma[Fecha de inicio Programada (¿Cuándo?)]),"") | K3: Hoy es: | L3: =TODAY() -> 46176
B4: Actividad (¿Qué?) | C4: Responsable (¿Quién?) | D4: Propósito o Actividad (¿Por Qué?) | E4: Fecha de inicio Programada (¿Cuándo?) | F4: Fecha de fin Programada (¿Cuándo?) | G4: Días estimados | H4: Fecha de inicio Real | I4: Fecha de fin Real | J4: Días reales | K4: % Ejecución | L4: Estado
B5: Actividades de Sensibilización | C5: Líder de calidad- Líderes de procesos | D5: Informar y educar a todos los integrantes de la organización sobre los objetivos, metas y beneficios del PAMEC | G5: =IF(cronograma[[#This Row],[Fecha de fin Programada (¿Cuándo?)]]="","",cronograma[[#This Row],[Fecha de fin Programada (¿Cuándo?)]]-cronograma[[#This Row],[Fecha de inicio Programada (¿Cuándo?)]]) | J5: =IF(cronograma[[#This Row],[Fecha de fin Real]]="","",cronograma[[#This Row],[Fecha de fin Real]]-cronograma[[#This Row],[Fecha de inicio Real]]) | L5: =IF(cronograma[[#This Row],[Fecha de fin Programada (¿Cuándo?)]]="","",IF(cronograma[[#This Row],[Fecha de fin Real]]<>"","Actividad cumplida",IF(TODAY()-F5>0,"Actividad atrasada "&ABS(TODAY()-F5)&" días","Tiene disponibles "&ABS(TODAY()-F5)&" días")))
B6: Conceptualización teórica | C6: Líder de calidad | D6: Proporcionar a los participantes una visión integral de los elementos estructurales que sustentan esta metodología, comprendiendo su importancia y su aplicación práctica | G6: =IF(cronograma[[#This Row],[Fecha de fin Programada (¿Cuándo?)]]="","",cronograma[[#This Row],[Fecha de fin Programada (¿Cuándo?)]]-cronograma[[#This Row],[Fecha de inicio Programada (¿Cuándo?)]]) | J6: =IF(cronograma[[#This Row],[Fecha de fin Real]]="","",cronograma[[#This Row],[Fecha de fin Real]]-cronograma[[#This Row],[Fecha de inicio Real]]) | L6: =IF(cronograma[[#This Row],[Fecha de fin Programada (¿Cuándo?)]]="","",IF(cronograma[[#This Row],[Fecha de fin Real]]<>"","Actividad cumplida",IF(TODAY()-F6>0,"Actividad atrasada "&ABS(TODAY()-F6)&" días","Tiene disponibles "&ABS(TODAY()-F6)&" días")))
B7: Formación equipo PAMEC | C7: Líder de calidad | D7: Identificar y seleccionar a las personas que formarán parte de los equipos de autoevaluación y mejora | G7: =IF(cronograma[[#This Row],[Fecha de fin Programada (¿Cuándo?)]]="","",cronograma[[#This Row],[Fecha de fin Programada (¿Cuándo?)]]-cronograma[[#This Row],[Fecha de inicio Programada (¿Cuándo?)]]) | J7: =IF(cronograma[[#This Row],[Fecha de fin Real]]="","",cronograma[[#This Row],[Fecha de fin Real]]-cronograma[[#This Row],[Fecha de inicio Real]]) | L7: =IF(cronograma[[#This Row],[Fecha de fin Programada (¿Cuándo?)]]="","",IF(cronograma[[#This Row],[Fecha de fin Real]]<>"","Actividad cumplida",IF(TODAY()-F7>0,"Actividad atrasada "&ABS(TODAY()-F7)&" días","Tiene disponibles "&ABS(TODAY()-F7)&" días")))
B8: Autoevaluación | C8: Líderes de procesos | D8: Identificar principales problemas de calidad y oportunidades de mejora | G8: =IF(cronograma[[#This Row],[Fecha de fin Programada (¿Cuándo?)]]="","",cronograma[[#This Row],[Fecha de fin Programada (¿Cuándo?)]]-cronograma[[#This Row],[Fecha de inicio Programada (¿Cuándo?)]]) | J8: =IF(cronograma[[#This Row],[Fecha de fin Real]]="","",cronograma[[#This Row],[Fecha de fin Real]]-cronograma[[#This Row],[Fecha de inicio Real]]) | L8: =IF(cronograma[[#This Row],[Fecha de fin Programada (¿Cuándo?)]]="","",IF(cronograma[[#This Row],[Fecha de fin Real]]<>"","Actividad cumplida",IF(TODAY()-F8>0,"Actividad atrasada "&ABS(TODAY()-F8)&" días","Tiene disponibles "&ABS(TODAY()-F8)&" días")))
B9: Selección de procesos a mejorar | C9: Líderes de procesos | D9: Identificar los procesos a mejorar | G9: =IF(cronograma[[#This Row],[Fecha de fin Programada (¿Cuándo?)]]="","",cronograma[[#This Row],[Fecha de fin Programada (¿Cuándo?)]]-cronograma[[#This Row],[Fecha de inicio Programada (¿Cuándo?)]]) | J9: =IF(cronograma[[#This Row],[Fecha de fin Real]]="","",cronograma[[#This Row],[Fecha de fin Real]]-cronograma[[#This Row],[Fecha de inicio Real]]) | L9: =IF(cronograma[[#This Row],[Fecha de fin Programada (¿Cuándo?)]]="","",IF(cronograma[[#This Row],[Fecha de fin Real]]<>"","Actividad cumplida",IF(TODAY()-F9>0,"Actividad atrasada "&ABS(TODAY()-F9)&" días","Tiene disponibles "&ABS(TODAY()-F9)&" días")))
B10: Priorización de procesos a mejorar | C10: Líderes de procesos | D10: Seleccionar los procesos a intervenir en el corto, mediano y largo plazo | G10: =IF(cronograma[[#This Row],[Fecha de fin Programada (¿Cuándo?)]]="","",cronograma[[#This Row],[Fecha de fin Programada (¿Cuándo?)]]-cronograma[[#This Row],[Fecha de inicio Programada (¿Cuándo?)]]) | J10: =IF(cronograma[[#This Row],[Fecha de fin Real]]="","",cronograma[[#This Row],[Fecha de fin Real]]-cronograma[[#This Row],[Fecha de inicio Real]]) | L10: =IF(cronograma[[#This Row],[Fecha de fin Programada (¿Cuándo?)]]="","",IF(cronograma[[#This Row],[Fecha de fin Real]]<>"","Actividad cumplida",IF(TODAY()-F10>0,"Actividad atrasada "&ABS(TODAY()-F10)&" días","Tiene disponibles "&ABS(TODAY()-F10)&" días")))
B11: Definición de la calidad esperada | C11: Líderes de procesos | D11: Establecer la meta a alcanzar | G11: =IF(cronograma[[#This Row],[Fecha de fin Programada (¿Cuándo?)]]="","",cronograma[[#This Row],[Fecha de fin Programada (¿Cuándo?)]]-cronograma[[#This Row],[Fecha de inicio Programada (¿Cuándo?)]]) | J11: =IF(cronograma[[#This Row],[Fecha de fin Real]]="","",cronograma[[#This Row],[Fecha de fin Real]]-cronograma[[#This Row],[Fecha de inicio Real]]) | L11: =IF(cronograma[[#This Row],[Fecha de fin Programada (¿Cuándo?)]]="","",IF(cronograma[[#This Row],[Fecha de fin Real]]<>"","Actividad cumplida",IF(TODAY()-F11>0,"Actividad atrasada "&ABS(TODAY()-F11)&" días","Tiene disponibles "&ABS(TODAY()-F11)&" días")))
B12: Medición del desempeño de los procesos | C12: Líder de calidad | D12: Definir los procedimientos de auditoría sobre el desempeño de los procesos. | G12: =IF(cronograma[[#This Row],[Fecha de fin Programada (¿Cuándo?)]]="","",cronograma[[#This Row],[Fecha de fin Programada (¿Cuándo?)]]-cronograma[[#This Row],[Fecha de inicio Programada (¿Cuándo?)]]) | J12: =IF(cronograma[[#This Row],[Fecha de fin Real]]="","",cronograma[[#This Row],[Fecha de fin Real]]-cronograma[[#This Row],[Fecha de inicio Real]]) | L12: =IF(cronograma[[#This Row],[Fecha de fin Programada (¿Cuándo?)]]="","",IF(cronograma[[#This Row],[Fecha de fin Real]]<>"","Actividad cumplida",IF(TODAY()-F12>0,"Actividad atrasada "&ABS(TODAY()-F12)&" días","Tiene disponibles "&ABS(TODAY()-F12)&" días")))
B13: Elaboración de planes de acción | C13: Líderes de procesos | D13: Establecer acciones que permitan garantizar el mejoramiento continuo de los procesos y la disminución de la diferencia entre la calidad esperada y la calidad encontrada | G13: =IF(cronograma[[#This Row],[Fecha de fin Programada (¿Cuándo?)]]="","",cronograma[[#This Row],[Fecha de fin Programada (¿Cuándo?)]]-cronograma[[#This Row],[Fecha de inicio Programada (¿Cuándo?)]]) | J13: =IF(cronograma[[#This Row],[Fecha de fin Real]]="","",cronograma[[#This Row],[Fecha de fin Real]]-cronograma[[#This Row],[Fecha de inicio Real]]) | L13: =IF(cronograma[[#This Row],[Fecha de fin Programada (¿Cuándo?)]]="","",IF(cronograma[[#This Row],[Fecha de fin Real]]<>"","Actividad cumplida",IF(TODAY()-F13>0,"Actividad atrasada "&ABS(TODAY()-F13)&" días","Tiene disponibles "&ABS(TODAY()-F13)&" días")))
B14: Ejecución y seguimiento de planes de acción | C14: Líderes de procesos | D14: Garantizar la ejecución de las acciones de mejora establecidas | G14: =IF(cronograma[[#This Row],[Fecha de fin Programada (¿Cuándo?)]]="","",cronograma[[#This Row],[Fecha de fin Programada (¿Cuándo?)]]-cronograma[[#This Row],[Fecha de inicio Programada (¿Cuándo?)]]) | J14: =IF(cronograma[[#This Row],[Fecha de fin Real]]="","",cronograma[[#This Row],[Fecha de fin Real]]-cronograma[[#This Row],[Fecha de inicio Real]]) | L14: =IF(cronograma[[#This Row],[Fecha de fin Programada (¿Cuándo?)]]="","",IF(cronograma[[#This Row],[Fecha de fin Real]]<>"","Actividad cumplida",IF(TODAY()-F14>0,"Actividad atrasada "&ABS(TODAY()-F14)&" días","Tiene disponibles "&ABS(TODAY()-F14)&" días")))
B15: Evaluación del mejoramiento | C15: Líder de calidad | D15: Evaluar el cumplimiento y calidad del programa de auditoria y verificar si los planes de acción fueron eficaces | G15: =IF(cronograma[[#This Row],[Fecha de fin Programada (¿Cuándo?)]]="","",cronograma[[#This Row],[Fecha de fin Programada (¿Cuándo?)]]-cronograma[[#This Row],[Fecha de inicio Programada (¿Cuándo?)]]) | J15: =IF(cronograma[[#This Row],[Fecha de fin Real]]="","",cronograma[[#This Row],[Fecha de fin Real]]-cronograma[[#This Row],[Fecha de inicio Real]]) | L15: =IF(cronograma[[#This Row],[Fecha de fin Programada (¿Cuándo?)]]="","",IF(cronograma[[#This Row],[Fecha de fin Real]]<>"","Actividad cumplida",IF(TODAY()-F15>0,"Actividad atrasada "&ABS(TODAY()-F15)&" días","Tiene disponibles "&ABS(TODAY()-F15)&" días")))
B16: Aprendizaje organizacional | C16: Líderes de procesos | D16: Tomar de decisiones de acuerdo a los resultados obtenidos para realizarle mejoras al proceso Retroalimentar a todo el personal | G16: =IF(cronograma[[#This Row],[Fecha de fin Programada (¿Cuándo?)]]="","",cronograma[[#This Row],[Fecha de fin Programada (¿Cuándo?)]]-cronograma[[#This Row],[Fecha de inicio Programada (¿Cuándo?)]]) | J16: =IF(cronograma[[#This Row],[Fecha de fin Real]]="","",cronograma[[#This Row],[Fecha de fin Real]]-cronograma[[#This Row],[Fecha de inicio Real]]) | L16: =IF(cronograma[[#This Row],[Fecha de fin Programada (¿Cuándo?)]]="","",IF(cronograma[[#This Row],[Fecha de fin Real]]<>"","Actividad cumplida",IF(TODAY()-F16>0,"Actividad atrasada "&ABS(TODAY()-F16)&" días","Tiene disponibles "&ABS(TODAY()-F16)&" días")))

Sheet Datos
A1: Consulta_Externa | B1: Cirugía | C1: Internación | D1: Apoyo_Diagnóstico_Compl._Terapéutica | E1: Atención_Inmediata | F1: COMPLEJIDAD | G1: Fuentes OM | H1: Procesos orden | I1: Procesos | J1: Auxiliar | K1: Orden | L1: Procesos | M1: Cantidad procesos vs OM | O1: Atributos calidad | P1: Valores unicos practicas seguras
A2: 301-ANESTESIA | B2: 201-CIRUGÍA DE CABEZA Y CUELLO | C2: 105-CUIDADO INTERMEDIO NEONATAL | D2: 706-LABORATORIO CLÍNICO | E2: 1101-ATENCIÓN DEL PARTO | F2: Baja | G2: Resultado auditorías Internas | H2: 1 | I2: =proceso1 -> 0 | J2: =IF(I2="",0,I2<>0)*1 -> 0 | K2: =(RANK($J2,$J$2:$J$56,0)+COUNTIF($J$2:$J2,J2)-1)*J2 -> 0 | L2: =IFERROR(INDEX($H$2:$K$51,MATCH(H2,$K$2:$K$51,0),2),"") | M2: =IF(L2<>"",COUNTIFS(cualitativa[[#All],[Proceso 1]:[Proceso 5]],L2),"") | O2: Accesibilidad | P2: {=IFERROR(INDEX(cualitativa[Práctica Segura],MATCH(0,INDEX(COUNTIF($P$1:P1,cualitativa[Práctica Segura]),0,0),0)),"")} -> 0
A3: 302-CARDIOLOGÍA | B3: 202-CIRUGÍA CARDIOVASCULAR | C3: 106-CUIDADO INTERMEDIO PEDIÁTRICO | D3: 709-QUIMIOTERAPIA | E3: 1102-URGENCIAS | F3: Mediana | G3: Resultado Auditorías externas | H3: 2 | I3: =proceso2 -> 0 | J3: =IF(I3="",0,I3<>0)*1 -> 0 | K3: =(RANK($J3,$J$2:$J$56,0)+COUNTIF($J$2:$J3,J3)-1)*J3 -> 0 | L3: =IFERROR(INDEX($H$2:$K$51,MATCH(H3,$K$2:$K$51,0),2),"") | M3: =IF(L3<>"",COUNTIFS(cualitativa[[#All],[Proceso 1]:[Proceso 5]],L3),"") | O3: Continuidad | P3: {=IFERROR(INDEX(cualitativa[Práctica Segura],MATCH(0,INDEX(COUNTIF($P$1:P2,cualitativa[Práctica Segura]),0,0),0)),"")}
A4: 361-CARDIOLOGÍA PEDIÁTRICA | B4: 203-CIRUGÍA GENERAL | C4: 107-CUIDADO INTERMEDIO ADULTOS | D4: 711-RADIOTERAPIA | E4: 1103-TRANSPORTE ASISTENCIAL BASICO | F4: Alta | G4: Comités Institucionales | H4: 3 | I4: =proceso3 -> 0 | J4: =IF(I4="",0,I4<>0)*1 -> 0 | K4: =(RANK($J4,$J$2:$J$56,0)+COUNTIF($J$2:$J4,J4)-1)*J4 -> 0 | L4: =IFERROR(INDEX($H$2:$K$51,MATCH(H4,$K$2:$K$51,0),2),"") | M4: =IF(L4<>"",COUNTIFS(cualitativa[[#All],[Proceso 1]:[Proceso 5]],L4),"") | O4: Oportunidad | P4: {=IFERROR(INDEX(cualitativa[Práctica Segura],MATCH(0,INDEX(COUNTIF($P$1:P3,cualitativa[Práctica Segura]),0,0),0)),"")}
A5: 303-CIRUGÍA CARDIOVASCULAR | B5: 204-CIRUGÍA GINECOLÓGICA | C5: 108-CUIDADO INTENSIVO NEONATAL | D5: 712-TOMA DE MUESTRAS DE LABORATORIO CLÍNICO | E5: 1104-TRANSPORTE ASISTENCIAL MEDICALIZADO | F5: Sin complejidad | G5: Resultado de Indicadores | H5: 4 | I5: =proceso4 -> 0 | J5: =IF(I5="",0,I5<>0)*1 -> 0 | K5: =(RANK($J5,$J$2:$J$56,0)+COUNTIF($J$2:$J5,J5)-1)*J5 -> 0 | L5: =IFERROR(INDEX($H$2:$K$51,MATCH(H5,$K$2:$K$51,0),2),"") | M5: =IF(L5<>"",COUNTIFS(cualitativa[[#All],[Proceso 1]:[Proceso 5]],L5),"") | O5: Pertinencia | P5: {=IFERROR(INDEX(cualitativa[Práctica Segura],MATCH(0,INDEX(COUNTIF($P$1:P4,cualitativa[Práctica Segura]),0,0),0)),"")}
A6: 362-CIRUGÍA DE CABEZA Y CUELLO | B6: 205-CIRUGÍA MAXILOFACIAL | C6: 109-CUIDADO INTENSIVO PEDIÁTRICO | D6: 714-SERVICIO FARMACÉUTICO | E6: 1105-ATENCIÓN PREHOSPITALARIA | G6: Voz del cliente | H6: 5 | I6: =proceso5 -> 0 | J6: =IF(I6="",0,I6<>0)*1 -> 0 | K6: =(RANK($J6,$J$2:$J$56,0)+COUNTIF($J$2:$J6,J6)-1)*J6 -> 0 | L6: =IFERROR(INDEX($H$2:$K$51,MATCH(H6,$K$2:$K$51,0),2),"") | M6: =IF(L6<>"",COUNTIFS(cualitativa[[#All],[Proceso 1]:[Proceso 5]],L6),"") | O6: Satisfacción del Usuario | P6: {=IFERROR(INDEX(cualitativa[Práctica Segura],MATCH(0,INDEX(COUNTIF($P$1:P5,cualitativa[Práctica Segura]),0,0),0)),"")}
A7: 364-CIRUGÍA DE MAMA Y TUMORES TEJIDOS BLANDOS | B7: 207-CIRUGÍA ORTOPÉDICA | C7: 110-CUIDADO INTENSIVO ADULTOS | D7: 715-MEDICINA NUCLEAR | G7: Mejoramiento continuo | H7: 6 | I7: =proceso6 -> 0 | J7: =IF(I7="",0,I7<>0)*1 -> 0 | K7: =(RANK($J7,$J$2:$J$56,0)+COUNTIF($J$2:$J7,J7)-1)*J7 -> 0 | L7: =IFERROR(INDEX($H$2:$K$51,MATCH(H7,$K$2:$K$51,0),2),"") | M7: =IF(L7<>"",COUNTIFS(cualitativa[[#All],[Proceso 1]:[Proceso 5]],L7),"") | O7: Seguridad | P7: {=IFERROR(INDEX(cualitativa[Práctica Segura],MATCH(0,INDEX(COUNTIF($P$1:P6,cualitativa[Práctica Segura]),0,0),0)),"")}
A8: 363-CIRUGÍA DE MANO | B8: 208-CIRUGÍA OFTALMOLÓGICA | C8: 120-CUIDADO BÁSICO NEONATAL | D8: 717-LABORATORIO CITOLOGÍAS CERVICO-UTERINAS | H8: 7 | I8: =proceso7 -> 0 | J8: =IF(I8="",0,I8<>0)*1 -> 0 | K8: =(RANK($J8,$J$2:$J$56,0)+COUNTIF($J$2:$J8,J8)-1)*J8 -> 0 | L8: =IFERROR(INDEX($H$2:$K$51,MATCH(H8,$K$2:$K$51,0),2),"") | M8: =IF(L8<>"",COUNTIFS(cualitativa[[#All],[Proceso 1]:[Proceso 5]],L8),"") | P8: {=IFERROR(INDEX(cualitativa[Práctica Segura],MATCH(0,INDEX(COUNTIF($P$1:P7,cualitativa[Práctica Segura]),0,0),0)),"")}
A9: 366-CIRUGÍA DE TÓRAX | B9: 209-CIRUGÍA OTORRINOLARINGOLOGÍA | C9: 129-HOSPITALIZACIÓN ADULTOS | D9: 728-TERAPIA OCUPACIONAL | H9: 8 | I9: =proceso8 -> 0 | J9: =IF(I9="",0,I9<>0)*1 -> 0 | K9: =(RANK($J9,$J$2:$J$56,0)+COUNTIF($J$2:$J9,J9)-1)*J9 -> 0 | L9: =IFERROR(INDEX($H$2:$K$51,MATCH(H9,$K$2:$K$51,0),2),"") | M9: =IF(L9<>"",COUNTIFS(cualitativa[[#All],[Proceso 1]:[Proceso 5]],L9),"") | P9: {=IFERROR(INDEX(cualitativa[Práctica Segura],MATCH(0,INDEX(COUNTIF($P$1:P8,cualitativa[Práctica Segura]),0,0),0)),"")}
A10: 365-CIRUGÍA DERMATOLÓGICA | B10: 210-CIRUGÍA ONCOLÓGICA | C10: 130-HOSPITALIZACIÓN PEDIÁTRICA | D10: 729-TERAPIA RESPIRATORIA | H10: 9 | I10: =proceso9 -> 0 | J10: =IF(I10="",0,I10<>0)*1 -> 0 | K10: =(RANK($J10,$J$2:$J$56,0)+COUNTIF($J$2:$J10,J10)-1)*J10 -> 0 | L10: =IFERROR(INDEX($H$2:$K$51,MATCH(H10,$K$2:$K$51,0),2),"") | M10: =IF(L10<>"",COUNTIFS(cualitativa[[#All],[Proceso 1]:[Proceso 5]],L10),"") | P10: {=IFERROR(INDEX(cualitativa[Práctica Segura],MATCH(0,INDEX(COUNTIF($P$1:P9,cualitativa[Práctica Segura]),0,0),0)),"")}
A11: 367-CIRUGÍA GASTROINTESTINAL | B11: 211-CIRUGÍA ORAL | C11: 131-HOSPITALIZACIÓN EN SALUD MENTAL | D11: 731-LABORATORIO DE HISTOTECNOLOGÍA | H11: 10 | I11: =proceso10 -> 0 | J11: =IF(I11="",0,I11<>0)*1 -> 0 | K11: =(RANK($J11,$J$2:$J$56,0)+COUNTIF($J$2:$J11,J11)-1)*J11 -> 0 | L11: =IFERROR(INDEX($H$2:$K$51,MATCH(H11,$K$2:$K$51,0),2),"") | M11: =IF(L11<>"",COUNTIFS(cualitativa[[#All],[Proceso 1]:[Proceso 5]],L11),"") | P11: {=IFERROR(INDEX(cualitativa[Práctica Segura],MATCH(0,INDEX(COUNTIF($P$1:P10,cualitativa[Práctica Segura]),0,0),0)),"")}
A12: 304-CIRUGÍA GENERAL | B12: 212-CIRUGÍA PEDIÁTRICA | C12: 132-HOSPITALIZACIÓN PARCIAL | D12: 733-HEMODIÁLISIS | H12: 11 | I12: =proceso11 -> 0 | J12: =IF(I12="",0,I12<>0)*1 -> 0 | K12: =(RANK($J12,$J$2:$J$56,0)+COUNTIF($J$2:$J12,J12)-1)*J12 -> 0 | L12: =IFERROR(INDEX($H$2:$K$51,MATCH(H12,$K$2:$K$51,0),2),"") | M12: =IF(L12<>"",COUNTIFS(cualitativa[[#All],[Proceso 1]:[Proceso 5]],L12),"") | P12: {=IFERROR(INDEX(cualitativa[Práctica Segura],MATCH(0,INDEX(COUNTIF($P$1:P11,cualitativa[Práctica Segura]),0,0),0)),"")}
A13: 368-CIRUGÍA GINECOLÓGICA LAPAROSCÓPICA | B13: 213-CIRUGÍA PLÁSTICA Y ESTÉTICA | C13: 133-HOSPITALIZACIÓN PACIENTE CRÓNICO CON VENTILADOR | D13: 734-DIÁLISIS PERITONEAL | H13: 12 | I13: =proceso12 -> 0 | J13: =IF(I13="",0,I13<>0)*1 -> 0 | K13: =(RANK($J13,$J$2:$J$56,0)+COUNTIF($J$2:$J13,J13)-1)*J13 -> 0 | L13: =IFERROR(INDEX($H$2:$K$51,MATCH(H13,$K$2:$K$51,0),2),"") | M13: =IF(L13<>"",COUNTIFS(cualitativa[[#All],[Proceso 1]:[Proceso 5]],L13),"") | P13: {=IFERROR(INDEX(cualitativa[Práctica Segura],MATCH(0,INDEX(COUNTIF($P$1:P12,cualitativa[Práctica Segura]),0,0),0)),"")}
A14: 411-CIRUGÍA MAXILOFACIAL | B14: 214-CIRUGÍA VASCULAR Y ANGIOLÓGICA | C14: 134-HOSPITALIZACIÓN PACIENTE CRÓNICO SIN VENTILADOR | D14: 739-FISIOTERAPIA | H14: 13 | I14: =proceso13 -> 0 | J14: =IF(I14="",0,I14<>0)*1 -> 0 | K14: =(RANK($J14,$J$2:$J$56,0)+COUNTIF($J$2:$J14,J14)-1)*J14 -> 0 | L14: =IFERROR(INDEX($H$2:$K$51,MATCH(H14,$K$2:$K$51,0),2),"") | M14: =IF(L14<>"",COUNTIFS(cualitativa[[#All],[Proceso 1]:[Proceso 5]],L14),"") | P14: {=IFERROR(INDEX(cualitativa[Práctica Segura],MATCH(0,INDEX(COUNTIF($P$1:P13,cualitativa[Práctica Segura]),0,0),0)),"")}
A15: 373-CIRUGÍA ONCOLÓGICA | B15: 215-CIRUGÍA UROLÓGICA | C15: 135-HOSPITALIZACIÓN EN CONSUMO DE SUSTANCIAS PSICOACTIVAS | D15: 740-FONOAUDIOLOGÍA Y/O TERAPIA DEL LENGUAJE | H15: 14 | I15: =proceso14 -> 0 | J15: =IF(I15="",0,I15<>0)*1 -> 0 | K15: =(RANK($J15,$J$2:$J$56,0)+COUNTIF($J$2:$J15,J15)-1)*J15 -> 0 | L15: =IFERROR(INDEX($H$2:$K$51,MATCH(H15,$K$2:$K$51,0),2),"") | M15: =IF(L15<>"",COUNTIFS(cualitativa[[#All],[Proceso 1]:[Proceso 5]],L15),"") | P15: {=IFERROR(INDEX(cualitativa[Práctica Segura],MATCH(0,INDEX(COUNTIF($P$1:P14,cualitativa[Práctica Segura]),0,0),0)),"")}
A16: 374-CIRUGÍA ONCOLÓGICA PEDIÁTRICA | B16: 217-OTRAS CIRUGÍAS | C16: 138-CUIDADO BÁSICO DEL CONSUMO DE SUSTANCIAS PSICOACTIVAS | D16: 742-DIAGNÓSTICO VASCULAR | H16: 15 | I16: =proceso15 -> 0 | J16: =IF(I16="",0,I16<>0)*1 -> 0 | K16: =(RANK($J16,$J$2:$J$56,0)+COUNTIF($J$2:$J16,J16)-1)*J16 -> 0 | L16: =IFERROR(INDEX($H$2:$K$51,MATCH(H16,$K$2:$K$51,0),2),"") | M16: =IF(L16<>"",COUNTIFS(cualitativa[[#All],[Proceso 1]:[Proceso 5]],L16),"") | P16: {=IFERROR(INDEX(cualitativa[Práctica Segura],MATCH(0,INDEX(COUNTIF($P$1:P15,cualitativa[Práctica Segura]),0,0),0)),"")}
A17: 410-CIRUGÍA ORAL | B17: 218-CIRUGÍA ENDOVASCULAR NEUROLÓGICA | D17: 743-HEMODINAMIA E INTERVENCIONISMO | H17: 16 | I17: =proceso16 -> 0 | J17: =IF(I17="",0,I17<>0)*1 -> 0 | K17: =(RANK($J17,$J$2:$J$56,0)+COUNTIF($J$2:$J17,J17)-1)*J17 -> 0 | L17: =IFERROR(INDEX($H$2:$K$51,MATCH(H17,$K$2:$K$51,0),2),"") | M17: =IF(L17<>"",COUNTIFS(cualitativa[[#All],[Proceso 1]:[Proceso 5]],L17),"") | P17: {=IFERROR(INDEX(cualitativa[Práctica Segura],MATCH(0,INDEX(COUNTIF($P$1:P16,cualitativa[Práctica Segura]),0,0),0)),"")}
A18: 306-CIRUGÍA PEDIÁTRICA | B18: 227-CIRUGÍA ONCOLÓGICA PEDIÁTRICA | D18: 744-IMÁGENES DIAGNOSTICAS- IONIZANTES | H18: 17 | I18: =proceso17 -> 0 | J18: =IF(I18="",0,I18<>0)*1 -> 0 | K18: =(RANK($J18,$J$2:$J$56,0)+COUNTIF($J$2:$J18,J18)-1)*J18 -> 0 | L18: =IFERROR(INDEX($H$2:$K$51,MATCH(H18,$K$2:$K$51,0),2),"") | M18: =IF(L18<>"",COUNTIFS(cualitativa[[#All],[Proceso 1]:[Proceso 5]],L18),"") | P18: {=IFERROR(INDEX(cualitativa[Práctica Segura],MATCH(0,INDEX(COUNTIF($P$1:P17,cualitativa[Práctica Segura]),0,0),0)),"")}
A19: 370-CIRUGÍA PLÁSTICA ONCOLÓGICA | B19: 231-CIRUGÍA DE LA MANO | D19: 745-IMÁGENES DIAGNOSTICAS - NO IONIZANTES | H19: 18 | I19: =proceso18 -> 0 | J19: =IF(I19="",0,I19<>0)*1 -> 0 | K19: =(RANK($J19,$J$2:$J$56,0)+COUNTIF($J$2:$J19,J19)-1)*J19 -> 0 | L19: =IFERROR(INDEX($H$2:$K$51,MATCH(H19,$K$2:$K$51,0),2),"") | M19: =IF(L19<>"",COUNTIFS(cualitativa[[#All],[Proceso 1]:[Proceso 5]],L19),"") | P19: {=IFERROR(INDEX(cualitativa[Práctica Segura],MATCH(0,INDEX(COUNTIF($P$1:P18,cualitativa[Práctica Segura]),0,0),0)),"")}
A20: 369-CIRUGÍA PLÁSTICA Y ESTÉTICA | B20: 232-CIRUGÍA DE MAMA Y TUMORES TEJIDOS BLANDOS | D20: 746-GESTION PRE-TRANSFUSIONAL | H20: 19 | I20: =proceso19 -> 0 | J20: =IF(I20="",0,I20<>0)*1 -> 0 | K20: =(RANK($J20,$J$2:$J$56,0)+COUNTIF($J$2:$J20,J20)-1)*J20 -> 0 | L20: =IFERROR(INDEX($H$2:$K$51,MATCH(H20,$K$2:$K$51,0),2),"") | M20: =IF(L20<>"",COUNTIFS(cualitativa[[#All],[Proceso 1]:[Proceso 5]],L20),"") | P20: {=IFERROR(INDEX(cualitativa[Práctica Segura],MATCH(0,INDEX(COUNTIF($P$1:P19,cualitativa[Práctica Segura]),0,0),0)),"")}
A21: 372-CIRUGÍA VASCULAR | B21: 233-CIRUGÍA DERMATOLÓGICA | D21: 747-PATOLOGÍA | H21: 20 | I21: =proceso20 -> 0 | J21: =IF(I21="",0,I21<>0)*1 -> 0 | K21: =(RANK($J21,$J$2:$J$56,0)+COUNTIF($J$2:$J21,J21)-1)*J21 -> 0 | L21: =IFERROR(INDEX($H$2:$K$51,MATCH(H21,$K$2:$K$51,0),2),"") | M21: =IF(L21<>"",COUNTIFS(cualitativa[[#All],[Proceso 1]:[Proceso 5]],L21),"") | P21: {=IFERROR(INDEX(cualitativa[Práctica Segura],MATCH(0,INDEX(COUNTIF($P$1:P20,cualitativa[Práctica Segura]),0,0),0)),"")}
A22: 377-COLOPROCTOLOGÍA | B22: 234-CIRUGÍA DE TÓRAX | D22: 748-RADIOLOGÍA ODONTOLÓGICA | H22: 21 | I22: =proceso21 -> 0 | J22: =IF(I22="",0,I22<>0)*1 -> 0 | K22: =(RANK($J22,$J$2:$J$56,0)+COUNTIF($J$2:$J22,J22)-1)*J22 -> 0 | L22: =IFERROR(INDEX($H$2:$K$51,MATCH(H22,$K$2:$K$51,0),2),"") | M22: =IF(L22<>"",COUNTIFS(cualitativa[[#All],[Proceso 1]:[Proceso 5]],L22),"") | P22: {=IFERROR(INDEX(cualitativa[Práctica Segura],MATCH(0,INDEX(COUNTIF($P$1:P21,cualitativa[Práctica Segura]),0,0),0)),"")}
A23: 308-DERMATOLOGÍA | B23: 235-CIRUGÍA GASTROINTESTINAL | D23: 749-TOMA DE MUESTRAS DE CUELLO UTERINO Y GINECOLÓGICAS | H23: 22 | I23: =proceso22 -> 0 | J23: =IF(I23="",0,I23<>0)*1 -> 0 | K23: =(RANK($J23,$J$2:$J$56,0)+COUNTIF($J$2:$J23,J23)-1)*J23 -> 0 | L23: =IFERROR(INDEX($H$2:$K$51,MATCH(H23,$K$2:$K$51,0),2),"") | M23: =IF(L23<>"",COUNTIFS(cualitativa[[#All],[Proceso 1]:[Proceso 5]],L23),"") | P23: {=IFERROR(INDEX(cualitativa[Práctica Segura],MATCH(0,INDEX(COUNTIF($P$1:P22,cualitativa[Práctica Segura]),0,0),0)),"")}
A24: 375-DERMATOLOGÍA ONCOLÓGICA | B24: 237-CIRUGÍA PLÁSTICA ONCOLÓGICA | H24: 23 | I24: =proceso23 -> 0 | J24: =IF(I24="",0,I24<>0)*1 -> 0 | K24: =(RANK($J24,$J$2:$J$56,0)+COUNTIF($J$2:$J24,J24)-1)*J24 -> 0 | L24: =IFERROR(INDEX($H$2:$K$51,MATCH(H24,$K$2:$K$51,0),2),"") | M24: =IF(L24<>"",COUNTIFS(cualitativa[[#All],[Proceso 1]:[Proceso 5]],L24),"") | P24: {=IFERROR(INDEX(cualitativa[Práctica Segura],MATCH(0,INDEX(COUNTIF($P$1:P23,cualitativa[Práctica Segura]),0,0),0)),"")}
A25: 309-DOLOR Y CUIDADOS PALIATIVOS | B25: 245-NEUROCIRUGÍA | H25: 24 | I25: =proceso24 -> 0 | J25: =IF(I25="",0,I25<>0)*1 -> 0 | K25: =(RANK($J25,$J$2:$J$56,0)+COUNTIF($J$2:$J25,J25)-1)*J25 -> 0 | L25: =IFERROR(INDEX($H$2:$K$51,MATCH(H25,$K$2:$K$51,0),2),"") | M25: =IF(L25<>"",COUNTIFS(cualitativa[[#All],[Proceso 1]:[Proceso 5]],L25),"") | P25: {=IFERROR(INDEX(cualitativa[Práctica Segura],MATCH(0,INDEX(COUNTIF($P$1:P24,cualitativa[Práctica Segura]),0,0),0)),"")}
A26: 310-ENDOCRINOLOGÍA | H26: 25 | I26: =proceso25 -> 0 | J26: =IF(I26="",0,I26<>0)*1 -> 0 | K26: =(RANK($J26,$J$2:$J$56,0)+COUNTIF($J$2:$J26,J26)-1)*J26 -> 0 | L26: =IFERROR(INDEX($H$2:$K$51,MATCH(H26,$K$2:$K$51,0),2),"") | M26: =IF(L26<>"",COUNTIFS(cualitativa[[#All],[Proceso 1]:[Proceso 5]],L26),"") | P26: {=IFERROR(INDEX(cualitativa[Práctica Segura],MATCH(0,INDEX(COUNTIF($P$1:P25,cualitativa[Práctica Segura]),0,0),0)),"")}
A27: 311-ENDODONCIA | H27: 26 | I27: =proceso26 -> 0 | J27: =IF(I27="",0,I27<>0)*1 -> 0 | K27: =(RANK($J27,$J$2:$J$56,0)+COUNTIF($J$2:$J27,J27)-1)*J27 -> 0 | L27: =IFERROR(INDEX($H$2:$K$51,MATCH(H27,$K$2:$K$51,0),2),"") | M27: =IF(L27<>"",COUNTIFS(cualitativa[[#All],[Proceso 1]:[Proceso 5]],L27),"") | P27: {=IFERROR(INDEX(cualitativa[Práctica Segura],MATCH(0,INDEX(COUNTIF($P$1:P26,cualitativa[Práctica Segura]),0,0),0)),"")}
A28: 312-ENFERMERÍA | H28: 27 | I28: =proceso27 -> 0 | J28: =IF(I28="",0,I28<>0)*1 -> 0 | K28: =(RANK($J28,$J$2:$J$56,0)+COUNTIF($J$2:$J28,J28)-1)*J28 -> 0 | L28: =IFERROR(INDEX($H$2:$K$51,MATCH(H28,$K$2:$K$51,0),2),"") | M28: =IF(L28<>"",COUNTIFS(cualitativa[[#All],[Proceso 1]:[Proceso 5]],L28),"") | P28: {=IFERROR(INDEX(cualitativa[Práctica Segura],MATCH(0,INDEX(COUNTIF($P$1:P27,cualitativa[Práctica Segura]),0,0),0)),"")}
A29: 313-ESTOMATOLOGÍA | H29: 28 | I29: =proceso28 -> 0 | J29: =IF(I29="",0,I29<>0)*1 -> 0 | K29: =(RANK($J29,$J$2:$J$56,0)+COUNTIF($J$2:$J29,J29)-1)*J29 -> 0 | L29: =IFERROR(INDEX($H$2:$K$51,MATCH(H29,$K$2:$K$51,0),2),"") | M29: =IF(L29<>"",COUNTIFS(cualitativa[[#All],[Proceso 1]:[Proceso 5]],L29),"") | P29: {=IFERROR(INDEX(cualitativa[Práctica Segura],MATCH(0,INDEX(COUNTIF($P$1:P28,cualitativa[Práctica Segura]),0,0),0)),"")}
A30: 316-GASTROENTEROLOGÍA | H30: 29 | I30: =proceso29 -> 0 | J30: =IF(I30="",0,I30<>0)*1 -> 0 | K30: =(RANK($J30,$J$2:$J$56,0)+COUNTIF($J$2:$J30,J30)-1)*J30 -> 0 | L30: =IFERROR(INDEX($H$2:$K$51,MATCH(H30,$K$2:$K$51,0),2),"") | M30: =IF(L30<>"",COUNTIFS(cualitativa[[#All],[Proceso 1]:[Proceso 5]],L30),"") | P30: {=IFERROR(INDEX(cualitativa[Práctica Segura],MATCH(0,INDEX(COUNTIF($P$1:P29,cualitativa[Práctica Segura]),0,0),0)),"")}
A31: 317-GENÉTICA | H31: 30 | I31: =proceso30 -> 0 | J31: =IF(I31="",0,I31<>0)*1 -> 0 | K31: =(RANK($J31,$J$2:$J$56,0)+COUNTIF($J$2:$J31,J31)-1)*J31 -> 0 | L31: =IFERROR(INDEX($H$2:$K$51,MATCH(H31,$K$2:$K$51,0),2),"") | M31: =IF(L31<>"",COUNTIFS(cualitativa[[#All],[Proceso 1]:[Proceso 5]],L31),"") | P31: {=IFERROR(INDEX(cualitativa[Práctica Segura],MATCH(0,INDEX(COUNTIF($P$1:P30,cualitativa[Práctica Segura]),0,0),0)),"")}
A32: 318-GERIATRÍA | H32: 31 | I32: =proceso31 -> 0 | J32: =IF(I32="",0,I32<>0)*1 -> 0 | K32: =(RANK($J32,$J$2:$J$56,0)+COUNTIF($J$2:$J32,J32)-1)*J32 -> 0 | L32: =IFERROR(INDEX($H$2:$K$51,MATCH(H32,$K$2:$K$51,0),2),"") | M32: =IF(L32<>"",COUNTIFS(cualitativa[[#All],[Proceso 1]:[Proceso 5]],L32),"") | P32: {=IFERROR(INDEX(cualitativa[Práctica Segura],MATCH(0,INDEX(COUNTIF($P$1:P31,cualitativa[Práctica Segura]),0,0),0)),"")}
A33: 320-GINECOBSTETRICIA | H33: 32 | I33: =proceso32 -> 0 | J33: =IF(I33="",0,I33<>0)*1 -> 0 | K33: =(RANK($J33,$J$2:$J$56,0)+COUNTIF($J$2:$J33,J33)-1)*J33 -> 0 | L33: =IFERROR(INDEX($H$2:$K$51,MATCH(H33,$K$2:$K$51,0),2),"") | M33: =IF(L33<>"",COUNTIFS(cualitativa[[#All],[Proceso 1]:[Proceso 5]],L33),"") | P33: {=IFERROR(INDEX(cualitativa[Práctica Segura],MATCH(0,INDEX(COUNTIF($P$1:P32,cualitativa[Práctica Segura]),0,0),0)),"")}
A34: 379-GINECOLOGÍA ONCOLÓGICA | H34: 33 | I34: =proceso33 -> 0 | J34: =IF(I34="",0,I34<>0)*1 -> 0 | K34: =(RANK($J34,$J$2:$J$56,0)+COUNTIF($J$2:$J34,J34)-1)*J34 -> 0 | L34: =IFERROR(INDEX($H$2:$K$51,MATCH(H34,$K$2:$K$51,0),2),"") | M34: =IF(L34<>"",COUNTIFS(cualitativa[[#All],[Proceso 1]:[Proceso 5]],L34),"") | P34: {=IFERROR(INDEX(cualitativa[Práctica Segura],MATCH(0,INDEX(COUNTIF($P$1:P33,cualitativa[Práctica Segura]),0,0),0)),"")}
A35: 321-HEMATOLOGÍA | H35: 34 | I35: =proceso34 -> 0 | J35: =IF(I35="",0,I35<>0)*1 -> 0 | K35: =(RANK($J35,$J$2:$J$56,0)+COUNTIF($J$2:$J35,J35)-1)*J35 -> 0 | L35: =IFERROR(INDEX($H$2:$K$51,MATCH(H35,$K$2:$K$51,0),2),"") | M35: =IF(L35<>"",COUNTIFS(cualitativa[[#All],[Proceso 1]:[Proceso 5]],L35),"") | P35: {=IFERROR(INDEX(cualitativa[Práctica Segura],MATCH(0,INDEX(COUNTIF($P$1:P34,cualitativa[Práctica Segura]),0,0),0)),"")}
A36: 406-HEMATOLOGÍA ONCOLÓGICA | H36: 35 | I36: =proceso35 -> 0 | J36: =IF(I36="",0,I36<>0)*1 -> 0 | K36: =(RANK($J36,$J$2:$J$56,0)+COUNTIF($J$2:$J36,J36)-1)*J36 -> 0 | L36: =IFERROR(INDEX($H$2:$K$51,MATCH(H36,$K$2:$K$51,0),2),"") | M36: =IF(L36<>"",COUNTIFS(cualitativa[[#All],[Proceso 1]:[Proceso 5]],L36),"") | P36: {=IFERROR(INDEX(cualitativa[Práctica Segura],MATCH(0,INDEX(COUNTIF($P$1:P35,cualitativa[Práctica Segura]),0,0),0)),"")}
A37: 323-INFECTOLOGÍA | H37: 36 | I37: =proceso36 -> 0 | J37: =IF(I37="",0,I37<>0)*1 -> 0 | K37: =(RANK($J37,$J$2:$J$56,0)+COUNTIF($J$2:$J37,J37)-1)*J37 -> 0 | L37: =IFERROR(INDEX($H$2:$K$51,MATCH(H37,$K$2:$K$51,0),2),"") | M37: =IF(L37<>"",COUNTIFS(cualitativa[[#All],[Proceso 1]:[Proceso 5]],L37),"") | P37: {=IFERROR(INDEX(cualitativa[Práctica Segura],MATCH(0,INDEX(COUNTIF($P$1:P36,cualitativa[Práctica Segura]),0,0),0)),"")}
A38: 324-INMUNOLOGÍA | H38: 37 | I38: =proceso37 -> 0 | J38: =IF(I38="",0,I38<>0)*1 -> 0 | K38: =(RANK($J38,$J$2:$J$56,0)+COUNTIF($J$2:$J38,J38)-1)*J38 -> 0 | L38: =IFERROR(INDEX($H$2:$K$51,MATCH(H38,$K$2:$K$51,0),2),"") | M38: =IF(L38<>"",COUNTIFS(cualitativa[[#All],[Proceso 1]:[Proceso 5]],L38),"") | P38: {=IFERROR(INDEX(cualitativa[Práctica Segura],MATCH(0,INDEX(COUNTIF($P$1:P37,cualitativa[Práctica Segura]),0,0),0)),"")}
A39: 413-MEDICINA ALTERNATIVA Y COMPLEMENTARIA - AYURVÉDICA | H39: 38 | I39: =proceso38 -> 0 | J39: =IF(I39="",0,I39<>0)*1 -> 0 | K39: =(RANK($J39,$J$2:$J$56,0)+COUNTIF($J$2:$J39,J39)-1)*J39 -> 0 | L39: =IFERROR(INDEX($H$2:$K$51,MATCH(H39,$K$2:$K$51,0),2),"") | M39: =IF(L39<>"",COUNTIFS(cualitativa[[#All],[Proceso 1]:[Proceso 5]],L39),"") | P39: {=IFERROR(INDEX(cualitativa[Práctica Segura],MATCH(0,INDEX(COUNTIF($P$1:P38,cualitativa[Práctica Segura]),0,0),0)),"")}
A40: 412-MEDICINA ALTERNATIVA Y COMPLEMENTARIA - HOMEOPÁTICA | H40: 39 | I40: =proceso39 -> 0 | J40: =IF(I40="",0,I40<>0)*1 -> 0 | K40: =(RANK($J40,$J$2:$J$56,0)+COUNTIF($J$2:$J40,J40)-1)*J40 -> 0 | L40: =IFERROR(INDEX($H$2:$K$51,MATCH(H40,$K$2:$K$51,0),2),"") | M40: =IF(L40<>"",COUNTIFS(cualitativa[[#All],[Proceso 1]:[Proceso 5]],L40),"") | P40: {=IFERROR(INDEX(cualitativa[Práctica Segura],MATCH(0,INDEX(COUNTIF($P$1:P39,cualitativa[Práctica Segura]),0,0),0)),"")}
...

Sheet AUTOEV CUALIT
D1: Anexo 1. Autoevaluación Cualitativa
J3: Proceso Relacionado
B4: Num. | C4: Eje de Seguridad | D4: Práctica Segura | E4: Categoría | F4: Criterio | G4: Fortaleza | H4: Oportunidad de Mejora | I4: Fuente Oportunidad Mejora | J4: Proceso 1 | K4: Proceso 2 | L4: Proceso 3 | M4: Proceso 4 | N4: Proceso 5
B5: 1
B6: 2
B7: 3
B8: 4
B9: 5
B10: 6
B11: 7
B12: 8
B13: 9
B14: 10
B15: 11
B16: 12
... B204: 200

Sheet RADAR
C1: Hoja Radar
B3: Fuente: Resolucion-2082-de-2014
B4: ENFOQUE | C4: 1 | D4: 2 | E4: 3 | F4: 4 | G4: 5
B5: Enfoque Sistémico: Ejercicio de aplicación disciplinado que abarca todos los procesos y el contenido del estandar; que hace una visión de conjunto de la institucion; que contempla un ciclo PHVA. | C5: El enfoque es esporádico, no está presente en todos los servicios o procesos, no es sistemico y no se relaciona con el direccionamiento estratégico. | D5: Comienzo de un enfoque sistemico para los propósitos básicos del estándar y empieza a estar presente en algunos servicios o procesos. El enfoque y los procesos a través de los cuales se despliega esta documentado. | E5: El enfoque es sistemico, alcanzable para lograr los propósitos del estándar que se desea evaluar en procesos claves. | F5: El enfoque es sistemico tiene buen grado de integración que responde a todos los propósitos del estándar en la mayoría de los procesos. Relacionado con el direccionamiento estratégico. | G5: El enfoque es explícito y se aplica de manera organizada en todos los procesos, responde a los distintos criterios del estándar y está relacionado con el direccionamiento estratégico.
B6: Enfoque Proactivo: Grado en que el enfoque es preventivo y se adelanta a la ocurrencia del problema de calidad, a partir de la gestion del riesgo. | C6: Los enfoques son mayoritariamente reactivos, la informacion presentada es anecdotica y desarticulada, sin evidencia de la gestion del riesgo. | D6: Etapas iniciales de transición de la reacción a la prevención de problemas. Etapas iniciales de la gestion del riesgo. | E6: Enfoque mayoritariamente preventivo hacia el manejo y control de los procesos aún cuando existen algunos procesos en donde se actúa reactivamente. Se identifican herramientas de gestion del riesgo. | F6: El enfoque es mayoritariamente proactivo y preventivo en todos los procesos y se evidencian resultados parciales de la gestion del riesgo. | G6: El enfoque es proactivo y preventivo en todos los procesos. Hay evidencia de la gestion del riesgo.
B7: Enfoque evaluado y mejorado: Forma en que se evalua y mejora el enfoque y su asimilación | C7: La información presentada es anecdótica y desarticulada, no hay evidencias (hechos y datos) . | D7: La evidencia de un proceso de evaluación y mejoramiento del enfoque es limitada. Esbozo de algunos hechos y datos, desarticulados. | E7: El proceso de mejoramiento está basado en hechos y datos (acciones específicas realizadas y registradas) sobre procesos claves que abarcan la mayoría de productos y servicios. | F7: Existe un proceso de mejoramiento basado en hechos y datos como herramienta básica de dirección. | G7: Existen ciclos sistemáticos de evaluación, la información recogida es consistente y válida, oportuna y se emplea para la evaluación y definir acciones de mejoramiento.
B8: IMPLEMENTACIÓN | C8: 1 | D8: 2 | E8: 3 | F8: 4 | G8: 5
B9: Despliegue en la institución: Grado en que se ha implementado el enfoque y es consistente en los distintos servicios o procesos de la organización. | C9: El enfoque se ha implementado en algunos servicios o procesos pero se refleja su debilidad. | D9: La implementación del enfoque se da en algunos servicios o procesos operativos principales y existen brechas muy significativas en procesos importantes. | E9: La implementación está más avanzada en servicios o procesos claves y no existen grandes brechas con respecto a otros servicios o procesos. | F9: Existe un enfoque bien desplegado en todos los servicios o procesos, con brechas no significativas en aquellos de soporte. | G9: La implementación del enfoque se amplía continuamente para cubrir nuevos servicios o procesos en forma integral y responde al enfoque definido en todos los servicios o procesos claves.
B10: Apropiación por el cliente interno y/o externo: Grado en que el cliente del despliegue (cliente interno y/o externo) entiende y aplica el enfoque, según la naturaleza y propositos del estandar. | C10: El enfoque no lo apropian los clientes. | D10: Hay evidencias de apropiación a unos pocos clientes internos o externos, pero éste no es consistente. | E10: Hay evidencias de apropiación parcial del enfoque en los principales clientes con un grado mínimo de consistencia. | F10: El enfoque lo apropian la mayoría de los usuarios y es medianamente consistente. | G10: El enfoque está apropiado en la totalidad de los usuarios y es totalmente consistente.
B11: RESULTADOS | C11: 1 | D11: 2 | E11: 3 | F11: 4 | G11: 5
B12: Pertinencia: Grado en que los resultados referidos (hechos, datos e indicadores) se relacionan con los criterios y requisitos del estándar. | C12: Los datos presentados no responden a los factores, productos o servicios claves del estándar. | D12: Los datos presentados son parciales y se refieren a unos pocos factores, productos o servicios claves solicitados en el estándar. | E12: Los datos presentados se refieren al desempeño de algunos servicios o procesos claves, factores, productos y/o servicios solicitados. | F12: La mayoría de los resultados referidos se relacionan con el servicio o proceso, factores, productos y/o servicios solicitados en el estándar, alcanzando los objetivos y metas propuestas. | G12: Todos los resultados se relacionan con el servicio o proceso o el punto del estándar a evaluar y alcanzan los objetivos y metas propuestas
B13: Consistencia: Relacion de los resultados como producto de la implementacion del enfoque. | C13: Solo existen ejemplos anecdóticos de aspectos poco relevantes y no hay evidencia de que sean resultado de la implementación del enfoque. | D13: Se comienzan a obtener resultados todavía incipientes de la aplicación del enfoque. | E13: Existe evidencia de algunos logros son causados por el enfoque implementado y por las acciones de mejoramiento | F13: La mayoría de los resultados responden a la implementación del enfoque y a las acciones de mejoramiento | G13: Todos los resultados son causados por la implementación de enfoques y a las acciones sistemáticas de mejoramiento
B14: Avance de la medición: Grado en que la medicion responde a una práctica sistémica de la organización en un periodo de tiempo que le permita su consolidacion y existen indicadores definidos para la medicion del estandar evaluado, calidad y pertinencia de los mismos. | C14: No existen indicadores que muestren tendencias en la calidad y el desempeño de los procesos. La organización se encuentra en una etapa muy temprana de medición. | D14: Existen algunos indicadores que muestran el desempeño de procesos. La organización se encuentra en una etapa media del desarrollo de la medición | E14: Existen indicadores que monitorean los procesos y muestran ya tendencias positivas de mejoramiento en algunos servicios o procesos claves, factores, productos y/o servicios solicitados en el estándar. Algunos servicios o procesos reportados pueden estar en etapas recientes de medición. | F14: Existen procesos de medición sistemáticos para la mayoría de los servicios o procesos y factores claves de éxito solicitados en el estándar | G14: Los resultados son monitoreados directamente por los líderes de todos los niveles de la organización y la información se utiliza para la toma de decisiones y el mejoramiento de los procesos.
B15: Tendencia: Desempeño de los indicadores en el tiempo. Puede ser positiva cuando los datos muestran una mejoria general a lo largo del tiempo. | C15: El estadio de la medición y por lo tanto de los resultados, no garantizan tendencias confiables | D15: Se muestran resultados muy recientes que aunque no permiten tener suficientes bases para establecer tendencias, el proceso es sistemático y se empiezan a tomar decisiones operativas con base en la información | E15: Se presentan tendencias de mejoramiento de algunos factores claves del estándar. Proceso sistemático y estructurado. | F15: La mayoría de los indicadores alcanzan niveles satisfactorios y muestran firmes tendencias de mejoramiento de los servicios o procesos claves, factores, productos y/o servicios, lo cual se refleja en que van de bueno a excelente | G15: Se observan tendencias positivas y sostenidas de mejoramiento de todos los datos a lo largo del tiempo
B16: Comparación: Grado en que los resultados son comparados con referentes nacionales e internacionales y la calidad de los mismos. | C16: No existen políticas, ni prácticas de comparación de los procesos de la organización con los mejores. | D16: Se encuentran algunas prácticas independientes de comparación, poco estructuradas y no sistemáticas. | E16: Existe una política de comparación con las mejores prácticas y se encuentra en etapa temprana de comparación de algunos procesos, productos críticos y servicios solicitados en el estándar. | F16: Se encuentra en etapa madura de comparación con las mejores prácticas a nivel nacional de servicios o procesos, productos, factores y/o servicios claves solicitados en el estándar. | G16: Los resultados son comparados con referentes nacionales e internacionales y se ubican en niveles cercanos a las tendencias de clase mundial. Cuenta con un sistema de evaluación y mejora de los sistemas de comparación.

Sheet AUTOEV CUANTI IND
D1: Anexo 1A. Autoevaluación Cuantitativa Registro Individual
B3: Atención: esta hoja está formulada y muestra los criterios que se han registrado en la hoja Autoev Cualit. Para evaluar filtre sólo los criterios que tengan oportunidad de mejora asociada | H3: ENFOQUE | K3: IMPLEMENTACION | M3: RESULTADO
B4: Num. | C4: Eje de Seguridad | D4: Práctica Segura | E4: Criterio | F4: Fortaleza | G4: Oportunidad de Mejora | H4: Enfoque sistémico | I4: Enfoque proactivo | J4: Enfoque evaluado y mejorado | K4: Despliegue en la institución | L4: Apropiación por cliente interno y/o externo | M4: Pertinencia | N4: Consistencia | O4: Avance de la medición | P4: Tendencia | Q4: Comparación | R4: Calificación total
B5: 1 | C5: {=Eje_de_Seguridad} -> 0 | D5: {=practica_segura} -> 0 | E5: {=criterio} -> 0 | F5: {=fortaleza} -> 0 | G5: {=om} -> 0 | R5: =IFERROR(AVERAGE('AUTOEV CUANTI IND'!$H5:$Q5),"")
B6: 2 | C6: 0 | D6: 0 | E6: 0 | F6: 0 | G6: 0 | R6: =IFERROR(AVERAGE('AUTOEV CUANTI IND'!$H6:$Q6),"")
B7: 3 | C7: 0 | D7: 0 | E7: 0 | F7: 0 | G7: 0 | R7: =IFERROR(AVERAGE('AUTOEV CUANTI IND'!$H7:$Q7),"")
B8: 4 | C8: 0 | D8: 0 | E8: 0 | F8: 0 | G8: 0 | R8: =IFERROR(AVERAGE('AUTOEV CUANTI IND'!$H8:$Q8),"")
B9: 5 | C9: 0 | D9: 0 | E9: 0 | F9: 0 | G9: 0 | R9: =IFERROR(AVERAGE('AUTOEV CUANTI IND'!$H9:$Q9),"")
B10: 6 | C10: 0 | D10: 0 | E10: 0 | F10: 0 | G10: 0 | R10: =IFERROR(AVERAGE('AUTOEV CUANTI IND'!$H10:$Q10),"")
B11: 7 | C11: 0 | D11: 0 | E11: 0 | F11: 0 | G11: 0 | R11: =IFERROR(AVERAGE('AUTOEV CUANTI IND'!$H11:$Q11),"")
B12: 8 | C12: 0 | D12: 0 | E12: 0 | F12: 0 | G12: 0 | R12: =IFERROR(AVERAGE('AUTOEV CUANTI IND'!$H12:$Q12),"")
B13: 9 | C13: 0 | D13: 0 | E13: 0 | F13: 0 | G13: 0 | R13: =IFERROR(AVERAGE('AUTOEV CUANTI IND'!$H13:$Q13),"")
B14: 10 | C14: 0 | D14: 0 | E14: 0 | F14: 0 | G14: 0 | R14: =IFERROR(AVERAGE('AUTOEV CUANTI IND'!$H14:$Q14),"")
B15: 11 | C15: 0 | D15: 0 | E15: 0 | F15: 0 | G15: 0 | R15: =IFERROR(AVERAGE('AUTOEV CUANTI IND'!$H15:$Q15),"")
B16: 12 | C16: 0 | D16: 0 | E16: 0 | F16: 0 | G16: 0 | R16: =IFERROR(AVERAGE('AUTOEV CUANTI IND'!$H16:$Q16),"")
B17: 13 | C17: 0 | D17: 0 | E17: 0 | F17: 0 | G17: 0 | R17: =IFERROR(AVERAGE('AUTOEV CUANTI IND'!$H17:$Q17),"")
... B204: 200 | C204: 0 | D204: 0 | E204: 0 | F204: 0 | G204: 0 | R204: =IFERROR(AVERAGE('AUTOEV CUANTI IND'!$H204:$Q204),"")

Sheet AUTOEV CUANTI MULT
D1: Anexo 1A. Autoevaluación Cuantitativa Registro de hasta 10 calificaciones por criterio
H3: ENFOQUE | AL3: Implementación | BF3: Resultados
B4: Atención: esta hoja está formulada y muestra los criterios que se han registrado en la hoja Autoev Cualit | H4: Enfoque sistémico | R4: Enfoque proactivo | AB4: Enfoque evaluado y mejorado | AL4: Despliegue en la institución | AV4: Apropiación por cliente interno y/o externo | BF4: Pertinencia | BP4: Consistencia | BZ4: Avance de la medición | CJ4: Tendencia | CT4: Comparación
B5: Num. | C5: Eje de Seguridad | D5: Práctica Segura | E5: Criterio | F5: Fortaleza | G5: Oportunidad de Mejora | H5: Eval1ES | I5: Eval2ES | J5: Eval3ES | K5: Eval4ES | L5: Eval5ES | M5: Eval6ES | N5: Eval7ES | O5: Eval8ES | P5: Eval9ES | Q5: Eval10ES | R5: Eval1EP | S5: Eval2EP | T5: Eval3EP | U5: Eval4EP | V5: Eval5EP | W5: Eval6EP | X5: Eval7EP | Y5: Eval8EP | Z5: Eval9EP | AA5: Eval10EP | AB5: Eval1EV | AC5: Eval2EV | AD5: Eval3EV | AE5: Eval4EV | AF5: Eval5EV | AG5: Eval6EV | AH5: Eval7EV | AI5: Eval8EV | AJ5: Eval9EV | AK5: Eval10EV | AL5: Eval1DI | AM5: Eval2DI | AN5: Eval3DI | AO5: Eval4DI | AP5: Eval5DI | AQ5: Eval6DI | AR5: Eval7DI | AS5: Eval8DI | AT5: Eval9DI | AU5: Eval10DI | AV5: Eval1AC | AW5: Eval2AC | AX5: Eval3AC | AY5: Eval4AC | AZ5: Eval5AC | BA5: Eval6AC | BB5: Eval7AC | BC5: Eval8AC | BD5: Eval9AC | BE5: Eval10AC | BF5: Eval1PE | BG5: Eval2PE | BH5: Eval3PE | BI5: Eval4PE | BJ5: Eval5PE | BK5: Eval6PE | BL5: Eval7PE | BM5: Eval8PE | BN5: Eval9PE | BO5: Eval10PE | BP5: Eval1CO | BQ5: Eval2CO | BR5: Eval3CO | BS5: Eval4CO | BT5: Eval5CO | BU5: Eval6CO | BV5: Eval7CO | BW5: Eval8CO | BX5: Eval9CO | BY5: Eval10CO | BZ5: Eval1AV | CA5: Eval2AV | CB5: Eval3AV | CC5: Eval4AV | CD5: Eval5AV | CE5: Eval6AV | CF5: Eval7AV | CG5: Eval8AV | CH5: Eval9AV | CI5: Eval10AV | CJ5: Eval1TE | CK5: Eval2TE | CL5: Eval3TE | CM5: Eval4TE | CN5: Eval5TE | CO5: Eval6TE | CP5: Eval7TE | CQ5: Eval8TE | CR5: Eval9TE | CS5: Eval10TE | CT5: Eval1COM | CU5: Eval2COM | CV5: Eval3COM | CW5: Eval4COM | CX5: Eval5COM | CY5: Eval6COM | CZ5: Eval7COM | DA5: Eval8COM | DB5: Eval9COM | DC5: Eval10COM | DD5: Calificación total
B6: 1 | C6: {=Eje_de_Seguridad} -> 0 | D6: {=practica_segura} -> 0 | E6: {=criterio} -> 0 | F6: {=fortaleza} -> 0 | G6: {=om} -> 0 | DD6: =IFERROR(AVERAGE('AUTOEV CUANTI MULT'!$H6:$DC6),"")
