Workbook

Sheet Instructivo de Uso
A1: 📋 INSTRUCTIVO DE USO — HERRAMIENTA DE AUDITORÍA PROFESIONAL INDEPENDIENTE EN SALUD
A2: Resolución 3100 de 2019 | Sistema Único de Habilitación | Audisalud Colombia S.A.S. | Versión 2.0
A4: 1. PROPÓSITO Y ALCANCE DE LA HERRAMIENTA
B5: ASPECTO | C5: DETALLE
B6: ¿Para qué sirve? | C6: Auditar el cumplimiento de los estándares de habilitación (Res. 3100/2019) para PROFESIONALES INDEPENDIENTES. Cubre Talento Humano, Infraestructura, Dotación, Medicamentos/DM/Insumos, Procesos Prioritarios, Historia Clínica e Interdependencia para todos los servicios que puede habilitar un profesional independiente.
B7: ¿A quién aplica? | C7: Profesionales independientes habilitados individualmente: médicos, enfermeras, nutricionistas, psicólogos, optómetras, fisioterapeutas, fonoaudiólogos, terapeutas ocupacionales, terapeutas respiratorios, bacteriólogos y demás profesionales con habilitación individual ante la Secretaría de Salud.
B8: ¿Qué NO cubre? | C8: No cubre IPS, servicios hospitalarios, UCI, urgencias complejas, cirugías mayores, bancos de sangre, servicios de internación ni radioterapia / medicina nuclear. Para estos servicios se requieren instrumentos adicionales.
B9: Normativa base | C9: Resolución 3100 de 2019 — MinSalud Colombia. La herramienta usa el texto LITERAL de la norma, organizado por sección, número de referencia (11.1.1 – 11.3.12) y modalidad de prestación (intramural, extramural, telemedicina).
A11: 2. ESTRUCTURA DEL LIBRO — DESCRIPCIÓN DE CADA HOJA
A12: # | B12: PESTAÑA | C12: DESCRIPCIÓN | D12: CUÁNDO USARLA
A13: 1 | B13: Instructivo de Uso | C13: Este documento. Explica la herramienta, íconos y flujo de trabajo recomendado. | D13: Leer SIEMPRE antes de iniciar una auditoría
A14: 2 | B14: Recomendaciones | C14: Recomendaciones prácticas por estándar con nivel de riesgo 🔴🟡🟠🟢. | D14: Consultar antes de cada visita para anticipar hallazgos
A15: 3 | B15: Diferencias Servicios | C15: Tabla comparativa de exigencias entre servicios y puntos críticos por tipo de servicio. | D15: Consultar cuando el prestador tiene más de un servicio habilitado
A16: 4 | B16: Dashboard | C16: Panel de control: % cumplimiento, semáforo y alertas críticas. Se actualiza automáticamente al marcar X. | D16: Ver durante y después de cada auditoría
A17: 5 | B17: Criterios Generales | C17: Criterios generales (Sec. 11.1.1–11.1.7) filtrados para profesional independiente. | D17: Aplicar PRIMERO — aplica a todos los servicios habilitados
A18: 6 | B18: Ficha Prestador | C18: Datos del prestador, habilitación, auditoría y semáforo automático de vencimientos de documentos. | D18: Diligenciar al inicio de TODA visita
A19: 7 | B19: Auditoría Documental | C19: Lista de chequeo de documentos requeridos por los estándares generales. | D19: Verificación de carpetas y archivos del prestador
A20: 8 | B20: Auditoría Infraestructura | C20: Criterios de infraestructura física según la Resolución 3100/2019. | D20: Recorrido físico por las instalaciones
A21: 9 | B21: Consulta Externa | C21: Criterios específicos CE General (Baja) y CE Especializada (Mediana), todas las modalidades incluida telemedicina. | D21: Cuando el prestador tiene habilitado servicio de CE
A22: 10 | B22: Terapias | C22: Criterios del servicio de Terapias Física, Ocupacional, Lenguaje y Respiratoria — Sec. 11.3.1. | D22: Cuando el prestador es fisioterapeuta, fonoaudiólogo, TO o TR
A23: 11 | B23: Laboratorio Clínico | C23: Criterios de Laboratorio Clínico Baja Complejidad — Sec. 11.3.12, incluye modalidad telemedicina. | D23: Cuando el prestador es bacteriólogo con laboratorio habilitado
... A26: 14 | B26: Claude Log | C26: Registro de versiones y cambios realizados en la herramienta. | D26: Consultar para verificar versión
A28: 3. FLUJO DE TRABAJO RECOMENDADO — PASO A PASO
A29: ANTES DE LA VISITA
A30: 1. Descarga y abre una COPIA del archivo (no trabajes sobre el original).
A31: 2. Revisa el semáforo de vencimientos en la Ficha Prestador para identificar alertas previas.
A32: 3. Identifica qué servicios tiene habilitados el prestador (CE, Terapias, Lab…).
A33: 4. Prepara los formatos a aplicar según los servicios habilitados.
A35: DURANTE LA VISITA
A36: 5. Diligencia la Ficha Prestador con datos del prestador y de la auditoría.
A37: 6. Aplica Criterios Generales (aplican a TODOS los servicios).
A38: 7. Aplica las hojas de servicio específico según lo habilitado.
A39: 8. Marca X en columna C (Cumple), NC (No Cumple) o NA (No Aplica) en cada criterio.
A40: 9. Registra el hallazgo exacto en la columna 'Hallazgo / Evidencia'.
... A53: 4. ÍCONOS, COLORES Y CONVENCIONES
B54: ÍCONO / COLOR | C54: SIGNIFICADO | D54: ACCIÓN REQUERIDA
B55: ⚠️ Fondo AMARILLO en fila | C55: Criterio CRÍTICO — incumplimiento puede generar requerimiento o cierre del servicio | D55: Documentar con detalle. Si NC → Requerimiento formal obligatorio
B56: ★ Número con estrella | C56: Criterio explícito para Profesional Independiente en la norma | D56: Verificar con prioridad — la norma hace distinción específica
B57: ⊘ Fila GRIS tachada | C57: Criterio EXCLUIDO: no aplica al profesional independiente (aplica a IPS, hospitales) | D57: No evaluar — marcar NA si el sistema lo requiere
B58: Fila 🟢 VERDE | C58: Criterio marcado C (Cumple) | D58: Documenta la evidencia en la columna Hallazgo
...

Sheet Dashboard
A1: DASHBOARD DE AUDITORIA — HABILITACION EN SALUD — PROFESIONAL INDEPENDIENTE
A2: Resolucion 3100 de 2019 | Sistema Unico de Habilitacion | Audisalud Colombia S.A.S.
A3: PRESTADOR: | F3: FECHA:
A4: AUDITOR: | E4: HORA INICIO: | G4: TIPO AUDITORIA:
A5: LEYENDA: C = Cumple | NC = No Cumple | NA = No Aplica — Marque X en cada criterio en la hoja correspondiente
A6: CUMPLIMIENTO POR INSTRUMENTO DE AUDITORIA
A7: # | B7: INSTRUMENTO | C7: TOTAL | D7: CUMPLE (C) | E7: NO CUMPLE (NC) | F7: NO APLICA (NA) | G7: % CUMPL. | H7: SEMAFORO | I7: ESTADO NC
A8: 1 | B8: Criterios Generales | C8: =COUNTA('Criterios Generales'!D8:D174) -> 138 | D8: =COUNTIF('Criterios Generales'!G8:G174,"X") -> 1 | E8: =COUNTIF('Criterios Generales'!H8:H174,"X") -> 0 | F8: =COUNTIF('Criterios Generales'!I8:I174,"X") -> 0 | G8: =IF((D8+E8)=0,0,D8/(D8+E8)) -> 1 | H8: =IF((D8+E8)=0,"SIN EVALUAR",IF(G8>=0.9,"CUMPLE",IF(G8>=0.7,"EN PROCESO","NO CUMPLE"))) -> CUMPLE | I8: =IF(E8=0,"Sin hallazgos NC","ATENCION: "&E8&" hallazgo(s) NC") -> Sin hallazgos NC
A9: 2 | B9: Auditoria Documental | C9: =COUNTA('Auditoría Documental'!D8:D97) -> 87 | D9: =COUNTIF('Auditoría Documental'!F8:F97,"X") -> 0 | E9: =COUNTIF('Auditoría Documental'!G8:G97,"X") -> 0 | F9: =COUNTIF('Auditoría Documental'!H8:H97,"X") -> 0 | G9: =IF((D9+E9)=0,0,D9/(D9+E9)) -> 0 | H9: =IF((D9+E9)=0,"SIN EVALUAR",IF(G9>=0.9,"CUMPLE",IF(G9>=0.7,"EN PROCESO","NO CUMPLE"))) -> SIN EVALUAR | I9: =IF(E9=0,"Sin hallazgos NC","ATENCION: "&E9&" hallazgo(s) NC") -> Sin hallazgos NC
A10: 3 | B10: Auditoria Infraestructura | C10: =COUNTA('Auditoría Infraestructura'!D8:D62) -> 55 | D10: =COUNTIF('Auditoría Infraestructura'!F8:F62,"X") -> 0 | E10: =COUNTIF('Auditoría Infraestructura'!G8:G62,"X") -> 0 | F10: =COUNTIF('Auditoría Infraestructura'!H8:H62,"X") -> 0 | G10: =IF((D10+E10)=0,0,D10/(D10+E10)) -> 0 | H10: =IF((D10+E10)=0,"SIN EVALUAR",IF(G10>=0.9,"CUMPLE",IF(G10>=0.7,"EN PROCESO","NO CUMPLE"))) -> SIN EVALUAR | I10: =IF(E10=0,"Sin hallazgos NC","ATENCION: "&E10&" hallazgo(s) NC") -> Sin hallazgos NC
A11: 4 | B11: Consulta Externa | C11: =COUNTA('Consulta Externa'!D11:D203) -> 131 | D11: =COUNTIF('Consulta Externa'!F11:F203,"X") -> 0 | E11: =COUNTIF('Consulta Externa'!G11:G203,"X") -> 0 | F11: =COUNTIF('Consulta Externa'!H11:H203,"X") -> 0 | G11: =IF((D11+E11)=0,0,D11/(D11+E11)) -> 0 | H11: =IF((D11+E11)=0,"SIN EVALUAR",IF(G11>=0.9,"CUMPLE",IF(G11>=0.7,"EN PROCESO","NO CUMPLE"))) -> SIN EVALUAR | I11: =IF(E11=0,"Sin hallazgos NC","ATENCION: "&E11&" hallazgo(s) NC") -> Sin hallazgos NC
A12: 5 | B12: Terapias | C12: =COUNTA(Terapias!D8:D55) -> 45 | D12: =COUNTIF(Terapias!F8:F55,"X") -> 0 | E12: =COUNTIF(Terapias!G8:G55,"X") -> 0 | F12: =COUNTIF(Terapias!H8:H55,"X") -> 0 | G12: =IF((D12+E12)=0,0,D12/(D12+E12)) -> 0 | H12: =IF((D12+E12)=0,"SIN EVALUAR",IF(G12>=0.9,"CUMPLE",IF(G12>=0.7,"EN PROCESO","NO CUMPLE"))) -> SIN EVALUAR | I12: =IF(E12=0,"Sin hallazgos NC","ATENCION: "&E12&" hallazgo(s) NC") -> Sin hallazgos NC
A13: 6 | B13: Laboratorio Clinico | C13: =COUNTA('Laboratorio Clínico'!D10:D97) -> 66 | D13: =COUNTIF('Laboratorio Clínico'!G10:G97,"X") -> 0 | E13: =COUNTIF('Laboratorio Clínico'!H10:H97,"X") -> 0 | F13: =COUNTIF('Laboratorio Clínico'!I10:I97,"X") -> 0 | G13: =IF((D13+E13)=0,0,D13/(D13+E13)) -> 0 | H13: =IF((D13+E13)=0,"SIN EVALUAR",IF(G13>=0.9,"CUMPLE",IF(G13>=0.7,"EN PROCESO","NO CUMPLE"))) -> SIN EVALUAR | I13: =IF(E13=0,"Sin hallazgos NC","ATENCION: "&E13&" hallazgo(s) NC") -> Sin hallazgos NC
A14: 7 | B14: Toma de Muestras Lab | C14: =COUNTA('Toma de Muestras Lab'!D10:D60) -> 35 | D14: =COUNTIF('Toma de Muestras Lab'!G10:G60,"X") -> 0 | E14: =COUNTIF('Toma de Muestras Lab'!H10:H60,"X") -> 0 | F14: =COUNTIF('Toma de Muestras Lab'!I10:I60,"X") -> 0 | G14: =IF((D14+E14)=0,0,D14/(D14+E14)) -> 0 | H14: =IF((D14+E14)=0,"SIN EVALUAR",IF(G14>=0.9,"CUMPLE",IF(G14>=0.7,"EN PROCESO","NO CUMPLE"))) -> SIN EVALUAR | I14: =IF(E14=0,"Sin hallazgos NC","ATENCION: "&E14&" hallazgo(s) NC") -> Sin hallazgos NC
A15: TOTAL GENERAL | C15: =SUM(C8:C14) -> 557 | D15: =SUM(D8:D14) -> 1 | E15: =SUM(E8:E14) -> 0 | F15: =SUM(F8:F14) -> 0 | G15: =IF((D15+E15)=0,0,D15/(D15+E15)) -> 1 | H15: =IF((D15+E15)=0,"SIN EVALUAR",IF(G15>=0.9,"CUMPLE",IF(G15>=0.7,"EN PROCESO","NO CUMPLE"))) -> CUMPLE | I15: =IF(E15=0,"Sin hallazgos","ATENCION: "&E15&" NC") -> Sin hallazgos
A17: ALERTAS CRITICAS — CRITERIOS CON CAUSAL DE CIERRE O SANCION
A18: # | B18: CRITERIO CRITICO | C18: INSTRUMENTO / HOJA | I18: ESTADO
A19: 1 | B19: Tarjeta profesional VIGENTE del prestador | C19: CE / Terapias / Lab Clinico / Toma Muestras | I19: Pendiente
A20: 2 | B20: Habilitacion vigente en REPS | C20: Ficha Prestador | I20: Pendiente
A21: 3 | B21: Concepto sanitario vigente | C21: Ficha Prestador / Auditoria Infraestructura | I21: Pendiente
A22: 4 | B22: Certificado RETIE vigente | C22: Ficha Prestador / Auditoria Documental | I22: Pendiente
A23: 5 | B23: Programa de seguridad del paciente documentado | C23: Criterios Generales / CE / Terapias / Lab | I23: Pendiente
A24: 6 | B24: Consentimiento informado funcional y verificable | C24: Criterios Generales / CE / Terapias | I24: Pendiente
A25: 7 | B25: Protocolo de higiene de manos con insumos | C25: Criterios Generales / CE / Terapias / Lab | I25: Pendiente
A26: 8 | B26: Historia clinica con componentes minimos (Res. 1995/99) | C26: CE / Terapias | I26: Pendiente
A27: 9 | B27: Plan de gestion integral de residuos (PGIRHS) | C27: Auditoria Documental / Infraestructura | I27: Pendiente
A28: 10 | B28: Reactivos con registro sanitario INVIMA vigente | C28: Laboratorio Clinico | I28: Pendiente
A29: 11 | B29: Doc. atencion victimas de violencias sexuales | C29: Criterios Generales / Consulta Externa | I29: Pendiente
A30: 12 | B30: Protocolo de bioseguridad especifico del servicio | C30: Criterios Generales / CE / Terapias / Lab | I30: Pendiente
A32: LEYENDA DE SEMAFOROS
A33: CUMPLE | C33: 90% o mas de criterios cumplen
A34: EN PROCESO | C34: Entre 70% y 89% cumplen
A35: NO CUMPLE | C35: Menos del 70% cumplen
A36: SIN EVALUAR | C36: Sin datos marcados aun

Sheet Recomendaciones
A1: 💡 RECOMENDACIONES DE AUDITORÍA Y HABILITACIÓN — PROFESIONAL INDEPENDIENTE
A2: Basadas en Res. 3100/2019 y experiencia práctica en el Sistema Único de Habilitación | Audisalud Colombia S.A.S.
A4: TALENTO HUMANO
A5: # | B5: ASPECTO | C5: RIESGO | D5: RECOMENDACIÓN PRÁCTICA
A6: 1 | B6: Tarjeta profesional vigente | C6: 🔴 CRÍTICO | D6: El criterio más verificado y más incumplido. La tarjeta no puede estar vencida ni cancelada. Verificar siempre en el portal ReTHUS (https://web.sispro.gov.co/THS/Cliente/ConsultasPublicas/ConsultaPublicaDeTHxIdentificacion.aspx) — el registro electrónico prevalece sobre el documento físico. Es causal de cierre inmediato del servicio.
A7: 2 | B7: ReTHUS actualizado | C7: 🔴 CRÍTICO | D7: Todo profesional debe estar inscrito en el Registro Único Nacional de Talento Humano en Salud. Si hay discrepancia entre la tarjeta profesional y el ReTHUS, prevalece el ReTHUS. Verificar en línea en el momento de la visita.incluyendo especialistas.
A8: 3 | B8: Formación continua | C8: 🟡 ATENCIÓN | D8: La norma NO exige horas mínimas — basta con evidenciar continuidad en la actualización. Guardar constancias de cursos, congresos y talleres. Si cuenta con personal de apoyo incluye formacion continuia
A9: 4 | B9: Formación en telemedicina | C9: 🟡 ATENCIÓN | D9: Si presta servicios en modalidad telemedicina, debe tener constancia de formación en el manejo de la tecnología utilizada. Es uno de los criterios más omitidos en habilitación de modalidad virtual.
A10: 5 | B10: Estudiantes en práctica formativa | C10: No aplica | D10: NO APLICA AL PROFESIONAL INDEPENDIENTE — El criterio de escenarios de práctica formativa (convenio con IES y estudio de capacidad instalada) aplica a IPS y entidades con objeto social diferente que tienen estudiantes en práctica. El profesional independiente NO puede tener estudiantes asignados como escenario de práctica formativa; si lo hace, cambia su naturaleza jurídica de independiente a institución.
A11: 6 | B11: Sedación: talento humano requerido | C11: 🔴 CRÍTICO | D11: Si realiza procedimientos bajo sedación fuera de salas de cirugía: verificar grado de sedación y el profesional anestesiólogo requerido. Grado I y II pueden ser realizados con médico capacitado en soporte vital y sedación. Grado IV requiere anestesiólogo obligatorio.
A12: 7 | B12: Facturación como profesional independiente | C12: Critico | D12: El profesional independiente DEBE facturar como persona natural (cédula), NO como persona jurídica (NIT). Facturar bajo un NIT cambia automáticamente la naturaleza jurídica del prestador de 'Profesional Independiente' a 'Entidad con Objeto Social Diferente (EOSD)' o IPS, lo que implica requisitos de habilitación completamente distintos y más exigentes. IMPLICACIONES PRÁCTICAS: • La habilitación en REPS debe estar registrada a nombre del profesional (cédula), no a nombre de una empresa. • Las facturas de venta de servicios de salud deben llevar el número de cédula del profesional. • Si tiene empleados o contrata otros profesionales a su nombre, puede perder la categoría de independiente. • El RUT del profesional debe reflejar la actividad de prestación de servicios de salud (código CIIU correspondiente). • En la DIAN: registrarse como persona natural responsable de IVA o no responsable, según ingresos. VERIFICAR EN AUDITORIA: Solicitar la factura de servicios o el contrato con la entidad pagadora — debe aparecer el nombre y cédula del profesional, NO una razón social ni un NIT de empresa.
A15: INFRAESTRUCTURA
A16: # | B16: ASPECTO | C16: RIESGO | D16: RECOMENDACIÓN PRÁCTICA
A17: 1 | B17: Concepto sanitario vigente | C17: 🔴 CRÍTICO | D17: Es el documento que más demora en obtenerse (puede tardar 2-3 meses). Tramitar con anticipación ante la Secretaría de Salud. Su vencimiento afecta directamente la habilitación vigente en REPS.
A18: 2 | B18: Certificado RETIE | C18: 🔴 CRÍTICO | D18: Debe ser emitido por ingeniero eléctrico con matrícula vigente. Aplica incluso en consultorios pequeños. Verificar que cubra las instalaciones actuales y que la matrícula del ingeniero esté vigente. Si la infraestructura es antes de mayo 2025 si es posterior se debe hacer con una empresa avalada por la onac
A19: 3 | B19: Certificado de Bomberos | C19: 🔴 CRÍTICO | D19: Gestionarlo con la Secretaría de Gobierno o el Cuerpo de Bomberos local. En municipios pequeños puede tramitarse con la administración municipal. Renovar con la misma periodicidad que define la entidad emisora.
A20: 4 | B20: Consultorio: dimensiones mínimas | C20: 🔴 CRÍTICO | D20: Consultorio con examen físico: mínimo 10 m² SIN incluir la unidad sanitaria. Consultorio solo entrevista: mínimo 4 m². Medir siempre — el incumplimiento es más frecuente de lo que parece en consultorios pequeños.
A21: 5 | B21: Pisos en media caña | C21: 🟡 ATENCIÓN | D21: Obligatorio en laboratorios, consultorios de procedimientos y consulta odontológica. La unión entre pared y piso debe ser en media caña (sin aristas). Verificar visualmente durante el recorrido.
A22: 6 | B22: Accesibilidad (ascensor / rampa) | C22: 🟡 ATENCIÓN | D22: Si el consultorio está en 2° o 3° piso, es obligatorio contar con ascensor, rampa o sistema alternativo de elevación (incluso para prestadores pequeños). Verificar el tipo de sistema y sus condiciones. Aplica para los inscritos despues de el 25 noviembre 2019 (resolucion 544)
A23: 7 | B23: Edificación mixta — infraestructura | C23: 🟢 OPORTUNIDAD | D23: La norma permite edificios mixtos (consultorio en edificio residencial/comercial). Cada prestador debe tener área delimitada físicamente. Pueden compartir: sala de espera y unidades sanitarias.
A24: 8 | B24: Señalización rutas de evacuación | C24: 🟡 ATENCIÓN | D24: Cada piso debe tener planos y señalización de rutas de evacuación, salidas de emergencia y puntos de encuentro, visibles al público. Es un criterio frecuentemente olvidado en consultorios pequeños.
A26: DOTACIÓN
A27: # | B27: ASPECTO | C27: RIESGO | D27: RECOMENDACIÓN PRÁCTICA
A28: 1 | B28: Hoja de vida de equipos | C28: 🟡 ATENCIÓN | D28: Cada equipo biomédico — incluidos tensiómetros, fonendos y báscula — debe tener hoja de vida con registro de mantenimientos. Error frecuente: omitir equipos de bajo costo pensando que no aplica.
A29: 2 | B29: Calibración y mantenimiento | C29: 🔴 CRÍTICO | D29: Los equipos que miden variables fisiológicas (tensiómetros, glucómetros, balanzas) deben tener certificado de calibración vigente. Verificar fechas. El mantenimiento puede ser del fabricante o de técnico contratado.
A30: 3 | B30: Programa de mantenimiento preventivo | C30: 🟡 ATENCIÓN | D30: Puede ser un cronograma anual simple, pero debe existir. Incluir las recomendaciones del fabricante para cada equipo. El mantenimiento correctivo también debe registrarse.
A31: 4 | B31: Suficiencia de dotación | C31: 🟢 OPORTUNIDAD | D31: La norma NO exige número mínimo de equipos — exige que la dotación sea suficiente para la demanda del servicio. El prestador debe documentar su análisis de suficiencia según carga asistencial.
A32: 5 | B32: No adaptar DM en extramural | C32: 🔴 CRÍTICO | D32: En modalidad extramural está PROHIBIDO adaptar o fabricar dispositivos médicos sobre medida. Solo se pueden usar equipos con registro sanitario INVIMA vigente.
A33: 6 | B33: Equipos telemedicina: certificación | C33: 🟡 ATENCIÓN | D33: Los equipos de captura y transmisión de información deben estar certificados por ingeniero biomédico y/o de sistemas. Las pantallas para diagnóstico deben cumplir especificaciones técnicas de dot pitch y resolución.
A35: MEDICAMENTOS, DM E INSUMOS
A36: # | B36: ASPECTO | C36: RIESGO | D36: RECOMENDACIÓN PRÁCTICA
A37: 1 | B37: Registro INVIMA vigente | C37: 🔴 CRÍTICO | D37: Todos los medicamentos y dispositivos médicos deben tener registro sanitario INVIMA vigente. Verificar en vía.invima.gov.co en el momento de la visita. Las fechas de vencimiento físicas también deben estar visibles y controladas.
A38: 2 | B38: Cadena de frío | C38: 🔴 CRÍTICO | D38: Si maneja insulinas, vacunas, biológicos o reactivos termolábiles: la cadena de frío es obligatoria. Debe tener nevera, termómetro calibrado y registro DIARIO de temperatura documentado.
A39: 3 | B39: Kit de derrames | C39: 🟡 ATENCIÓN | D39: Obligatorio para todo prestador que maneje medicamentos. Debe estar señalizado, accesible y documentado. El prestador define su contenido según los medicamentos que usa y las fichas técnicas del fabricante.
A40: 4 | B40: Farmacovigilancia / Tecnovigilancia | C40: 🟡 ATENCIÓN | D40: El profesional independiente que dispensa o administra medicamentos debe estar inscrito en el programa de Farmacovigilancia del INVIMA. Es uno de los criterios más frecuentemente incumplidos en independientes.
A41: 5 | B41: Control de cadena de frío en extramural | C41: 🟠 VIGILAR | D41: En modalidad domiciliaria y extramural, los medicamentos e insumos deben mantenerse en condiciones apropiadas durante el transporte. Documentar el procedimiento de manejo de temperatura en extramural.
A42: 6 | B42: Relaciones de insumos actualizadas | C42: 🟢 OPORTUNIDAD | D42: Las relaciones de medicamentos, DM y reactivos deben estar actualizadas. Mantenerlas en formato digital facilita la actualización y la presentación durante la auditoría.
A44: PROCESOS PRIORITARIOS
A45: # | B45: ASPECTO | C45: RIESGO | D45: RECOMENDACIÓN PRÁCTICA
A46: 1 | B46: Política de seguridad del paciente | C46: 🔴 CRÍTICO | D46: Es el documento estratégico más importante. Para el profesional independiente debe existir, estar firmado, fechado y socializado. La norma permite que el mismo prestador sea el comité.
...

Sheet Diferencias entre Servicios
A1: 🔍 DIFERENCIAS ENTRE SERVICIOS Y PUNTOS CRÍTICOS POR SERVICIO HABILITADO
A2: Resolución 3100 de 2019 | Comparación de exigencias por tipo de servicio | Profesional Independiente | Audisalud Colombia S.A.S.
A4: 1. COMPARATIVA DE EXIGENCIAS POR SERVICIO HABILITADO
A5: # | B5: ASPECTO / CRITERIO | C5: CE General | D5: CE Especializada | E5: Terapias | F5: Lab Clínico | G5: Toma Muestras
A6: 1 | B6: PROFESIONAL HABILITANTE | C6: Médico/Enf/Nut/Psic/u otro | D6: Especialista (MEN) | E6: Fisio/Fono/TO/TR | F6: Bacteriólogo | G6: Bacteriólogo o auxiliar
A7: 2 | B7: COMPLEJIDAD EXIGIDA | C7: Baja | D7: Mediana | E7: ❌ | F7: ❌ | G7: ❌
A8: 3 | B8: Consultorio examen físico ≥10 m² | C8: ✅ | D8: ✅ | E8: ❌ | F8: ❌ | G8: ❌
A9: 4 | B9: Barrera física entre áreas | C9: ✅ | D9: ✅ | E9: ⚙️ Cond. | F9: ❌ | G9: ❌
A10: 5 | B10: Área de procedimientos separada | C10: ⚙️ Cond. | D10: ⚙️ Cond. | E10: ❌ | F10: ❌ | G10: ❌
A11: 6 | B11: Ambiente técnico de procesamiento | C11: ❌ | D11: ❌ | E11: ❌ | F11: ✅ | G11: ❌
A12: 7 | B12: Cubículo específico toma de muestras | C12: ❌ | D12: ❌ | E12: ❌ | F12: ⚙️ Cond. | G12: ✅
A13: 8 | B13: Ducha/lavaojos en área técnica | C13: ❌ | D13: ❌ | E13: ❌ | F13: ✅ | G13: ❌
A14: 9 | B14: Área hidroterapia o húmeda | C14: ❌ | D14: ❌ | E14: ⚙️ Cond. | F14: ❌ | G14: ❌
A15: 10 | B15: Cabina sono-amortiguada / audiometría | C15: ❌ | D15: ❌ | E15: ⚙️ Cond. | F15: ❌ | G15: ❌
A16: 11 | B16: Camilla fija + escalerilla | C16: ✅ | D16: ✅ | E16: ⚙️ Cond. | F16: ❌ | G16: ❌
... A35: 30 | B35: Inscripción RELAB (pruebas ISP) | C35: ⚙️ Cond. | D35: ⚙️ Cond. | E35: ❌ | F35: ✅ | G35: ❌
A37: LEYENDA: | C37: ✅ Aplica siempre | D37: ❌ No aplica / No exigido | E37: ⚙️ Cond. Condicional
A39: 2. PUNTOS CRÍTICOS POR SERVICIO — LO QUE NO PUEDE FALTAR EN NINGUNA VISITA
A40: ⚠️ CE GENERAL — Baja Complejidad
B41: NIVEL | C41: PUNTO CRÍTICO
A42: 1 | B42: ⚠️ CRÍTICO | C42: Tarjeta profesional VIGENTE del profesional — verificar en ReTHUS en tiempo real
A43: 2 | B43: ⚠️ CRÍTICO | C43: Concepto sanitario vigente — emitido por la Secretaría de Salud
A44: 3 | B44: ⚠️ CRÍTICO | C44: Certificado RETIE vigente — emitido por ingeniero eléctrico matriculado
A45: 4 | B45: ⚠️ CRÍTICO | C45: Protocolo de higiene de manos documentado, visible y con insumos disponibles
A46: 5 | B46: ⚠️ CRÍTICO | C46: Consentimiento informado firmado, funcional y archivado en HC
A47: 6 | B47: ⚠️ CRÍTICO | C47: Historia clínica con componentes mínimos de la Resolución 1995/99
A48: 7 | B48: ⚠️ CRÍTICO | C48: Documento para atención de víctimas de violencias sexuales (criterio específico del independiente)
A49: 8 | B49: ⚠️ CRÍTICO | C49: Programa de seguridad del paciente — puede ser el mismo prestador en el caso del independiente
A50: 9 | B50: Importante | C50: Consultorio con examen físico: mínimo 10 m² con áreas separadas por barrera física
A51: 10 | B51: Importante | C51: Tensiómetro y fonendoscopio disponibles y con mantenimiento / calibración
A52: 11 | B52: Importante | C52: Sala de espera disponible con unidades sanitarias accesibles
A53: 12 | B53: Condicional | C53: Para ERA: sala señalizada + protocolo de tiempos y condiciones de manejo documentado
A55: ⚠️ CE ESPECIALIZADA — Mediana Complejidad
B56: NIVEL | C56: PUNTO CRÍTICO
A57: 1 | B57: ⚠️ CRÍTICO | C57: Título de ESPECIALISTA reconocido— sin este título no puede habilitar CE especializada
A58: 2 | B58: ⚠️ CRÍTICO | C58: Para medicina/terapias alternativas: certificación académica de la especialidad expedida reconocida
A59: 3 | B59: ⚠️ CRÍTICO | C59: TODOS los criterios de CE General aplican como base — no son opcionales
A60: 4 | B60: Importante | C60: Dotación específica para los procedimientos de la especialidad documentada en Procesos Prioritarios
A61: 5 | B61: Importante | C61: GPC adoptadas / adaptadas / desarrolladas para las patologías más frecuentes de la especialidad
A62: 6 | B62: Importante | C62: Información al paciente sobre preparación, complicaciones y controles post-procedimiento
...

Sheet Ficha Prestador
A1: FICHA TÉCNICA DEL PRESTADOR DE SERVICIOS DE SALUD
A2: Resolución 3100 de 2019 — Habilitación de Servicios de Salud — Profesionales Independientes
A3: 1. DATOS BÁSICOS DEL PRESTADOR
A4: Nombre y apellido | E4: Cédula:
A5: Código REPS: | E5: Código de Habilitación:
A6: Dirección: | E6: Municipio / Departamento:
A7: Teléfono: | E7: Correo electrónico:
A8: Representante Legal: | E8: Tipo de prestador:
A9: Profesión: | E9: N°. Tarjeta Profesional:
A10: Naturaleza jurídica: | E10: Complejidad:
A12: 2. INFORMACIÓN DE HABILITACIÓN
A13: Servicios habilitados:
A14: Modalidad de prestación: | E14: Horario de atención:
A15: Fecha de habilitación: | E15: Fecha vencimiento:
A16: Sede: | E16: N° de sede:
A17: Estado actual REPS: | E17: Fecha última actualización:
A19: 3. INFORMACIÓN DE LA AUDITORÍA
A20: Tipo de auditoría: | E20: Fecha de auditoría:
A21: Hora inicio: | E21: Hora finalización:
A22: Nombre del auditor: | E22: Cargo:
A23: Profesión del auditor: | E23: N°. Tarjeta profesional:
A24: Entidad contratante: | E24: Objeto de la auditoría:
A25: Hallazgos previos:
A26: Plan de mejora vigente:
A27: Fecha próxima visita: | E27: Responsable seguimiento:
A29: 4. CONTROL DE DOCUMENTOS Y VENCIMIENTOS
A30: N° | B30: DOCUMENTO | C30: FECHA VENCIMIENTO | D30: DÍAS RESTANTES | E30: ESTADO
A31: 1 | B31: Licencia de construcción / Uso de suelos | D31: =IF(C31="","",C31-TODAY()) | E31: =IF(C31="","Sin fecha registrada",IF(D31<0,"VENCIDO",IF(D31<30,"PROXIMO A VENCER",IF(D31<90,"ATENCION","VIGENTE")))) -> Sin fecha registrada
A32: 2 | B32: Certificado de Bomberos | D32: =IF(C32="","",C32-TODAY()) | E32: =IF(C32="","Sin fecha registrada",IF(D32<0,"VENCIDO",IF(D32<30,"PROXIMO A VENCER",IF(D32<90,"ATENCION","VIGENTE")))) -> Sin fecha registrada
A33: 3 | B33: Certificado RETIE (Ingeniero eléctrico) | D33: =IF(C33="","",C33-TODAY()) | E33: =IF(C33="","Sin fecha registrada",IF(D33<0,"VENCIDO",IF(D33<30,"PROXIMO A VENCER",IF(D33<90,"ATENCION","VIGENTE")))) -> Sin fecha registrada
A34: 4 | B34: Concepto sanitario (Salud Pública) | D34: =IF(C34="","",C34-TODAY()) | E34: =IF(C34="","Sin fecha registrada",IF(D34<0,"VENCIDO",IF(D34<30,"PROXIMO A VENCER",IF(D34<90,"ATENCION","VIGENTE")))) -> Sin fecha registrada
A35: 5 | B35: Habilitación vigente REPS | D35: =IF(C35="","",C35-TODAY()) | E35: =IF(C35="","Sin fecha registrada",IF(D35<0,"VENCIDO",IF(D35<30,"PROXIMO A VENCER",IF(D35<90,"ATENCION","VIGENTE")))) -> Sin fecha registrada
A36: 6 | B36: Seguro de responsabilidad civil profesional | D36: =IF(C36="","",C36-TODAY()) | E36: =IF(C36="","Sin fecha registrada",IF(D36<0,"VENCIDO",IF(D36<30,"PROXIMO A VENCER",IF(D36<90,"ATENCION","VIGENTE")))) -> Sin fecha registrada
A37: 7 | B37: Plan de gestión integral de residuos (PGIRHS) | D37: =IF(C37="","",C37-TODAY()) | E37: =IF(C37="","Sin fecha registrada",IF(D37<0,"VENCIDO",IF(D37<30,"PROXIMO A VENCER",IF(D37<90,"ATENCION","VIGENTE")))) -> Sin fecha registrada
A38: 8 | B38: Certificado de fumigación | D38: =IF(C38="","",C38-TODAY()) | E38: =IF(C38="","Sin fecha registrada",IF(D38<0,"VENCIDO",IF(D38<30,"PROXIMO A VENCER",IF(D38<90,"ATENCION","VIGENTE")))) -> Sin fecha registrada
A39: 9 | B39: Certificado lavado de tanques de agua | D39: =IF(C39="","",C39-TODAY()) | E39: =IF(C39="","Sin fecha registrada",IF(D39<0,"VENCIDO",IF(D39<30,"PROXIMO A VENCER",IF(D39<90,"ATENCION","VIGENTE")))) -> Sin fecha registrada
A40: 10 | B40: Licencia práctica radiológica (si aplica) | D40: =IF(C40="","",C40-TODAY()) | E40: =IF(C40="","Sin fecha registrada",IF(D40<0,"VENCIDO",IF(D40<30,"PROXIMO A VENCER",IF(D40<90,"ATENCION","VIGENTE")))) -> Sin fecha registrada
A41: 11 | B41: Tarjeta profesional del prestador | D41: =IF(C41="","",C41-TODAY()) | E41: =IF(C41="","Sin fecha registrada",IF(D41<0,"VENCIDO",IF(D41<30,"PROXIMO A VENCER",IF(D41<90,"ATENCION","VIGENTE")))) -> Sin fecha registrada
A42: 12 | B42: Inscripción Farmacovigilancia / Tecnovigilancia | D42: =IF(C42="","",C42-TODAY()) | E42: =IF(C42="","Sin fecha registrada",IF(D42<0,"VENCIDO",IF(D42<30,"PROXIMO A VENCER",IF(D42<90,"ATENCION","VIGENTE")))) -> Sin fecha registrada

Sheet Criterios Generales
A1: CRITERIOS GENERALES APLICABLES AL PROFESIONAL INDEPENDIENTE DE SALUD
A2: Resolución 3100 de 2019 | Secciones 11.1.1 a 11.1.7 | Filtrado: Excluye servicios hospitalarios, urgencias, cirugía mayor, UCI, parto y transfusional
A3: PRESTADOR: | I3: FECHA:
A4: LEYENDA: ⚠️ = Crítico | ★ = Criterio explícito para Profesional Independiente en la norma | C = Condicional (cuando aplique según servicios ofertados) | G = General (aplica a todos) | Fila GRIS = No aplica a independiente (excluido del instrumento)
A5: ⚠️ Los criterios marcados son CRÍTICOS. Su incumplimiento puede generar requerimiento o cierre del servicio. Los criterios en fondo amarillo son de marcación crítica directa en la Resolución 3100/2019.
A6: N° | B6: N° REF | C6: ESTÁNDAR | D6: CRITERIO — SOLO APLICABLE A PROFESIONAL INDEPENDIENTE | E6: MODO VERIFICACIÓN | F6: ⚠️ | G6: C | H6: NC | I6: NA | J6: HALLAZGO / EVIDENCIA | K6: PLAN DE MEJORA | L6: RESPONSABLE | M6: FECHA COMPROMISO
A7: ESTÁNDAR DE TALENTO HUMANO — Sección 11.1.1 | Todas las modalidades
A8: 1 | B8: 1 | C8: TALENTO HUMANO | D8: El talento humano en salud y otros profesionales que se relacionan con la atención cuentan con los títulos de educación superior o certificados de aptitud ocupacional expedidos por la entidad educativa competente. En el caso de títulos obtenidos en el extranjero: copia de la resolución de convalidación expedida por el MEN | E8: Inspección Documental | F8: ⚠️ | G8: X
A9: 2 | B9: 2 | C9: TALENTO HUMANO | D9: El talento humano en salud cuenta con copia de la resolución de autorización del ejercicio expedida por la autoridad competente o inscripción en el Registro Único Nacional de Talento Humano en Salud — ReTHUS | E9: Inspección Documental | F9: ⚠️
A10: ⊘ EXCLUIDO [3 ⚠️ EXCLUIDO] — CRITERIO NO APLICA PARA PROFESIONAL INDEPENDIENTE: Criterio 3 sobre determinación de cantidad de talento humano requerido — la norma establece explícitamente que no aplica para el profesional independiente
A11: 3 | B11: 4 | C11: TALENTO HUMANO | D11: Cuando el prestador actúe como escenario de práctica formativa cuenta con: convenio vigente con institución educativa autorizada, información documentada de mecanismos de supervisión permanente del personal en entrenamiento y estudio de capacidad instalada que determine el número máximo de estudiantes según los lineamientos del MinSalud | E11: Inspección Documental
A12: 4 | B12: 5 | C12: TALENTO HUMANO | D12: En los servicios donde se atienden pacientes con enfermedades terminales, crónicas, degenerativas e irreversibles con conducta médica de manejo del dolor y cuidado paliativo: el profesional de la medicina tratante cuenta con constancia de formación continua en manejo del dolor y cuidado paliativo, cuando no sea especialista en la materia | E12: Inspección Documental
A13: 5 | B13: 10 | C13: TALENTO HUMANO | D13: El talento humano en salud de los servicios de CE, internación y urgencias cuenta con constancia de formación continua en atención integral en salud de personas víctimas de violencia sexual | E13: Inspección Documental
A14: 6 | B14: 12 | C14: TALENTO HUMANO | D14: Cuando en un servicio se realicen pruebas en el punto de atención del paciente (POCT): el talento humano que las realice, con excepción del profesional de bacteriología, cuenta con constancia de formación continua en el manejo de estas pruebas | E14: Inspección Documental
A15: 7 | B15: 13 – Sedación | C15: TALENTO HUMANO | D15: Cuando se realicen procedimientos bajo sedación Grado I y II fuera de salas de cirugía: adicional al profesional que realiza el procedimiento, cuenta con: profesional de medicina especialista en anestesiología o profesional de medicina/odontología encargado de administrar el medicamento y monitoreo continuo; todos con constancia de formación en soporte vital básico y sedación (excepto anestesiólogo) | E15: Inspección Documental
A16: 8 | B16: 13 – Sedación III | C16: TALENTO HUMANO | D16: Cuando fuera de salas de cirugía se realicen procedimientos bajo sedación Grado III: profesional de medicina con especialidad médico-quirúrgica responsable de administrar la sedación | E16: Inspección Documental
A17: 9 | B17: 13 – Sedación IV | C17: TALENTO HUMANO | D17: Cuando fuera de salas de cirugía se realicen procedimientos bajo sedación Grado IV: profesional de medicina especialista en anestesiología responsable de administrar la sedación | E17: Inspección Documental
A18: ▸ Modalidad Telemedicina — Prestador Remisor y Prestador de Referencia
A19: 10 | B19: 14 | C19: TALENTO HUMANO – Telemedicina | D19: El talento humano que presta directamente servicios bajo la modalidad de telemedicina cuenta con constancia de formación continua en el manejo de la tecnología utilizada, los procesos y herramientas inherentes a la prestación bajo esta modalidad | E19: Inspección Documental | F19: ⚠️
A20: ESTÁNDAR DE INFRAESTRUCTURA — Sección 11.1.2
A21: ▸ Edificaciones de Uso Mixto — Aplica para profesional independiente en consultorio compartido
A22: 11 | B22: 6 | C22: INFRAESTRUCTURA – Uso Mixto | D22: Cuando en una edificación de uso mixto funcionen varios prestadores de servicios de salud, cada uno cuenta con infraestructura separada y delimitada físicamente. Se pueden compartir salas de espera y unidades sanitarias | E22: Inspección Visual | F22: ⚠️
A23: 12 | B23: 7 | C23: INFRAESTRUCTURA – Uso Mixto | D23: En edificaciones de uso mixto pueden funcionar prestadores que oferten servicios de los grupos de consulta externa, apoyo diagnóstico y complementación terapéutica y cirugía ambulatoria | E23: Inspección Visual
A24: 13 | B24: 3 | C24: INFRAESTRUCTURA – Uso Exclusivo Salud | D24: Cuando en una edificación de uso exclusivo de salud funcionen varios prestadores con CE y apoyo diagnóstico, cada prestador cuenta con infraestructura separada y delimitada físicamente. Pueden compartir: aseo, salas de espera y unidades sanitarias | E24: Inspección Visual
A25: ▸ Accesibilidad — Aplica para todos
A26: 14 | B26: 8 | C26: INFRAESTRUCTURA – Accesibilidad | D26: Prestadores ubicados en edificaciones hasta 3 pisos que funcionen en 2° o 3° nivel cuentan con ascensor, rampa o sistema alternativo de elevación (el sistema alternativo no aplica para servicios hospitalarios, cirugía, urgencias, parto — estos no aplican a profesional independiente) | E26: Inspección Visual | F26: ⚠️
A27: 15 | B27: 9.1 a 9.4 | C27: INFRAESTRUCTURA – Accesibilidad | D27: Sistemas alternativos de elevación: su ubicación no interfiere con la evacuación, disponibles para acceso y evacuación, manejo autónomo y garantizan seguridad durante su uso | E27: Inspección Visual
A28: 16 | B28: 10 | C28: INFRAESTRUCTURA – Accesibilidad | D28: Las edificaciones con más de 3 pisos cuentan con ascensor | E28: Inspección Visual | F28: ⚠️
A29: 17 | B29: 12 | C29: INFRAESTRUCTURA – Accesibilidad | D29: Si se tienen escaleras o rampas: piso uniforme, antideslizante, pasamanos a uno o ambos lados y protecciones laterales hacia espacios libres | E29: Inspección Visual
A30: ▸ Servicios Básicos y Concepto Sanitario
A31: 18 | B31: 13 | C31: INFRAESTRUCTURA – Servicios Básicos | D31: Las edificaciones donde se presten servicios de salud cuentan con suministro de agua, energía eléctrica, conexión a la red de alcantarillado y sistemas de comunicaciones | E31: Inspección Visual | F31: ⚠️
A32: 19 | B32: 15 | C32: INFRAESTRUCTURA – Servicios Básicos | D32: Cuando se utilicen equipos generadores de radiaciones ionizantes: licencia de práctica médica vigente expedida por la entidad competente | E32: Inspección Documental | F32: ⚠️
A33: ⊘ NO APLICA PARA PROFESIONAL INDEPENDIENTE — [16] Fuentes radioactivas: aplica exclusivamente a medicina nuclear e imágenes diagnósticas con isótopos. No es aplicable al perfil de profesional independiente en CE y apoyo diagnóstico.
A34: 21 | B34: 17 | C34: INFRAESTRUCTURA – Servicios Básicos | D34: Concepto sanitario vigente que dé cumplimiento a la normatividad sanitaria: agua para consumo humano, gestión de residuos, control de vectores, orden y aseo, condiciones locativas, entre otros | E34: Inspección Documental | F34: ⚠️
A35: ▸ Generalidades de Ambientes y Áreas — Aplica para profesional independiente
A36: 22 | B36: 18 | C36: INFRAESTRUCTURA – Generalidades | D36: Las áreas y ambientes de todos los servicios cuentan con ventilación e iluminación natural o artificial | E36: Inspección Visual | F36: ⚠️
A37: 23 | B37: 19 | C37: INFRAESTRUCTURA – Generalidades | D37: Las áreas de circulación están libres de obstáculos que permitan la movilización de pacientes, talento humano, usuarios y equipos biomédicos | E37: Inspección Visual | F37: ⚠️
A38: 24 | B38: 20 | C38: INFRAESTRUCTURA – Generalidades | D38: Los ambientes y áreas permiten la instalación y movilización de equipos biomédicos y personal para la atención del paciente en condiciones de rutina o emergencia | E38: Inspección Visual
A39: 25 | B39: 22 | C39: INFRAESTRUCTURA – Generalidades | D39: Cada piso o nivel cuenta con señalización y planos indicativos de rutas de evacuación, salidas de emergencia y puntos de encuentro, visibles al público | E39: Inspección Visual | F39: ⚠️
A40: 26 | B40: 24 | C40: INFRAESTRUCTURA – Generalidades | D40: Cuando se realicen procedimientos bajo sedación fuera de salas de cirugía: disponibilidad de área o ambiente para recuperación del paciente garantizando privacidad del usuario | E40: Inspección Visual
...

Sheet Auditoría Documental
A1: AUDITORÍA DE PROCESOS DOCUMENTALES — HABILITACIÓN EN SALUD
A2: Resolución 3100 de 2019 | Profesionales Independientes
A3: PRESTADOR:
A4: FECHA: | C4: AUDITOR: | F4: HORA INICIO: | I4: HORA FINAL:
A5: ⚠️ Los criterios marcados con este símbolo son de carácter CRÍTICO. Su incumplimiento puede generar requerimiento o cierre del servicio.
A7: N° | B7: ESTÁNDAR | C7: CRITERIO | D7: MODO DE VERIFICACIÓN | E7: ⚠️ | F7: C | G7: NC | H7: NA | I7: HALLAZGO / EVIDENCIA | J7: PLAN DE MEJORA | K7: RESPONSABLE | L7: FECHA COMPROMISO
A8: 1 | B8: TALENTO HUMANO | C8: Programa de capacitación al personal: i) análisis de necesidades, ii) planificación, iii) contenidos, iv) duración, v) formadores, vi) ejecución, evaluación y seguimiento | D8: Inspección Documental | E8: ⚠️
A9: 2 | B9: TALENTO HUMANO | C9: Cronograma del programa de capacitación | D9: Inspección Documental
A10: 3 | B10: TALENTO HUMANO | C10: Soportes de ejecución del programa de capacitación (listas de asistencia, certificados) | D10: Inspección Documental
A11: 4 | B11: TALENTO HUMANO | C11: Listado de documentos para hoja de vida del personal | D11: Inspección Documental
A12: 5 | B12: INFRAESTRUCTURA | C12: Licencia de construcción | D12: Inspección Documental | E12: ⚠️
A13: 6 | B13: INFRAESTRUCTURA | C13: Uso de suelos | D13: Inspección Documental | E13: ⚠️
A14: 7 | B14: INFRAESTRUCTURA | C14: Certificado de Bomberos | D14: Inspección Documental | E14: ⚠️
A15: 8 | B15: INFRAESTRUCTURA | C15: Certificado RETIE / Ingeniero eléctrico | D15: Inspección Documental | E15: ⚠️
A16: 9 | B16: INFRAESTRUCTURA | C16: Acta de visita de salud pública (concepto sanitario) | D16: Inspección Documental | E16: ⚠️
A17: 10 | B17: INFRAESTRUCTURA | C17: Programa de mantenimiento de infraestructura y equipos fijos | D17: Inspección Documental
A18: 11 | B18: INFRAESTRUCTURA | C18: Protocolo de lavado de tanques y caracterización del agua | D18: Inspección Documental
A19: 12 | B19: INFRAESTRUCTURA | C19: Protocolo de fumigación | D19: Inspección Documental
A20: 13 | B20: INFRAESTRUCTURA | C20: Plan hospitalario de emergencia | D20: Inspección Documental
A21: 14 | B21: INFRAESTRUCTURA | C21: Plan de gestión integral de residuos hospitalarios y RH1 | D21: Inspección Documental | E21: ⚠️
A22: 15 | B22: INFRAESTRUCTURA | C22: Formato RH1 | D22: Inspección Documental
A23: 16 | B23: INFRAESTRUCTURA | C23: Planillas de limpieza y desinfección | D23: Inspección Documental
A24: 17 | B24: INFRAESTRUCTURA | C24: Ruta de evacuación por piso (señalizada y visible) | D24: Inspección Documental y Visual
A25: 18 | B25: INFRAESTRUCTURA | C25: Ruta sanitaria de residuos | D25: Inspección Documental y Visual
A26: 19 | B26: DOTACIÓN | C26: Relación de equipos biomédicos: nombre, marca, modelo, serie, registro sanitario, clasificación del riesgo | D26: Inspección Documental
A27: 20 | B27: DOTACIÓN | C27: Formato hoja de vida de equipos biomédicos | D27: Inspección Documental
A28: 21 | B28: DOTACIÓN | C28: Formato cronograma de mantenimientos de los equipos biomédicos | D28: Inspección Documental
A29: 22 | B29: DOTACIÓN | C29: Registro de mantenimientos de equipos biomédicos (preventivo, correctivo, calibraciones) | D29: Inspección Documental
A30: 23 | B30: DOTACIÓN | C30: Programa de mantenimiento preventivo de equipos biomédicos, incluye recomendaciones del fabricante | D30: Inspección Documental
A31: 24 | B31: DOTACIÓN | C31: Capacitaciones en equipos biomédicos (cuando se requieran), incluidas dentro del programa de capacitaciones | D31: Inspección Documental
A32: 25 | B32: DOTACIÓN | C32: Registro de suficiencia de equipos biomédicos | D32: Inspección Documental
A33: 26 | B33: DOTACIÓN | C33: Hoja de vida del responsable de mantenimiento de equipos con soportes y/o contrato | D33: Inspección Documental
... A37: 30 | B37: INSUMOS | C37: Relación de reactivos: nombre, marca, presentación comercial, registro sanitario, clasificación del riesgo, vida útil, fecha de vencimiento, lote | D37: Inspección Documental
A38: 31 | B38: INSUMOS | C38: Información documentada: selección, adquisición, transporte, recepción, almacenamiento, conservación, control de fechas de vencimiento, cadena de frío, distribución, dispensación, devolución, disposición final | D38: Inspección Documental | E38: ⚠️
A39: 32 | B39: INSUMOS | C39: Medicamentos de control: resolución de autorización vigente expedida por el Fondo Nacional de Estupefacientes (cuando aplique) | D39: Inspección Documental | E39: ⚠️
A40: 33 | B40: INSUMOS | C40: Programa de Farmacovigilancia: inscripción y reportes mensuales | D40: Inspección Documental
A41: 34 | B41: INSUMOS | C41: Programa de Tecnovigilancia: inscripción y reportes trimestrales | D41: Inspección Documental
A42: 35 | B42: INSUMOS | C42: Programa de Reactivovigilancia: inscripción y reportes trimestrales (cuando aplique) | D42: Inspección Documental
A43: 36 | B43: INSUMOS | C43: Alertas sanitarias y seguimiento a las mismas | D43: Inspección Documental
A44: 37 | B44: INSUMOS | C44: Formato control de temperatura y humedad | D44: Inspección Documental
...

Sheet Auditoría Infraestructura
A1: AUDITORÍA DE INFRAESTRUCTURA — HABILITACIÓN EN SALUD
A2: Resolución 3100 de 2019 | Profesionales Independientes
A3: PRESTADOR:
A4: FECHA: | C4: AUDITOR: | F4: HORA INICIO: | I4: HORA FINAL:
A5: ⚠️ Los criterios marcados con este símbolo son de carácter CRÍTICO. Su incumplimiento puede generar requerimiento o cierre del servicio.
A7: N° | B7: ESTÁNDAR | C7: CRITERIO | D7: MODO DE VERIFICACIÓN | E7: ⚠️ | F7: C | G7: NC | H7: NA | I7: HALLAZGO / EVIDENCIA | J7: PLAN DE MEJORA | K7: RESPONSABLE | L7: FECHA COMPROMISO
A8: 1 | B8: INFRAESTRUCTURA: Edificaciones de uso exclusivo en salud | C8: Los servicios de urgencias, atención del parto, hospitalarios y cirugía con procedimientos quirúrgicos no ambulatorios, solo se prestan en edificaciones de uso exclusivo de salud | D8: Inspección Visual | E8: ⚠️
A9: 2 | B9: INFRAESTRUCTURA: Edificaciones de uso exclusivo en salud | C9: Servicios de urgencias, cirugía e internación y donde se realice esterilización, cuentan con ambiente de aseo de uso exclusivo | D9: Inspección Visual
A10: 3 | B10: INFRAESTRUCTURA: Edificaciones de uso exclusivo en salud | C10: Cuando funcionen más de un prestador con servicios de consulta externa y apoyo diagnóstico, cada prestador tiene infraestructura separada y delimitada. Pueden compartir: aseo, salas de espera y unidades sanitarias | D10: Inspección Visual
A11: 4 | B11: INFRAESTRUCTURA: Edificaciones de uso exclusivo en salud | C11: Edificaciones donde se presten servicios de urgencias e internación cuentan con tanque de almacenamiento de agua (mínimo 24 horas, 600 lt por cama/camilla/día) | D11: Inspección Visual
A12: 5 | B12: INFRAESTRUCTURA: Edificaciones de uso mixto | C12: Cuando en edificación de uso mixto funcionen varios prestadores, cada uno cuenta con infraestructura separada y delimitada. Pueden compartir salas de espera y unidades sanitarias | D12: Inspección Visual
A13: 6 | B13: INFRAESTRUCTURA: Edificaciones de uso mixto | C13: En edificaciones de uso mixto pueden funcionar prestadores de consulta externa, apoyo diagnóstico y cirugía ambulatoria | D13: Inspección Visual
A14: 7 | B14: INFRAESTRUCTURA: Accesibilidad | C14: Edificaciones hasta 3 pisos con servicios en 2° o 3° nivel cuentan con ascensor, rampa o sistema alternativo de elevación (no aplica para hospitalizaci, cirugía, urgencias, parto) | D14: Inspección Visual | E14: ⚠️
A15: 8 | B15: INFRAESTRUCTURA: Accesibilidad | C15: Si hay escaleras o rampas: piso uniforme, antideslizante, pasamanos a uno o ambos lados y protecciones laterales hacia espacios libres | D15: Inspección Visual
A16: 9 | B16: INFRAESTRUCTURA: Accesibilidad | C16: Edificaciones con más de 3 pisos cuentan con ascensor | D16: Inspección Visual
A17: 10 | B17: INFRAESTRUCTURA: Servicios básicos | C17: Las edificaciones donde se presten servicios de salud cuentan con suministro de agua, energía eléctrica, conexión a la red de alcantarillado y sistemas de comunicaciones | D17: Inspección Visual | E17: ⚠️
A18: 11 | B18: INFRAESTRUCTURA: Servicios básicos | C18: Servicios de cirugía, parto, laboratorio clínico, urgencias, gestión pre-transfusional, diálisis, hospitalarios, imágenes diagnósticas, vacunación, farmacéutico y cadena de frío, cuentan con planta eléctrica | D18: Inspección Visual
A19: 12 | B19: INFRAESTRUCTURA: Servicios básicos | C19: Cada prestador cuenta con concepto sanitario vigente (agua, residuos, vectores, orden y aseo, condiciones locativas) | D19: Inspección Documental | E19: ⚠️
A20: 13 | B20: INFRAESTRUCTURA: Servicios básicos | C20: Prestador que use equipos generadores de radiaciones ionizantes cuenta con licencia de práctica médica vigente (entidad competente) | D20: Inspección Documental | E20: ⚠️
A21: 14 | B21: INFRAESTRUCTURA: Servicios básicos | C21: Prestador que use fuentes radioactivas cuenta con autorización vigente de empleo de material radiactivo | D21: Inspección Documental | E21: ⚠️
A22: 15 | B22: INFRAESTRUCTURA: Gestión ambiental | C22: Protocolo de lavado de tanques y caracterización del agua | D22: Inspección Documental
A23: 16 | B23: INFRAESTRUCTURA: Gestión ambiental | C23: Protocolo de fumigación | D23: Inspección Documental
A24: 17 | B24: INFRAESTRUCTURA: Gestión ambiental | C24: Plan hospitalario de emergencia | D24: Inspección Documental
A25: 18 | B25: INFRAESTRUCTURA: Gestión ambiental | C25: Plan de gestión integral de residuos hospitalarios y RH1 (15 puntos o 7 según aplique) | D25: Inspección Documental | E25: ⚠️
A26: 19 | B26: INFRAESTRUCTURA: Gestión ambiental | C26: Formato RH1 | D26: Inspección Documental
A27: 20 | B27: INFRAESTRUCTURA: Gestión ambiental | C27: Planillas de limpieza y desinfección | D27: Inspección Documental
A28: 21 | B28: INFRAESTRUCTURA: Gestión ambiental | C28: Ruta sanitaria de residuos | D28: Inspección Documental y Visual
A29: 22 | B29: INFRAESTRUCTURA: Generalidades de ambientes y áreas | C29: Las áreas y ambientes de todos los servicios cuentan con ventilación e iluminación natural o artificial | D29: Inspección Visual | E29: ⚠️
A30: 23 | B30: INFRAESTRUCTURA: Generalidades de ambientes y áreas | C30: Las áreas de circulación están libres de obstáculos para movilización de pacientes, talento humano, usuarios y equipos | D30: Inspección Visual | E30: ⚠️
A31: 24 | B31: INFRAESTRUCTURA: Generalidades de ambientes y áreas | C31: Los ambientes permiten la instalación y movilización de equipos biomédicos y personal para atención en condiciones de rutina o emergencia | D31: Inspección Visual
A32: 25 | B32: INFRAESTRUCTURA: Generalidades de ambientes y áreas | C32: Cada piso cuenta con señalización y planos de rutas de evacuación, salidas de emergencia y puntos de encuentro, visibles al público | D32: Inspección Visual | E32: ⚠️
A33: 26 | B33: INFRAESTRUCTURA: Generalidades de ambientes y áreas | C33: Si se realizan procedimientos bajo sedación fuera de salas de cirugía: disponibilidad de área o ambiente para recuperación de pacientes garantizando privacidad | D33: Inspección Visual
A34: 27 | B34: INFRAESTRUCTURA: Características de ambientes | C34: Consultorio donde se realiza examen físico: mínimo 10 m² (sin incluir unidad sanitaria) con área de entrevista, área de examen y lavamanos | D34: Inspección Visual | E34: ⚠️
A35: 28 | B35: INFRAESTRUCTURA: Características de ambientes | C35: Áreas de entrevista y examen separadas por barrera física fija o móvil (excepto urgencias, optometría y oftalmología) | D35: Inspección Visual | E35: ⚠️
A36: 29 | B36: INFRAESTRUCTURA: Características de ambientes | C36: Consultorio donde se realizan procedimientos: mínimo 10 m², área de entrevista, área de procedimientos separadas por barrera fija, mesón de trabajo, poceta y lavamanos | D36: Inspección Visual | E36: ⚠️
A37: 30 | B37: INFRAESTRUCTURA: Características de ambientes | C37: Consultorio de entrevista (sin examen físico ni procedimientos): mínimo 4 m² con lavamanos | D37: Inspección Visual
A38: 31 | B38: INFRAESTRUCTURA: Características de ambientes | C38: Consultorio odontológico con una unidad: mínimo 10 m² con área de entrevista, área para unidad, lavamanos y mesón con poceta | D38: Inspección Visual
A39: 32 | B39: INFRAESTRUCTURA: Características de ambientes | C39: Sala de procedimientos / curaciones: mínimo 8 m², mesón de trabajo, poceta (cuando requiera) y lavamanos | D39: Inspección Visual
A40: 33 | B40: INFRAESTRUCTURA: Características de ambientes | C40: Sistema de alarma cuando cuente con red de distribución de gases medicinales | D40: Inspección Visual
A41: 34 | B41: INFRAESTRUCTURA: Características de ambientes | C41: Sala de espera: área variable, independiente de circulación, con ventilación e iluminación natural/artificial; disponibilidad de unidades sanitarias por sexo | D41: Inspección Visual
...

Sheet Consulta Externa
A1: AUDITORÍA — SERVICIO DE CONSULTA EXTERNA | General y Especializada
A2: Resolución 3100 de 2019 | Criterios por Estándar, Complejidad y Modalidad de Prestación
A3: PRESTADOR:
A4: FECHA: | D4: AUDITOR: | H4: HORA INICIO: | K4: HORA FINAL:
A5: ⚠️ Los criterios marcados con este símbolo son CRÍTICOS según la Resolución 3100/2019. Su incumplimiento puede generar requerimiento o cierre del servicio.
A6: LEYENDA: C = Cumple · NC = No Cumple · NA = No Aplica | Marque X en la columna correspondiente. La fila cambia de color automáticamente.
A7: N° | B7: ESTÁNDAR | C7: CRITERIO | D7: MODO DE VERIFICACIÓN | E7: ⚠️ | F7: C | G7: NC | H7: NA | I7: HALLAZGO / EVIDENCIA | J7: PLAN DE MEJORA | K7: RESPONSABLE | L7: FECHA COMPROMISO
A8: 11.2.1 SERVICIO DE CONSULTA EXTERNA GENERAL | Complejidad: Baja | Resolución 3100 de 2019, Pág. 80-93
A9: ESTÁNDAR DE TALENTO HUMANO
A10: ▸ Modalidades: Intramural · Extramural Unidad Móvil · Jornada de Salud · Domiciliaria
A11: 1 | B11: TALENTO HUMANO | C11: Profesional de la salud de acuerdo con el servicio a ofertar (medicina, enfermería, nutrición, psicología, optometría u otra especialidad) | D11: Inspección Documental | E11: ⚠️
A12: 2 | B12: TALENTO HUMANO | C12: Tarjeta profesional vigente del profesional independiente (criterio crítico de habilitación) | D12: Inspección Documental | E12: ⚠️
A13: 3 | B13: TALENTO HUMANO | C13: Resolución de autorización del servicio cuando aplique según normatividad | D13: Inspección Documental | E13: ⚠️
A14: 4 | B14: TALENTO HUMANO | C14: Constancia de formación continua en las actividades relacionadas con el servicio ofertado | D14: Inspección Documental
A15: 5 | B15: TALENTO HUMANO | C15: ERA – Disponibilidad de: Profesional de medicina | D15: Inspección Documental
A16: 6 | B16: TALENTO HUMANO | C16: ERA – Disponibilidad de: Profesional de enfermería o terapia respiratoria o fisioterapia | D16: Inspección Documental
A17: ▸ Modalidad Telemedicina – Categoría Interactiva y No Interactiva (Prestador de Referencia)
A18: 7 | B18: TALENTO HUMANO – Telemedicina Interactiva/No Interactiva | C18: Profesional de la salud de acuerdo con el servicio a ofertar (criterios aplicables de todos los servicios) | D18: Inspección Documental | E18: ⚠️
A19: ▸ Modalidad Telemedicina – Categoría Telexperticia (Prestador Remisor)
A20: 8 | B20: TALENTO HUMANO – Telexperticia Remisor | C20: Cuando se realice telexperticia entre profesionales: profesional de la salud de acuerdo con el servicio a ofertar | D20: Inspección Documental
A21: 9 | B21: TALENTO HUMANO – Telexperticia Remisor | C21: Cuando se realice telexperticia entre personal no profesional y profesional: técnico, tecnólogo o auxiliar que atiende presencialmente al usuario | D21: Inspección Documental
A22: ▸ Modalidad Telemedicina – Categoría Telexperticia (Prestador de Referencia)
A23: 10 | B23: TALENTO HUMANO – Telexperticia Referencia | C23: Profesional de la salud que atiende a distancia, de acuerdo con el servicio a ofertar | D23: Inspección Documental
A24: ▸ Modalidad Telemedicina – Categoría Telemonitoreo (Prestador de Referencia)
A25: 11 | B25: TALENTO HUMANO – Telemonitoreo Referencia | C25: Personal de salud profesional requerido para realizar el telemonitoreo según lo documentado en el estándar de procesos prioritarios | D25: Inspección Documental
A26: ESTÁNDAR DE INFRAESTRUCTURA
A27: ▸ Modalidades: Intramural · Extramural Unidad Móvil · Jornada de Salud · Domiciliaria
A28: 12 | B28: INFRAESTRUCTURA | C28: Cumple con los criterios que le sean aplicables de todos los servicios (criterios generales de infraestructura Res. 3100/2019) | D28: Inspección Visual y Documental
A29: 13 | B29: INFRAESTRUCTURA | C29: Consultorio donde se realiza examen físico: mínimo 10 m² (sin unidad sanitaria), con área de entrevista, área de examen y lavamanos | D29: Inspección Visual | E29: ⚠️
A30: 14 | B30: INFRAESTRUCTURA | C30: Áreas de entrevista y examen separadas por barrera física fija o móvil (excepto CE urgencias, optometría y oftalmología) | D30: Inspección Visual | E30: ⚠️
A31: 15 | B31: INFRAESTRUCTURA | C31: Consultorio donde se realizan procedimientos: mínimo 10 m², área de entrevista, área de procedimientos separadas por barrera fija, mesón de trabajo, poceta (cuando la requiera) y lavamanos | D31: Inspección Visual | E31: ⚠️
A32: 16 | B32: INFRAESTRUCTURA | C32: Ambiente de entrevista donde no se realiza examen físico ni procedimientos: mínimo 4 m² con lavamanos | D32: Inspección Visual
A33: 17 | B33: INFRAESTRUCTURA | C33: Consultorio odontológico con una unidad odontológica: mínimo 10 m², área entrevista, área para unidad, lavamanos, mesón de trabajo con poceta | D33: Inspección Visual
A34: 18 | B34: INFRAESTRUCTURA | C34: Sala de procedimientos cuando se requiera (ver criterio 30 generalidades) | D34: Inspección Visual
A35: 19 | B35: INFRAESTRUCTURA | C35: Disponibilidad de sala de espera (área variable, independiente de circulación, ventilación e iluminación natural/artificial) | D35: Inspección Visual
A36: 20 | B36: INFRAESTRUCTURA | C36: Hasta 2 consultorios: mínimo 1 unidad sanitaria de uso mixto apta para personas con movilidad reducida | D36: Inspección Visual
A37: 21 | B37: INFRAESTRUCTURA | C37: Más de 2 consultorios: mínimo 1 unidad sanitaria discriminada por sexo apta para personas con movilidad reducida o batería sanitaria discriminada por sexo | D37: Inspección Visual
A38: 22 | B38: INFRAESTRUCTURA | C38: ERA – El ambiente cuenta con: lavamanos, mesón de trabajo, poceta (cuando la requiera según procedimientos documentados), barrera física móvil o fija para separación entre sillas | D38: Inspección Visual
A39: 23 | B39: INFRAESTRUCTURA | C39: Cuando se realicen terapias/intervenciones grupales para consumo de sustancias psicoactivas o alteraciones en salud mental: ambiente con dimensión variable | D39: Inspección Visual
A40: 24 | B40: INFRAESTRUCTURA | C40: Cuando se realicen actividades grupales de educación para la salud: disponibilidad de ambiente con dimensión variable | D40: Inspección Visual
...

Sheet Terapias
A1: AUDITORÍA — SERVICIO DE TERAPIAS (Física, Ocupacional, Lenguaje, Respiratoria)
A2: Resolución 3100 de 2019 | Criterios Específicos del Servicio
A3: PRESTADOR:
A4: FECHA: | C4: AUDITOR: | F4: HORA INICIO: | I4: HORA FINAL:
A5: ⚠️ Los criterios marcados con este símbolo son de carácter CRÍTICO. Su incumplimiento puede generar requerimiento o cierre del servicio.
A7: N° | B7: ESTÁNDAR | C7: CRITERIO | D7: MODO DE VERIFICACIÓN | E7: ⚠️ | F7: C | G7: NC | H7: NA | I7: HALLAZGO / EVIDENCIA | J7: PLAN DE MEJORA | K7: RESPONSABLE | L7: FECHA COMPROMISO
A8: 1 | B8: TALENTO HUMANO | C8: Profesional de la salud con título según programas autorizados por el MEN en el ámbito de la rehabilitación (fisioterapia, fonoaudiología, terapia ocupacional, terapia respiratoria) | D8: Inspección Documental | E8: ⚠️
A9: 2 | B9: TALENTO HUMANO | C9: Tarjeta profesional vigente | D9: Inspección Documental | E9: ⚠️
A10: 3 | B10: TALENTO HUMANO | C10: Si oferta integración neurosensorial: constancia de formación continua | D10: Inspección Documental
A11: 4 | B11: INFRAESTRUCTURA | C11: Área para camillas, sillas de ruedas y aditamentos ortopédicos (cuando se requiera) | D11: Inspección Visual
A12: 5 | B12: INFRAESTRUCTURA | C12: Vestidor de pacientes con área para casilleros y unidad sanitaria de uso mixto (cuando el tipo de terapia lo requiera) | D12: Inspección Visual
A13: 6 | B13: INFRAESTRUCTURA | C13: Ambiente para realizar entrevista (cuando se requiera según procesos prioritarios) | D13: Inspección Visual
A14: 7 | B14: INFRAESTRUCTURA | C14: Área para atención individual con barrera física fija o móvil (cuando se requiera privacidad) | D14: Inspección Visual
A15: 8 | B15: INFRAESTRUCTURA | C15: Área de depósito para almacenamiento de insumos, equipos biomédicos y materiales | D15: Inspección Visual
A16: 9 | B16: INFRAESTRUCTURA | C16: Área con equipamiento para actividades de terapia ocupacional (cuando se requiera) | D16: Inspección Visual
A17: 10 | B17: INFRAESTRUCTURA | C17: Área húmeda o hidroterapia (si se oferta): pisos antideslizantes y tomas eléctricas con protección para ambientes húmedos | D17: Inspección Visual
A18: 11 | B18: INFRAESTRUCTURA | C18: Para fonoaudiología o terapia ocupacional: área para sillas y mesas de trabajo individual o grupal | D18: Inspección Visual
A19: 12 | B19: INFRAESTRUCTURA | C19: Cabina sono-amortiguada o equipo de audiometría (según procedimientos ofertados en fonoaudiología) | D19: Inspección Visual
